<mujoco model="null_mobile_base">
    <actuator>
		<!-- Physical limits of the actuator. -->
		<velocity ctrllimited="true" ctrlrange="-1.00 1.00" joint="joint_mobile_forward" kv="1000" name="actuator_mobile_forward" forcelimited="true" forcerange="-600 600"/>
		<velocity ctrllimited="true" ctrlrange="-1.00 1.00" joint="joint_mobile_side" kv="1000" name="actuator_mobile_side" forcelimited="true" forcerange="-600 600"/>
		<velocity ctrllimited="true" ctrlrange="-1.50 1.50" joint="joint_mobile_yaw" kv="1000" name="actuator_mobile_yaw" forcelimited="true" forcerange="-600 600"/>
	</actuator>
    <worldbody>
        <body name="support" pos="0 0 0">
            <!-- <joint name="base_joint_z" pos="0 0 0" axis="0 0 1" type="slide" limited="true" range="0 0.34" damping="0.01" armature="0.0" frictionloss="1000" ref="0"/> -->

            <site name="center" type="sphere" pos="0 0 0" size="0.01" group="1" rgba="0 0 0 0"/>

            <joint name="joint_mobile_forward" pos="0 0 0" axis="0 1 0" type="slide" limited="false" damping="0" armature="0.0" frictionloss="250"/>
			<joint name="joint_mobile_side" pos="0 0 0" axis="1 0 0" type="slide" limited="false" damping="0" armature="0.0" frictionloss="250"/>
			<joint name="joint_mobile_yaw" pos="-0.21 0 0" axis="0 0 1" type="hinge" limited="false" damping="0" armature="0.0" frictionloss="250"/>
        </body>
    </worldbody>
</mujoco>
