<mujoco>
	<compiler angle="radian" autolimits="true" />
	<visual>
		<global ellipsoidinertia="true" />
	</visual>
    <asset>

   		<material name="groundplane" texture="groundplane" texuniform="true" texrepeat="5 5" reflectance="0.2" />
    	<texture type="2d" name="groundplane" builtin="checker" mark="edge" rgb1="0.2 0.3 0.4" rgb2="0.1 0.2 0.3" markrgb="0.8 0.8 0.8" width="300" height="300" />
      <material name="Black" rgba="0.0 0.0 0.0 1.0" />
      <material name="Blue" rgba="0.0 0.0 0.8 1.0" />
      <material name="Green" rgba="0.0 0.8 0.0 1.0" />
      <material name="Grey" rgba="0.5 0.5 0.5 1.0" />
      <material name="Light_Grey" rgba="0.8 0.8 0.8 1.0" />
      <material name="Ivory" rgba="1.0 1.0 0.94 1.0" />
      <material name="Orange" rgba="1.0 0.423529411765 0.0392156862745 1.0" />
      <material name="Brown" rgba="0.870588235294 0.811764705882 0.764705882353 1.0" />
      <material name="Red" rgba="0.8 0.0 0.0 1.0" />
      <material name="White" rgba="1.0 1.0 1.0 1.0" />
      <mesh name="body" file="meshes/body.stl" />
      <mesh name="coarse_body" file="meshes/coarse/body.stl" />
      <mesh name="link_1" file="meshes/link_1.stl" />
      <mesh name="coarse_link_1" file="meshes/coarse/link_1.stl" />
      <mesh name="link_2" file="meshes/link_2.stl" />
      <mesh name="coarse_link_2" file="meshes/coarse/link_2.stl" />
      <mesh name="link_3" file="meshes/link_3.stl" />
      <mesh name="coarse_link_3" file="meshes/coarse/link_3.stl" />
      <mesh name="link_4" file="meshes/link_4.stl" />
      <mesh name="coarse_link_4" file="meshes/coarse/link_4.stl" />
      <mesh name="link_5" file="meshes/link_5.stl" />
      <mesh name="coarse_link_5" file="meshes/coarse/link_5.stl" />
      <mesh name="link_6" file="meshes/link_6.stl" />
      <mesh name="coarse_link_6" file="meshes/coarse/link_6.stl" />
      <mesh name="link_7" file="meshes/link_7.stl" />
      <mesh name="coarse_link_7" file="meshes/coarse/link_7.stl" />
      
    </asset>


    <worldbody>
    	<light pos="0 0.1 2.5" />
		<geom name="floor" size="2 2 0.05" type="plane" material="groundplane" pos="0 0 -.75" group="3" />
    <!--Start of base-->
    <body name="base">
    <body name="yumi_body" pos="0.0 0.0 0.0" quat="1.0 0.0 0.0 0.0">
      <inertial pos="0 0 0" quat="1.0 0.0 0.0 0.0" mass="15" diaginertia="0.5 0.6 0.3" />
      <geom pos="0.0 0.0 0.0" quat="1.0 0.0 0.0 0.0" name="yumi_body_visual" group="1" contype="0" conaffinity="0" mesh="body" type="mesh" />
      <geom pos="0.0 0.0 0.0" quat="1.0 0.0 0.0 0.0" name="yumi_body_collision" group="0" mesh="coarse_body" type="mesh" />
    <body name="right_arm" pos="0.0 0.0 0.0" quat="1 0 0 0">
        <!--Start of yumi_link_1_r-->
          <site name="right_center" pos="0 0 0" size="0.01" rgba="1 0.3 0.3 1" group="2"/>
        <body name="yumi_link_1_r" pos="0.05355 -0.0725 0.41492" quat="0.21925457634717457 -0.4077963603936713 0.31428982822327584 -0.8287650228357129">
        <joint name="yumi_joint_1_r" type="hinge" frictionloss="0.1" damping="0.1" stiffness="0.1" axis="0 0 1" range="-2.94087978961 2.94087978961" />
      <inertial pos="0 -0.03 0.12" quat="1.0 0.0 0.0 0.0" mass="2" diaginertia="0.1 0.1 0.1" />
      <geom pos="0.0 0.0 0.0" quat="1.0 0.0 0.0 0.0" name="yumi_link_1_r_visual" group="1" contype="0" conaffinity="0" mesh="link_1" type="mesh" />
      <geom pos="0.0 0.0 0.0" quat="1.0 0.0 0.0 0.0" name="yumi_link_1_r_collision" group="0" mesh="coarse_link_1" type="mesh" />
          <!--Start of yumi_link_2_r-->
          <body name="yumi_link_2_r" pos="0.03 0.0 0.1" quat="0.7071067811882787 0.7071067811848163 0.0 0.0">
          <joint name="yumi_joint_2_r" type="hinge" frictionloss="0.1" damping="0.1" stiffness="0.1" axis="0 0 1" range="-2.50454747661 0.759218224618" />
      <inertial pos="0 0 0" quat="1.0 0.0 0.0 0.0" mass="2" diaginertia="0.1 0.1 0.1" />
      <geom pos="0.0 0.0 0.0" quat="1.0 0.0 0.0 0.0" name="yumi_link_2_r_visual" group="1" contype="0" conaffinity="0" mesh="link_2" type="mesh" />
      <geom pos="0.0 0.0 0.0" quat="1.0 0.0 0.0 0.0" name="yumi_link_2_r_collision" group="0" mesh="coarse_link_2" type="mesh" />
            <!--Start of yumi_link_3_r-->
            <body name="yumi_link_3_r" pos="-0.03 0.17283 0.0" quat="0.7071067811882787 -0.7071067811848163 0.0 0.0">
            <joint name="yumi_joint_7_r" type="hinge" frictionloss="0.1" damping="0.1" stiffness="0.1" axis="0 0 1" range="-2.94087978961 2.94087978961" />
      <inertial pos="0 0 0" quat="1.0 0.0 0.0 0.0" mass="2" diaginertia="0.1 0.1 0.1" />
      <geom pos="0.0 0.0 0.0" quat="1.0 0.0 0.0 0.0" name="yumi_link_3_r_visual" group="1" contype="0" conaffinity="0" mesh="link_3" type="mesh" />
      <geom pos="0.0 0.0 0.0" quat="1.0 0.0 0.0 0.0" name="yumi_link_3_r_collision" group="0" mesh="coarse_link_3" type="mesh" />
              <!--Start of yumi_link_4_r-->
              <body name="yumi_link_4_r" pos="-0.04188 0.0 0.07873" quat="0.5000000000024483 0.5 -0.5 0.4999999999975517">
              <joint name="yumi_joint_3_r" type="hinge" frictionloss="0.1" damping="0.1" stiffness="0.1" axis="0 0 1" range="-2.15548162621 1.3962634016" />
      <inertial pos="0 0 0" quat="1.0 0.0 0.0 0.0" mass="2" diaginertia="0.1 0.1 0.1" />
      <geom pos="0.0 0.0 0.0" quat="1.0 0.0 0.0 0.0" name="yumi_link_4_r_visual" group="1" contype="0" conaffinity="0" mesh="link_4" type="mesh" />
      <geom pos="0.0 0.0 0.0" quat="1.0 0.0 0.0 0.0" name="yumi_link_4_r_collision" group="0" mesh="coarse_link_4" type="mesh" />
                <!--Start of yumi_link_5_r-->
                <body name="yumi_link_5_r" pos="0.0405 0.16461 0.0" quat="0.7071067811882787 -0.7071067811848163 0.0 0.0">
                <joint name="yumi_joint_4_r" type="hinge" frictionloss="0.1" damping="0.1" stiffness="0.1" axis="0 0 1" range="-5.06145483078 5.06145483078" />
      <inertial pos="0 0 0" quat="1.0 0.0 0.0 0.0" mass="2" diaginertia="0.1 0.1 0.1" />
      <geom pos="0.0 0.0 0.0" quat="1.0 0.0 0.0 0.0" name="yumi_link_5_r_visual" group="1" contype="0" conaffinity="0" mesh="link_5" type="mesh" />
      <geom pos="0.0 0.0 0.0" quat="1.0 0.0 0.0 0.0" name="yumi_link_5_r_collision" group="0" mesh="coarse_link_5" type="mesh" />
                  <!--Start of yumi_link_6_r-->
                  <body name="yumi_link_6_r" pos="-0.027 0.0 0.10039" quat="0.7071067811882787 0.7071067811848163 0.0 0.0">
                  <joint name="yumi_joint_5_r" type="hinge" frictionloss="0.1" damping="0.1" stiffness="0.1" axis="0 0 1" range="-1.53588974176 2.40855436775" />
      <inertial pos="0 0 0" quat="1.0 0.0 0.0 0.0" mass="2" diaginertia="0.1 0.1 0.1" />
      <geom pos="0.0 0.0 0.0" quat="1.0 0.0 0.0 0.0" name="yumi_link_6_r_visual" group="1" contype="0" conaffinity="0" mesh="link_6" type="mesh" />
      <geom pos="0.0 0.0 0.0" quat="1.0 0.0 0.0 0.0" name="yumi_link_6_r_collision" group="0" mesh="coarse_link_6" type="mesh" />
                    <!--Start of yumi_link_7_r-->
                    <body name="yumi_link_7_r" pos="0.027 0.029 0.0" quat="0.7071067811882787 -0.7071067811848163 0.0 0.0">
                    <joint name="yumi_joint_6_r" type="hinge" frictionloss="0.1" damping="0.1" stiffness="0.1" axis="0 0 1" range="-3.99680398707 3.99680398707" />
      <inertial pos="0 0 0" quat="1.0 0.0 0.0 0.0" mass="2" diaginertia="0.1 0.1 0.1" />
      <geom pos="0.0 0.0 0.0" quat="1.0 0.0 0.0 0.0" name="yumi_link_7_r_visual" group="1" contype="0" conaffinity="0" mesh="link_7" type="mesh" />
      <geom pos="0.0 0.0 0.0" quat="1.0 0.0 0.0 0.0" name="yumi_link_7_r_collision" group="0" mesh="coarse_link_7" type="mesh" />
      <!--Start of right_hand-->
      <body name="right_hand" pos="0.0 0.0 0.0" quat="1 0 0 0">
        <camera mode="fixed" name="right_eye_in_hand" pos="0.0 0.05 0.03" quat="0 1 0 0" fovy="75"/>
      </body>
      <!--End of right_hand-->
                  </body>
                    <!--End of yumi_link_7_r-->
                </body>
                  <!--End of yumi_link_6_r-->
              </body>
                <!--End of yumi_link_5_r-->
            </body>
              <!--End of yumi_link_4_r-->
          </body>
            <!--End of yumi_link_3_r-->
        </body>
          <!--End of yumi_link_2_r-->
      </body>
        <!--End of yumi_link_1_r-->
      </body><body name="left_arm" pos="0.0 0.0 0.0" quat="1 0 0 0">
        <site name="left_center" pos="0 0 0" size="0.01" rgba="1 0.3 0.3 1" group="2"/>
        <!--Start of yumi_link_1_l-->
        <body name="yumi_link_1_l" pos="0.05355 0.0725 0.41492" quat="0.21763235981918536 0.40848028010665555 0.3134367343687632 0.8291787685847762">
        <joint name="yumi_joint_1_l" type="hinge" frictionloss="0.1" damping="0.1" stiffness="0.1" axis="0 0 1" range="-2.94087978961 2.94087978961" />
      <inertial pos="0 -0.03 0.12" quat="1.0 0.0 0.0 0.0" mass="2" diaginertia="0.1 0.1 0.1" />
      <geom pos="0.0 0.0 0.0" quat="1.0 0.0 0.0 0.0" name="yumi_link_1_l_visual" group="1" contype="0" conaffinity="0" mesh="link_1" type="mesh" />
      <geom pos="0.0 0.0 0.0" quat="1.0 0.0 0.0 0.0" name="yumi_link_1_l_collision" group="0" mesh="coarse_link_1" type="mesh" />
          <!--Start of yumi_link_2_l-->
          <body name="yumi_link_2_l" pos="0.03 0.0 0.1" quat="0.7071067811882787 0.7071067811848163 0.0 0.0">
          <joint name="yumi_joint_2_l" type="hinge" frictionloss="0.1" damping="0.1" stiffness="0.1" axis="0 0 1" range="-2.50454747661 0.759218224618" />
      <inertial pos="0 0 0" quat="1.0 0.0 0.0 0.0" mass="2" diaginertia="0.1 0.1 0.1" />
      <geom pos="0.0 0.0 0.0" quat="1.0 0.0 0.0 0.0" name="yumi_link_2_l_visual" group="1" contype="0" conaffinity="0" mesh="link_2" type="mesh" />
      <geom pos="0.0 0.0 0.0" quat="1.0 0.0 0.0 0.0" name="yumi_link_2_l_collision" group="0" mesh="coarse_link_2" type="mesh" />
            <!--Start of yumi_link_3_l-->
            <body name="yumi_link_3_l" pos="-0.03 0.17283 0.0" quat="0.7071067811882787 -0.7071067811848163 0.0 0.0">
            <joint name="yumi_joint_7_l" type="hinge" frictionloss="0.1" damping="0.1" stiffness="0.1" axis="0 0 1" range="-2.94087978961 2.94087978961" />
      <inertial pos="0 0 0" quat="1.0 0.0 0.0 0.0" mass="2" diaginertia="0.1 0.1 0.1" />
      <geom pos="0.0 0.0 0.0" quat="1.0 0.0 0.0 0.0" name="yumi_link_3_l_visual" group="1" contype="0" conaffinity="0" mesh="link_3" type="mesh" />
      <geom pos="0.0 0.0 0.0" quat="1.0 0.0 0.0 0.0" name="yumi_link_3_l_collision" group="0" mesh="coarse_link_3" type="mesh" />
              <!--Start of yumi_link_4_l-->
              <body name="yumi_link_4_l" pos="-0.04188 0.0 0.07873" quat="0.5000000000024483 0.5 -0.5 0.4999999999975517">
              <joint name="yumi_joint_3_l" type="hinge" frictionloss="0.1" damping="0.1" stiffness="0.1" axis="0 0 1" range="-2.15548162621 1.3962634016" />
      <inertial pos="0 0 0" quat="1.0 0.0 0.0 0.0" mass="2" diaginertia="0.1 0.1 0.1" />
      <geom pos="0.0 0.0 0.0" quat="1.0 0.0 0.0 0.0" name="yumi_link_4_l_visual" group="1" contype="0" conaffinity="0" mesh="link_4" type="mesh" />
      <geom pos="0.0 0.0 0.0" quat="1.0 0.0 0.0 0.0" name="yumi_link_4_l_collision" group="0" mesh="coarse_link_4" type="mesh" />
                <!--Start of yumi_link_5_l-->
                <body name="yumi_link_5_l" pos="0.0405 0.16461 0.0" quat="0.7071067811882787 -0.7071067811848163 0.0 0.0">
                <joint name="yumi_joint_4_l" type="hinge" frictionloss="0.1" damping="0.1" stiffness="0.1" axis="0 0 1" range="-5.06145483078 5.06145483078" />
      <inertial pos="0 0 0" quat="1.0 0.0 0.0 0.0" mass="2" diaginertia="0.1 0.1 0.1" />
      <geom pos="0.0 0.0 0.0" quat="1.0 0.0 0.0 0.0" name="yumi_link_5_l_visual" group="1" contype="0" conaffinity="0" mesh="link_5" type="mesh" />
      <geom pos="0.0 0.0 0.0" quat="1.0 0.0 0.0 0.0" name="yumi_link_5_l_collision" group="0" mesh="coarse_link_5" type="mesh" />
                  <!--Start of yumi_link_6_l-->
                  <body name="yumi_link_6_l" pos="-0.027 0.0 0.10039" quat="0.7071067811882787 0.7071067811848163 0.0 0.0">
                    <joint name="yumi_joint_5_l" type="hinge" frictionloss="0.1" damping="0.1" stiffness="0.1" axis="0 0 1" range="-1.53588974176 2.40855436775" />
      <inertial pos="0 0 0" quat="1.0 0.0 0.0 0.0" mass="2" diaginertia="0.1 0.1 0.1" />
      <geom pos="0.0 0.0 0.0" quat="1.0 0.0 0.0 0.0" name="yumi_link_6_l_visual" group="1" contype="0" conaffinity="0" mesh="link_6" type="mesh" />
      <geom pos="0.0 0.0 0.0" quat="1.0 0.0 0.0 0.0" name="yumi_link_6_l_collision" group="0" mesh="coarse_link_6" type="mesh" />
                    <!--Start of yumi_link_7_l-->
                    <body name="yumi_link_7_l" pos="0.027 0.029 0.0" quat="0.7071067811882787 -0.7071067811848163 0.0 0.0">
                    <joint name="yumi_joint_6_l" type="hinge" frictionloss="0.1" damping="0.1" stiffness="0.1" axis="0 0 1" range="-3.99680398707 3.99680398707" />
      <inertial pos="0 0 0" quat="1.0 0.0 0.0 0.0" mass="2" diaginertia="0.1 0.1 0.1" />
      <geom pos="0.0 0.0 0.0" quat="1.0 0.0 0.0 0.0" name="yumi_link_7_l_visual" group="1" contype="0" conaffinity="0" mesh="link_7" type="mesh" />
      <geom pos="0.0 0.0 0.0" quat="1.0 0.0 0.0 0.0" name="yumi_link_7_l_collision" group="0" mesh="coarse_link_7" type="mesh" />
      <!--Start of left_hand-->
      <body name="left_hand" pos="0.0 0.0 0.0" quat="1 0 0 0">
        <camera mode="fixed" name="left_eye_in_hand" pos="0.0 0.05 0.03" quat="0 1 0 0" fovy="75"/>
    </body>
      <!--End of left_hand-->
                  </body>
                    <!--End of yumi_link_7_l-->
                </body>
                  <!--End of yumi_link_6_l-->
              </body>
                <!--End of yumi_link_5_l-->
            </body>
              <!--End of yumi_link_4_l-->
          </body>
            <!--End of yumi_link_3_l-->
        </body>
          <!--End of yumi_link_2_l-->
      </body>
        <!--End of yumi_link_1_l-->
      </body></body>
  </body>
    <!--End of base-->
  </worldbody>

	<actuator>
      <motor name="yumi_actuator_1_r" joint="yumi_joint_1_r" ctrlrange="-50 50" ctrllimited="true" />
      <motor name="yumi_actuator_2_r" joint="yumi_joint_2_r" ctrlrange="-50 50" ctrllimited="true" />
      <motor name="yumi_actuator_7_r" joint="yumi_joint_7_r" ctrlrange="-50 50" ctrllimited="true" />
      <motor name="yumi_actuator_3_r" joint="yumi_joint_3_r" ctrlrange="-50 50" ctrllimited="true" />
      <motor name="yumi_actuator_4_r" joint="yumi_joint_4_r" ctrlrange="-50 50" ctrllimited="true" />
      <motor name="yumi_actuator_5_r" joint="yumi_joint_5_r" ctrlrange="-50 50" ctrllimited="true" />
      <motor name="yumi_actuator_6_r" joint="yumi_joint_6_r" ctrlrange="-50 50" ctrllimited="true" />
      <motor name="yumi_actuator_1_l" joint="yumi_joint_1_l" ctrlrange="-50 50" ctrllimited="true" />
      <motor name="yumi_actuator_2_l" joint="yumi_joint_2_l" ctrlrange="-50 50" ctrllimited="true" />
      <motor name="yumi_actuator_7_l" joint="yumi_joint_7_l" ctrlrange="-50 50" ctrllimited="true" />
      <motor name="yumi_actuator_3_l" joint="yumi_joint_3_l" ctrlrange="-50 50" ctrllimited="true" />
      <motor name="yumi_actuator_4_l" joint="yumi_joint_4_l" ctrlrange="-50 50" ctrllimited="true" />
      <motor name="yumi_actuator_5_l" joint="yumi_joint_5_l" ctrlrange="-50 50" ctrllimited="true" />
      <motor name="yumi_actuator_6_l" joint="yumi_joint_6_l" ctrlrange="-50 50" ctrllimited="true" />
    </actuator>
</mujoco>