<?xml version='1.0' encoding='utf8'?>
<mujoco model="base">
  <compiler angle="radian" meshdir="meshes/" inertiagrouprange="0 0" autolimits="true" />
  <option impratio="20" cone="elliptic" density="1.2" viscosity="0.00002" timestep="0.002" />
  <size nconmax="5000" njmax="5000" />

  <asset>
  <texture builtin="gradient" height="256" rgb1=".9 .9 1." rgb2=".2 .3 .4" type="skybox" width="256" />
    <texture file="/home/abhiram03/Desktop/robocasa/robosuite-dev/robosuite/models/assets/arenas/../textures/light-gray-floor-tile.png" type="2d" name="texplane" />
    <material name="floorplane" reflectance="0.01" shininess="0.0" specular="0.0" texrepeat="2 2" texture="texplane" texuniform="true" />
    
    <texture file="/home/abhiram03/Desktop/robocasa/robosuite-dev/robosuite/models/assets/arenas/../textures/ceramic.png" type="cube" name="tex-ceramic" />
    <material name="table_ceramic" reflectance="0.0" shininess="0.0" specular="0.2" texrepeat="1 1" texture="tex-ceramic" />
    
    <texture file="/home/abhiram03/Desktop/robocasa/robosuite-dev/robosuite/models/assets/arenas/../textures/steel-brushed.png" type="cube" name="tex-steel-brushed" />
    <material name="table_legs_metal" reflectance="0.8" shininess="0.8" texrepeat="1 1" texture="tex-steel-brushed" />
    
    <texture file="/home/abhiram03/Desktop/robocasa/robosuite-dev/robosuite/models/assets/arenas/../textures/light-gray-plaster.png" type="2d" name="tex-light-gray-plaster" />
    <material name="walls_mat" reflectance="0.0" shininess="0.1" specular="0.1" texrepeat="3 3" texture="tex-light-gray-plaster" texuniform="true" />
    
    <texture name="textable" builtin="flat" height="512" width="512" rgb1="0.5 0.5 0.5" rgb2="0.5 0.5 0.5" />
    <material name="table_mat" texture="textable" />

  <material name="robot0_DarkGrey" specular="0.5" shininess="0.45" rgba="0.1 0.1 0.1 1.0" />
    <material name="robot0_Grey" specular="0.5" shininess="0.45" rgba="0.7 0.7 0.7 1.0" />
    <material name="robot0_LightGrey" specular="0.5" shininess="0.45" rgba="0.7 0.7 0.7 1.0" />
    <material name="robot0_White" specular="0.5" shininess="0.45" rgba="1.0 1.0 1.0 1.0" />
    <material name="robot0_Orange" specular="0.5" shininess="0.45" rgba="1.0 0.35 0.0 1.0" />
    <mesh name="robot0_base" file="/home/abhiram03/Desktop/robocasa/robosuite-dev/robosuite/models/assets/robots/tiago/meshes/base/base.stl" />
    <mesh name="robot0_base_collision" file="/home/abhiram03/Desktop/robocasa/robosuite-dev/robosuite/models/assets/robots/tiago/meshes/base/high_resolution/base_collision.stl" />
    <mesh name="robot0_base_ring" file="/home/abhiram03/Desktop/robocasa/robosuite-dev/robosuite/models/assets/robots/tiago/meshes/base/base_ring.stl" />
    <mesh name="robot0_wheel" file="/home/abhiram03/Desktop/robocasa/robosuite-dev/robosuite/models/assets/robots/tiago/meshes/wheels/wheel.stl" />
    <mesh name="robot0_caster_1" file="/home/abhiram03/Desktop/robocasa/robosuite-dev/robosuite/models/assets/robots/tiago/meshes/wheels/caster_1.stl" />
    <mesh name="robot0_caster_2" file="/home/abhiram03/Desktop/robocasa/robosuite-dev/robosuite/models/assets/robots/tiago/meshes/wheels/caster_2.stl" />
    <mesh name="robot0_torso_fix" file="/home/abhiram03/Desktop/robocasa/robosuite-dev/robosuite/models/assets/robots/tiago/meshes/torso/torso_fix.stl" />
    <mesh name="robot0_torso_lift_dual_arm" file="/home/abhiram03/Desktop/robocasa/robosuite-dev/robosuite/models/assets/robots/tiago/meshes/torso/torso_lift_dual_arm.stl" />
    <mesh name="robot0_torso_lift_collision_core" file="/home/abhiram03/Desktop/robocasa/robosuite-dev/robosuite/models/assets/robots/tiago/meshes/torso/torso_lift_collision_core.stl" />
    <mesh name="robot0_torso_lift_collision_shoulder" file="/home/abhiram03/Desktop/robocasa/robosuite-dev/robosuite/models/assets/robots/tiago/meshes/torso/torso_lift_collision_shoulder.stl" />
    
    <mesh name="robot0_head_1" file="/home/abhiram03/Desktop/robocasa/robosuite-dev/robosuite/models/assets/robots/tiago/meshes/head/head_1.stl" />
    <mesh name="robot0_head_1_collision" file="/home/abhiram03/Desktop/robocasa/robosuite-dev/robosuite/models/assets/robots/tiago/meshes/head/head_1.stl" />
    <mesh name="robot0_head_2" file="/home/abhiram03/Desktop/robocasa/robosuite-dev/robosuite/models/assets/robots/tiago/meshes/head/head_2.stl" />
    <mesh name="robot0_head_2_collision" file="/home/abhiram03/Desktop/robocasa/robosuite-dev/robosuite/models/assets/robots/tiago/meshes/head/head_2.stl" />
    <mesh name="robot0_arm_1" file="/home/abhiram03/Desktop/robocasa/robosuite-dev/robosuite/models/assets/robots/tiago/meshes/arm/arm_1.stl" />
    <mesh name="robot0_arm_1_collision" file="/home/abhiram03/Desktop/robocasa/robosuite-dev/robosuite/models/assets/robots/tiago/meshes/arm/arm_1.stl" />
    <mesh name="robot0_arm_2" file="/home/abhiram03/Desktop/robocasa/robosuite-dev/robosuite/models/assets/robots/tiago/meshes/arm/arm_2.stl" />
    <mesh name="robot0_arm_2_collision" file="/home/abhiram03/Desktop/robocasa/robosuite-dev/robosuite/models/assets/robots/tiago/meshes/arm/arm_2.stl" />
    <mesh name="robot0_arm_3" file="/home/abhiram03/Desktop/robocasa/robosuite-dev/robosuite/models/assets/robots/tiago/meshes/arm/arm_3.stl" />
    <mesh name="robot0_arm_3_collision" file="/home/abhiram03/Desktop/robocasa/robosuite-dev/robosuite/models/assets/robots/tiago/meshes/arm/arm_3.stl" />
    <mesh name="robot0_arm_4" file="/home/abhiram03/Desktop/robocasa/robosuite-dev/robosuite/models/assets/robots/tiago/meshes/arm/arm_4.stl" />
    <mesh name="robot0_arm_4_collision" file="/home/abhiram03/Desktop/robocasa/robosuite-dev/robosuite/models/assets/robots/tiago/meshes/arm/arm_4.stl" />
    <mesh name="robot0_arm_5-wrist-2017" file="/home/abhiram03/Desktop/robocasa/robosuite-dev/robosuite/models/assets/robots/tiago/meshes/arm/arm_5-wrist-2017.stl" />
    <mesh name="robot0_arm_5_collision-wrist-2017" file="/home/abhiram03/Desktop/robocasa/robosuite-dev/robosuite/models/assets/robots/tiago/meshes/arm/arm_5-wrist-2017.stl" />
    <mesh name="robot0_arm_6-wrist-2017" file="/home/abhiram03/Desktop/robocasa/robosuite-dev/robosuite/models/assets/robots/tiago/meshes/arm/arm_6-wrist-2017.stl" />
    <mesh name="robot0_arm_6_collision-wrist-2017" file="/home/abhiram03/Desktop/robocasa/robosuite-dev/robosuite/models/assets/robots/tiago/meshes/arm/arm_6-wrist-2017.stl" />
    <mesh name="robot0_arm_1_left" file="/home/abhiram03/Desktop/robocasa/robosuite-dev/robosuite/models/assets/robots/tiago/meshes/arm/arm_1.stl" scale="1 -1 -1" />
    <mesh name="robot0_arm_1_left_collision" file="/home/abhiram03/Desktop/robocasa/robosuite-dev/robosuite/models/assets/robots/tiago/meshes/arm/arm_1.stl" scale="1 -1 -1" />
    <mesh name="robot0_arm_2_left" file="/home/abhiram03/Desktop/robocasa/robosuite-dev/robosuite/models/assets/robots/tiago/meshes/arm/arm_2.stl" scale="1 1 -1" />
    <mesh name="robot0_arm_2_left_collision" file="/home/abhiram03/Desktop/robocasa/robosuite-dev/robosuite/models/assets/robots/tiago/meshes/arm/arm_2.stl" scale="1 1 -1" />
    <mesh name="robot0_arm_3_left" file="/home/abhiram03/Desktop/robocasa/robosuite-dev/robosuite/models/assets/robots/tiago/meshes/arm/arm_3.stl" scale="1 1 -1" />
    <mesh name="robot0_arm_3_left_collision" file="/home/abhiram03/Desktop/robocasa/robosuite-dev/robosuite/models/assets/robots/tiago/meshes/arm/arm_3.stl" scale="1 1 -1" />
    <mesh name="robot0_arm_4_left" file="/home/abhiram03/Desktop/robocasa/robosuite-dev/robosuite/models/assets/robots/tiago/meshes/arm/arm_4.stl" scale="-1 -1 -1" />
    <mesh name="robot0_arm_4_left_collision" file="/home/abhiram03/Desktop/robocasa/robosuite-dev/robosuite/models/assets/robots/tiago/meshes/arm/arm_4.stl" scale="-1 -1 -1" />
    <mesh name="robot0_arm_5_left-wrist-2017" file="/home/abhiram03/Desktop/robocasa/robosuite-dev/robosuite/models/assets/robots/tiago/meshes/arm/arm_5-wrist-2017.stl" scale="-1 -1 -1" />
    <mesh name="robot0_arm_5_left_collision-wrist-2017" file="/home/abhiram03/Desktop/robocasa/robosuite-dev/robosuite/models/assets/robots/tiago/meshes/arm/arm_5-wrist-2017.stl" scale="-1 -1 -1" />
    <mesh name="robot0_arm_6_left-wrist-2017" file="/home/abhiram03/Desktop/robocasa/robosuite-dev/robosuite/models/assets/robots/tiago/meshes/arm/arm_6-wrist-2017.stl" scale="-1 1 1" />
    <mesh name="robot0_arm_6_left_collision-wrist-2017" file="/home/abhiram03/Desktop/robocasa/robosuite-dev/robosuite/models/assets/robots/tiago/meshes/arm/arm_6-wrist-2017.stl" scale="-1 1 1" />
    <mesh name="robot0_gripper_link" file="/home/abhiram03/Desktop/robocasa/robosuite-dev/robosuite/models/assets/robots/tiago/meshes/grippers/gripper_link.stl" />
    <mesh name="robot0_gripper_link_collision" file="/home/abhiram03/Desktop/robocasa/robosuite-dev/robosuite/models/assets/robots/tiago/meshes/grippers/gripper_link_collision.stl" />
    <mesh name="robot0_gripper_finger_link" file="/home/abhiram03/Desktop/robocasa/robosuite-dev/robosuite/models/assets/robots/tiago/meshes/grippers/gripper_finger_link.stl" />
    <mesh name="robot0_palm" file="/home/abhiram03/Desktop/robocasa/robosuite-dev/robosuite/models/assets/robots/tiago/meshes/grippers/palm.stl" />
    <mesh name="robot0_palm_collision" file="/home/abhiram03/Desktop/robocasa/robosuite-dev/robosuite/models/assets/robots/tiago/meshes/grippers/palm_collision.stl" />
    <mesh name="robot0_thumb_abd_collision" file="/home/abhiram03/Desktop/robocasa/robosuite-dev/robosuite/models/assets/robots/tiago/meshes/grippers/thumb_abd_collision.stl" />
    <mesh name="robot0_finger_flex_collision" file="/home/abhiram03/Desktop/robocasa/robosuite-dev/robosuite/models/assets/robots/tiago/meshes/grippers/finger_flex_collision.stl" />
    <mesh name="robot0_finger_flex_tip_collision" file="/home/abhiram03/Desktop/robocasa/robosuite-dev/robosuite/models/assets/robots/tiago/meshes/grippers/finger_flex_tip_collision.stl" />
    <mesh name="robot0_finger_abd_collision" file="/home/abhiram03/Desktop/robocasa/robosuite-dev/robosuite/models/assets/robots/tiago/meshes/grippers/finger_abd_collision.stl" />
  <mesh name="gripper0_right_robotiq_arg2f_base_link" file="/home/abhiram03/Desktop/robocasa/robosuite-dev/robosuite/models/assets/grippers/meshes/robotiq_85_gripper/robotiq_arg2f_base_link.stl" />
        <mesh name="gripper0_right_robotiq_arg2f_85_outer_knuckle" file="/home/abhiram03/Desktop/robocasa/robosuite-dev/robosuite/models/assets/grippers/meshes/robotiq_85_gripper/robotiq_arg2f_85_outer_knuckle.stl" scale="0.001 0.001 0.001" />
        <mesh name="gripper0_right_robotiq_arg2f_85_outer_finger" file="/home/abhiram03/Desktop/robocasa/robosuite-dev/robosuite/models/assets/grippers/meshes/robotiq_85_gripper/robotiq_arg2f_85_outer_finger.stl" scale="0.001 0.001 0.001" />
        <mesh name="gripper0_right_robotiq_arg2f_85_inner_finger" file="/home/abhiram03/Desktop/robocasa/robosuite-dev/robosuite/models/assets/grippers/meshes/robotiq_85_gripper/robotiq_arg2f_85_inner_finger.stl" scale="0.001 0.001 0.001" />
        <mesh name="gripper0_right_robotiq_arg2f_85_inner_knuckle" file="/home/abhiram03/Desktop/robocasa/robosuite-dev/robosuite/models/assets/grippers/meshes/robotiq_85_gripper/robotiq_arg2f_85_inner_knuckle.stl" scale="0.001 0.001 0.001" />
        <mesh name="gripper0_right_robotiq_arg2f_85_outer_knuckle_vis" file="/home/abhiram03/Desktop/robocasa/robosuite-dev/robosuite/models/assets/grippers/meshes/robotiq_85_gripper/robotiq_arg2f_85_outer_knuckle_vis.stl" scale="0.001 0.001 0.001" />
        <mesh name="gripper0_right_robotiq_arg2f_85_outer_finger_vis" file="/home/abhiram03/Desktop/robocasa/robosuite-dev/robosuite/models/assets/grippers/meshes/robotiq_85_gripper/robotiq_arg2f_85_outer_finger_vis.stl" scale="0.001 0.001 0.001" />
        <mesh name="gripper0_right_robotiq_arg2f_85_inner_finger_vis" file="/home/abhiram03/Desktop/robocasa/robosuite-dev/robosuite/models/assets/grippers/meshes/robotiq_85_gripper/robotiq_arg2f_85_inner_finger_vis.stl" scale="0.001 0.001 0.001" />
        <mesh name="gripper0_right_robotiq_arg2f_85_inner_knuckle_vis" file="/home/abhiram03/Desktop/robocasa/robosuite-dev/robosuite/models/assets/grippers/meshes/robotiq_85_gripper/robotiq_arg2f_85_inner_knuckle_vis.stl" scale="0.001 0.001 0.001" />
    <mesh name="gripper0_left_robotiq_arg2f_base_link" file="/home/abhiram03/Desktop/robocasa/robosuite-dev/robosuite/models/assets/grippers/meshes/robotiq_85_gripper/robotiq_arg2f_base_link.stl" />
        <mesh name="gripper0_left_robotiq_arg2f_85_outer_knuckle" file="/home/abhiram03/Desktop/robocasa/robosuite-dev/robosuite/models/assets/grippers/meshes/robotiq_85_gripper/robotiq_arg2f_85_outer_knuckle.stl" scale="0.001 0.001 0.001" />
        <mesh name="gripper0_left_robotiq_arg2f_85_outer_finger" file="/home/abhiram03/Desktop/robocasa/robosuite-dev/robosuite/models/assets/grippers/meshes/robotiq_85_gripper/robotiq_arg2f_85_outer_finger.stl" scale="0.001 0.001 0.001" />
        <mesh name="gripper0_left_robotiq_arg2f_85_inner_finger" file="/home/abhiram03/Desktop/robocasa/robosuite-dev/robosuite/models/assets/grippers/meshes/robotiq_85_gripper/robotiq_arg2f_85_inner_finger.stl" scale="0.001 0.001 0.001" />
        <mesh name="gripper0_left_robotiq_arg2f_85_inner_knuckle" file="/home/abhiram03/Desktop/robocasa/robosuite-dev/robosuite/models/assets/grippers/meshes/robotiq_85_gripper/robotiq_arg2f_85_inner_knuckle.stl" scale="0.001 0.001 0.001" />
        <mesh name="gripper0_left_robotiq_arg2f_85_outer_knuckle_vis" file="/home/abhiram03/Desktop/robocasa/robosuite-dev/robosuite/models/assets/grippers/meshes/robotiq_85_gripper/robotiq_arg2f_85_outer_knuckle_vis.stl" scale="0.001 0.001 0.001" />
        <mesh name="gripper0_left_robotiq_arg2f_85_outer_finger_vis" file="/home/abhiram03/Desktop/robocasa/robosuite-dev/robosuite/models/assets/grippers/meshes/robotiq_85_gripper/robotiq_arg2f_85_outer_finger_vis.stl" scale="0.001 0.001 0.001" />
        <mesh name="gripper0_left_robotiq_arg2f_85_inner_finger_vis" file="/home/abhiram03/Desktop/robocasa/robosuite-dev/robosuite/models/assets/grippers/meshes/robotiq_85_gripper/robotiq_arg2f_85_inner_finger_vis.stl" scale="0.001 0.001 0.001" />
        <mesh name="gripper0_left_robotiq_arg2f_85_inner_knuckle_vis" file="/home/abhiram03/Desktop/robocasa/robosuite-dev/robosuite/models/assets/grippers/meshes/robotiq_85_gripper/robotiq_arg2f_85_inner_knuckle_vis.stl" scale="0.001 0.001 0.001" />
    <texture type="cube" name="cube_redwood" file="/home/abhiram03/Desktop/robocasa/robosuite-dev/robosuite/models/assets/textures/red-wood.png" /><material texrepeat="1 1" specular="0.4" shininess="0.1" name="cube_redwood_mat" texture="cube_redwood" /></asset>

  <visual>
    <map znear="0.001" />
  </visual>

  <actuator>
  <motor ctrllimited="true" ctrlrange="-50 50" joint="robot0_arm_right_1_joint" name="robot0_torq_right_j1" />
    <motor ctrllimited="true" ctrlrange="-50 50" joint="robot0_arm_right_2_joint" name="robot0_torq_right_j2" />
    <motor ctrllimited="true" ctrlrange="-15 15" joint="robot0_arm_right_3_joint" name="robot0_torq_right_j3" />
    <motor ctrllimited="true" ctrlrange="-15 15" joint="robot0_arm_right_4_joint" name="robot0_torq_right_j4" />
    <motor ctrllimited="true" ctrlrange="-15 15" joint="robot0_arm_right_5_joint" name="robot0_torq_right_j5" />
    <motor ctrllimited="true" ctrlrange="-15 15" joint="robot0_arm_right_6_joint" name="robot0_torq_right_j6" />
    <motor ctrllimited="true" ctrlrange="-15 15" joint="robot0_arm_left_1_joint" name="robot0_torq_left_j1" />
    <motor ctrllimited="true" ctrlrange="-50 50" joint="robot0_arm_left_2_joint" name="robot0_torq_left_j2" />
    <motor ctrllimited="true" ctrlrange="-50 50" joint="robot0_arm_left_3_joint" name="robot0_torq_left_j3" />
    <motor ctrllimited="true" ctrlrange="-15 15" joint="robot0_arm_left_4_joint" name="robot0_torq_left_j4" />
    <motor ctrllimited="true" ctrlrange="-15 15" joint="robot0_arm_left_5_joint" name="robot0_torq_left_j5" />
    <motor ctrllimited="true" ctrlrange="-15 15" joint="robot0_arm_left_6_joint" name="robot0_torq_left_j6" />
    <motor ctrllimited="true" ctrlrange="-15 15" joint="robot0_head_1_joint" name="robot0_torq_head_pitch" />
    <motor ctrllimited="true" ctrlrange="-15 15" joint="robot0_head_2_joint" name="robot0_torq_head_yaw" />
    <motor ctrllimited="true" ctrlrange="-1000.0 1000.0" joint="robot0_torso_lift_joint" name="robot0_torq_torso_lift" forcelimited="false" />
  <velocity ctrllimited="true" ctrlrange="-1.00 1.00" joint="mobilebase0_joint_mobile_forward" kv="1000" name="mobilebase0_actuator_mobile_forward" forcelimited="true" forcerange="-600 600" />
		<velocity ctrllimited="true" ctrlrange="-1.00 1.00" joint="mobilebase0_joint_mobile_side" kv="1000" name="mobilebase0_actuator_mobile_side" forcelimited="true" forcerange="-600 600" />
		<velocity ctrllimited="true" ctrlrange="-1.50 1.50" joint="mobilebase0_joint_mobile_yaw" kv="1000" name="mobilebase0_actuator_mobile_yaw" forcelimited="true" forcerange="-600 600" />
	<position name="gripper0_right_finger_1" ctrllimited="true" kp="20" joint="gripper0_right_finger_joint" ctrlrange="0 0.8" />
        <position name="gripper0_right_finger_2" ctrllimited="true" kp="20" joint="gripper0_right_right_outer_knuckle_joint" ctrlrange="0 0.8" />
    <position name="gripper0_left_finger_1" ctrllimited="true" kp="20" joint="gripper0_left_finger_joint" ctrlrange="0 0.8" />
        <position name="gripper0_left_finger_2" ctrllimited="true" kp="20" joint="gripper0_left_right_outer_knuckle_joint" ctrlrange="0 0.8" />
    </actuator>

  <worldbody>
  <geom condim="3" group="1" material="floorplane" name="floor" pos="0.0 0.0 0.0" size="3 3 .125" type="plane" />
    
    <geom pos="-1.25 2.25 1.5" quat="0.6532815 0.6532815 0.2705981 0.2705981" size="1.06 1.5 0.01" type="box" conaffinity="0" contype="0" group="1" name="wall_leftcorner_visual" material="walls_mat" />
    <geom pos="-1.25 -2.25 1.5" quat="0.6532815 0.6532815 -0.2705981 -0.2705981" size="1.06 1.5 0.01" type="box" conaffinity="0" contype="0" group="1" name="wall_rightcorner_visual" material="walls_mat" />
    <geom pos="1.25 3.0 1.5" quat="0.7071 0.7071 0 0" size="1.75 1.5 0.01" type="box" conaffinity="0" contype="0" group="1" name="wall_left_visual" material="walls_mat" />
    <geom pos="1.25 -3.0 1.5" quat="0.7071 -0.7071 0 0" size="1.75 1.5 0.01" type="box" conaffinity="0" contype="0" group="1" name="wall_right_visual" material="walls_mat" />
    <geom pos="-2.0 0.0 1.5" quat="0.5 0.5 0.5 0.5" size="1.5 1.5 0.01" type="box" conaffinity="0" contype="0" group="1" name="wall_rear_visual" material="walls_mat" />
    <geom pos="3.0 0.0 1.5" quat="0.5 0.5 -0.5 -0.5" size="3 1.5 0.01" type="box" conaffinity="0" contype="0" group="1" name="wall_front_visual" material="walls_mat" />
    
    <body name="table" pos="0.0 0.0 0.775">
      <geom pos="0 0 0" size="0.4 0.4 0.025" type="box" group="0" name="table_collision" friction="1.0 0.005 0.0001" rgba="0.5 0.5 0 1" />
      <geom pos="0 0 0" size="0.4 0.4 0.025" type="box" conaffinity="0" contype="0" group="1" name="table_visual" material="table_ceramic" />
      <site pos="0.0 0.0 0.025" name="table_top" size="0.001 0.001 0.001" rgba="0 0 0 0" />
      
      <geom pos="0.30000000000000004 0.30000000000000004 -0.3875" size="0.025 0.3875" type="cylinder" conaffinity="0" contype="0" group="1" name="table_leg1_visual" material="table_legs_metal" />
      <geom pos="-0.30000000000000004 0.30000000000000004 -0.3875" size="0.025 0.3875" type="cylinder" conaffinity="0" contype="0" group="1" name="table_leg2_visual" material="table_legs_metal" />
      <geom pos="-0.30000000000000004 -0.30000000000000004 -0.3875" size="0.025 0.3875" type="cylinder" conaffinity="0" contype="0" group="1" name="table_leg3_visual" material="table_legs_metal" />
      <geom pos="0.30000000000000004 -0.30000000000000004 -0.3875" size="0.025 0.3875" type="cylinder" conaffinity="0" contype="0" group="1" name="table_leg4_visual" material="table_legs_metal" />
    </body>
    <light pos="1.0 1.0 1.5" dir="-0.2 -0.2 -1" specular="0.3 0.3 0.3" directional="true" castshadow="false" />
    
    <camera mode="fixed" name="frontview" pos="1.6 0.0 1.45" quat="0.56 0.43 0.43 0.56" />
    
    <camera mode="fixed" name="birdview" pos="-0.2 0.0 3.0" quat="0.7071 0 0 0.7071" />
    
    <camera mode="fixed" name="agentview" pos="0.5 0.0 1.35" quat="0.653 0.271 0.271 0.653" />
    
    <camera mode="fixed" name="sideview" pos="-0.05651774593317116 1.2761224129427358 1.4879572214102434" quat="0.009905065491771751 0.006877963156909582 0.5912228352893879 0.806418094001364" />
  <body mocap="true" pos="0.0 0.0 -1.0" name="left_eef_target"><geom rgba="0.898 0.420 0.435 0.5" conaffinity="0" contype="0" type="box" size="0.05 0.05 0.05" pos="0 0 0" group="2" name="left_eef_target_box" /><geom rgba="0.898 0.420 0.435 0.8" conaffinity="0" contype="0" type="sphere" size="0.01" pos="0 0 0" group="2" name="left_eef_target_sphere" /></body><body mocap="true" pos="0.0 0.0 -1.0" name="right_eef_target"><geom rgba="0.208 0.314 0.439 0.5" conaffinity="0" contype="0" type="box" size="0.05 0.05 0.05" pos="0 0 0" group="2" name="right_eef_target_box" /><geom rgba="0.208 0.314 0.439 0.8" conaffinity="0" contype="0" type="sphere" size="0.01" pos="0 0 0" group="2" name="right_eef_target_sphere" /></body><body name="robot0_base" pos="-0.6000000000000001 0.0 0.0">
      
      <inertial pos="0 0 0" mass="0.001" diaginertia="0.4 0.4 0.4" />
      <body name="mobilebase0_support" pos="0.0 0.0 0.0">
            

            <site name="mobilebase0_center" type="sphere" pos="0 0 0" size="0.01" group="1" rgba="0 0 0 0" />

            <joint name="mobilebase0_joint_mobile_forward" pos="0 0 0" axis="0 1 0" type="slide" limited="false" damping="0" armature="0.0" frictionloss="250" />
			<joint name="mobilebase0_joint_mobile_side" pos="0 0 0" axis="1 0 0" type="slide" limited="false" damping="0" armature="0.0" frictionloss="250" />
			<joint name="mobilebase0_joint_mobile_yaw" pos="-0.21 0 0" axis="0 0 1" type="hinge" limited="false" damping="0" armature="0.0" frictionloss="250" />
        <body name="robot0_base_link" pos="0 0 0.0985">
        <inertial pos="-0.00000106 0.00000109 0.0000387" mass="28.26649" diaginertia="0.4 0.4 0.4" />
        <geom type="mesh" material="robot0_White" contype="0" conaffinity="0" group="1" mesh="robot0_base" name="robot0_g0_vis" />
        <geom type="mesh" name="robot0_base_collision" group="0" friction="1 0 0" mesh="robot0_base_collision" rgba="0 0.5 0 1" />
        <body name="robot0_wheeled_base">
          
          <body name="robot0_base_cover_link" pos="0 0 0.13">
            <inertial pos="0.22414000000 0.00002000000 0.04681000000" mass="0.25821000000" diaginertia="0.4 0.4 0.4" />
            <geom type="mesh" material="robot0_Orange" contype="0" conaffinity="0" group="1" mesh="robot0_base_ring" name="robot0_g1_vis" />
          </body>
          
          <body name="robot0_wheel_right_link" pos="0 -0.2022 0" euler="-1.57079632679 0 0">
            <inertial pos="0 0 -0.00207" mass="1.82362" diaginertia="0.4 0.4 0.4" />
            <geom type="mesh" material="robot0_DarkGrey" contype="0" conaffinity="0" group="1" mesh="robot0_wheel" name="robot0_g2_vis" />
            <geom type="cylinder" name="robot0_wheel_right_collision" group="0" friction="1 0 0" size="0.0985 0.04" rgba="0 0.5 0 1" />
          </body>
          
          
          <body name="robot0_wheel_left_link" pos="0 0.2022 0" euler="-1.57079632679 0 0">
            <inertial pos="0 0 0.00207" mass="1.82362" diaginertia="0.4 0.4 0.4" />
            <geom type="mesh" material="robot0_DarkGrey" contype="0" conaffinity="0" group="1" mesh="robot0_wheel" name="robot0_g3_vis" />
            <geom type="cylinder" name="robot0_wheel_left_collision" group="0" friction="1 0 0" size="0.0985 0.04" rgba="0 0.5 0 1" />
          </body>
          
          
          <body name="robot0_ignore_caster_front_right_1_link" pos="0.1695 -0.102 -0.0335">
            <inertial pos="-0.00634599 0.00005347 -0.02037519" mass="0.05144761" diaginertia="0.4 0.4 0.4" />
            <geom type="mesh" material="robot0_Grey" contype="0" conaffinity="0" group="1" mesh="robot0_caster_1" name="robot0_g4_vis" />
            <body name="robot0_ignore_caster_front_right_2_link" pos="-0.016 0.0000 -0.040" euler="-1.57079632679 0 0">
              <inertial pos="0 0 0" mass="0.08855784" diaginertia="0.4 0.4 0.4" />
              <geom type="mesh" material="robot0_DarkGrey" contype="0" conaffinity="0" group="1" mesh="robot0_caster_2" name="robot0_g5_vis" />
              <geom type="cylinder" name="robot0_front_right_caster_2" group="0" friction="1 0 0" size="0.025 0.015" rgba="0 0.5 0 1" />
            </body>
          </body>
          
          
          <body name="robot0_ignore_caster_front_left_1_link" pos="0.1695 0.102 -0.0335">
            <inertial pos="-0.00634599 0.00005347 -0.02037519" mass="0.05144761" diaginertia="0.4 0.4 0.4" />
            <geom type="mesh" material="robot0_Grey" contype="0" conaffinity="0" group="1" mesh="robot0_caster_1" name="robot0_g6_vis" />
            <body name="robot0_ignore_caster_front_left_2_link" pos="-0.016 0.0000 -0.040" euler="-1.57079632679 0 0">
              <inertial pos="0 0 0" mass="0.08855784" diaginertia="0.4 0.4 0.4" />
              <geom type="mesh" material="robot0_DarkGrey" contype="0" conaffinity="0" group="1" mesh="robot0_caster_2" name="robot0_g7_vis" />
              <geom type="cylinder" name="robot0_front_left_caster_2" group="0" friction="1 0 0" size="0.025 0.015" rgba="0 0.5 0 1" />
            </body>
          </body>
          
          
          <body name="robot0_ignore_caster_back_right_1_link" pos="-0.1735 -0.102 -0.0335">
            <inertial pos="-0.00634599 0.00005347 -0.02037519" mass="0.05144761" diaginertia="0.4 0.4 0.4" />
            <geom type="mesh" material="robot0_Grey" contype="0" conaffinity="0" group="1" mesh="robot0_caster_1" name="robot0_g8_vis" />
            <body name="robot0_ignore_caster_back_right_2_link" pos="-0.016 0.0000 -0.040" euler="-1.57079632679 0 0">
              <inertial pos="0 0 0" mass="0.08855784" diaginertia="0.4 0.4 0.4" />
              <geom type="mesh" material="robot0_DarkGrey" contype="0" conaffinity="0" group="1" mesh="robot0_caster_2" name="robot0_g9_vis" />
              <geom type="cylinder" name="robot0_back_right_caster_2" group="0" friction="1 0 0" size="0.025 0.015" rgba="0 0.5 0 1" />
            </body>
          </body>
          
          
          <body name="robot0_ignore_caster_back_left_1_link" pos="-0.1735 0.102 -0.0335">
            <inertial pos="-0.00634599 0.00005347 -0.02037519" mass="0.05144761" diaginertia="0.4 0.4 0.4" />
            <geom type="mesh" material="robot0_Grey" contype="0" conaffinity="0" group="1" mesh="robot0_caster_1" name="robot0_g10_vis" />
            <body name="robot0_ignore_caster_back_left_2_link" pos="-0.016 0.0000 -0.040" euler="-1.57079632679 0 0">
              <inertial pos="0 0 0" mass="0.08855784" diaginertia="0.4 0.4 0.4" />
              <geom type="mesh" material="robot0_DarkGrey" contype="0" conaffinity="0" group="1" mesh="robot0_caster_2" name="robot0_g11_vis" />
              <geom type="cylinder" name="robot0_back_left_caster_2" group="0" friction="1 0 0" size="0.025 0.015" rgba="0 0.5 0 1" />
            </body>
          </body>
          
        </body>
        
        
        <body name="robot0_torso">
          <site name="robot0_center" pos="0 0 0" size="0.01" rgba="1 0.3 0.3 1" group="2" />
          <body name="robot0_torso_fixed_link" pos="-0.062 0.0 0.193">
            <inertial pos="0.02435 -0.00464 0.15900" mass="14.01360" diaginertia="0.4 0.4 0.4" />
            <geom type="mesh" material="robot0_LightGrey" contype="0" conaffinity="0" group="1" mesh="robot0_torso_fix" name="robot0_g12_vis" />
            <geom type="box" name="robot0_torso_fixed_collision_box_1" group="0" friction="1 0 0" size="0.25 0.25 0.04" pos="0.085 0.0 0.02" rgba="0 0.5 0 1" />
            <body name="robot0_torso_fixed_column_link" pos="0 0 0.195">
                            <inertial pos="0 0 0" mass="0.01" diaginertia="0.4 0.4 0.4" />
                            <geom type="box" material="robot0_LightGrey" contype="0" conaffinity="0" group="1" size="0.10 0.10 0.3" name="robot0_g13_vis" />
                            <geom type="box" name="robot0_torso_fixed_column_collision" group="0" friction="1 0 0" size="0.10 0.10 0.3" rgba="0 0.5 0 1" />
                        </body>
            
            <body name="robot0_torso_lift_link" pos="0.0 0.0 0">
              <joint name="robot0_torso_lift_joint" type="slide" axis="0 0 1" damping="1000" range="0 0.35" frictionloss="0.1" armature="5.0" />
              <inertial pos="0.04361 -0.00116 -0.17334" mass="9.594213" diaginertia="0.4 0.4 0.4" />
              <geom type="mesh" material="robot0_White" contype="0" conaffinity="0" group="1" mesh="robot0_torso_lift_dual_arm" pos="0.0 0.0 0.597" name="robot0_g14_vis" />
              <geom type="mesh" name="robot0_torso_lift_collision" group="0" friction="1 0 0" mesh="robot0_torso_lift_collision_core" pos="0.0 0.0 0" rgba="0 0.5 0 1" />
              <geom type="mesh" name="robot0_torso_lift_collision_shoulder_right" group="0" friction="1 0 0" mesh="robot0_torso_lift_collision_shoulder" pos="0.18 0.17 0.15556" rgba="0 0.5 0 1" />
              <geom type="mesh" name="robot0_torso_lift_collision_shoulder_left" group="0" friction="1 0 0" mesh="robot0_torso_lift_collision_shoulder" pos="0.18 -0.20 0.15556" rgba="0 0.5 0 1" />
              
              <body name="robot0_head" pos="0 0 0.597">
                <body name="robot0_head_1_link" pos="0.182 0.0 0.0" euler="0 0 0">
                  <joint name="robot0_head_1_joint" type="hinge" limited="true" axis="0 0 1" damping="20" range="-1.308996939 1.308996939" frictionloss="0.1" armature="2.5" />
                  <inertial pos="-0.00508 0.00237 0.07229" mass="0.62220" diaginertia="0.4 0.4 0.4" />
                  <geom type="mesh" material="robot0_White" contype="0" conaffinity="0" group="1" mesh="robot0_head_1" name="robot0_g15_vis" />
                  <geom type="mesh" name="robot0_head_1_collision" group="0" friction="1 0 0" mesh="robot0_head_1_collision" rgba="0 0.5 0 1" />
                  <body name="robot0_head_2_link" pos="0.005 0.0 0.098" euler="1.57079632679 0 0">
                    
                    <camera mode="fixed" name="robot0_robotview" pos="0.07 0 0" quat="0.7071067811865476 0.0 -0.7071067811865475 0.0" />
                    <joint name="robot0_head_2_joint" type="hinge" limited="true" axis="0 0 1" damping="20" range="-1.0471975512 0.785398163397" frictionloss="0.1" armature="1.6666666666666667" />
                    <inertial pos="0.04700 0.05542 0.00022" mass="0.66123" diaginertia="0.4 0.4 0.4" />
                    <geom type="mesh" material="robot0_White" contype="0" conaffinity="0" group="1" mesh="robot0_head_2" name="robot0_g16_vis" />
                    <geom type="mesh" name="robot0_head_2_collision" group="0" friction="1 0 0" mesh="robot0_head_2_collision" rgba="0 0.5 0 1" />
                  </body>
                </body>
              </body>
              
              
              <body name="robot0_right_arm_mount" pos="0 0 0.597">
                
                <site name="robot0_right_center" pos="0 0 0" size="0.01" rgba="1 0.3 0.3 1" group="2" />
                <body name="robot0_arm_right_1_link" pos="0.02556 -0.19 -0.171" euler="0 0 -1.57079632679">
                  <joint name="robot0_arm_right_1_joint" type="hinge" limited="true" axis="0 0 1" damping="10.0" range="-1.1780972451 1.57079632679" frictionloss="0.1" armature="1.25" />
                  <inertial pos="0.061191 -0.022397 -0.012835" mass="1.563428" diaginertia="0.4 0.4 0.4" />
                  <geom type="mesh" material="robot0_White" contype="0" conaffinity="0" group="1" mesh="robot0_arm_1" name="robot0_g17_vis" />
                  <geom type="mesh" name="robot0_arm_1_collision" group="0" friction="1 0 0" mesh="robot0_arm_1_collision" rgba="0 0.5 0 1" />
                  
                  <body name="robot0_arm_right_2_link" pos="0.125 -0.0195 -0.031" euler="-1.57079632679 0.0 0.0">
                    <joint name="robot0_arm_right_2_joint" type="hinge" limited="true" axis="0 0 1" damping="100.0" range="-1.1780972451 1.57079632679" frictionloss="0.1" armature="1.0" />
                    <inertial pos="0.030432 0.000229 -0.005942" mass="1.800397" diaginertia="0.4 0.4 0.4" />
                    <geom type="mesh" material="robot0_DarkGrey" contype="0" conaffinity="0" group="1" mesh="robot0_arm_2" name="robot0_g18_vis" />
                    <geom type="mesh" name="robot0_arm_2_collision" group="0" friction="1 0 0" mesh="robot0_arm_2_collision" rgba="0 0.5 0 1" />
                    
                    <body name="robot0_arm_right_3_link" pos="0.0895 0.0 -0.0015" quat="0.5 -0.5 -0.5 0.5">
                      <joint name="robot0_arm_right_3_joint" type="hinge" limited="true" axis="0 0 1" damping="30.0" range="-0.785398163397 3.92699081699" frictionloss="0.1" armature="0.8333333333333334" />
                      <inertial pos="0.007418 -0.004361 -0.134194" mass="2.343502" diaginertia="0.4 0.4 0.4" />
                      <geom type="mesh" material="robot0_DarkGrey" contype="0" conaffinity="0" group="1" mesh="robot0_arm_3" name="robot0_g19_vis" />
                      <geom type="mesh" name="robot0_arm_3_collision" group="0" friction="1 0 0" mesh="robot0_arm_3_collision" rgba="0 0.5 0 1" />
                      
                      <body name="robot0_arm_right_4_link" pos="-0.02 -0.027 -0.222" quat="0.5 -0.5 -0.5 -0.5">
                        <joint name="robot0_arm_right_4_joint" type="hinge" limited="true" axis="0 0 1" damping="10.0" range="-0.392699081699 2.35619449019" frictionloss="0.1" armature="0.7142857142857143" />
                        <inertial pos="-0.095658 0.014666 0.018133" mass="1.432697" diaginertia="0.4 0.4 0.4" />
                        <geom type="mesh" material="robot0_DarkGrey" contype="0" conaffinity="0" group="1" mesh="robot0_arm_4" name="robot0_g20_vis" />
                        <geom type="mesh" name="robot0_arm_4_collision" group="0" friction="1 0 0" mesh="robot0_arm_4_collision" rgba="0 0.5 0 1" />
                        
                        <body name="robot0_arm_right_5_link" pos="-0.162 0.02 0.027" quat="0.7071067811865475 1.7312262734492379e-12 -0.7071067811865475 -1.7311707622980066e-12">
                          <joint name="robot0_arm_right_5_joint" type="hinge" limited="true" axis="0 0 1" damping="10.0" range="-2.09439510239 2.09439510239" frictionloss="0.1" armature="0.625" />
                          <inertial pos="0.001078 -0.000151 -0.077173" mass="1.655819" diaginertia="0.4 0.4 0.4" />
                          <geom type="mesh" material="robot0_LightGrey" contype="0" conaffinity="0" group="1" mesh="robot0_arm_5-wrist-2017" name="robot0_g21_vis" />
                          <geom type="mesh" name="robot0_arm_5_collision" group="0" friction="1 0 0" mesh="robot0_arm_5_collision-wrist-2017" rgba="0 0.5 0 1" />
                          
                          <body name="robot0_arm_right_6_link" pos="0 0 0.15" quat="0.5 -0.5 -0.5 -0.5">
                            <joint name="robot0_arm_right_6_joint" type="hinge" limited="true" axis="0 0 1" damping="10.0" range="-1.41371669412 1.41371669412" frictionloss="0.1" armature="0.5555555555555556" />
                            <inertial pos="-0.000153 -0.003122 0.000183" mass="0.370063" diaginertia="0.4 0.4 0.4" />
                            <geom type="mesh" material="robot0_LightGrey" contype="0" conaffinity="0" group="1" mesh="robot0_arm_6-wrist-2017" name="robot0_g22_vis" />
                            <geom type="mesh" name="robot0_arm_6_collision" group="0" friction="1 0 0" mesh="robot0_arm_6_collision-wrist-2017" rgba="0 0.5 0 1" />
                            
                            <body name="robot0_right_hand" pos="0.05 0 0" quat="0.5 0.5 0.5 0.5">
                                                        <body name="gripper0_right_robotiq_85_adapter_link" pos="0.0 0 0">
            <site name="gripper0_right_ft_frame" pos="0 0 0" size="0.01 0.01 0.01" rgba="1 0 0 1" type="sphere" group="1" />
            
            <body name="gripper0_right_eef" pos="0 0 0.145" quat="0.707105 0 0 -0.707105">
                <site name="gripper0_right_grip_site" pos="0 0 0" size="0.01 0.01 0.01" rgba="1 0 0 0.5" type="sphere" group="1" />
                <site name="gripper0_right_ee_x" pos="0.1 0 0" size="0.005 .1" quat="0.707105  0 0.707108 0 " rgba="1 0 0 0" type="cylinder" group="1" />
                <site name="gripper0_right_ee_y" pos="0 0.1 0" size="0.005 .1" quat="0.707105 0.707108 0 0" rgba="0 1 0 0" type="cylinder" group="1" />
                <site name="gripper0_right_ee_z" pos="0 0 0.1" size="0.005 .1" quat="1 0 0 0" rgba="0 0 1 0" type="cylinder" group="1" />
                
                <site name="gripper0_right_grip_site_cylinder" pos="0 0 0" size="0.005 10" rgba="0 1 0 0.3" type="cylinder" group="1" />
            </body>
            <inertial pos="0 0 0" mass="0.01" diaginertia="0.001 0.001 0.001" />
            <geom type="mesh" contype="0" conaffinity="0" group="1" rgba="0.1 0.1 0.1 1" name="gripper0_right_hand_visual" mesh="gripper0_right_robotiq_arg2f_base_link" />
            <geom type="mesh" group="0" rgba="0 0 0.5 1" mesh="gripper0_right_robotiq_arg2f_base_link" name="gripper0_right_hand_collision" />
            <body name="gripper0_right_left_outer_knuckle" pos="0 -0.0306011 0.054904" quat="0 0 0 1">
                <inertial pos="0.000163875 0.0554825 -0.0100755" quat="0.920541 0.390623 -0.00362953 0.00231744" mass="0.0311462" diaginertia="5.11372e-05 4.89464e-05 4.95906e-06" />
                <joint name="gripper0_right_finger_joint" pos="0 0 0" axis="1 0 0" limited="true" range="0 0.8" />
                <geom type="mesh" contype="0" conaffinity="0" group="1" rgba="0.792157 0.819608 0.933333 1" name="gripper0_right_left_outer_knuckle_visual" mesh="gripper0_right_robotiq_arg2f_85_outer_knuckle_vis" />
                <geom type="mesh" group="0" rgba="0 0 0.5 1" mesh="gripper0_right_robotiq_arg2f_85_outer_knuckle" name="gripper0_right_left_outer_knuckle_collision" solref="0.01 0.25" />
                <geom pos="0 0.0315 -0.0041" type="mesh" contype="0" conaffinity="0" group="1" rgba="0.1 0.1 0.1 1" name="gripper0_right_left_outer_finger_visual" mesh="gripper0_right_robotiq_arg2f_85_outer_finger_vis" />
                <geom pos="0 0.0315 -0.0041" type="mesh" group="0" rgba="0 0 0.5 1" mesh="gripper0_right_robotiq_arg2f_85_outer_finger" name="gripper0_right_left_outer_finger_collision" solref="0.01 0.25" />
                <body name="gripper0_right_left_inner_finger" pos="0 0.0376 0.043">
                    <inertial pos="0.000199506 0.0032692 0.00175282" quat="0.933621 0.35825 -0.00273441 0.00104851" mass="0.0156391" diaginertia="1.57977e-05 1.51089e-05 1.4647e-06" />
                    <joint name="gripper0_right_left_inner_finger_joint" pos="0 0 0" axis="1 0 0" limited="true" range="-0.8757 0.8757" />
                    <geom type="mesh" contype="0" conaffinity="0" group="1" rgba="0.1 0.1 0.1 1" name="gripper0_right_left_inner_finger_visual" mesh="gripper0_right_robotiq_arg2f_85_inner_finger_vis" />
                    <geom type="mesh" group="0" rgba="0 0 0.5 1" mesh="gripper0_right_robotiq_arg2f_85_inner_finger" name="gripper0_right_left_inner_finger_collision" solref="0.01 0.25" />
                    <geom size="0.011 0.003175 0.01875" pos="0 -0.0220203 0.03242" type="box" contype="0" conaffinity="0" group="1" rgba="0.9 0.9 0.9 1" name="gripper0_right_left_fingertip_visual" />
                    <geom size="0.011 0.003175 0.01875" pos="0 -0.0220203 0.03242" type="box" group="0" rgba="0 0 0.5 1" name="gripper0_right_left_fingertip_collision" solref="0.01 0.25" />
                    <geom size="0.010 0.001 0.01675" pos="0 -0.0245203 0.03242" type="box" group="0" name="gripper0_right_left_fingerpad_collision" rgba="0 0 0.5 1" />
                </body>
            </body>
            <body name="gripper0_right_left_inner_knuckle" pos="0 -0.0127 0.06142" quat="0 0 0 1">
                <inertial pos="0.000123012 0.0507851 0.00103969" quat="0.497203 0.502496 -0.507943 0.492221" mass="0.0271177" diaginertia="2.83809e-05 2.61936e-05 2.81319e-06" />
                <joint name="gripper0_right_left_inner_knuckle_joint" pos="0 0 0" axis="1 0 0" limited="true" range="0 0.8757" />
                <geom type="mesh" contype="0" conaffinity="0" group="1" rgba="0.1 0.1 0.1 1" name="gripper0_right_left_inner_knuckle_visual" mesh="gripper0_right_robotiq_arg2f_85_inner_knuckle_vis" />
                <geom type="mesh" group="0" rgba="0 0 0.5 1" mesh="gripper0_right_robotiq_arg2f_85_inner_knuckle" name="gripper0_right_left_inner_knuckle_collision" />
            </body>
            <body name="gripper0_right_right_outer_knuckle" pos="0 0.0306011 0.054904">
                <inertial pos="0.000163875 0.0554825 -0.0100755" quat="0.920541 0.390623 -0.00362953 0.00231744" mass="0.0311462" diaginertia="5.11372e-05 4.89464e-05 4.95906e-06" />
                <joint name="gripper0_right_right_outer_knuckle_joint" pos="0 0 0" axis="1 0 0" limited="true" range="0 0.8" />
                <geom type="mesh" contype="0" conaffinity="0" group="1" rgba="0.792157 0.819608 0.933333 1" name="gripper0_right_right_outer_knuckle_visual" mesh="gripper0_right_robotiq_arg2f_85_outer_knuckle_vis" />
                <geom type="mesh" group="0" rgba="0 0 0.5 1" mesh="gripper0_right_robotiq_arg2f_85_outer_knuckle" name="gripper0_right_right_outer_knuckle_collision" solref="0.01 0.25" />
                <geom pos="0 0.0315 -0.0041" type="mesh" contype="0" conaffinity="0" group="1" rgba="0.1 0.1 0.1 1" name="gripper0_right_right_outer_finger_visual" mesh="gripper0_right_robotiq_arg2f_85_outer_finger_vis" />
                <geom pos="0 0.0315 -0.0041" type="mesh" group="0" rgba="0 0 0.5 1" mesh="gripper0_right_robotiq_arg2f_85_outer_finger" name="gripper0_right_right_outer_finger_collision" solref="0.01 0.25" />
                <body name="gripper0_right_right_inner_finger" pos="0 0.0376 0.043">
                    <inertial pos="0.000199506 0.0032692 0.00175282" quat="0.933621 0.35825 -0.00273441 0.00104851" mass="0.0156391" diaginertia="1.57977e-05 1.51089e-05 1.4647e-06" />
                    <joint name="gripper0_right_right_inner_finger_joint" pos="0 0 0" axis="1 0 0" limited="true" range="-0.8757 0.8757" />
                    <geom type="mesh" contype="0" conaffinity="0" group="1" rgba="0.1 0.1 0.1 1" name="gripper0_right_right_inner_finger_visual" mesh="gripper0_right_robotiq_arg2f_85_inner_finger_vis" />
                    <geom type="mesh" group="0" rgba="0 0 0.5 1" mesh="gripper0_right_robotiq_arg2f_85_inner_finger" name="gripper0_right_right_inner_finger_collision" solref="0.01 0.25" />
                    <geom size="0.011 0.003175 0.01875" pos="0 -0.0220203 0.03242" type="box" contype="0" conaffinity="0" group="1" rgba="0.9 0.9 0.9 1" name="gripper0_right_right_fingertip_visual" />
                    <geom size="0.011 0.003175 0.01875" pos="0 -0.0220203 0.03242" type="box" group="0" rgba="0 0 0.5 1" name="gripper0_right_right_fingertip_collision" solref="0.01 0.25" />
                    <geom size="0.010 0.001 0.01675" pos="0 -0.0245203 0.03242" type="box" group="0" name="gripper0_right_right_fingerpad_collision" rgba="0 0 0.5 1" />
                </body>
            </body>
            <body name="gripper0_right_right_inner_knuckle" pos="0 0.0127 0.06142">
                <inertial pos="0.000123012 0.0507851 0.00103969" quat="0.497203 0.502496 -0.507943 0.492221" mass="0.0271177" diaginertia="2.83809e-05 2.61936e-05 2.81319e-06" />
                <joint name="gripper0_right_right_inner_knuckle_joint" pos="0 0 0" axis="1 0 0" limited="true" range="0 0.8757" />
                <geom type="mesh" contype="0" conaffinity="0" group="1" rgba="0.1 0.1 0.1 1" name="gripper0_right_right_inner_knuckle_visual" mesh="gripper0_right_robotiq_arg2f_85_inner_knuckle_vis" />
                <geom type="mesh" group="0" rgba="0 0 0.5 1" mesh="gripper0_right_robotiq_arg2f_85_inner_knuckle" name="gripper0_right_right_inner_knuckle_collision" />
            </body>
        </body>
    </body>
                            
                          </body>
                          
                        </body>
                        
                      </body>
                      
                    </body>
                    
                  </body>
                  
                </body>
                
              </body>
              
              
              <body name="robot0_left_arm_mount" pos="0 0 0.597">
                <site name="robot0_left_center" pos="0 0 0" size="0.01" rgba="1 0.3 0.3 1" group="2" />
                
                <body name="robot0_arm_left_1_link" pos="0.02556 0.19 -0.171" quat="0 0.7071067811882787 0.7071067811848163 0">
                  <joint name="robot0_arm_left_1_joint" type="hinge" limited="true" axis="0 0 1" damping="10.0" range="-1.1780972451 1.57079632679" frictionloss="0.1" armature="0.5" />
                  <inertial pos="0.061191 -0.022397 -0.012835" mass="1.563428" diaginertia="0.4 0.4 0.4" />
                  <geom type="mesh" material="robot0_White" contype="0" conaffinity="0" group="1" mesh="robot0_arm_1_left" name="robot0_g23_vis" />
                  <geom type="mesh" name="robot0_arm_1_left_collision" group="0" friction="1 0 0" mesh="robot0_arm_1_left_collision" rgba="0 0.5 0 1" />
                  
                  <body name="robot0_arm_left_2_link" pos="0.125 -0.0195 0.031" euler="1.57079632679 0.0 0.0">
                    <joint name="robot0_arm_left_2_joint" type="hinge" limited="true" axis="0 0 1" damping="100.0" range="-1.1780972451 1.57079632679" frictionloss="0.1" armature="0.45454545454545453" />
                    <inertial pos="0.030432 0.000229 -0.005942" mass="1.800397" diaginertia="0.4 0.4 0.4" />
                    <geom type="mesh" material="robot0_DarkGrey" contype="0" conaffinity="0" group="1" mesh="robot0_arm_2_left" name="robot0_g24_vis" />
                    <geom type="mesh" name="robot0_arm_2_left_collision" group="0" friction="1 0 0" mesh="robot0_arm_2_left_collision" rgba="0 0.5 0 1" />
                    
                    <body name="robot0_arm_left_3_link" pos="0.0895 0.0 -0.0015" quat="0.5 0.5 0.5 0.5">
                      <joint name="robot0_arm_left_3_joint" type="hinge" limited="true" axis="0 0 1" damping="30.0" range="-0.785398163397 3.92699081699" frictionloss="0.1" armature="0.4166666666666667" />
                      <inertial pos="0.007418 -0.004361 -0.134194" mass="2.343502" diaginertia="0.4 0.4 0.4" />
                      <geom type="mesh" material="robot0_DarkGrey" contype="0" conaffinity="0" group="1" mesh="robot0_arm_3_left" name="robot0_g25_vis" />
                      <geom type="mesh" name="robot0_arm_3_left_collision" group="0" friction="1 0 0" mesh="robot0_arm_3_left_collision" rgba="0 0.5 0 1" />
                      
                      <body name="robot0_arm_left_4_link" pos="-0.02 -0.027 0.222" quat="0.5 0.5 -0.5 0.5">
                        <joint name="robot0_arm_left_4_joint" type="hinge" limited="true" axis="0 0 1" damping="10.0" range="-0.392699081699 2.35619449019" frictionloss="0.1" armature="0.38461538461538464" />
                        <inertial pos="-0.095658 0.014666 0.018133" mass="1.432697" diaginertia="0.4 0.4 0.4" />
                        <geom type="mesh" material="robot0_DarkGrey" contype="0" conaffinity="0" group="1" mesh="robot0_arm_4_left" name="robot0_g26_vis" />
                        <geom type="mesh" name="robot0_arm_4_left_collision" group="0" friction="1 0 0" mesh="robot0_arm_4_left_collision" rgba="0 0.5 0 1" />
                        
                        <body name="robot0_arm_left_5_link" pos="0.162 -0.02 -0.027" quat="0.7071067811865475 0 -0.7071067811865475 0">
                          <joint name="robot0_arm_left_5_joint" type="hinge" limited="true" axis="0 0 1" damping="10.0" range="-2.09439510239 2.09439510239" frictionloss="0.1" armature="0.35714285714285715" />
                          <inertial pos="0.001078 -0.000151 -0.077173" mass="1.655819" diaginertia="0.4 0.4 0.4" />
                          <geom type="mesh" material="robot0_LightGrey" contype="0" conaffinity="0" group="1" mesh="robot0_arm_5_left-wrist-2017" name="robot0_g27_vis" />
                          <geom type="mesh" name="robot0_arm_5_left_collision" group="0" friction="1 0 0" mesh="robot0_arm_5_left_collision-wrist-2017" rgba="0 0.5 0 1" />
                          
                          <body name="robot0_arm_left_6_link" pos="0 0 -0.15" quat="0.5 -0.5 -0.5 -0.5">
                            <joint name="robot0_arm_left_6_joint" type="hinge" limited="true" axis="0 0 1" damping="10.0" range="-1.41371669412 1.41371669412" frictionloss="0.1" armature="0.3333333333333333" />
                            <inertial pos="-0.000153 -0.003122 0.000183" mass="0.370063" diaginertia="0.4 0.4 0.4" />
                            <geom type="mesh" material="robot0_LightGrey" contype="0" conaffinity="0" group="1" mesh="robot0_arm_6_left-wrist-2017" name="robot0_g28_vis" />
                            <geom type="mesh" name="robot0_arm_6_left_collision" group="0" friction="1 0 0" mesh="robot0_arm_6_left_collision-wrist-2017" rgba="0 0.5 0 1" />
                            
                            <body name="robot0_left_hand" pos="-0.05 0 0" quat="0.5 -0.5 -0.5 0.5">
                                                        <body name="gripper0_left_robotiq_85_adapter_link" pos="0.0 0 0">
            <site name="gripper0_left_ft_frame" pos="0 0 0" size="0.01 0.01 0.01" rgba="1 0 0 1" type="sphere" group="1" />
            
            <body name="gripper0_left_eef" pos="0 0 0.145" quat="0.707105 0 0 -0.707105">
                <site name="gripper0_left_grip_site" pos="0 0 0" size="0.01 0.01 0.01" rgba="1 0 0 0.5" type="sphere" group="1" />
                <site name="gripper0_left_ee_x" pos="0.1 0 0" size="0.005 .1" quat="0.707105  0 0.707108 0 " rgba="1 0 0 0" type="cylinder" group="1" />
                <site name="gripper0_left_ee_y" pos="0 0.1 0" size="0.005 .1" quat="0.707105 0.707108 0 0" rgba="0 1 0 0" type="cylinder" group="1" />
                <site name="gripper0_left_ee_z" pos="0 0 0.1" size="0.005 .1" quat="1 0 0 0" rgba="0 0 1 0" type="cylinder" group="1" />
                
                <site name="gripper0_left_grip_site_cylinder" pos="0 0 0" size="0.005 10" rgba="0 1 0 0.3" type="cylinder" group="1" />
            </body>
            <inertial pos="0 0 0" mass="0.01" diaginertia="0.001 0.001 0.001" />
            <geom type="mesh" contype="0" conaffinity="0" group="1" rgba="0.1 0.1 0.1 1" name="gripper0_left_hand_visual" mesh="gripper0_left_robotiq_arg2f_base_link" />
            <geom type="mesh" group="0" rgba="0 0 0.5 1" mesh="gripper0_left_robotiq_arg2f_base_link" name="gripper0_left_hand_collision" />
            <body name="gripper0_left_left_outer_knuckle" pos="0 -0.0306011 0.054904" quat="0 0 0 1">
                <inertial pos="0.000163875 0.0554825 -0.0100755" quat="0.920541 0.390623 -0.00362953 0.00231744" mass="0.0311462" diaginertia="5.11372e-05 4.89464e-05 4.95906e-06" />
                <joint name="gripper0_left_finger_joint" pos="0 0 0" axis="1 0 0" limited="true" range="0 0.8" />
                <geom type="mesh" contype="0" conaffinity="0" group="1" rgba="0.792157 0.819608 0.933333 1" name="gripper0_left_left_outer_knuckle_visual" mesh="gripper0_left_robotiq_arg2f_85_outer_knuckle_vis" />
                <geom type="mesh" group="0" rgba="0 0 0.5 1" mesh="gripper0_left_robotiq_arg2f_85_outer_knuckle" name="gripper0_left_left_outer_knuckle_collision" solref="0.01 0.25" />
                <geom pos="0 0.0315 -0.0041" type="mesh" contype="0" conaffinity="0" group="1" rgba="0.1 0.1 0.1 1" name="gripper0_left_left_outer_finger_visual" mesh="gripper0_left_robotiq_arg2f_85_outer_finger_vis" />
                <geom pos="0 0.0315 -0.0041" type="mesh" group="0" rgba="0 0 0.5 1" mesh="gripper0_left_robotiq_arg2f_85_outer_finger" name="gripper0_left_left_outer_finger_collision" solref="0.01 0.25" />
                <body name="gripper0_left_left_inner_finger" pos="0 0.0376 0.043">
                    <inertial pos="0.000199506 0.0032692 0.00175282" quat="0.933621 0.35825 -0.00273441 0.00104851" mass="0.0156391" diaginertia="1.57977e-05 1.51089e-05 1.4647e-06" />
                    <joint name="gripper0_left_left_inner_finger_joint" pos="0 0 0" axis="1 0 0" limited="true" range="-0.8757 0.8757" />
                    <geom type="mesh" contype="0" conaffinity="0" group="1" rgba="0.1 0.1 0.1 1" name="gripper0_left_left_inner_finger_visual" mesh="gripper0_left_robotiq_arg2f_85_inner_finger_vis" />
                    <geom type="mesh" group="0" rgba="0 0 0.5 1" mesh="gripper0_left_robotiq_arg2f_85_inner_finger" name="gripper0_left_left_inner_finger_collision" solref="0.01 0.25" />
                    <geom size="0.011 0.003175 0.01875" pos="0 -0.0220203 0.03242" type="box" contype="0" conaffinity="0" group="1" rgba="0.9 0.9 0.9 1" name="gripper0_left_left_fingertip_visual" />
                    <geom size="0.011 0.003175 0.01875" pos="0 -0.0220203 0.03242" type="box" group="0" rgba="0 0 0.5 1" name="gripper0_left_left_fingertip_collision" solref="0.01 0.25" />
                    <geom size="0.010 0.001 0.01675" pos="0 -0.0245203 0.03242" type="box" group="0" name="gripper0_left_left_fingerpad_collision" rgba="0 0 0.5 1" />
                </body>
            </body>
            <body name="gripper0_left_left_inner_knuckle" pos="0 -0.0127 0.06142" quat="0 0 0 1">
                <inertial pos="0.000123012 0.0507851 0.00103969" quat="0.497203 0.502496 -0.507943 0.492221" mass="0.0271177" diaginertia="2.83809e-05 2.61936e-05 2.81319e-06" />
                <joint name="gripper0_left_left_inner_knuckle_joint" pos="0 0 0" axis="1 0 0" limited="true" range="0 0.8757" />
                <geom type="mesh" contype="0" conaffinity="0" group="1" rgba="0.1 0.1 0.1 1" name="gripper0_left_left_inner_knuckle_visual" mesh="gripper0_left_robotiq_arg2f_85_inner_knuckle_vis" />
                <geom type="mesh" group="0" rgba="0 0 0.5 1" mesh="gripper0_left_robotiq_arg2f_85_inner_knuckle" name="gripper0_left_left_inner_knuckle_collision" />
            </body>
            <body name="gripper0_left_right_outer_knuckle" pos="0 0.0306011 0.054904">
                <inertial pos="0.000163875 0.0554825 -0.0100755" quat="0.920541 0.390623 -0.00362953 0.00231744" mass="0.0311462" diaginertia="5.11372e-05 4.89464e-05 4.95906e-06" />
                <joint name="gripper0_left_right_outer_knuckle_joint" pos="0 0 0" axis="1 0 0" limited="true" range="0 0.8" />
                <geom type="mesh" contype="0" conaffinity="0" group="1" rgba="0.792157 0.819608 0.933333 1" name="gripper0_left_right_outer_knuckle_visual" mesh="gripper0_left_robotiq_arg2f_85_outer_knuckle_vis" />
                <geom type="mesh" group="0" rgba="0 0 0.5 1" mesh="gripper0_left_robotiq_arg2f_85_outer_knuckle" name="gripper0_left_right_outer_knuckle_collision" solref="0.01 0.25" />
                <geom pos="0 0.0315 -0.0041" type="mesh" contype="0" conaffinity="0" group="1" rgba="0.1 0.1 0.1 1" name="gripper0_left_right_outer_finger_visual" mesh="gripper0_left_robotiq_arg2f_85_outer_finger_vis" />
                <geom pos="0 0.0315 -0.0041" type="mesh" group="0" rgba="0 0 0.5 1" mesh="gripper0_left_robotiq_arg2f_85_outer_finger" name="gripper0_left_right_outer_finger_collision" solref="0.01 0.25" />
                <body name="gripper0_left_right_inner_finger" pos="0 0.0376 0.043">
                    <inertial pos="0.000199506 0.0032692 0.00175282" quat="0.933621 0.35825 -0.00273441 0.00104851" mass="0.0156391" diaginertia="1.57977e-05 1.51089e-05 1.4647e-06" />
                    <joint name="gripper0_left_right_inner_finger_joint" pos="0 0 0" axis="1 0 0" limited="true" range="-0.8757 0.8757" />
                    <geom type="mesh" contype="0" conaffinity="0" group="1" rgba="0.1 0.1 0.1 1" name="gripper0_left_right_inner_finger_visual" mesh="gripper0_left_robotiq_arg2f_85_inner_finger_vis" />
                    <geom type="mesh" group="0" rgba="0 0 0.5 1" mesh="gripper0_left_robotiq_arg2f_85_inner_finger" name="gripper0_left_right_inner_finger_collision" solref="0.01 0.25" />
                    <geom size="0.011 0.003175 0.01875" pos="0 -0.0220203 0.03242" type="box" contype="0" conaffinity="0" group="1" rgba="0.9 0.9 0.9 1" name="gripper0_left_right_fingertip_visual" />
                    <geom size="0.011 0.003175 0.01875" pos="0 -0.0220203 0.03242" type="box" group="0" rgba="0 0 0.5 1" name="gripper0_left_right_fingertip_collision" solref="0.01 0.25" />
                    <geom size="0.010 0.001 0.01675" pos="0 -0.0245203 0.03242" type="box" group="0" name="gripper0_left_right_fingerpad_collision" rgba="0 0 0.5 1" />
                </body>
            </body>
            <body name="gripper0_left_right_inner_knuckle" pos="0 0.0127 0.06142">
                <inertial pos="0.000123012 0.0507851 0.00103969" quat="0.497203 0.502496 -0.507943 0.492221" mass="0.0271177" diaginertia="2.83809e-05 2.61936e-05 2.81319e-06" />
                <joint name="gripper0_left_right_inner_knuckle_joint" pos="0 0 0" axis="1 0 0" limited="true" range="0 0.8757" />
                <geom type="mesh" contype="0" conaffinity="0" group="1" rgba="0.1 0.1 0.1 1" name="gripper0_left_right_inner_knuckle_visual" mesh="gripper0_left_robotiq_arg2f_85_inner_knuckle_vis" />
                <geom type="mesh" group="0" rgba="0 0 0.5 1" mesh="gripper0_left_robotiq_arg2f_85_inner_knuckle" name="gripper0_left_right_inner_knuckle_collision" />
            </body>
        </body>
    </body>
                            
                          </body>
                          
                        </body>
                        
                      </body>
                      
                    </body>
                    
                  </body>
                  
                </body>
                
              </body>
              
            </body>
            
          </body>
        </body>
        
      </body>
    </body>
    </body>
    
  <body pos="0 0 0" name="cube_main"><geom rgba="0.5 0 0 1" density="1000" friction="1 0.005 0.0001" solref="0.02 1.0" solimp="0.9 0.95 0.001" type="box" size="0.020532910119463184 0.02040227650680866 0.02108786078049668" pos="0 0 0" group="0" name="cube_g0" /><geom conaffinity="0" contype="0" mass="1e-8" material="cube_redwood_mat" type="box" size="0.020532910119463184 0.02040227650680866 0.02108786078049668" pos="0 0 0" group="1" name="cube_g0_vis" /><joint type="free" name="cube_joint0" /><site type="sphere" group="0" pos="0 0 0" size="0.002 0.002 0.002" rgba="1 0 0 1" name="cube_default_site" /></body></worldbody>

  <equality>
  </equality>
<sensor><force name="gripper0_right_force_ee" site="gripper0_right_ft_frame" />
        <torque name="gripper0_right_torque_ee" site="gripper0_right_ft_frame" />
    <force name="gripper0_left_force_ee" site="gripper0_left_ft_frame" />
        <torque name="gripper0_left_torque_ee" site="gripper0_left_ft_frame" />
    </sensor><tendon><fixed name="gripper0_right_finger2_12_cpl" range="-1 1" stiffness="0.4" springlength="0.001" limited="true">
			<joint joint="gripper0_right_finger_joint" coef="1" />
			<joint joint="gripper0_right_left_inner_finger_joint" coef="-3" />
			<joint joint="gripper0_right_left_inner_knuckle_joint" coef="1" />
		</fixed>

		
        <fixed name="gripper0_right_finger1_12_cpl" range="-1 1" stiffness="0.4" springlength="0.001" limited="true">
			<joint joint="gripper0_right_right_outer_knuckle_joint" coef="1" />
			<joint joint="gripper0_right_right_inner_finger_joint" coef="-3" />
			<joint joint="gripper0_right_right_inner_knuckle_joint" coef="1" />
		</fixed>
	<fixed name="gripper0_left_finger2_12_cpl" range="-1 1" stiffness="0.4" springlength="0.001" limited="true">
			<joint joint="gripper0_left_finger_joint" coef="1" />
			<joint joint="gripper0_left_left_inner_finger_joint" coef="-3" />
			<joint joint="gripper0_left_left_inner_knuckle_joint" coef="1" />
		</fixed>

		
        <fixed name="gripper0_left_finger1_12_cpl" range="-1 1" stiffness="0.4" springlength="0.001" limited="true">
			<joint joint="gripper0_left_right_outer_knuckle_joint" coef="1" />
			<joint joint="gripper0_left_right_inner_finger_joint" coef="-3" />
			<joint joint="gripper0_left_right_inner_knuckle_joint" coef="1" />
		</fixed>
	</tendon><contact /></mujoco>