<mujoco model="base">
  <compiler angle="radian" meshdir="meshes/" />
  <option cone="elliptic" impratio="20" />
  <size nconmax="5000" njmax="5000" />

  <asset>
  <texture builtin="gradient" height="256" rgb1=".9 .9 1." rgb2=".2 .3 .4" type="skybox" width="256" />
    <texture builtin="checker" height="512" name="texplane" rgb1=".2 .3 .4" rgb2=".1 0.15 0.2" type="2d" width="512" />
    <texture file="/Users/ajaymandlekar/MujocoManipulation/robosuite/models/assets/arenas/../textures/light-wood.png" name="tex-light-wood" type="2d" />
    <texture file="/Users/ajaymandlekar/MujocoManipulation/robosuite/models/assets/arenas/../textures/dark-wood.png" name="tex-dark-wood" type="2d" />
    <material name="light-wood" reflectance="0.5" texrepeat="15 15" texture="tex-light-wood" texuniform="true" />
    <material name="dark-wood" reflectance="0.5" texrepeat="5 5" texture="tex-dark-wood" texuniform="true" />
    <material name="floorplane" reflectance="0.5" texrepeat="1 1" texture="texplane" texuniform="true" />
  <mesh file="/Users/ajaymandlekar/MujocoManipulation/robosuite/models/assets/robots/sawyer/meshes/pedestal.stl" name="pedestal" />
    <mesh file="/Users/ajaymandlekar/MujocoManipulation/robosuite/models/assets/robots/sawyer/meshes/base.stl" name="base" />
    <mesh file="/Users/ajaymandlekar/MujocoManipulation/robosuite/models/assets/robots/sawyer/meshes/l0.stl" name="l0" />
    <mesh file="/Users/ajaymandlekar/MujocoManipulation/robosuite/models/assets/robots/sawyer/meshes/head.stl" name="head" />
    <mesh file="/Users/ajaymandlekar/MujocoManipulation/robosuite/models/assets/robots/sawyer/meshes/l1.stl" name="l1" />
    <mesh file="/Users/ajaymandlekar/MujocoManipulation/robosuite/models/assets/robots/sawyer/meshes/l2.stl" name="l2" />
    <mesh file="/Users/ajaymandlekar/MujocoManipulation/robosuite/models/assets/robots/sawyer/meshes/l3.stl" name="l3" />
    <mesh file="/Users/ajaymandlekar/MujocoManipulation/robosuite/models/assets/robots/sawyer/meshes/l4.stl" name="l4" />
    <mesh file="/Users/ajaymandlekar/MujocoManipulation/robosuite/models/assets/robots/sawyer/meshes/l5.stl" name="l5" />
    <mesh file="/Users/ajaymandlekar/MujocoManipulation/robosuite/models/assets/robots/sawyer/meshes/l6.stl" name="l6" />
  <mesh file="/Users/ajaymandlekar/MujocoManipulation/robosuite/models/assets/grippers/meshes/two_finger_gripper/electric_gripper_base.STL" name="electric_gripper_base" />
        <mesh file="/Users/ajaymandlekar/MujocoManipulation/robosuite/models/assets/grippers/meshes/two_finger_gripper/standard_narrow.STL" name="standard_narrow" />
        <mesh file="/Users/ajaymandlekar/MujocoManipulation/robosuite/models/assets/grippers/meshes/two_finger_gripper/half_round_tip.STL" name="half_round_tip" />
    <mesh file="/Users/ajaymandlekar/MujocoManipulation/robosuite/models/assets/objects/meshes/milk.stl" name="milk_mesh" scale="0.9 0.9 0.9" />
    <texture file="/Users/ajaymandlekar/MujocoManipulation/robosuite/models/assets/objects/../textures/ceramic.png" name="tex-ceramic" />
    <material name="ceramic" reflectance="0.5" texrepeat="1 1" texture="tex-ceramic" texuniform="true" />
  <mesh file="/Users/ajaymandlekar/MujocoManipulation/robosuite/models/assets/objects/meshes/bread.stl" name="bread_mesh" scale="0.8 0.8 0.8" />
    <texture file="/Users/ajaymandlekar/MujocoManipulation/robosuite/models/assets/objects/../textures/bread.png" name="tex-bread" type="2d" />
    <material name="bread" reflectance="0.7" texrepeat="15 15" texture="tex-bread" texuniform="true" />
  <mesh file="/Users/ajaymandlekar/MujocoManipulation/robosuite/models/assets/objects/meshes/cereal.stl" name="cereal_mesh" scale="0.4 1.0 0.4" />
    <texture file="/Users/ajaymandlekar/MujocoManipulation/robosuite/models/assets/objects/../textures/cereal.png" name="tex-cereal" rgb1="1 1 1" type="cube" />
    <material name="cereal" reflectance="0.5" texrepeat="3 3" texture="tex-cereal" texuniform="false" />
  <mesh file="/Users/ajaymandlekar/MujocoManipulation/robosuite/models/assets/objects/meshes/can.stl" name="can_mesh" />
    <texture file="/Users/ajaymandlekar/MujocoManipulation/robosuite/models/assets/objects/../textures/can.png" name="tex-can" />
    <material name="coke" reflectance="0.7" texrepeat="5 5" texture="tex-can" texuniform="true" />
  </asset>

  <actuator>
  <velocity ctrllimited="true" ctrlrange="-1.74 1.74" joint="right_j0" kv="8.0" name="vel_right_j0" />
        <velocity ctrllimited="true" ctrlrange="-1.328 1.328" joint="right_j1" kv="7.0" name="vel_right_j1" />
        <velocity ctrllimited="true" ctrlrange="-1.957 1.957" joint="right_j2" kv="6.0" name="vel_right_j2" />
        <velocity ctrllimited="true" ctrlrange="-1.957 1.957" joint="right_j3" kv="4.0" name="vel_right_j3" />
        <velocity ctrllimited="true" ctrlrange="-3.485 3.485" joint="right_j4" kv="2.0" name="vel_right_j4" />
        <velocity ctrllimited="true" ctrlrange="-3.485 3.485" joint="right_j5" kv="0.5" name="vel_right_j5" />
        <velocity ctrllimited="true" ctrlrange="-4.545 4.545" joint="right_j6" kv="0.1" name="vel_right_j6" />
  <position ctrllimited="true" ctrlrange="-0.0115 0.020833" forcelimited="true" forcerange="-20 20" joint="r_gripper_r_finger_joint" kp="10000" name="gripper_r_gripper_r_finger_joint" />
        <position ctrllimited="true" ctrlrange="-0.020833 0.0115" forcelimited="true" forcerange="-20 20" joint="r_gripper_l_finger_joint" kp="10000" name="gripper_r_gripper_l_finger_joint" />

    </actuator>

  <worldbody>
  <geom condim="3" material="floorplane" name="floor" pos="0.5 -0.3 0.0" size="3 3 .125" type="plane" />
    <geom pos="0.6 0.2 0.7" rgba="0 0 0 0" size="0.5 1 .2" type="plane" />
    <body name="bin1" pos="0.6 -0.15 0.8">
      <geom friction="1 0.005 0.0001" pos="0 0 0" size="0.2 0.25 0.02" type="box" />
      <geom conaffinity="0" contype="0" group="1" material="light-wood" pos="0 0 0" size="0.2 0.25 0.02" type="box" />
        <geom friction="1 0.005 0.0001" pos="0 0.25 0.05" rgba="0 0 1 1" size="0.21 0.01 0.05" type="box" />
        <geom conaffinity="0" contype="0" group="1" material="light-wood" pos="0 0.25 0.05" size="0.21 0.01 0.05" type="box" />
        <geom friction="1 0.005 0.0001" pos="0 -0.25 0.05" rgba="0 0 1 1" size="0.21 0.01 0.05" type="box" />
        <geom conaffinity="0" contype="0" group="1" material="light-wood" pos="0 -0.25 0.05" size="0.21 0.01 0.05" type="box" />
        <geom friction="1 0.005 0.0001" pos="0.2 0 0.05" rgba="0 0 1 1" size="0.01 0.25 0.05" type="box" />
        <geom conaffinity="0" contype="0" group="1" material="light-wood" pos="0.2 0 0.05" size="0.01 0.25 0.05" type="box" />
        <geom friction="1 0.005 0.0001" pos="-0.2 0 0.05" rgba="0 0 1 1" size="0.01 0.25 0.05" type="box" />
        <geom conaffinity="0" contype="0" group="1" material="light-wood" pos="-0.2 0 0.05" size="0.01 0.25 0.05" type="box" />
    </body>
    <body name="bin2" pos="0.6 0.38000000000000006 0.8">
      <geom friction="1 0.005 0.0001" pos="0 0 0" size="0.2 0.25 0.02" type="box" />
      <geom conaffinity="0" contype="0" group="1" material="dark-wood" pos="0 0 0" size="0.2 0.25 0.02" type="box" />
        <geom friction="1 0.005 0.0001" pos="0 0.25 0.05" rgba="1 0 0 1" size="0.21 0.01 0.05" type="box" />
        <geom conaffinity="0" contype="0" group="1" material="dark-wood" pos="0 0.25 0.05" size="0.21 0.01 0.05" type="box" />
        <geom friction="1 0.005 0.0001" pos="0 0 0.05" rgba="1 0 0 1" size="0.2 0.01 0.05" type="box" />
        <geom conaffinity="0" contype="0" group="1" material="dark-wood" pos="0 0 0.05" size="0.2 0.01 0.05" type="box" />
        <geom friction="1 0.005 0.0001" pos="0 -0.25 0.05" rgba="1 0 0 1" size="0.21 0.01 0.05" type="box" />
        <geom conaffinity="0" contype="0" group="1" material="dark-wood" pos="0 -0.25 0.05" size="0.21 0.01 0.05" type="box" />
        <geom friction="1 0.005 0.0001" pos="0.2 0 0.05" rgba="1 0 0 1" size="0.01 0.25 0.05" type="box" />
        <geom conaffinity="0" contype="0" group="1" material="dark-wood" pos="0.2 0 0.05" size="0.01 0.25 0.05" type="box" />
        <geom friction="1 0.005 0.0001" pos="0 0 0.05" rgba="1 0 0 1" size="0.01 0.25 0.05" type="box" />
        <geom conaffinity="0" contype="0" group="1" material="dark-wood" pos="0 0 0.05" size="0.01 0.25 0.05" type="box" />
        <geom friction="1 0.005 0.0001" pos="-0.2 0 0.05" rgba="1 0 0 1" size="0.01 0.25 0.05" type="box" />
        <geom conaffinity="0" contype="0" group="1" material="dark-wood" pos="-0.2 0 0.05" size="0.01 0.25 0.05" type="box" />
    </body>

    <light castshadow="false" diffuse=".8 .8 .8" dir="0 -.15 -1" directional="false" pos="1.5 0.7 4.0" specular="0.3 0.3 0.3" />
    <light castshadow="false" diffuse=".8 .8 .8" dir="0 -.15 -1" directional="false" pos="-2.5 -3.3 4.0" specular="0.3 0.3 0.3" />
    
    <camera mode="fixed" name="frontview" pos="2.1 0.10000000000000003 1.45" quat="0.56 0.43 0.43 0.56" />
    
    <camera mode="fixed" name="birdview" pos="0.3 0.10000000000000003 3.0" quat="0.7071 0 0 0.7071" />
    
    <camera mode="fixed" name="agentview" pos="1.5 0.10000000000000003 1.75" quat="0.653 0.271 0.271 0.653" />
  <body name="base" pos="0.0 0.0 0.913">
      <inertial diaginertia="0 0 0" mass="0" pos="0 0 0" />
      <body name="controller_box" pos="0 0 0">
        <inertial diaginertia="1.71363 1.27988 0.809981" mass="46.64" pos="-0.325 0 -0.38" />
        <geom pos="-0.325 0 -0.38" size="0.11 0.2 0.265" type="box" />
      </body>
      <body name="pedestal_feet" pos="0 0 0">
        <inertial diaginertia="8.16095 9.59375 15.0785" mass="167.09" pos="-0.1225 0 -0.758" />
        <geom pos="-0.1225 0 -0.758" size="0.385 0.35 0.155" type="box" />
      </body>
      <body name="torso" pos="0 0 0">
        <inertial diaginertia="1e-08 1e-08 1e-08" mass="0.0001" pos="0 0 0" />
        <geom conaffinity="0" contype="0" group="1" rgba="0.2 0.2 0.2 1" size="0.05 0.05 0.05" type="box" />
      </body>
      <body name="pedestal" pos="0 0 0">
        <inertial diaginertia="6.0869 5.81635 4.20915" mass="60.864" pos="0 0 0" quat="0.659267 -0.259505 -0.260945 0.655692" />
        <geom conaffinity="0" contype="0" group="1" mesh="pedestal" pos="0.26 0.345 -0.91488" quat="0.5 0.5 -0.5 -0.5" rgba="0.2 0.2 0.2 1" type="mesh" />
        <geom pos="-0.02 0 -0.29" rgba="0.2 0.2 0.2 1" size="0.18 0.31" type="cylinder" />
      </body>
      <body name="right_arm_base_link" pos="0 0 0">
        <inertial diaginertia="0.00740351 0.00681776 0.00672942" mass="2.0687" pos="-0.0006241 -2.8025e-05 0.065404" quat="-0.209285 0.674441 0.227335 0.670558" />
        <geom conaffinity="0" contype="0" group="1" mesh="base" rgba="0.5 0.1 0.1 1" type="mesh" />
        <geom pos="0 0 0.12" rgba="0.5 0.1 0.1 1" size="0.08 0.12" type="cylinder" />
        <body name="right_l0" pos="0 0 0.08">
          <inertial diaginertia="0.0651588 0.0510944 0.0186218" mass="5.3213" pos="0.024366 0.010969 0.14363" quat="0.894823 0.00899958 -0.170275 0.412573" />
          <joint axis="0 0 1" limited="true" name="right_j0" pos="0 0 0" range="-3.0503 3.0503" />
          <geom conaffinity="0" contype="0" group="1" mesh="l0" rgba="0.5 0.1 0.1 1" type="mesh" />
          <geom pos="0.08 0 0.23" rgba="0.5 0.1 0.1 1" size="0.07" />
          <body name="head" pos="0 0 0.2965">
            <inertial diaginertia="0.0118334 0.00827089 0.00496574" mass="1.5795" pos="0.0053207 -2.6549e-05 0.1021" quat="0.999993 7.08405e-05 -0.00359857 -0.000626247" />
            <joint axis="0 0 1" limited="true" name="head_pan" pos="0 0 0" range="-5.0952 0.9064" />
            <geom conaffinity="0" contype="0" group="1" mesh="head" rgba="0.5 0.1 0.1 1" type="mesh" />
            <geom pos="0 0 0.08" rgba="0.5 0.1 0.1 1" size="0.018" />
            <body name="screen" pos="0.03 0 0.105" quat="0.5 0.5 0.5 0.5">
              <inertial diaginertia="1e-08 1e-08 1e-08" mass="0.0001" pos="0 0 0" />
              <geom conaffinity="0" contype="0" group="1" rgba="0.2 0.2 0.2 1" size="0.12 0.07 0.001" type="box" />
              <geom rgba="0.2 0.2 0.2 1" size="0.001" />
            </body>
            <body name="head_camera" pos="0.0228027 0 0.216572" quat="0.342813 -0.618449 0.618449 -0.342813">
              <inertial diaginertia="0 0 0" mass="0" pos="0.0228027 0 0.216572" quat="0.342813 -0.618449 0.618449 -0.342813" />
            </body>
          </body>
          <body name="right_torso_itb" pos="-0.055 0 0.22" quat="0.707107 0 -0.707107 0">
            <inertial diaginertia="1e-08 1e-08 1e-08" mass="0.0001" pos="0 0 0" />
          </body>
          <body name="right_l1" pos="0.081 0.05 0.237" quat="0.5 -0.5 0.5 0.5">
            <inertial diaginertia="0.0224339 0.0221624 0.0097097" mass="4.505" pos="-0.0030849 -0.026811 0.092521" quat="0.424888 0.891987 0.132364 -0.0794296" />
            <joint axis="0 0 1" limited="true" name="right_j1" pos="0 0 0" range="-3.8095 2.2736" />
            <geom conaffinity="0" contype="0" group="1" mesh="l1" rgba="0.5 0.1 0.1 1" type="mesh" />
            <geom pos="0 0 0.1225" rgba="0.5 0.1 0.1 1" size="0.07" />
            <body name="right_l2" pos="0 -0.14 0.1425" quat="0.707107 0.707107 0 0">
              <inertial diaginertia="0.0257928 0.025506 0.00292515" mass="1.745" pos="-0.00016044 -0.014967 0.13582" quat="0.707831 -0.0524761 0.0516007 0.702537" />
              <joint axis="0 0 1" limited="true" name="right_j2" pos="0 0 0" range="-3.0426 3.0426" />
              <geom conaffinity="0" contype="0" group="1" mesh="l2" rgba="0.5 0.1 0.1 1" type="mesh" />
              <geom pos="0 0 0.08" rgba="0.5 0.1 0.1 1" size="0.06 0.17" type="cylinder" />
              <body name="right_l3" pos="0 -0.042 0.26" quat="0.707107 -0.707107 0 0">
                <inertial diaginertia="0.0102404 0.0096997 0.00369622" mass="2.5097" pos="-0.0048135 -0.0281 -0.084154" quat="0.902999 0.385391 -0.0880901 0.168247" />
                <joint axis="0 0 1" limited="true" name="right_j3" pos="0 0 0" range="-3.0439 3.0439" />
                <geom conaffinity="0" contype="0" group="1" mesh="l3" rgba="0.5 0.1 0.1 1" type="mesh" />
                <geom pos="0 -0.01 -0.12" rgba="0.5 0.1 0.1 1" size="0.06" />
                <body name="right_l4" pos="0 -0.125 -0.1265" quat="0.707107 0.707107 0 0">
                  <inertial diaginertia="0.0136549 0.0135493 0.00127353" mass="1.1136" pos="-0.0018844 0.0069001 0.1341" quat="0.803612 0.031257 -0.0298334 0.593582" />
                  <joint axis="0 0 1" limited="true" name="right_j4" pos="0 0 0" range="-2.9761 2.9761" />
                  <geom conaffinity="0" contype="0" group="1" mesh="l4" rgba="0.5 0.1 0.1 1" type="mesh" />
                  <geom pos="0 0 0.11" rgba="0.5 0.1 0.1 1" size="0.045 0.15" type="cylinder" />
                  <body name="right_arm_itb" pos="-0.055 0 0.075" quat="0.707107 0 -0.707107 0">
                    <inertial diaginertia="1e-08 1e-08 1e-08" mass="0.0001" pos="0 0 0" />
                  </body>
                  <body name="right_l5" pos="0 0.031 0.275" quat="0.707107 -0.707107 0 0">
                    <inertial diaginertia="0.00474131 0.00422857 0.00190672" mass="1.5625" pos="0.0061133 -0.023697 0.076416" quat="0.404076 0.9135 0.0473125 0.00158335" />
                    <joint axis="0 0 1" damping="0.2" limited="true" name="right_j5" pos="0 0 0" range="-2.9761 2.9761" />
                    <geom conaffinity="0" contype="0" group="1" mesh="l5" rgba="0.5 0.1 0.1 1" type="mesh" />
                    <geom pos="0 0 0.1" rgba="0.5 0.1 0.1 1" size="0.06" />
                    <body name="right_hand_camera" pos="0.039552 -0.033 0.0695" quat="0.707107 0 0.707107 0">
                      <inertial diaginertia="0 0 0" mass="0" pos="0.039552 -0.033 0.0695" quat="0.707107 0 0.707107 0" />
                    </body>
                    <body name="right_wrist" pos="0 0 0.10541" quat="0.707107 0.707107 0 0">
                      <inertial diaginertia="0 0 0" mass="0" pos="0 0 0.10541" quat="0.707107 0.707107 0 0" />
                    </body>
                    <body name="right_l6" pos="0 -0.11 0.1053" quat="0.0616248 0.06163 -0.704416 0.704416">
                      <inertial diaginertia="0.000360258 0.000311068 0.000214974" mass="0.3292" pos="-8.0726e-06 0.0085838 -0.0049566" quat="0.479044 0.515636 -0.513069 0.491322" />
                      <joint axis="0 0 1" damping="0.1" limited="true" name="right_j6" pos="0 0 0" range="-4.7124 4.7124" />
                      <geom conaffinity="0" contype="0" group="1" mesh="l6" rgba="0.5 0.1 0.1 1" type="mesh" />
                      <geom pos="0 0.015 -0.01" rgba="0.5 0.1 0.1 1" size="0.055 0.025" type="cylinder" />
                      <body name="right_hand" pos="0 0 0.0245" quat="0.707105 0 0 0.707108">
                                              
                                          <inertial diaginertia="1e-08 1e-08 1e-08" mass="1e-08" pos="1e-08 1e-08 1e-08" quat="0.820473 0.339851 -0.17592 0.424708" />
        <geom size="1e-08 5e-09" type="cylinder" />
        <body name="right_gripper_base" pos="0 0 0.025">
            <inertial diaginertia="3e-08 2e-08 2e-08" mass="0.3" pos="0 0 0" quat="-0.5 0.5 0.5 0.5" />
            <geom conaffinity="0" contype="0" group="1" mesh="electric_gripper_base" quat="0 0 0.707107 0.707107" type="mesh" />
            <geom quat="0 0 0.707107 0.707107" size="0.029 0.05" type="cylinder" />
            <body name="right_gripper" pos="0 0 0.095">
                <inertial diaginertia="0 0 0" mass="0.0001" pos="0 0 0" />
                
                <site group="1" name="grip_site" pos="0 0 0" rgba="1 0 0 1" size="0.01 0.01 0.01" type="sphere" />
                
                <site group="1" name="grip_site_cylinder" pos="0 0 0" rgba="0 1 0 0.3" size="0.005 10" type="cylinder" />
                
                <camera fovy="75" mode="fixed" name="eye_in_hand" pos="0 0 0" quat="0 -1 1 0" />
            </body>
            
            
            <body name="r_gripper_l_finger" pos="0 0.01 0.02">
                <inertial diaginertia="0.01 0.01 0.01" mass="0.02" pos="0 0 0" quat="0 0 0 -1" />
                

                

                

                
                <joint axis="0 1 0" damping="100" limited="true" name="r_gripper_l_finger_joint" pos="0 0 0" range="-0.0115 0.020833" type="slide" />

                <geom conaffinity="0" contype="0" group="1" mesh="standard_narrow" name="r_gripper_l_finger" quat="0 0 0 -1" type="mesh" />

                
                

                
                <geom conaffinity="1" contype="0" friction="0 0 0" name="l_finger_g0" pos="0 0.01725 0.04" quat="0 0 0 -1" size="0.005 0.00675 0.0375" type="box" />
                <geom conaffinity="1" contype="0" friction="0 0 0" name="l_finger_g1" pos="-0.005 -0.003 0.0083" quat="0 0 0 -1" size="0.005 0.025 0.0085" type="box" />

                <body name="r_gripper_l_finger_tip" pos="0 0.01725 0.075">
                    <inertial diaginertia="0.01 0.01 0.01" mass="0.01" pos="0 0 0" quat="0 0 0 1" />
                    <geom conaffinity="0" contype="0" group="1" mesh="half_round_tip" quat="0 0 0 1" type="mesh" />

                    
                    

                    
                    <geom conaffinity="1" contype="0" friction="0 0 0" name="l_fingertip_g0" pos="0 -0.0045 -0.015" quat="0 0 0 1" size="0.004 0.004 0.0185" type="box" />

                    
                    

                    
                    

                </body>
            </body>
            
            
            <body name="r_gripper_r_finger" pos="0 -0.01 0.02">
                <inertial diaginertia="0.01 0.01 0.01" mass="0.02" pos="0 0 0" />
                

                

                

                
                <joint axis="0 1 0" damping="100" limited="true" name="r_gripper_r_finger_joint" pos="0 0 0" range="-0.020833 0.0115" type="slide" />

                <geom conaffinity="0" contype="0" group="1" mesh="standard_narrow" name="r_gripper_r_finger" type="mesh" />

                
                

                
                <geom conaffinity="1" contype="0" friction="0 0 0" name="r_finger_g0" pos="0 -0.01725 0.04" size="0.005 0.00675 0.0375" type="box" />
                <geom conaffinity="1" contype="0" friction="0 0 0" name="r_finger_g1" pos="0.005 0.003 0.0083" size="0.005 0.025 0.0085" type="box" />


                <body name="r_gripper_r_finger_tip" pos="0 -0.01725 0.075">
                    <inertial diaginertia="0.01 0.01 0.01" mass="0.01" pos="0 0 0" />
                    <geom conaffinity="0" contype="0" group="1" mesh="half_round_tip" type="mesh" />

                    
                    

                    
                    <geom conaffinity="1" contype="0" friction="0 0 0" name="r_fingertip_g0" pos="0 0.0045 -0.015" size="0.004 0.004 0.0185" type="box" />

                    
                    

                    
                    

                </body>
            </body>
        </body>
    </body>
                    </body>
                  </body>
                  <body name="right_l4_2" pos="0 0 0">
                    <inertial diaginertia="1e-08 1e-08 1e-08" mass="1e-08" pos="1e-08 1e-08 1e-08" quat="0.820473 0.339851 -0.17592 0.424708" />
                    <geom pos="0 0.01 0.26" size="0.06" />
                  </body>
                </body>
              </body>
              <body name="right_l2_2" pos="0 0 0">
                <inertial diaginertia="1e-08 1e-08 1e-08" mass="1e-08" pos="1e-08 1e-08 1e-08" quat="0.820473 0.339851 -0.17592 0.424708" />
                <geom pos="0 0 0.26" size="0.06" />
              </body>
            </body>
            <body name="right_l1_2" pos="0 0 0">
              <inertial diaginertia="1e-08 1e-08 1e-08" mass="1e-08" pos="1e-08 1e-08 1e-08" quat="0.820473 0.339851 -0.17592 0.424708" />
              <geom pos="0 0 0.035" size="0.07 0.07" type="cylinder" />
            </body>
          </body>
        </body>
      </body>
    </body>
  <body name="Milk0" pos="0.5914725062856444 -0.20688955777032125 0.885" quat="-0.6014140322206998 0 0 0.7989375206159985">
        <geom condim="4" density="100" friction="0.95 0.3 0.1" group="1" material="ceramic" mesh="milk_mesh" name="Milk0" pos="0 0 0" solimp="0.998 0.998 0.001" solref="0.001 1" type="mesh" />
      <site name="Milk0" pos="0 0 0" rgba="1 0 0 0" size="0.002 0.002 0.002" type="sphere" /><joint damping="0.0005" name="Milk0" type="free" /></body>
      <body name="Bread0" pos="0.658981625362531 -0.026282214990152125 0.8450000000000001" quat="0.9516242742791996 0 0 0.30726412189285424">
        <geom condim="4" density="50" friction="0.95 0.3 0.1" group="1" material="bread" mesh="bread_mesh" name="Bread0" pos="0 0 0" solimp="0.998 0.998 0.001" solref="0.001 1" type="mesh" />
      <site name="Bread0" pos="0 0 0" rgba="1 0 0 0" size="0.002 0.002 0.002" type="sphere" /><joint damping="0.0005" name="Bread0" type="free" /></body>
      <body name="Cereal0" pos="0.6190806537739068 -0.09894565421828824 0.8500000000000001" quat="-0.3598453233837343 0 0 0.933011973791792">
        <geom condim="4" density="150" friction="0.95 0.3 0.1" group="1" material="cereal" mesh="cereal_mesh" name="Cereal0" pos="0 0 0" solimp="0.998 0.998 0.001" solref="0.001 1" type="mesh" />
      <site name="Cereal0" pos="0 0 0" rgba="1 0 0 0" size="0.002 0.002 0.002" type="sphere" /><joint damping="0.0005" name="Cereal0" type="free" /></body>
      <body name="Can0" pos="0.5737912727003498 -0.05982020186216466 0.8600000000000001" quat="-0.991496825849005 0 0 0.13013087385915742">
        <geom condim="4" density="100" friction="0.95 0.3 0.1" group="1" material="coke" mesh="can_mesh" name="Can0" pos="0 0 0" solimp="0.998 0.998 0.001" solref="0.001 1" type="mesh" />
      <site name="Can0" pos="0 0 0" rgba="1 0 0 0" size="0.002 0.002 0.002" type="sphere" /><joint damping="0.0005" name="Can0" type="free" /></body>
      <body name="&lt;class 'robosuite.models.objects.xml_objects.MilkVisualObject'&gt;" pos="0.5025 0.25750000000000006 0.885">
        <geom conaffinity="0" contype="0" group="0" mass="0.0001" mesh="milk_mesh" pos="0 0 0" rgba="0.8 0.8 0.8 0.3" type="mesh" />
        <geom conaffinity="0" contype="0" group="1" mass="0.0001" mesh="milk_mesh" pos="0 0 0" rgba="0.8 0.8 0.8 0.3" type="mesh" />
      </body>
      <body name="&lt;class 'robosuite.models.objects.xml_objects.BreadVisualObject'&gt;" pos="0.6975 0.25750000000000006 0.8450000000000001">
        <geom conaffinity="0" contype="0" group="0" mass="0.0001" mesh="bread_mesh" pos="0 0 0" rgba="0.8 0.8 0.8 0.3" type="mesh" />
        <geom conaffinity="0" contype="0" group="1" mass="0.0001" mesh="bread_mesh" pos="0 0 0" rgba="0.8 0.8 0.8 0.3" type="mesh" />
      </body>
      <body name="&lt;class 'robosuite.models.objects.xml_objects.CerealVisualObject'&gt;" pos="0.5025 0.5025000000000001 0.8500000000000001">
        <geom conaffinity="0" contype="0" group="0" mass="0.0001" mesh="cereal_mesh" pos="0 0 0" rgba="0.8 0.8 0.8 0.3" type="mesh" />
        <geom conaffinity="0" contype="0" group="1" mass="0.0001" mesh="cereal_mesh" pos="0 0 0" rgba="0.8 0.8 0.8 0.3" type="mesh" />
      </body>
      <body name="&lt;class 'robosuite.models.objects.xml_objects.CanVisualObject'&gt;" pos="0.6975 0.5025000000000001 0.8600000000000001">
        <geom conaffinity="0" contype="0" group="0" mass="0.0001" mesh="can_mesh" pos="0 0 0" rgba="0.8 0.8 0.8 0.3" type="mesh" />
        <geom conaffinity="0" contype="0" group="1" mass="0.0001" mesh="can_mesh" pos="0 0 0" rgba="0.8 0.8 0.8 0.3" type="mesh" />
      </body>
      </worldbody>

  <equality>
  </equality>
<contact /><default /></mujoco>