<mujoco model="GR1T1">
    <compiler angle="radian" autolimits="true"/>
    <default>
    <motor ctrlrange="-1 1" ctrllimited="true"/>
        <default class="body">
            <geom type="box" condim="1" friction="1.0 0.05 0.05" solimp=".9 .99 .003" solref=".015 1"/>
            <joint type="hinge" armature=".007" limited="true" solimplimit="0 .99 .01"/>
            <site size="10" group="3"/>
        </default>
  </default>
  <asset>
    <material name="LightGrey" specular="0.9" shininess="0.9" rgba="0.4 0.4 0.4 1.0"/>
    <material name="Purple" specular="0.9" shininess="0.9" rgba="0.58 0.42 0.58 1.0"/>
    <material name="Black" specular="0.9" shininess="0.9" rgba="0.1 0.1 0.1 1.0"/>
    <texture type="skybox" builtin="gradient" rgb1=".3 .5 .7" rgb2="0 0 0" width="32" height="512"/>
    <texture name="body" type="cube" builtin="flat" mark="cross" width="128" height="128" rgb1="0.8 0.6 0.4" rgb2="0.8 0.6 0.4" markrgb="1 1 1" random="0.01"/>
    <material name="body" texture="body" texuniform="true" rgba="0.8 0.6 .4 1"/>
    <texture name="grid" type="2d" builtin="checker" width="512" height="512" rgb1=".1 .2 .3" rgb2=".2 .3 .4"/>
    <material name="grid" texture="grid" texrepeat="1 1" texuniform="true" reflectance="0.02"/>

    <!-- Define mesh model files -->
    <mesh name="base" file="./meshes/base.STL"/>
    <mesh name="l_thigh_roll" file="./meshes/l_thigh_roll.STL"/>
    <mesh name="l_thigh_yaw" file="./meshes/l_thigh_yaw.STL"/>
    <mesh name="l_thigh_pitch" file="./meshes/l_thigh_pitch.STL"/>
    <mesh name="l_shank_pitch" file="./meshes/l_shank_pitch.STL"/>
    <mesh name="l_foot_pitch" file="./meshes/l_foot_pitch.STL"/>
    <mesh name="l_foot_roll" file="./meshes/l_foot_roll.STL"/>
    <mesh name="r_thigh_roll" file="./meshes/r_thigh_roll.STL"/>
    <mesh name="r_thigh_yaw" file="./meshes/r_thigh_yaw.STL"/>
    <mesh name="r_thigh_pitch" file="./meshes/r_thigh_pitch.STL"/>
    <mesh name="r_shank_pitch" file="./meshes/r_shank_pitch.STL"/>
    <mesh name="r_foot_pitch" file="./meshes/r_foot_pitch.STL"/>
    <mesh name="r_foot_roll" file="./meshes/r_foot_roll.STL"/>
    <mesh name="torso_waist_yaw" file="./meshes/waist_yaw.STL"/>
    <mesh name="torso_waist_pitch" file="./meshes/waist_pitch.STL"/>
    <mesh name="torso_waist_roll" file="./meshes/torso.STL"/>
    <mesh name="head_yaw" file="./meshes/head_yaw.STL"/>
    <mesh name="head_roll" file="./meshes/head_roll.STL"/>
    <mesh name="head_pitch" file="./meshes/head_pitch.STL"/>
    <mesh name="l_upper_arm_pitch" file="./meshes/l_upper_arm_pitch.STL"/>
    <mesh name="l_upper_arm_roll" file="./meshes/l_upper_arm_roll.STL"/>
    <mesh name="l_upper_arm_yaw" file="./meshes/l_upper_arm_yaw.STL"/>
    <mesh name="l_lower_arm_pitch" file="./meshes/l_lower_arm_pitch.STL"/>
    <mesh name="l_hand_yaw" file="./meshes/l_hand_yaw.STL"/>
    <mesh name="l_hand_roll" file="./meshes/l_hand_roll.STL"/>
    <mesh name="l_hand_pitch" file="./meshes/l_hand_pitch.STL"/>
    <mesh name="r_upper_arm_pitch" file="./meshes/r_upper_arm_pitch.STL"/>
    <mesh name="r_upper_arm_roll" file="./meshes/r_upper_arm_roll.STL"/>
    <mesh name="r_upper_arm_yaw" file="./meshes/r_upper_arm_yaw.STL"/>
    <mesh name="r_lower_arm_pitch" file="./meshes/r_lower_arm_pitch.STL"/>
    <mesh name="r_hand_yaw" file="./meshes/r_hand_yaw.STL"/>
    <mesh name="r_hand_roll" file="./meshes/r_hand_roll.STL"/>
    <mesh name="r_hand_pitch" file="./meshes/r_hand_pitch.STL"/>
    <!-- End of mesh model files -->
  </asset>
  <worldbody>
        <!-- Camera for observing hands-->
        <!-- <camera name="obs_hands" pos="0.035 0.000 1.535" xyaxes="0.000 1.000 0.000 -0.707 0.000 0.707"/> -->
    <!-- Base -->
    <body name="base">
        <inertial pos="-0.0508888 0.000109183 -0.0455794" quat="0.706855 0.707166 0.0123661 -0.0109307" mass="6.45117" diaginertia="0.0149302 0.0127972 0.00640923"/>
        <!-- <inertial diaginertia="0 0 0" mass="0" pos="0 0 0"/> -->
        <!-- Base mesh -->
        <freejoint/>
        <!-- <joint armature="0" damping="0" limited="false" name="root" pos="0 0 0" stiffness="0" type="free"/> -->
        <!-- Torso center of mass -->
        <!-- <body name="torso_link">
            <body name="base_com" />
        </body> -->

        <body name="whole_body">
            <geom type="mesh" contype="0" conaffinity="0" group="1" density="0" material="Purple" mesh="base"/>
            <geom size="0.04 0.04 0.04" pos="0 0 -0.06" type="box" material="LightGrey"/>

            <!-- Torso -->
            <!-- Waist yaw -->
            <body name="torso_waist_yaw" pos="0 0 0.0065">
                <site name="waist" pos="0 0 0" size="0.06 0.06 0.06" rgba="1 0 0 0" type="sphere" group="1"/>
                <inertial pos="-0.010388 -0.00169636 0.0224709" quat="8.03475e-05 0.752953 -6.91813e-06 0.658075" mass="0.37886" diaginertia="0.000387148 0.000354992 0.000193448"/>
                <joint name="torso_waist_yaw" pos="0 0 0" damping="50.4164" stiffness="453.15" axis="-1.221e-05 -6.8349e-05 1" range="-1.05 1.05"/>

                <geom type="mesh" contype="0" conaffinity="0" group="1" density="0" material="LightGrey" mesh="torso_waist_yaw"/>
                <geom size="0.04 0.04 0.04" pos="0 0 -0.06" quat="0.707388 0.706825 0 0" type="box" material="LightGrey"/>

                <!-- Waist pitch -->
                <body name="torso_waist_pitch" pos="0 0 0.055">
                    <inertial pos="0.00229173 -0.00229364 0.0425378" quat="0.998452 -0.0194486 0.0162447 0.0495079" mass="4.40328" diaginertia="0.00487449 0.00487146 0.00355351"/>
                    <joint name="torso_waist_pitch" pos="0 0 0" damping="50.4164" stiffness="453.15" axis="0 1 -6.8349e-05" range="-0.52 1.22"/>

                    <geom type="mesh" contype="0" conaffinity="0" group="1" density="0" material="LightGrey" mesh="torso_waist_pitch"/>
                    <geom size="0.04 0.04 0.06" type="box" material="LightGrey"/>

                    <!-- Waist roll -->
                    <body name="torso_waist_roll" pos="0 0 0.085">
                        <site name="chest" pos="0 0 0.2" size="0.06 0.06 0.06" rgba="1 0 0 0" type="sphere" group="1"/>
                        <inertial pos="-0.00982804 -1.2954e-05 0.160653" quat="0.999997 1.84368e-05 -0.00260593 -4.00255e-05" mass="7.34393" diaginertia="0.0305266 0.0217567 0.0136783"/>
                        <joint name="torso_waist_roll" pos="0 0 0" damping="50.4164" stiffness="453.15" axis="1 0 1.221e-05" range="-0.7 0.7"/>

                        <geom pos="0 0 0.15" type="mesh" contype="0" conaffinity="0" group="1" density="0" material="LightGrey" mesh="torso_waist_roll"/>
                        <geom size="0.09 0.09 0.09" pos="0 0 0.15" type="box" material="LightGrey"/>

                        <!-- Head yaw -->
                        <body name="head_yaw" pos="0.001 -0.00022551 0.295">
                            <site name="neck" pos="0 0 0" size="0.03 0.03 0.03" rgba="1 0 0 0" type="sphere" group="1"/>
                            <inertial pos="0.000255273 -1.43143e-05 0.0571737" quat="0.698659 0.111628 0.112302 0.697713" mass="0.168425" diaginertia="0.00013241 0.000126266 6.86988e-05"/>
                            <joint name="head_yaw" pos="0 0 0" axis="-1.221e-05 -6.8349e-05 1" range="-1.5707963267948966 1.5707963267948966" damping="7" armature="1.0" frictionloss="0.2"/>

                            <geom type="mesh" contype="0" conaffinity="0" group="1" density="0" material="LightGrey" mesh="head_yaw"/>
                            <geom size="0.02 0.02 0.02" pos="0 0 -0.03" type="box" material="LightGrey"/>

                            <!-- Head roll -->
                            <body name="head_roll" pos="0 0 0">
                                <inertial pos="-0.000539717 0.00299723 -0.00194711" quat="0.498775 0.509039 0.50481 0.487104" mass="0.0189574" diaginertia="5.66154e-06 3.71917e-06 3.07146e-06"/>
                                <joint name="head_roll" pos="0 0 0" axis="1 0 1.221e-05" range="-0.2617993877991494 0.2617993877991494" damping="7" armature="1.0" frictionloss="0.2"/>

                                <geom type="mesh" contype="0" conaffinity="0" group="1" density="0" material="LightGrey" mesh="head_roll"/>
                                <geom size="0.02 0.02 0.02" pos="0 0 -0.1" type="box" material="LightGrey"/>

                                <!-- Head pitch -->
                                <body name="head_pitch" pos="0 5.373E-05 0.036">
                                    <site name="head" pos="0 0 0" size="0.06 0.06 0.06" rgba="1 0 0 0" type="sphere" group="1"/>
                                    <inertial pos="0.0179937 0.000157203 -0.0107884" quat="-0.00317787 0.890883 0.0047882 0.454197" mass="0.315067" diaginertia="0.00129389 0.00105273 0.000852366"/>
                                    <joint name="head_pitch" pos="0 0 0" axis="0 1 6.8349e-05" range="-0.2617993877991494 0.2617993877991494" damping="7" armature="1.0" frictionloss="0.2"/>

                                    <geom type="mesh" contype="0" conaffinity="0" group="1" density="0" mass="0.1" material="Black" mesh="head_pitch"/>
                                    <geom size="0.05 0.05 0.05" type="box" material="LightGrey"/>

                                </body>
                                <!-- End of Head pitch -->
                            </body>
                            <!-- End of Head roll -->
                        </body>
                        <!-- End of Head yaw -->

                        <!-- Right arm -->
                        <body name="right_arm_mount" pos="0 -0.12664 0.21725" quat="0.976303 -0.216409 0 0">
                        <site name="right_center" pos="0 0 0" size="0.01" rgba="1 0.3 0.3 1" group="2"/>
                        <!-- r upper arm pitch -->
                        <body name="r_upper_arm_pitch">
                            <site name="r_shoulder_site" pos="0 0 0" size="0.03 0.03 0.03" rgba="1 0 0 0" type="sphere" group="1"/>
                            <inertial pos="0.00515735 -0.0587916 0.000122944" quat="0.999675 -0.0254775 -0.000125407 -0.000494276" mass="0.777391" diaginertia="0.00054641 0.000340601 0.00031934"/>
                            <joint name="r_shoulder_pitch" pos="0 0 0" axis="0 1 0" range="-2.6179938779914944 1.0471975511965976" damping="7" armature="1.0" frictionloss="0.2"/>

                            <geom type="mesh" contype="0" conaffinity="0" group="1" density="0" material="LightGrey" mesh="r_upper_arm_pitch"/>
                            <geom size="0.02 0.02 0.02" type="box" material="LightGrey"/>

                            <!-- r upper arm roll -->
                            <body name="r_upper_arm_roll" pos="0 -0.067 0" quat="0.976303 0.216409 0 0">
                                <inertial pos="0.0260059 -0.0238264 -0.0272109" quat="0.906733 -0.298529 0.228698 0.190821" mass="0.0840989" diaginertia="9.66585e-05 8.99068e-05 2.54689e-05"/>
                                <joint name="r_shoulder_roll" pos="0 0 0" axis="-1 0 1.221e-05" range="0.0 2.6179938779914944" damping="7" armature="1.0" frictionloss="0.2"/>

                                <geom type="mesh" contype="0" conaffinity="0" group="1" density="0" material="LightGrey" mesh="r_upper_arm_roll"/>
                                <geom size="0.02 0.02 0.02" type="box" material="LightGrey"/>

                                <!-- r upper arm yaw -->
                                <body name="r_upper_arm_yaw" pos="0 -0.039996 -0.057473">
                                    <site name="r_collar_site" pos="0 0 0" size="0.03 0.03 0.03" rgba="1 0 0 0" type="sphere" group="1"/>
                                    <inertial pos="0.00017083 -0.00124148 -0.100981" quat="0.712176 -0.02561 0.0250075 0.701088" mass="0.78993" diaginertia="0.000481112 0.000420147 0.000315576"/>
                                    <joint name="r_shoulder_yaw" pos="0 0 0" axis="1.221e-05 6.8349e-05 1" range="-1.5707963267948966 1.5707963267948966" damping="7" armature="1.0" frictionloss="0.2"/>

                                    <geom type="mesh" contype="0" conaffinity="0" group="1" density="0" material="LightGrey" mesh="r_upper_arm_yaw"/>
                                    <geom size="0.025 0.025 0.06" pos="0 0 -0.05" type="box" material="LightGrey"/>

                                    <!-- r lower arm pitch -->
                                    <body name="r_lower_arm_pitch" pos="0 1.28859e-05 -0.18853">
                                        <site name="r_elbow_site" pos="0 0 0" size="0.03 0.03 0.03" rgba="1 0 0 0" type="sphere" group="1"/>
                                        <inertial pos="2.54538e-07 -0.0196908 -0.0210929" quat="0.675237 0.209883 -0.209892 0.67524" mass="0.0553958" diaginertia="2.92256e-05 2.63267e-05 1.3293e-05"/>
                                        <joint name="r_elbow_pitch" pos="0 0 0" axis="0 1 -6.835e-05" range="-1.5707963267948966 0.0" damping="7" armature="1.0" frictionloss="0.2"/>

                                        <geom type="mesh" contype="0" conaffinity="0" group="1" density="0" material="LightGrey" mesh="r_lower_arm_pitch"/>
                                        <geom size="0.02 0.02 0.02" type="box" material="LightGrey"/>

                                        <!-- r hand yaw -->
                                        <body name="r_hand_yaw" pos="0 0 -0.0405">
                                            <inertial pos="0.000158044 -0.000478822 -0.0559415" quat="0.999772 0.019131 0.00724385 -0.00608553" mass="0.606076" diaginertia="0.000748132 0.000708413 0.000280748"/>
                                            <joint name="r_wrist_yaw" pos="0 0 0" axis="1.221e-05 6.835e-05 1" range="-1.5707963267948966 1.5707963267948966" damping="7" armature="1.0" frictionloss="0.2"/>

                                            <geom type="mesh" contype="0" conaffinity="0" group="1" density="0" material="LightGrey" mesh="r_hand_yaw"/>
                                            <geom size="0.03 0.03 0.085" pos="0 0 -0.1" type="box" material="LightGrey"/>

                                            <!-- r hand roll -->
                                            <body name="r_hand_roll" pos="0 1.3775e-05 -0.20153">
                                                <inertial pos="1.5545e-08 0.00044846 4.1938e-08" quat="0 0.707105 0 0.707108" mass="0.0054473" diaginertia="3.6036e-07 3.5527e-07 7.344e-08"/>
                                                <joint name="r_wrist_roll" pos="0 0 0" axis="1 0 1.221e-05" range="-0.3665191429188092 0.3665191429188092" damping="7" armature="1.0" frictionloss="0.2"/>

                                                <geom type="mesh" contype="0" conaffinity="0" group="1" density="0" material="LightGrey" mesh="r_hand_roll"/>
                                                <!-- <geom size="0.01 0.01 0.01" type="box" rgba="0.75294 0.75294 0.75294 1"/> -->

                                                <!-- r hand pitch -->
                                                <body name="r_hand_pitch">
                                                    <site name="r_wrist_site" pos="0 0 0" size="0.03 0.03 0.03" rgba="1 0 0 0" type="sphere" group="1"/>
                                                    <inertial pos="0.0060733 0.0018907 -0.084578" quat="0.647336 -0.27161 -0.257721 0.6639" mass="0.53221" diaginertia="0.000319947 0.000196296 0.000182477"/>
                                                    <joint name="r_wrist_pitch" pos="0 0 0" axis="0 1 -6.835e-05" range="-0.3665191429188092 0.3665191429188092" damping="7" armature="1.0" frictionloss="0.2"/>

                                                    <!-- <geom size="0.02 0.02 0.04" pos="0 0 -0.07" type="box" rgba="0.75294 0.75294 0.75294 1"/> -->

                                                    <!-- right eef -->
                                                    <body name="right_eef" pos="0 0 0" quat="-0.707107 0 0 0.707107">
                                                        <body name="right_mount" quat="0 0 1 0"/>
                                                        <body name="right_hand_eef" pos="0 0 0"/>
                                                    </body>
                                                    <!-- End of right eef -->
                                                </body>
                                                <!-- End of r hand pitch -->
                                            </body>
                                            <!-- End of r hand roll -->
                                        </body>
                                        <!-- End of r hand yaw -->
                                    </body>
                                    <!-- End of r lower arm pitch -->
                                </body>
                                <!-- End of r upper arm yaw -->
                            </body>
                            <!-- End of r upper arm roll -->
                        </body>
                        <!-- End of r upper arm pitch -->
                        </body>
                        <!-- End of right arm mount -->
                        <!-- End of Right arm -->

                        <!-- Left arm -->
                        <body name="left_arm_mount" pos="0 0.12661 0.21727" quat="0.976289 0.216473 0 0">
                        <site name="left_center" pos="0 0 0" size="0.01" rgba="1 0.3 0.3 1" group="2"/>
                        <!-- l upper arm pitch -->
                        <body name="l_upper_arm_pitch">
                            <site name="l_shoulder_site" pos="0 0 0" size="0.03 0.03 0.03" rgba="1 0 0 0" type="sphere" group="1"/>
                            <inertial pos="0.00515733 0.0588337 0.000122944" quat="0.999793 0.0203364 -0.000117253 0.0011083" mass="0.777394" diaginertia="0.000546411 0.000340581 0.000319359"/>
                            <joint name="l_shoulder_pitch" pos="0 0 0" axis="0 -1 0" range="-1.0471975511965976 2.6179938779914944" damping="7" armature="1.0" frictionloss="0.2"/>
                            <geom type="mesh" contype="0" conaffinity="0" group="1" density="0" material="LightGrey" mesh="l_upper_arm_pitch"/>
                            <geom size="0.02 0.02 0.02" type="box" material="LightGrey"/>

                            <!-- l upper arm roll -->
                            <body name="l_upper_arm_roll" pos="0 0.067 0" quat="0.976289 -0.216473 0 0">
                                <inertial pos="0.0260055 0.0238305 -0.0272078" quat="0.906707 0.298574 0.228734 -0.190834" mass="0.084111" diaginertia="9.66711e-05 8.99184e-05 2.54726e-05"/>
                                <joint name="l_shoulder_roll" pos="0 0 0" axis="-1 0 1.221e-05" range="-2.6179938779914944 0.0" damping="7" armature="1.0" frictionloss="0.2"/>
                                <geom type="mesh" contype="0" conaffinity="0" group="1" density="0" material="LightGrey" mesh="l_upper_arm_roll"/>
                                <geom size="0.02 0.02 0.02" type="box" material="LightGrey"/>

                                <!-- l upper arm yaw -->
                                <body name="l_upper_arm_yaw" pos="0 0.040004 -0.057502">
                                    <site name="l_collar_site" pos="0 0 0" size="0.03 0.03 0.03" rgba="1 0 0 0" type="sphere" group="1"/>
                                    <inertial pos="-4.12427e-05 0.00135031 -0.101007" quat="0.706543 0.0248514 -0.0268343 0.706724" mass="0.78993" diaginertia="0.000480863 0.000420363 0.000315608"/>
                                    <joint name="l_shoulder_yaw" pos="0 0 0" axis="1.221e-05 6.8349e-05 1" range="-1.5707963267948966 1.5707963267948966" damping="7" armature="1.0" frictionloss="0.2"/>
                                    <geom type="mesh" contype="0" conaffinity="0" group="1" density="0" material="LightGrey" mesh="l_upper_arm_yaw"/>
                                    <geom size="0.025 0.025 0.06" pos="0 0 -0.05" type="box" material="LightGrey"/>

                                    <!-- l lower arm pitch -->
                                    <body name="l_lower_arm_pitch" pos="0 1.28869e-05 -0.188546">
                                        <site name="l_elbow_site" pos="0 0 0" size="0.03 0.03 0.03" rgba="1 0 0 0" type="sphere" group="1"/>
                                        <inertial pos="2.60519e-07 0.0196937 -0.0210902" quat="0.675254 -0.209845 0.209837 0.675252" mass="0.0553958" diaginertia="2.92256e-05 2.63267e-05 1.3293e-05"/>
                                        <joint name="l_elbow_pitch" pos="0 0 0" axis="0 -1 -6.83491e-05" range="0.0 1.5707963267948966" damping="7" armature="1.0" frictionloss="0.2"/>
                                        <geom type="mesh" contype="0" conaffinity="0" group="1" density="0" material="LightGrey" mesh="l_lower_arm_pitch"/>
                                        <geom size="0.02 0.02 0.02" type="box" material="LightGrey"/>

                                        <!-- l hand yaw -->
                                        <body name="l_hand_yaw" pos="0 0 -0.0405043">
                                            <inertial pos="-4.20996e-05 0.000336116 -0.0559829" quat="0.999784 -0.0189715 -0.00676208 0.00509819" mass="0.606076" diaginertia="0.000747266 0.000709257 0.000280769"/>
                                            <joint name="l_wrist_yaw" pos="0 0 0" axis="1.221e-05 6.83491e-05 1" range="-1.5707963267948966 1.5707963267948966" damping="7" armature="1.0" frictionloss="0.2"/>
                                            <geom type="mesh" contype="0" conaffinity="0" group="1" density="0" material="LightGrey" mesh="l_hand_yaw"/>
                                            <geom size="0.03 0.03 0.085" pos="0 0 -0.1" type="box" material="LightGrey"/>

                                            <!-- l hand roll -->
                                            <body name="l_hand_roll" pos="0 1.3775e-05 -0.20155">
                                                <inertial pos="-1.5483e-08 -0.00044846 -1.9394e-08" quat="0 0.7071 0 0.707114" mass="0.0054473" diaginertia="3.6036e-07 3.5527e-07 7.344e-08"/>
                                                <joint name="l_wrist_roll" pos="0 0 0" axis="-1 0 1.2211e-05" range="-0.3665191429188092 0.3665191429188092" damping="7" armature="1.0" frictionloss="0.2"/>
                                                <geom type="mesh" contype="0" conaffinity="0" group="1" density="0" material="LightGrey" mesh="l_hand_roll"/>
                                                <!-- <geom size="0.01 0.01 0.01" type="box" rgba="0.75294 0.75294 0.75294 1"/> -->

                                                <!-- l hand pitch -->
                                                <body name="l_hand_pitch">
                                                    <site name="l_wrist_site" pos="0 0 0" size="0.03 0.03 0.03" rgba="1 0 0 0" type="sphere" group="1"/>
                                                    <inertial pos="0.0071289 -0.0026192 -0.078567" quat="0.298548 0.646339 0.631172 0.307795" mass="0.5239" diaginertia="0.000345825 0.000211684 0.000195941"/>
                                                    <joint name="l_wrist_pitch" pos="0 0 0" axis="0 1 6.8349e-05" range="-0.3665191429188092 0.3665191429188092" damping="7" armature="1.0" frictionloss="0.2"/>

                                                    <!-- <geom size="0.02 0.02 0.02" pos="0 0 -0.07" type="box" rgba="0.75294 0.75294 0.75294 1"/> -->

                                                    <!-- left eef -->
                                                    <body name="left_eef" pos="0 0 0" quat="0.707107 0 0 0.707107">
                                                        <body name="left_mount" quat="0 0 1 0"/>
                                                        <body name="left_hand_eef" pos="0 0 0"/>
                                                    </body>
                                                    <!-- End of left eef -->
                                                </body>
                                                <!-- End of l hand pitch -->
                                            </body>
                                            <!-- End of l hand roll -->
                                        </body>
                                        <!-- End of l hand yaw -->
                                    </body>
                                    <!-- End of l lower arm pitch -->
                                </body>
                                <!-- End of l upper arm yaw -->
                            </body>
                            <!-- End of l upper arm roll -->
                        </body>
                        <!-- End of l upper arm pitch -->
                        </body>
                        <!-- End of left arm mount -->
                        <!-- End of Left arm -->


                    </body>
                    <!-- End of Waist roll -->
                </body>
                <!-- End of Waist pitch -->
            </body>
            <!-- End of Waist yaw -->
            <!-- End of Torso -->

            <body name="lower_body">
                <!-- Left leg -->
                <!-- l thigh roll -->
                <body name="l_thigh_roll" pos="-0.047999 0.105 -0.057493">
                    <inertial pos="0.04163 3.4568e-05 -0.0021382" quat="0.575529 0.581908 -0.40597 0.406619" mass="1.1437" diaginertia="0.00117548 0.00100413 0.000943892"/>
                    <joint name="l_leg_hip_roll" pos="0 0 0" axis="1 0 1.221e-05" range="-0.09 0.79"/>
                    <geom type="mesh" contype="0" conaffinity="0" group="1" density="0" material="LightGrey" mesh="l_thigh_roll"/>
                    <geom size="0.04 0.04 0.04" pos="-0.046 0 0" type="box" material="LightGrey"/>

                    <!-- l thigh yaw -->
                    <body name="l_thigh_yaw" pos="0.048 0 -0.030499">
                        <inertial pos="0.00018348 0.046462 -0.10389" quat="0.704251 -0.0226446 -0.0453749 0.708138" mass="3.9888" diaginertia="0.0163385 0.0100158 0.00924336"/>
                        <joint name="l_leg_hip_yaw" pos="0 0 0" axis="1.2209e-05 6.8349e-05 1" range="-0.7 0.7"/>
                        <geom type="mesh" contype="0" conaffinity="0" group="1" density="0" material="LightGrey" mesh="l_thigh_yaw"/>
                        <geom size="0.04 0.04 0.04" pos="0 0 0.01" type="box" material="LightGrey"/>

                        <!-- l thigh pitch -->
                        <body name="l_thigh_pitch" pos="0 0 -0.11">
                            <inertial pos="0.0028493 -0.021688 -0.090886" quat="0.707411 -0.0125435 -0.0111264 0.706604" mass="6.369" diaginertia="0.0532352 0.0425096 0.0134363"/>
                            <joint name="l_leg_hip_pitch" pos="0 0 0" axis="0 1 -6.8349e-05" range="-1.75 0.7"/>
                            <geom type="mesh" contype="0" conaffinity="0" group="1" density="0" material="LightGrey" mesh="l_thigh_pitch"/>
                            <geom size="0.04 0.04 0.175" pos="0 0 -0.15" type="box" material="LightGrey"/>

                            <!-- l shank pitch -->
                            <body name="l_shank_pitch" pos="0 2.4606e-05 -0.36">
                                <inertial pos="0.0024312 -2.9945e-05 -0.11554" quat="0.692137 0.00134576 0.00140217 0.721764" mass="2.1895" diaginertia="0.0162703 0.016117 0.00113627"/>
                                <joint name="l_leg_knee_pitch" pos="0 0 0" axis="0 1 6.8349e-05" range="-0.09 1.92"/>
                                <geom type="mesh" contype="0" conaffinity="0" group="1" density="0" material="LightGrey" mesh="l_shank_pitch"/>
                                <geom size="0.04 0.04 0.1" pos="0 0 -0.15" type="box" material="LightGrey"/>

                                <!-- l foot pitch -->
                                <body name="l_foot_pitch" pos="0 2.3239e-05 -0.34">
                                    <inertial pos="1.748e-11 4.3804e-11 0" quat="1 3.42295e-05 -6.07362e-06 -2.07897e-10" mass="0.080335" diaginertia="5.1022e-06 4.3976e-06 4.188e-06"/>
                                    <joint name="l_leg_ankle_pitch" pos="0 0 0" axis="0 1 6.8349e-05" range="-1.05 0.52"/>
                                    <geom type="mesh" contype="0" conaffinity="0" group="1" density="0" material="LightGrey" mesh="l_foot_pitch"/>
                                    <geom size="0.015 0.015 0.015" pos="0 0 0.01" type="box" material="LightGrey"/>

                                    <!-- l foot roll -->
                                    <body name="l_foot_roll">
                                        <inertial pos="0.039446 0.00035757 -0.038101" quat="-0.00087198 0.709539 -0.00177594 0.704664" mass="0.584" diaginertia="0.00271032 0.0024027 0.000369145"/>
                                        <joint name="l_leg_ankle_roll" pos="0 0 0" axis="1 0 1.221e-05" range="-0.44 0.44"/>
                                        <geom type="mesh" contype="0" conaffinity="0" group="1" density="0" material="Black" mesh="l_foot_roll"/>
                                        <geom name="l_foot_1" size="0.015 0.015 0.12" pos="0.05 0.02 -0.035" quat="0.707105 0 0.707108 0" type="box" material="LightGrey"/>
                                        <geom name="l_foot_2" size="0.015 0.015 0.12" pos="0.05 -0.02 -0.035" quat="0.707105 0 0.707108 0" type="box" material="LightGrey"/>
                                        <geom name="geom_left_A1_col" size="0.03 .08 0.12" pos="0.05 0 -0.035" quat="0.707105 0 0.707108 0" type="box" rgba="0 1 0 1"/>

                                        <body name="left_foot" pos="0 0 -0.076" quat="1 0 0 0"/>
                                    </body>
                                    <!-- End of l foot roll -->
                                </body>
                                <!-- End of l foot pitch -->
                            </body>
                            <!-- End of l shank pitch -->
                        </body>
                        <!-- End of l thigh pitch -->
                    </body>
                    <!-- End of l thigh yaw -->
                </body>
                <!-- End of l thigh roll -->
                <!-- End of Left leg -->
                
                <!-- Right leg -->
                <!-- r thigh roll -->
                <body name="r_thigh_roll" pos="-0.047999 -0.105 -0.057508">
                    <inertial pos="0.0416295 3.45678e-05 -0.00213824" quat="0.57555 0.581927 -0.405942 0.406589" mass="1.14367" diaginertia="0.00117548 0.00100417 0.000943891"/>
                    <joint name="r_leg_hip_roll" pos="0 0 0" axis="1 0 1.221e-05" range="-0.79 0.09"/>
                    <geom type="mesh" contype="0" conaffinity="0" group="1" density="0" material="LightGrey" mesh="r_thigh_roll"/>
                    <geom size="0.04 0.04 0.04" pos="-0.046 0 0" type="box" material="LightGrey"/>

                    <!-- r thigh yaw -->
                    <body name="r_thigh_yaw" pos="0.048 0 -0.030499">
                        <inertial pos="-0.00159762 -0.0464482 -0.103899" quat="0.709186 -0.0420808 -0.0194028 0.703497" mass="3.98882" diaginertia="0.0163388 0.0100142 0.00924469"/>
                        <joint name="r_leg_hip_yaw" pos="0 0 0" axis="1.2209e-05 6.8349e-05 1" range="-0.7 0.7"/>
                        <geom type="mesh" contype="0" conaffinity="0" group="1" density="0" material="LightGrey" mesh="r_thigh_yaw"/>
                        <geom size="0.04 0.04 0.04" pos="0 0 0.01" type="box" material="LightGrey"/>

                        <!-- r thigh pitch -->
                        <body name="r_thigh_pitch" pos="0 0 -0.11">
                            <inertial pos="0.002842 0.0217009 -0.0919987" quat="0.706586 -0.0113774 -0.0126258 0.707423" mass="6.36895" diaginertia="0.0532349 0.0424818 0.0134641"/>
                            <joint name="r_leg_hip_pitch" pos="0 0 0" axis="0 1 6.8349e-05" range="-1.75 0.7"/>
                            <geom type="mesh" contype="0" conaffinity="0" group="1" density="0" material="LightGrey" mesh="r_thigh_pitch"/>
                            <geom size="0.04 0.04 0.175" pos="0 0 -0.15" type="box" material="LightGrey"/>

                            <!-- r shank pitch -->
                            <body name="r_shank_pitch" pos="0 2.4606e-05 -0.36">
                                <inertial pos="0.00236658 4.56188e-05 -0.115532" quat="0.71872 0.00154106 0.00120241 0.695296" mass="2.18947" diaginertia="0.0162708 0.0161183 0.00113536"/>
                                <joint name="r_leg_knee_pitch" pos="0 0 0" axis="0 1 -6.8349e-05" range="-0.09 1.92"/>
                                <geom type="mesh" contype="0" conaffinity="0" group="1" density="0" material="LightGrey" mesh="r_shank_pitch"/>
                                <geom size="0.04 0.04 0.1" pos="0 0 -0.15" type="box" material="LightGrey"/>

                                <!-- r foot pitch -->
                                <body name="r_foot_pitch" pos="0 2.3239e-05 -0.34">
                                    <inertial pos="1.75705e-11 4.40342e-11 0" quat="1 3.42336e-05 -6.07409e-06 -2.07938e-10" mass="0.0799219" diaginertia="5.11122e-06 4.40004e-06 4.17954e-06"/>
                                    <joint name="r_leg_ankle_pitch" pos="0 0 0" axis="0 1 6.8349e-05" range="-1.05 0.52"/>
                                    <geom type="mesh" contype="0" conaffinity="0" group="1" density="0" material="LightGrey" mesh="r_foot_pitch"/>
                                    <geom size="0.015 0.015 0.015" pos="0 0 0.01" type="box" material="LightGrey"/>

                                    <!-- r foot roll -->
                                    <body name="r_foot_roll">
                                        <inertial pos="0.043909 -0.00032475 -0.039419" quat="0.000727105 0.710094 0.00155959 0.704104" mass="0.58089" diaginertia="0.00280098 0.0024886 0.000368482"/>
                                        <joint name="r_leg_ankle_roll" pos="0 0 0" axis="1 0 1.221e-05" range="-0.44 0.44"/>
                                        <geom type="mesh" contype="0" conaffinity="0" group="1" density="0" material="Black" mesh="r_foot_roll"/>
                                        <geom name="r_foot_1" size="0.015 0.015 0.12" pos="0.05 0.02 -0.035" quat="0.707105 0 0.707108 0" type="box" material="LightGrey"/>
                                        <geom name="r_foot_2" size="0.015 0.015 0.12" pos="0.05 -0.02 -0.035" quat="0.707105 0 0.707108 0" type="box" material="LightGrey"/>
                                        <geom name="geom_right_A1_col" size="0.03 .08 0.12" pos="0.05 0 -0.035" quat="0.707105 0 0.707108 0" type="box" rgba="1 0 0 1"/>

                                        <body name="right_foot" pos="0 0 -0.076" quat="1 0 0 0"/>
                                    </body>
                                    <!-- End of r foot roll -->
                                </body>
                                <!-- End of r foot pitch -->
                            </body>
                            <!-- End of r shank pitch -->
                        </body>
                        <!-- End of r thigh pitch -->
                    </body>
                    <!-- End of r thigh yaw -->
                </body>
                <!-- End of r thigh roll -->

                <!-- End of Right leg -->
            </body>
            <!-- End of lower body -->
        </body>
    </body>
    <!-- End of Base -->
  </worldbody>
  <actuator>

    <!-- Left leg motors -->
    <motor ctrllimited="true" ctrlrange="-20000 20000" joint="l_leg_hip_roll" name="l_leg_hip_roll"/>
    <motor ctrllimited="true" ctrlrange="-20000 20000" joint="l_leg_hip_yaw" name="l_leg_hip_yaw"/>
    <motor ctrllimited="true" ctrlrange="-20000 20000" joint="l_leg_hip_pitch" name="l_leg_hip_pitch"/>
    <motor ctrllimited="true" ctrlrange="-20000 20000" joint="l_leg_knee_pitch" name="l_leg_knee_pitch"/>
    <motor ctrllimited="true" ctrlrange="-20000 20000" joint="l_leg_ankle_pitch" name="l_leg_ankle_pitch"/>
    <motor ctrllimited="true" ctrlrange="-20000 20000" joint="l_leg_ankle_roll" name="l_leg_ankle_roll"/>
    <!-- End of Left leg motors -->

    <!-- Right leg motors -->
    <motor ctrllimited="true" ctrlrange="-20000 20000" joint="r_leg_hip_roll" name="r_leg_hip_roll"/>
    <motor ctrllimited="true" ctrlrange="-20000 20000" joint="r_leg_hip_yaw" name="r_leg_hip_yaw"/>
    <motor ctrllimited="true" ctrlrange="-20000 20000" joint="r_leg_hip_pitch" name="r_leg_hip_pitch"/>
    <motor ctrllimited="true" ctrlrange="-20000 20000" joint="r_leg_knee_pitch" name="r_leg_knee_pitch"/>
    <motor ctrllimited="true" ctrlrange="-20000 20000" joint="r_leg_ankle_pitch" name="r_leg_ankle_pitch"/>
    <motor ctrllimited="true" ctrlrange="-20000 20000" joint="r_leg_ankle_roll" name="r_leg_ankle_roll"/>
    <!-- End of Right leg motors -->

    <motor ctrllimited="true" ctrlrange="-20000 20000" joint="torso_waist_yaw" name="torso_waist_yaw"/>
    <motor ctrllimited="true" ctrlrange="-20000 20000" joint="torso_waist_pitch" name="torso_waist_pitch"/>
    <motor ctrllimited="true" ctrlrange="-20000 20000" joint="torso_waist_roll" name="torso_waist_roll"/>
    <motor ctrllimited="true" ctrlrange="-20000 20000" joint="head_yaw" name="head_yaw"/>
    <motor ctrllimited="true" ctrlrange="-20000 20000" joint="head_pitch" name="head_pitch"/>
    <motor ctrllimited="true" ctrlrange="-20000 20000" joint="head_roll" name="head_roll"/>
    
    <!-- Right arm motors -->
    <motor ctrllimited="true" ctrlrange="-20000 20000" joint="r_shoulder_pitch" name="r_shoulder_pitch"/>
    <motor ctrllimited="true" ctrlrange="-20000 20000" joint="r_shoulder_roll" name="r_shoulder_roll"/>
    <motor ctrllimited="true" ctrlrange="-20000 20000" joint="r_shoulder_yaw" name="r_shoulder_yaw"/>
    <motor ctrllimited="true" ctrlrange="-20000 20000" joint="r_elbow_pitch" name="r_elbow_pitch"/>
    <motor ctrllimited="true" ctrlrange="-20000 20000" joint="r_wrist_yaw" name="r_wrist_yaw"/>
    <motor ctrllimited="true" ctrlrange="-20000 20000" joint="r_wrist_roll" name="r_wrist_roll"/>
    <motor ctrllimited="true" ctrlrange="-20000 20000" joint="r_wrist_pitch" name="r_wrist_pitch"/>
    <!-- End of right arm motors -->

    <!-- Left arm motors -->
    <motor ctrllimited="true" ctrlrange="-20000 20000" joint="l_shoulder_pitch" name="l_shoulder_pitch"/>
    <motor ctrllimited="true" ctrlrange="-20000 20000" joint="l_shoulder_roll" name="l_shoulder_roll"/>
    <motor ctrllimited="true" ctrlrange="-20000 20000" joint="l_shoulder_yaw" name="l_shoulder_yaw"/>
    <motor ctrllimited="true" ctrlrange="-20000 20000" joint="l_elbow_pitch" name="l_elbow_pitch"/>
    <motor ctrllimited="true" ctrlrange="-20000 20000" joint="l_wrist_yaw" name="l_wrist_yaw"/>
    <motor ctrllimited="true" ctrlrange="-20000 20000" joint="l_wrist_roll" name="l_wrist_roll"/>
    <motor ctrllimited="true" ctrlrange="-20000 20000" joint="l_wrist_pitch" name="l_wrist_pitch"/>
    <!-- End of left arm motors -->

  </actuator>

  <contact>
    <exclude name="upper_lower_body" body1="torso_waist_yaw" body2="lower_body"/>
    <exclude name="torso_head_1" body1="torso_waist_roll" body2="head_yaw"/>
    <exclude name="torso_head_2" body1="torso_waist_roll" body2="head_roll"/>
    <exclude name="torso_head_3" body1="torso_waist_roll" body2="head_pitch"/>
    <exclude name="head_1" body1="head_roll" body2="head_yaw"/>
    <exclude name="head_2" body1="head_pitch" body2="head_yaw"/>    

  </contact>
</mujoco>
