<?xml version="1.0" ?>
<mujoco>
  <compiler angle="radian" autolimits="true"/>
  <visual>
    <global ellipsoidinertia="true"/>
  </visual>
  <default>
    <default class="arx5">
      <joint damping="0.1" frictionloss="0.001"/>
    </default>
  </default>
  <asset>
    <material name="groundplane" texture="groundplane" texuniform="true" texrepeat="5 5" reflectance="0.2"/>
    <texture type="2d" name="groundplane" builtin="checker" mark="edge" rgb1="0.2 0.3 0.4" rgb2="0.1 0.2 0.3" markrgb="0.8 0.8 0.8" width="300" height="300"/>
    <material name="arm" rgba="0.752941176470588 0.752941176470588 0.752941176470588 1" />

    <mesh name="base_link" file="meshes/base_link.STL"/>
    <mesh name="link1" file="meshes/link1.STL"/>
    <mesh name="link2" file="meshes/link2.STL"/>
    <mesh name="link3" file="meshes/link3.STL"/>
    <mesh name="link4" file="meshes/link4.STL"/>
    <mesh name="link5" file="meshes/link5.STL"/>
  </asset>
  <worldbody>
    <!--Start of base-->
    <body name="base" pos="0 0 0">
      <!--Start of hand base-->
      <body name="base_link" pos="0.0 0.0 0.0" quat="1 0 0 0">
        <inertial pos="-3.764e-5 0.00006519 0.03037877" quat="1.0 0.0 0.0 0.0" mass="0.428" diaginertia="0.00060728 0.00060832 1.917e-4"/>
        <site name="right_center" pos="0 0 0" size="0.01" rgba="1 0.3 0.3 1" group="2"/>
        <geom pos="0.0 0.0 0.0" quat="1.0 0.0 0.0 0.0" name="base_link_visual" group="1" contype="0" conaffinity="0" mesh="base_link" type="mesh"/>
        <geom pos="0.0 0.0 0.0" quat="1.0 0.0 0.0 0.0" name="base_link_collision" group="0" mesh="base_link" type="mesh"/>
        <!--Start of link1-->
        <body name="link1" pos="0.0 0.0 0.0603" quat="1.0 0.0 0.0 0.0">
          <joint name="joint1" type="hinge" class="arx5" axis="0 0 1" range="-10 10"/>
          <inertial pos="0.00571213 0.0002547 0.01750661" quat="1.0 0.0 0.0 0.0" mass="0.064" diaginertia="0.00008 0.00003 0.00007"/>
          <geom pos="0.0 0.0 0.0" quat="1.0 0.0 0.0 0.0" name="link1_visual" group="1" contype="0" material="arm" conaffinity="0" mesh="link1" type="mesh"/>
          <geom pos="0.0 0.0 0.0" quat="1.0 0.0 0.0 0.0" name="link1_collision" group="0" mesh="link1" type="mesh"/>
          <!--Start of link2-->
          <body name="link2" pos="0.02 0.0 0.0402" quat="1.0 0.0 0.0 0.0">
            <joint name="joint2" type="hinge" class="arx5" axis="0 1 0" range="0 3.14"/>
            <inertial pos="-0.13225701 0.00072373 4.274e-5" quat="1.0 0.0 0.0 0.0" mass="1.165" diaginertia="0.00057063 0.03669927 0.03683489"/>
            <geom pos="0.0 0.0 0.0" material="arm" quat="1.0 0.0 0.0 0.0" name="link2_visual" group="1" contype="0" conaffinity="0" mesh="link2" type="mesh"/>
            <geom pos="0.0 0.0 0.0" quat="1.0 0.0 0.0 0.0" name="link2_collision" group="0" mesh="link2" type="mesh"/>
            <!--Start of link3-->
            <body name="link3" pos="-0.264 0.0 0.0" quat="-3.673205103346574e-06 -0.9999999999932537 -0.0 0.0">
              <joint name="joint3" type="hinge" class="arx5" axis="0 1 0" range="0 3.14"/>
              <inertial pos="0.19096098 0.00069065 -0.05342172" quat="1.0 0.0 0.0 0.0" mass="0.546" diaginertia="0.00178249 0.02486615 0.02329476"/>
              <geom pos="0.0 0.0 0.0" quat="1.0 0.0 0.0 0.0" name="link3_visual" group="1" material="arm" contype="0" conaffinity="0" mesh="link3" type="mesh"/>
              <geom pos="0.15 0.0 -0.055" quat="0.7071067811865476 0.0 0.7071067811865475 0.0" name="link3_collision" group="0" type="box" size="0.02 0.02 0.075"/>
              <!--Start of link4-->
              <body name="link4" pos="0.245 0.0 -0.056" quat="1.0 0.0 0.0 0.0">
                <joint name="joint4" type="hinge" class="arx5" axis="0 1 0" range="-1.57079632679 1.57079632679"/>
                <inertial pos="0.03092317 0.0066107 -0.03138504" quat="1.0 0.0 0.0 0.0" mass="0.080971" diaginertia="0.00017832 0.00021182 0.00011328"/>
                <geom pos="0.0 0.0 0.0" quat="1.0 0.0 0.0 0.0" name="link4_visual" group="1" material="arm" contype="0" conaffinity="0" mesh="link4" type="mesh"/>
                <geom pos="0.06575 -0.001 -0.02" quat="1.0 0.0 0.0 0.0" name="link4_collision" group="0" type="box" size="0.025 0.025 0.025"/>
                <!--Start of link5-->
                <body name="link5" pos="0.06575 -0.001 -0.0825" quat="1.0 0.0 0.0 0.0">
                  <joint name="joint5" type="hinge" class="arx5" axis="0 0 1" range="-1.67 1.67"/>
                  <inertial pos="0.0040681 0.00000885 0.05120675" quat="1.0 0.0 0.0 0.0" mass="0.655" diaginertia="0.00254972 0.00255018 0.00026961"/>
                  <geom pos="0.0 0.0 0.0" quat="1.0 0.0 0.0 0.0" name="link5_visual" group="1" material="arm" contype="0" conaffinity="0" mesh="link5" type="mesh"/>
                  <geom pos="0.055 0.0 0.083" quat="0.7071067811865476 0.0 0.7071067811865475 0.0" name="link5_collision" group="0" type="box" size="0.02 0.02 0.0125"/>
                  <!--Start of link6-->
                  <body name="link6" pos="0.02845 0.0 0.0825" quat="-3.673205103346574e-06 -0.9999999999932537 -0.0 0.0">
                    <joint name="joint6" type="hinge" class="arx5" axis="1 0 0" range="-1.57 1.57"/>
                    <inertial pos="0.05435277 -0.00734005 0.01881196" quat="1.0 0.0 0.0 0.0" mass="0.902" diaginertia="0.00229822 0.00596005 0.00530799"/>
                    <!--Start of right_hand-->
                    <body name="right_hand" pos="0.0 0.0 0.0" quat="1 0 0 0">
                        <camera mode="fixed" name="right_eye_in_hand" pos="0.05 0 0" quat="0.5 0.5 -0.5 -0.5" fovy="75"/>
                    </body>
                  </body>
                  <!--End of link6-->
                </body>
                <!--End of link5-->
              </body>
              <!--End of link4-->
            </body>
            <!--End of link3-->
          </body>
          <!--End of link2-->
        </body>
        <!--End of link1-->
      </body>
      <!--End of hand base-->
    </body>
    <!--End of base-->
  </worldbody>
  <actuator>
    <motor name="actuator1" joint="joint1" ctrlrange="-50 50" ctrllimited="true"/>
    <motor name="actuator2" joint="joint2" ctrlrange="-50 50" ctrllimited="true"/>
    <motor name="actuator3" joint="joint3" ctrlrange="-50 50" ctrllimited="true"/>
    <motor name="actuator4" joint="joint4" ctrlrange="-50 50" ctrllimited="true"/>
    <motor name="actuator5" joint="joint5" ctrlrange="-50 50" ctrllimited="true"/>
    <motor name="actuator6" joint="joint6" ctrlrange="-50 50" ctrllimited="true"/>]
  </actuator>
</mujoco>