<?xml version="1.0" ?>
<mujoco model="h1">
  <compiler angle="radian" autolimits="true"/>
  <!-- <statistic meansize="0.219715" extent="1.9996" center="0.015564 2.74848e-06 -0.169929" /> -->
  <asset>
    <mesh name="pelvis" file="meshes/pelvis.STL"/>
    <mesh name="left_hip_yaw_link" file="meshes/left_hip_yaw_link.STL"/>
    <mesh name="left_hip_roll_link" file="meshes/left_hip_roll_link.STL"/>
    <mesh name="left_hip_pitch_link" file="meshes/left_hip_pitch_link.STL"/>
    <mesh name="left_knee_link" file="meshes/left_knee_link.STL"/>
    <mesh name="left_ankle_link" file="meshes/left_ankle_link.STL"/>
    <mesh name="right_hip_yaw_link" file="meshes/right_hip_yaw_link.STL"/>
    <mesh name="right_hip_roll_link" file="meshes/right_hip_roll_link.STL"/>
    <mesh name="right_hip_pitch_link" file="meshes/right_hip_pitch_link.STL"/>
    <mesh name="right_knee_link" file="meshes/right_knee_link.STL"/>
    <mesh name="right_ankle_link" file="meshes/right_ankle_link.STL"/>
    <mesh name="torso_link" file="meshes/torso_link.STL"/>
    <mesh name="left_shoulder_pitch_link" file="meshes/left_shoulder_pitch_link.STL"/>
    <mesh name="left_shoulder_roll_link" file="meshes/left_shoulder_roll_link.STL"/>
    <mesh name="left_shoulder_yaw_link" file="meshes/left_shoulder_yaw_link.STL"/>
    <mesh name="left_elbow_link" file="meshes/left_elbow_link.STL"/>
    <mesh name="right_shoulder_pitch_link" file="meshes/right_shoulder_pitch_link.STL"/>
    <mesh name="right_shoulder_roll_link" file="meshes/right_shoulder_roll_link.STL"/>
    <mesh name="right_shoulder_yaw_link" file="meshes/right_shoulder_yaw_link.STL"/>
    <mesh name="right_elbow_link" file="meshes/right_elbow_link.STL"/>
    <mesh name="logo_link" file="meshes/logo_link.STL"/>
    <material name="floor" reflectance=".1"/>
  </asset>
  <default>
    <motor ctrllimited="true" ctrlrange="-2000 2000"/>
  </default>
  <worldbody>
    <!-- <light pos=".4 -.4 .3" dir="-2 2 -1.5" diffuse=".6 .6 .6"/>
    <light pos="-.2 -.4 .3" dir="1 2 -1.5" diffuse=".6 .6 .6"/>
    <geom type="plane" size="5 5 .01" rgba="1 1 1 1" material="floor"/> -->
    <body name="base">
      <inertial pos="-0.0508888 0.000109183 -0.0455794" quat="0.706855 0.707166 0.0123661 -0.0109307" mass="1.45117" diaginertia="0.0149302 0.0127972 0.00640923"/>
      <freejoint/>
      <body name="pelvis" pos="0 0 1.1">
        <inertial pos="-0.0002 4e-05 -0.04522" quat="0.498303 0.499454 -0.500496 0.501741" mass="1.39" diaginertia="0.0490211 0.0445821 0.00824619"/>
        <!-- <joint name="floating_base_joint" type="free" /> -->
        <geom type="mesh" contype="0" conaffinity="0" group="1" density="0" rgba="0.1 0.1 0.1 1" mesh="pelvis"/>
        <geom type="mesh" rgba="0.1 0.1 0.1 1" mesh="pelvis"/>
        <body name="torso_link">
          <inertial pos="0.000489 0.002797 0.20484" quat="0.999989 -0.00130808 -0.00282289 -0.00349105" mass="7.789" diaginertia="0.487315 0.409628 0.127837"/>
          <joint name="torso_joint" pos="0 0 0" axis="0 0 1" range="-2.35 2.35" damping="100"/>
          <geom type="mesh" contype="0" conaffinity="0" group="1" density="0" rgba="0.1 0.1 0.1 1" mesh="torso_link"/>
          <geom type="mesh" rgba="0.1 0.1 0.1 1" mesh="torso_link"/>
          <geom type="mesh" contype="0" conaffinity="0" group="1" density="0" rgba="1 1 1 1" mesh="logo_link"/>
          <site name="imu" size="0.01" pos="-0.04452 -0.01891 0.27756"/>
          <camera mode="fixed" name="robotview" pos="0.07 0 0.65" quat="0.6123724356957945 0.3535533905932738 -0.3535533905932738 -0.6123724356957945"/>
          <!-- Right arm -->
          <body name="right_arm_mount" pos="0.0055 -0.15535 0.42999" quat="0.976296 -0.216438 0 0">
            <site name="right_center" pos="0 0 0" size="0.01" rgba="1 0.3 0.3 1" group="2"/>
            <body name="right_shoulder_pitch_link">
              <inertial pos="0.005045 -0.053657 -0.015715" quat="0.579236 0.814858 0.00936488 0.0201072" mass="1.033" diaginertia="0.00129936 0.000987113 0.000858198"/>
              <joint name="right_shoulder_pitch_joint" pos="0 0 0" axis="0 1 0" range="-2.87 2.87" damping="7" armature="1.0" frictionloss="0.2"/>
              <geom type="mesh" contype="0" conaffinity="0" group="1" density="0" rgba="0.1 0.1 0.1 1" mesh="right_shoulder_pitch_link"/>
              <geom type="mesh" rgba="0.1 0.1 0.1 1" mesh="right_shoulder_pitch_link"/>
              <body name="right_shoulder_roll_link" pos="-0.0055 -0.0565 -0.0165" quat="0.976296 0.216438 0 0">
                <inertial pos="0.000679 -0.00115 -0.094076" quat="0.676384 0.0766656 0.00917179 0.732491" mass="0.793" diaginertia="0.00170388 0.00158256 0.00100336"/>
                <joint name="right_shoulder_roll_joint" pos="0 0 0" axis="1 0 0" range="-3.11 0.34" damping="7" armature="1.0" frictionloss="0.2"/>
                <geom type="mesh" contype="0" conaffinity="0" group="1" density="0" rgba="0.1 0.1 0.1 1" mesh="right_shoulder_roll_link"/>
                <geom type="mesh" rgba="0.1 0.1 0.1 1" mesh="right_shoulder_roll_link"/>
                <body name="right_shoulder_yaw_link" pos="0 0 -0.1343">
                  <inertial pos="0.01365 -0.002767 -0.16266" quat="0.708798 -0.0473362 -0.0331229 0.703042" mass="0.839" diaginertia="0.00408038 0.00370367 0.000622687"/>
                  <joint name="right_shoulder_yaw_joint" pos="0 0 0" axis="0 0 1" range="-4.45 1.3" damping="7" armature="1.0" frictionloss="0.2"/>
                  <geom type="mesh" contype="0" conaffinity="0" group="1" density="0" rgba="0.1 0.1 0.1 1" mesh="right_shoulder_yaw_link"/>
                  <geom type="mesh" rgba="0.1 0.1 0.1 1" mesh="right_shoulder_yaw_link"/>
                  <body name="right_elbow_link" pos="0.0185 0 -0.198">
                    <inertial pos="0.15908 0.000144 -0.015776" quat="-0.0765232 0.720327 -0.0853116 0.684102" mass="0.669" diaginertia="0.00601829 0.00600579 0.000408305"/>
                    <joint name="right_elbow_joint" pos="0 0 0" axis="0 1 0" range="-1.25 2.61" damping="7" armature="1.0" frictionloss="0.2"/>
                    <geom type="mesh" contype="0" conaffinity="0" group="1" density="0" rgba="0.1 0.1 0.1 1" mesh="right_elbow_link"/>
                    <geom type="mesh" rgba="0.1 0.1 0.1 1" mesh="right_elbow_link"/>
                    <body name="right_hand" pos="0.3 0 0" quat="0.5 0.5 0.5 0.5">
                  </body>
                  </body>
                </body>
              </body>
            </body>
          </body>
          <!-- End of right arm -->
          <!-- Left arm -->
          <body name="left_arm_mount" pos="0.0055 0.15535 0.42999" quat="0.976296 0.216438 0 0">
            <site name="left_center" pos="0 0 0" size="0.01" rgba="1 0.3 0.3 1" group="2"/>
            <body name="left_shoulder_pitch_link">
              <inertial pos="0.005045 0.053657 -0.015715" quat="0.814858 0.579236 -0.0201072 -0.00936488" mass="1.033" diaginertia="0.00129936 0.000987113 0.000858198"/>
              <joint name="left_shoulder_pitch_joint" pos="0 0 0" axis="0 1 0" range="-2.87 2.87" damping="7" armature="1.0" frictionloss="0.2"/>
              <geom type="mesh" contype="0" conaffinity="0" group="1" density="0" rgba="0.1 0.1 0.1 1" mesh="left_shoulder_pitch_link"/>
              <geom type="mesh" rgba="0.1 0.1 0.1 1" mesh="left_shoulder_pitch_link"/>
              <body name="left_shoulder_roll_link" pos="-0.0055 0.0565 -0.0165" quat="0.976296 -0.216438 0 0">
                <inertial pos="0.000679 0.00115 -0.094076" quat="0.732491 0.00917179 0.0766656 0.676384" mass="0.793" diaginertia="0.00170388 0.00158256 0.00100336"/>
                <joint name="left_shoulder_roll_joint" pos="0 0 0" axis="1 0 0" range="-0.34 3.11" damping="7" armature="1.0" frictionloss="0.2"/>
                <geom type="mesh" contype="0" conaffinity="0" group="1" density="0" rgba="0.1 0.1 0.1 1" mesh="left_shoulder_roll_link"/>
                <geom type="mesh" rgba="0.1 0.1 0.1 1" mesh="left_shoulder_roll_link"/>
                <body name="left_shoulder_yaw_link" pos="0 0 -0.1343">
                  <inertial pos="0.01365 0.002767 -0.16266" quat="0.703042 -0.0331229 -0.0473362 0.708798" mass="0.839" diaginertia="0.00408038 0.00370367 0.000622687"/>
                  <joint name="left_shoulder_yaw_joint" pos="0 0 0" axis="0 0 1" range="-1.3 4.45" damping="7" armature="1.0" frictionloss="0.2"/>
                  <geom type="mesh" contype="0" conaffinity="0" group="1" density="0" rgba="0.1 0.1 0.1 1" mesh="left_shoulder_yaw_link"/>
                  <geom type="mesh" rgba="0.1 0.1 0.1 1" mesh="left_shoulder_yaw_link"/>
                  <body name="left_elbow_link" pos="0.0185 0 -0.198">
                    <inertial pos="0.15908 -0.000144 -0.015776" quat="0.0765232 0.720327 0.0853116 0.684102" mass="0.669" diaginertia="0.00601829 0.00600579 0.000408305"/>
                    <joint name="left_elbow_joint" pos="0 0 0" axis="0 1 0" range="-1.25 2.61" damping="7" armature="1.0" frictionloss="0.2"/>
                    <geom type="mesh" contype="0" conaffinity="0" group="1" density="0" rgba="0.1 0.1 0.1 1" mesh="left_elbow_link"/>
                    <geom type="mesh" rgba="0.1 0.1 0.1 1" mesh="left_elbow_link"/>
                    <body name="left_hand" pos="0.3 0 0" quat="0.5 0.5 0.5 0.5">
                  </body>
                  </body>
                </body>
              </body>
            </body>
          </body>
          <!-- End of left arm -->
        </body>
        <body name="lower_body">
          <!-- Left leg -->
          <body name="left_hip_yaw_link" pos="0 0.0875 -0.1742">
            <inertial pos="-0.04923 0.0001 0.0072" quat="0.69699 0.219193 0.233287 0.641667" mass="2.244" diaginertia="0.00304494 0.00296885 0.00189201"/>
            <joint name="left_leg_hip_yaw_joint" pos="0 0 0" axis="0 0 1" range="-0.43 0.43"/>
            <geom type="mesh" contype="0" conaffinity="0" group="1" density="0" rgba="0.1 0.1 0.1 1" mesh="left_hip_yaw_link"/>
            <geom size="0.06 0.035" pos="-0.067 0 0" quat="0.707123 0 0.70709 0" type="cylinder" rgba="0.1 0.1 0.1 1"/>
            <body name="left_hip_roll_link" pos="0.039468 0 0">
              <inertial pos="-0.0058 -0.00319 -9e-05" quat="0.0438242 0.70721 -0.0729075 0.701867" mass="2.232" diaginertia="0.00243264 0.00225325 0.00205492"/>
              <joint name="left_leg_hip_roll_joint" pos="0 0 0" axis="1 0 0" range="-0.43 0.43"/>
              <geom type="mesh" contype="0" conaffinity="0" group="1" density="0" rgba="0.1 0.1 0.1 1" mesh="left_hip_roll_link"/>
              <geom type="mesh" rgba="0.1 0.1 0.1 1" mesh="left_hip_roll_link"/>
              <body name="left_hip_pitch_link" pos="0 0.11536 0">
                <inertial pos="0.00746 -0.02346 -0.08193" quat="0.979828 0.0513522 -0.0169854 -0.192382" mass="4.152" diaginertia="0.0829503 0.0821457 0.00510909"/>
                <joint name="left_leg_hip_pitch_joint" pos="0 0 0" axis="0 1 0" range="-1.57 1.57"/>
                <geom type="mesh" contype="0" conaffinity="0" group="1" density="0" rgba="0.1 0.1 0.1 1" mesh="left_hip_pitch_link"/>
                <geom type="mesh" rgba="0.1 0.1 0.1 1" mesh="left_hip_pitch_link"/>
                <body name="left_knee_link" pos="0 0 -0.4">
                  <inertial pos="-0.00136 -0.00512 -0.1384" quat="0.626132 -0.034227 -0.0416277 0.177852" mass="1.721" diaginertia="0.0125237 0.0123104 0.0019428"/>
                  <joint name="left_leg_knee_joint" pos="0 0 0" axis="0 1 0" range="-0.26 2.05"/>
                  <geom type="mesh" contype="0" conaffinity="0" group="1" density="0" rgba="0.1 0.1 0.1 1" mesh="left_knee_link"/>
                  <geom type="mesh" rgba="0.1 0.1 0.1 1" mesh="left_knee_link"/>
                  <body name="left_ankle_link" pos="0 0 -0.4">
                    <inertial pos="0.06722 0.00015 -0.04497" quat="0.489101 0.503197 0.565782 0.432972" mass="0.446" diaginertia="0.00220848 0.00218961 0.000214202"/>
                    <joint name="left_leg_ankle_joint" pos="0 0 0" axis="0 1 0" range="-0.87 0.52"/>
                    <geom type="mesh" contype="0" conaffinity="0" group="1" density="0" rgba="0.1 0.1 0.1 1" mesh="left_ankle_link"/>
                    <geom type="mesh" rgba="0.1 0.1 0.1 1" mesh="left_ankle_link"/>
                  </body>
                </body>
              </body>
            </body>
          </body>
          <!-- End of left leg -->
          <!-- Right leg -->
          <body name="right_hip_yaw_link" pos="0 -0.0875 -0.1742">
            <inertial pos="-0.04923 -0.0001 0.0072" quat="0.641667 0.233287 0.219193 0.69699" mass="2.244" diaginertia="0.00304494 0.00296885 0.00189201"/>
            <joint name="right_leg_hip_yaw_joint" pos="0 0 0" axis="0 0 1" range="-0.43 0.43"/>
            <geom type="mesh" contype="0" conaffinity="0" group="1" density="0" rgba="0.1 0.1 0.1 1" mesh="right_hip_yaw_link"/>
            <geom size="0.06 0.035" pos="-0.067 0 0" quat="0.707123 0 0.70709 0" type="cylinder" rgba="0.1 0.1 0.1 1"/>
            <body name="right_hip_roll_link" pos="0.039468 0 0">
              <inertial pos="-0.0058 0.00319 -9e-05" quat="-0.0438242 0.70721 0.0729075 0.701867" mass="2.232" diaginertia="0.00243264 0.00225325 0.00205492"/>
              <joint name="right_leg_hip_roll_joint" pos="0 0 0" axis="1 0 0" range="-0.43 0.43"/>
              <geom type="mesh" contype="0" conaffinity="0" group="1" density="0" rgba="0.1 0.1 0.1 1" mesh="right_hip_roll_link"/>
              <geom type="mesh" rgba="0.1 0.1 0.1 1" mesh="right_hip_roll_link"/>
              <body name="right_hip_pitch_link" pos="0 -0.11536 0">
                <inertial pos="0.00746 0.02346 -0.08193" quat="0.979828 -0.0513522 -0.0169854 0.192382" mass="4.152" diaginertia="0.0829503 0.0821457 0.00510909"/>
                <joint name="right_leg_hip_pitch_joint" pos="0 0 0" axis="0 1 0" range="-1.57 1.57"/>
                <geom type="mesh" contype="0" conaffinity="0" group="1" density="0" rgba="0.1 0.1 0.1 1" mesh="right_hip_pitch_link"/>
                <geom type="mesh" rgba="0.1 0.1 0.1 1" mesh="right_hip_pitch_link"/>
                <body name="right_knee_link" pos="0 0 -0.4">
                  <inertial pos="-0.00136 0.00512 -0.1384" quat="0.177852 -0.0416277 -0.034227 0.626132" mass="1.721" diaginertia="0.0125237 0.0123104 0.0019428"/>
                  <joint name="right_leg_knee_joint" pos="0 0 0" axis="0 1 0" range="-0.26 2.05"/>
                  <geom type="mesh" contype="0" conaffinity="0" group="1" density="0" rgba="0.1 0.1 0.1 1" mesh="right_knee_link"/>
                  <geom type="mesh" rgba="0.1 0.1 0.1 1" mesh="right_knee_link"/>
                  <body name="right_ankle_link" pos="0 0 -0.4">
                    <inertial pos="0.06722 -0.00015 -0.04497" quat="0.432972 0.565782 0.503197 0.489101" mass="0.446" diaginertia="0.00220848 0.00218961 0.000214202"/>
                    <joint name="right_leg_ankle_joint" pos="0 0 0" axis="0 1 0" range="-0.87 0.52"/>
                    <geom type="mesh" contype="0" conaffinity="0" group="1" density="0" rgba="0.1 0.1 0.1 1" mesh="right_ankle_link"/>
                    <geom type="mesh" rgba="0.1 0.1 0.1 1" mesh="right_ankle_link"/>
                  </body>
                </body>
              </body>
            </body>
          </body>
          <!-- End of right leg -->
        </body>
      </body>
    </body>
  </worldbody>
  <contact>
    <exclude body1="torso_link" body2="left_shoulder_pitch_link"/>
    <exclude body1="torso_link" body2="right_shoulder_pitch_link"/>
    <exclude body1="torso_link" body2="left_arm_mount"/>
    <exclude body1="torso_link" body2="right_arm_mount"/>
  </contact>
  <actuator>
    <motor ctrllimited="true" ctrlrange="-20000 20000" name="left_leg_hip_yaw_actuator" joint="left_leg_hip_yaw_joint"/>
    <motor ctrllimited="true" ctrlrange="-20000 20000" name="left_leg_hip_roll_actuator" joint="left_leg_hip_roll_joint"/>
    <motor ctrllimited="true" ctrlrange="-20000 20000" name="left_leg_hip_pitch_actuator" joint="left_leg_hip_pitch_joint"/>
    <motor ctrllimited="true" ctrlrange="-20000 20000" name="left_leg_knee_actuator" joint="left_leg_knee_joint"/>
    <motor ctrllimited="true" ctrlrange="-20000 20000" name="left_leg_ankle_actuator" joint="left_leg_ankle_joint"/>
    <motor ctrllimited="true" ctrlrange="-20000 20000" name="right_leg_hip_yaw_actuator" joint="right_leg_hip_yaw_joint"/>
    <motor ctrllimited="true" ctrlrange="-20000 20000" name="right_leg_hip_roll_actuator" joint="right_leg_hip_roll_joint"/>
    <motor ctrllimited="true" ctrlrange="-20000 20000" name="right_leg_hip_pitch_actuator" joint="right_leg_hip_pitch_joint"/>
    <motor ctrllimited="true" ctrlrange="-20000 20000" name="right_leg_knee_actuator" joint="right_leg_knee_joint"/>
    <motor ctrllimited="true" ctrlrange="-20000 20000" name="right_leg_ankle_actuator" joint="right_leg_ankle_joint"/>
    <motor ctrllimited="true" ctrlrange="-200 200" name="torso_actuator" joint="torso_joint"/>
    <motor ctrllimited="true" ctrlrange="-200 200" name="right_shoulder_pitch_actuator" joint="right_shoulder_pitch_joint"/>
    <motor ctrllimited="true" ctrlrange="-200 200" name="right_shoulder_roll_actuator" joint="right_shoulder_roll_joint"/>
    <motor ctrllimited="true" ctrlrange="-200 200" name="right_shoulder_yaw_actuator" joint="right_shoulder_yaw_joint"/>
    <motor ctrllimited="true" ctrlrange="-200 200" name="right_elbow_actuator" joint="right_elbow_joint"/>
    <motor ctrllimited="true" ctrlrange="-200 200" name="left_shoulder_pitch_actuator" joint="left_shoulder_pitch_joint"/>
    <motor ctrllimited="true" ctrlrange="-200 200" name="left_shoulder_roll_actuator" joint="left_shoulder_roll_joint"/>
    <motor ctrllimited="true" ctrlrange="-200 200" name="left_shoulder_yaw_actuator" joint="left_shoulder_yaw_joint"/>
    <motor ctrllimited="true" ctrlrange="-200 200" name="left_elbow_actuator" joint="left_elbow_joint"/>
  </actuator>
  <sensor>
    <gyro name="imu-angular-velocity" site="imu" noise="5e-4" cutoff="34.9"/>
    <accelerometer name="imu-linear-acceleration" site="imu" noise="1e-2" cutoff="157"/>
  </sensor>
</mujoco>