<mujoco model="base">
    <compiler angle="radian" meshdir="meshes/" />
    <option impratio="20" density="1.2" viscosity="2e-05" cone="elliptic" />
    <size njmax="5000" nconmax="5000" />
    <visual>
        <map znear="0.001" />
    </visual>
    <asset>
        <texture type="skybox" builtin="gradient" rgb1="0.9 0.9 1" rgb2="0.2 0.3 0.4" width="256" height="1536" />
        <texture type="2d" name="texplane" file="/home/ahjoshi/.pyenv/versions/env375/lib/python3.7/site-packages/robosuite/models/assets/arenas/../textures/wood-tiles.png" />
        <texture type="cube" name="steel-metal" file="/home/ahjoshi/.pyenv/versions/env375/lib/python3.7/site-packages/robosuite/models/assets/arenas/../textures/steel-scratched.png" />
        <texture type="cube" name="brass-metal" file="/home/ahjoshi/.pyenv/versions/env375/lib/python3.7/site-packages/robosuite/models/assets/arenas/../textures/brass-ambra.png" />
        <texture type="cube" name="tex-ceramic" file="/home/ahjoshi/.pyenv/versions/env375/lib/python3.7/site-packages/robosuite/models/assets/arenas/../textures/ceramic.png" />
        <texture type="cube" name="tex-steel-brushed" file="/home/ahjoshi/.pyenv/versions/env375/lib/python3.7/site-packages/robosuite/models/assets/arenas/../textures/steel-brushed.png" />
        <texture type="2d" name="tex-cream-plaster" file="/home/ahjoshi/.pyenv/versions/env375/lib/python3.7/site-packages/robosuite/models/assets/arenas/../textures/cream-plaster.png" />
        <texture type="cube" name="textable" builtin="flat" rgb1="0.5 0.5 0.5" width="512" height="3072" />
        <texture type="cube" name="SquareNut_brass-metal" file="/home/ahjoshi/.pyenv/versions/env375/lib/python3.7/site-packages/robosuite/models/assets/objects/../textures/brass-ambra.png" />
        <texture type="cube" name="RoundNut_steel-metal" file="/home/ahjoshi/.pyenv/versions/env375/lib/python3.7/site-packages/robosuite/models/assets/objects/../textures/steel-scratched.png" />
        <material name="floorplane" texture="texplane" texuniform="true" texrepeat="2 2" specular="0" shininess="0" reflectance="0.01" />
        <material name="smetal" texture="steel-metal" texuniform="true" specular="1" shininess="1" reflectance="1" />
        <material name="bmetal" texture="brass-metal" texuniform="true" specular="1" shininess="1" reflectance="1" />
        <material name="table_ceramic" texture="tex-ceramic" specular="0.2" shininess="0" />
        <material name="table_legs_metal" texture="tex-steel-brushed" shininess="0.8" reflectance="0.8" />
        <material name="walls_mat" texture="tex-cream-plaster" texuniform="true" texrepeat="3 3" specular="0.1" shininess="0.1" />
        <material name="table_mat" texture="textable" />
        <material name="SquareNut_bmetal" texture="SquareNut_brass-metal" texuniform="true" specular="1" shininess="1" reflectance="1" />
        <material name="RoundNut_smetal" texture="RoundNut_steel-metal" texuniform="true" specular="1" shininess="1" reflectance="1" />
        <mesh name="robot0_link0" file="/home/ahjoshi/.pyenv/versions/env375/lib/python3.7/site-packages/robosuite/models/assets/robots/panda/meshes/link0.stl" />
        <mesh name="robot0_link1" file="/home/ahjoshi/.pyenv/versions/env375/lib/python3.7/site-packages/robosuite/models/assets/robots/panda/meshes/link1.stl" />
        <mesh name="robot0_link2" file="/home/ahjoshi/.pyenv/versions/env375/lib/python3.7/site-packages/robosuite/models/assets/robots/panda/meshes/link2.stl" />
        <mesh name="robot0_link3" file="/home/ahjoshi/.pyenv/versions/env375/lib/python3.7/site-packages/robosuite/models/assets/robots/panda/meshes/link3.stl" />
        <mesh name="robot0_link4" file="/home/ahjoshi/.pyenv/versions/env375/lib/python3.7/site-packages/robosuite/models/assets/robots/panda/meshes/link4.stl" />
        <mesh name="robot0_link5" file="/home/ahjoshi/.pyenv/versions/env375/lib/python3.7/site-packages/robosuite/models/assets/robots/panda/meshes/link5.stl" />
        <mesh name="robot0_link6" file="/home/ahjoshi/.pyenv/versions/env375/lib/python3.7/site-packages/robosuite/models/assets/robots/panda/meshes/link6.stl" />
        <mesh name="robot0_link7" file="/home/ahjoshi/.pyenv/versions/env375/lib/python3.7/site-packages/robosuite/models/assets/robots/panda/meshes/link7.stl" />
        <mesh name="robot0_link0_vis" file="/home/ahjoshi/.pyenv/versions/env375/lib/python3.7/site-packages/robosuite/models/assets/robots/panda/meshes/link0_vis.stl" />
        <mesh name="robot0_link1_vis" file="/home/ahjoshi/.pyenv/versions/env375/lib/python3.7/site-packages/robosuite/models/assets/robots/panda/meshes/link1_vis.stl" />
        <mesh name="robot0_link2_vis" file="/home/ahjoshi/.pyenv/versions/env375/lib/python3.7/site-packages/robosuite/models/assets/robots/panda/meshes/link2_vis.stl" />
        <mesh name="robot0_link3_vis" file="/home/ahjoshi/.pyenv/versions/env375/lib/python3.7/site-packages/robosuite/models/assets/robots/panda/meshes/link3_vis.stl" />
        <mesh name="robot0_link4_vis" file="/home/ahjoshi/.pyenv/versions/env375/lib/python3.7/site-packages/robosuite/models/assets/robots/panda/meshes/link4_vis.stl" />
        <mesh name="robot0_link5_vis" file="/home/ahjoshi/.pyenv/versions/env375/lib/python3.7/site-packages/robosuite/models/assets/robots/panda/meshes/link5_vis.stl" />
        <mesh name="robot0_link6_vis" file="/home/ahjoshi/.pyenv/versions/env375/lib/python3.7/site-packages/robosuite/models/assets/robots/panda/meshes/link6_vis.stl" />
        <mesh name="robot0_link7_vis" file="/home/ahjoshi/.pyenv/versions/env375/lib/python3.7/site-packages/robosuite/models/assets/robots/panda/meshes/link7_vis.stl" />
        <mesh name="mount0_pedestal" file="/home/ahjoshi/.pyenv/versions/env375/lib/python3.7/site-packages/robosuite/models/assets/mounts/meshes/rethink_mount/pedestal.stl" />
        <mesh name="gripper0_hand" file="/home/ahjoshi/.pyenv/versions/env375/lib/python3.7/site-packages/robosuite/models/assets/grippers/meshes/panda_gripper/hand.stl" />
        <mesh name="gripper0_hand_vis" file="/home/ahjoshi/.pyenv/versions/env375/lib/python3.7/site-packages/robosuite/models/assets/grippers/meshes/panda_gripper/hand_vis.stl" />
        <mesh name="gripper0_finger" file="/home/ahjoshi/.pyenv/versions/env375/lib/python3.7/site-packages/robosuite/models/assets/grippers/meshes/panda_gripper/finger.stl" />
        <mesh name="gripper0_finger_vis" file="/home/ahjoshi/.pyenv/versions/env375/lib/python3.7/site-packages/robosuite/models/assets/grippers/meshes/panda_gripper/finger_vis.stl" />
        <mesh name="gripper0_finger_vis2" file="/home/ahjoshi/.pyenv/versions/env375/lib/python3.7/site-packages/robosuite/models/assets/grippers/meshes/panda_gripper/finger_longer.stl" />
    </asset>
    <worldbody>
        <geom name="floor" size="3 3 0.125" type="plane" material="floorplane" />
        <geom name="wall_leftcorner_visual" size="1.06 1.5 0.01" pos="-1.25 2.25 1.5" quat="0.653281 0.653281 0.270598 0.270598" type="box" contype="0" conaffinity="0" group="1" material="walls_mat" />
        <geom name="wall_rightcorner_visual" size="1.06 1.5 0.01" pos="-1.25 -2.25 1.5" quat="0.653281 0.653281 -0.270598 -0.270598" type="box" contype="0" conaffinity="0" group="1" material="walls_mat" />
        <geom name="wall_left_visual" size="1.75 1.5 0.01" pos="1.25 3 1.5" quat="0.707107 0.707107 0 0" type="box" contype="0" conaffinity="0" group="1" material="walls_mat" />
        <geom name="wall_right_visual" size="1.75 1.5 0.01" pos="1.25 -3 1.5" quat="0.707107 -0.707107 0 0" type="box" contype="0" conaffinity="0" group="1" material="walls_mat" />
        <geom name="wall_rear_visual" size="1.5 1.5 0.01" pos="-2 0 1.5" quat="0.5 0.5 0.5 0.5" type="box" contype="0" conaffinity="0" group="1" material="walls_mat" />
        <geom name="wall_front_visual" size="3 1.5 0.01" pos="3 0 1.5" quat="0.5 0.5 -0.5 -0.5" type="box" contype="0" conaffinity="0" group="1" material="walls_mat" />
        <camera name="frontview" pos="1.6 0 1.45" quat="0.56 0.43 0.43 0.56" />
        <camera name="birdview" pos="-0.2 0 3" quat="0.7071 0 0 0.7071" />
        <camera name="agentview" pos="0.5 0 1.35" quat="0.653 0.271 0.271 0.653" />
        <camera name="sideview" pos="-0.0565177 1.27612 1.48796" quat="0.00990507 0.00687796 0.591223 0.806418" />
        <light pos="1 1 4" dir="0 -0.14834 -0.988936" castshadow="false" diffuse="0.8 0.8 0.8" />
        <light pos="-3 -3 4" dir="0 -0.14834 -0.988936" castshadow="false" diffuse="0.8 0.8 0.8" />
        <body name="table" pos="0 0 0.795">
            <inertial pos="0 0 0" mass="32" diaginertia="1.71333 1.71333 3.41333" />
            <geom name="table_collision" size="0.4 0.4 0.025" type="box" rgba="0.5 0.5 0 1" />
            <geom name="table_visual" size="0.4 0.4 0.025" type="box" contype="0" conaffinity="0" group="1" material="table_ceramic" />
            <geom name="table_leg1_visual" size="0.025 0.3975" pos="0.3 0.3 -0.3975" type="cylinder" contype="0" conaffinity="0" group="1" material="table_legs_metal" />
            <geom name="table_leg2_visual" size="0.025 0.3975" pos="-0.3 0.3 -0.3975" type="cylinder" contype="0" conaffinity="0" group="1" material="table_legs_metal" />
            <geom name="table_leg3_visual" size="0.025 0.3975" pos="-0.3 -0.3 -0.3975" type="cylinder" contype="0" conaffinity="0" group="1" material="table_legs_metal" />
            <geom name="table_leg4_visual" size="0.025 0.3975" pos="0.3 -0.3 -0.3975" type="cylinder" contype="0" conaffinity="0" group="1" material="table_legs_metal" />
            <site name="table_top" pos="0 0 0.025" size="0.001" rgba="0 0 0 0" />
        </body>
        <body name="peg1" pos="0.23 0.1 0.85">
            <inertial pos="0 0 0" mass="0.2048" diaginertia="0.000700143 0.000700143 3.49525e-05" />
            <geom size="0.016 0.016 0.1" type="box" rgba="0.5 0.5 0 1" />
            <geom size="0.016 0.016 0.1" type="box" contype="0" conaffinity="0" group="1" material="bmetal" />
        </body>
        <body name="peg2" pos="0.23 -0.1 0.85">
            <inertial pos="0 0 0" mass="0.251327" diaginertia="0.000862891 0.000862891 5.02655e-05" />
            <geom size="0.02 0.1" type="cylinder" rgba="0.5 0.5 0 1" />
            <geom size="0.02 0.1" type="cylinder" contype="0" conaffinity="0" group="1" material="smetal" />
        </body>
        <body name="robot0_base" pos="-0.56 0 0.912">
            <inertial pos="0 0 0" mass="0" diaginertia="0 0 0" />
            <camera name="robot0_robotview" pos="1 0 0.4" quat="0.653 0.271 0.271 0.653" />
            <body name="robot0_link0" pos="0 0 0">
                <inertial pos="0 0 0.05" mass="4" diaginertia="0.4 0.4 0.4" />
                <geom name="robot0_link0_visual" type="mesh" contype="0" conaffinity="0" group="1" rgba="1 1 1 1" mesh="robot0_link0_vis" />
                <geom name="robot0_link0_collision" type="mesh" rgba="0 0.5 0 1" mesh="robot0_link0" />
                <body name="robot0_link1" pos="0 0 0.333">
                    <inertial pos="0 0 -0.07" mass="3" diaginertia="0.3 0.3 0.3" />
                    <joint name="robot0_joint1" pos="0 0 0" axis="0 0 1" limited="true" range="-2.8973 2.8973" armature="5" damping="0.1" frictionloss="0.1" />
                    <geom name="robot0_link1_visual" type="mesh" contype="0" conaffinity="0" group="1" rgba="1 1 1 1" mesh="robot0_link1_vis" />
                    <geom name="robot0_link1_collision" type="mesh" rgba="0 0.5 0 1" mesh="robot0_link1" />
                    <body name="robot0_link2" pos="0 0 0" quat="0.707107 -0.707107 0 0">
                        <inertial pos="0 -0.1 0" mass="3" diaginertia="0.3 0.3 0.3" />
                        <joint name="robot0_joint2" pos="0 0 0" axis="0 0 1" limited="true" range="-1.7628 1.7628" armature="2.5" damping="0.1" frictionloss="0.1" />
                        <geom name="robot0_link2_visual" type="mesh" contype="0" conaffinity="0" group="1" rgba="1 1 1 1" mesh="robot0_link2_vis" />
                        <geom name="robot0_link2_collision" type="mesh" rgba="0 0.5 0 1" mesh="robot0_link2" />
                        <body name="robot0_link3" pos="0 -0.316 0" quat="0.707107 0.707107 0 0">
                            <inertial pos="0.04 0 -0.05" mass="2" diaginertia="0.2 0.2 0.2" />
                            <joint name="robot0_joint3" pos="0 0 0" axis="0 0 1" limited="true" range="-2.8973 2.8973" armature="1.66667" damping="0.1" frictionloss="0.1" />
                            <geom name="robot0_link3_visual" type="mesh" contype="0" conaffinity="0" group="1" rgba="1 1 1 1" mesh="robot0_link3_vis" />
                            <geom name="robot0_link3_collision" type="mesh" rgba="0 0.5 0 1" mesh="robot0_link3" />
                            <body name="robot0_link4" pos="0.0825 0 0" quat="0.707107 0.707107 0 0">
                                <inertial pos="-0.04 0.05 0" mass="2" diaginertia="0.2 0.2 0.2" />
                                <joint name="robot0_joint4" pos="0 0 0" axis="0 0 1" limited="true" range="-3.0718 -0.0698" armature="1.25" damping="0.1" frictionloss="0.1" />
                                <geom name="robot0_link4_visual" type="mesh" contype="0" conaffinity="0" group="1" rgba="1 1 1 1" mesh="robot0_link4_vis" />
                                <geom name="robot0_link4_collision" type="mesh" rgba="0 0.5 0 1" mesh="robot0_link4" />
                                <body name="robot0_link5" pos="-0.0825 0.384 0" quat="0.707107 -0.707107 0 0">
                                    <inertial pos="0 0 -0.15" mass="2" diaginertia="0.2 0.2 0.2" />
                                    <joint name="robot0_joint5" pos="0 0 0" axis="0 0 1" limited="true" range="-2.8973 2.8973" armature="1" damping="0.1" frictionloss="0.1" />
                                    <geom name="robot0_link5_visual" type="mesh" contype="0" conaffinity="0" group="1" rgba="1 1 1 1" mesh="robot0_link5_vis" />
                                    <geom name="robot0_link5_collision" type="mesh" rgba="0 0.5 0 1" mesh="robot0_link5" />
                                    <body name="robot0_link6" pos="0 0 0" quat="0.707107 0.707107 0 0">
                                        <inertial pos="0.06 0 0" mass="1.5" diaginertia="0.1 0.1 0.1" />
                                        <joint name="robot0_joint6" pos="0 0 0" axis="0 0 1" limited="true" range="-0.0175 3.7525" armature="0.833333" damping="0.01" frictionloss="0.1" />
                                        <geom name="robot0_link6_visual" type="mesh" contype="0" conaffinity="0" group="1" rgba="1 1 1 1" mesh="robot0_link6_vis" />
                                        <geom name="robot0_link6_collision" type="mesh" rgba="0 0.5 0 1" mesh="robot0_link6" />
                                        <body name="robot0_link7" pos="0.088 0 0" quat="0.707107 0.707107 0 0">
                                            <inertial pos="0 0 0.08" mass="0.5" diaginertia="0.05 0.05 0.05" />
                                            <joint name="robot0_joint7" pos="0 0 0" axis="0 0 1" limited="true" range="-2.8973 2.8973" armature="0.714286" damping="0.01" frictionloss="0.1" />
                                            <geom name="robot0_link7_visual" type="mesh" contype="0" conaffinity="0" group="1" rgba="1 1 1 1" mesh="robot0_link7_vis" />
                                            <geom name="robot0_link7_collision" type="mesh" rgba="0 0.5 0 1" mesh="robot0_link7" />
                                            <body name="robot0_right_hand" pos="0 0 0.1065" quat="0.923785 0 0 -0.382911">
                                                <inertial pos="0 0 0" mass="0.5" diaginertia="0.05 0.05 0.05" />
                                                <camera name="robot0_eye_in_hand" pos="0.05 0 0" quat="0 0.707108 0.707108 0" fovy="75" />
                                                <body name="gripper0_right_gripper" pos="0 0 0" quat="0.707107 0 0 -0.707107">
                                                    <inertial pos="0 0 0.17" quat="0.707107 0.707107 0 0" mass="0.3" diaginertia="0.09 0.07 0.05" />
                                                    <geom name="gripper0_hand_visual" quat="0.707107 0 0 0.707107" type="mesh" contype="0" conaffinity="0" group="1" rgba="1 1 1 1" mesh="gripper0_hand_vis" />
                                                    <geom name="gripper0_hand_collision" quat="0.707107 0 0 0.707107" type="mesh" rgba="0 0 0.5 1" mesh="gripper0_hand" />
                                                    <site name="gripper0_ft_frame" pos="0 0 0" size="0.01" group="1" rgba="1 0 0 1" />
                                                    <body name="gripper0_eef" pos="0 0 0.097">
                                                        <inertial pos="0 0 0.097" mass="0" diaginertia="0 0 0" />
                                                        <site name="gripper0_grip_site" pos="0 0 0" size="0.01" group="1" rgba="0.999977 2.3056e-05 0 0.5" />
                                                        <site name="gripper0_ee_x" pos="0.1 0 0" quat="0.707105 0 0.707108 0" size="0.005 0.1" group="1" type="cylinder" rgba="1 0 0 0" />
                                                        <site name="gripper0_ee_y" pos="0 0.1 0" quat="0.707105 0.707108 0 0" size="0.005 0.1" group="1" type="cylinder" rgba="0 1 0 0" />
                                                        <site name="gripper0_ee_z" pos="0 0 0.1" size="0.005 0.1" group="1" type="cylinder" rgba="0 0 1 0" />
                                                        <site name="gripper0_grip_site_cylinder" pos="0 0 0" size="0.005 10" group="1" type="cylinder" rgba="0 1 0 0.3" />
                                                    </body>
                                                    <body name="gripper0_leftfinger" pos="0 0 0.0524" quat="0.707107 0 0 0.707107">
                                                        <inertial pos="0 0 0.05" mass="0.1" diaginertia="0.01 0.01 0.005" />
                                                        <joint name="gripper0_finger_joint1" pos="0 0 0" axis="0 1 0" type="slide" limited="true" range="0 0.04" armature="1" damping="100" frictionloss="1" />
                                                        <geom name="gripper0_finger1_visual" type="mesh" contype="0" conaffinity="0" group="1" rgba="0.499 0.499 0.499 1" mesh="gripper0_finger_vis" />
                                                        <geom name="gripper0_finger1_collision" type="mesh" contype="0" condim="4" rgba="0 0 0.5 1" mesh="gripper0_finger" />
                                                        <body name="gripper0_finger_joint1_tip" pos="0 0.0085 0.056">
                                                            <inertial pos="0 0 0" quat="0 0 0 1" mass="0.01" diaginertia="0.01 0.01 0.01" />
                                                            <geom name="gripper0_finger1_pad_collision" size="0.008 0.004 0.008" pos="0 -0.005 -0.015" quat="0 0 0 1" type="box" friction="2 0.05 0.0001" solref="0.01 0.5" rgba="0 0 0.5 1" />
                                                        </body>
                                                    </body>
                                                    <body name="gripper0_rightfinger" pos="0 0 0.0524" quat="0.707107 0 0 0.707107">
                                                        <inertial pos="0 0 0.05" mass="0.1" diaginertia="0.01 0.01 0.005" />
                                                        <joint name="gripper0_finger_joint2" pos="0 0 0" axis="0 1 0" type="slide" limited="true" range="-0.04 0" armature="1" damping="100" frictionloss="1" />
                                                        <geom name="gripper0_finger2_visual" quat="0 0 0 1" type="mesh" contype="0" conaffinity="0" group="1" rgba="0.499 0.499 0.499 1" mesh="gripper0_finger_vis" />
                                                        <geom name="gripper0_finger2_collision" quat="0 0 0 1" type="mesh" contype="0" condim="4" rgba="0 0 0.5 1" mesh="gripper0_finger" />
                                                        <body name="gripper0_finger_joint2_tip" pos="0 -0.0085 0.056">
                                                            <inertial pos="0 0 0" quat="0 0 0 1" mass="0.01" diaginertia="0.01 0.01 0.01" />
                                                            <geom name="gripper0_finger2_pad_collision" size="0.008 0.004 0.008" pos="0 0.005 -0.015" quat="0 0 0 1" type="box" friction="2 0.05 0.0001" solref="0.01 0.5" rgba="0 0 0.5 1" />
                                                        </body>
                                                    </body>
                                                </body>
                                            </body>
                                        </body>
                                    </body>
                                </body>
                            </body>
                        </body>
                    </body>
                </body>
            </body>
            <body name="mount0_base" pos="0 0 0.01">
                <inertial pos="0 0 0.01" mass="0" diaginertia="0 0 0" />
                <body name="mount0_controller_box" pos="0 0 0">
                    <inertial pos="-0.325 0 -0.38" mass="46.64" diaginertia="1.71363 1.27988 0.809981" />
                    <geom name="mount0_controller_box_col" size="0.11 0.2 0.265" pos="-0.325 0 -0.38" type="box" rgba="0.5 0.5 0 1" />
                </body>
                <body name="mount0_pedestal_feet" pos="0 0 0">
                    <inertial pos="-0.1225 0 -0.758" mass="167.09" diaginertia="8.16095 9.59375 15.0785" />
                    <geom name="mount0_pedestal_feet_col" size="0.385 0.35 0.155" pos="-0.1225 0 -0.758" type="box" rgba="0.5 0.5 0 1" />
                </body>
                <body name="mount0_torso" pos="0 0 0">
                    <inertial pos="0 0 0" mass="0.0001" diaginertia="1e-08 1e-08 1e-08" />
                    <geom name="mount0_torso_vis" size="0.05 0.05 0.05" pos="0 0 -0.05" type="box" contype="0" conaffinity="0" group="1" rgba="0.2 0.2 0.2 1" />
                </body>
                <body name="mount0_pedestal" pos="0 0 0">
                    <inertial pos="0 0 0" quat="0.659267 -0.259505 -0.260945 0.655692" mass="60.864" diaginertia="6.0869 5.81635 4.20915" />
                    <geom name="mount0_pedestal_vis" type="mesh" contype="0" conaffinity="0" group="1" rgba="0.2 0.2 0.2 1" mesh="mount0_pedestal" />
                    <geom name="mount0_pedestal_col" size="0.18 0.31" pos="-0.02 0 -0.29" type="cylinder" rgba="0.5 0.5 0 1" />
                </body>
            </body>
        </body>
        <body name="SquareNut_main" pos="0 0 0">
            <inertial pos="0.0109551 0 0" quat="0 0.707107 0 0.707107" mass="0.0158068" diaginertia="2.91963e-05 1.87672e-05 1.14829e-05" />
            <joint name="SquareNut_joint0" type="free" damping="0.0005" />
            <geom name="SquareNut_g0" size="0.0105 0.04375 0.01" pos="-0.03325 0 0" type="box" condim="4" friction="0.95 0.3 0.2" solimp="0.998 0.998 0.001 0.5 2" rgba="0.5 0 0 1" />
            <geom name="SquareNut_g1" size="0.03125 0.0105 0.01" pos="0 0.03325 0" type="box" condim="4" friction="0.95 0.3 0.1" solimp="0.998 0.998 0.001 0.5 2" rgba="0.5 0 0 1" />
            <geom name="SquareNut_g2" size="0.03125 0.0105 0.01" pos="0 -0.03325 0" type="box" condim="4" friction="0.95 0.3 0.1" solimp="0.998 0.998 0.001 0.5 2" rgba="0.5 0 0 1" />
            <geom name="SquareNut_g3" size="0.0105 0.04375 0.01" pos="0.03325 0 0" type="box" condim="4" friction="0.95 0.3 0.1" solimp="0.998 0.998 0.001 0.5 2" rgba="0.5 0 0 1" />
            <geom name="SquareNut_g4" size="0.02525 0.015875 0.01" pos="0.054 0 0" type="box" condim="4" friction="0.95 0.3 0.1" solimp="0.998 0.998 0.001 0.5 2" rgba="0.5 0 0 1" />
            <geom name="SquareNut_g0_visual" size="0.0105 0.04375 0.01" pos="-0.03325 0 0" type="box" contype="0" conaffinity="0" condim="4" group="1" friction="0.95 0.3 0.2" solimp="0.998 0.998 0.001 0.5 2" material="SquareNut_bmetal" />
            <geom name="SquareNut_g1_visual" size="0.03125 0.0105 0.01" pos="0 0.03325 0" type="box" contype="0" conaffinity="0" condim="4" group="1" friction="0.95 0.3 0.1" solimp="0.998 0.998 0.001 0.5 2" material="SquareNut_bmetal" />
            <geom name="SquareNut_g2_visual" size="0.03125 0.0105 0.01" pos="0 -0.03325 0" type="box" contype="0" conaffinity="0" condim="4" group="1" friction="0.95 0.3 0.1" solimp="0.998 0.998 0.001 0.5 2" material="SquareNut_bmetal" />
            <geom name="SquareNut_g3_visual" size="0.0105 0.04375 0.01" pos="0.03325 0 0" type="box" contype="0" conaffinity="0" condim="4" group="1" friction="0.95 0.3 0.1" solimp="0.998 0.998 0.001 0.5 2" material="SquareNut_bmetal" />
            <geom name="SquareNut_g4_visual" size="0.02525 0.015875 0.01" pos="0.054 0 0" type="box" contype="0" conaffinity="0" condim="4" group="1" friction="0.95 0.3 0.1" solimp="0.998 0.998 0.001 0.5 2" material="SquareNut_bmetal" />
            <site name="SquareNut_handle_site" pos="0.054 0 0" rgba="1 0 0 1" />
            <site name="SquareNut_center_site" pos="0 0 0" size="0.003" rgba="1 0 0 1" />
            <site name="SquareNut_default_site" pos="0 0 0" size="0.002" rgba="1 0 0 0" />
        </body>
        <body name="RoundNut_main" pos="0 0 0">
            <inertial pos="0.00991433 0 0" quat="0 0.707107 0 0.707107" mass="0.0194067" diaginertia="4.3181e-05 2.72618e-05 1.7213e-05" />
            <joint name="RoundNut_joint0" type="free" damping="0.0005" />
            <geom name="RoundNut_g0" size="0.01125 0.0225 0.01" pos="-0.04245 0 0" type="box" condim="4" friction="0.95 0.3 0.1" solimp="0.998 0.998 0.001 0.5 2" rgba="0.5 0 0 1" />
            <geom name="RoundNut_g1" size="0.01125 0.0225 0.01" pos="0.04245 0 0" type="box" condim="4" friction="0.95 0.3 0.1" solimp="0.998 0.998 0.001 0.5 2" rgba="0.5 0 0 1" />
            <geom name="RoundNut_g2" size="0.0225 0.01125 0.01" pos="0 -0.04245 0" type="box" condim="4" friction="0.95 0.3 0.1" solimp="0.998 0.998 0.001 0.5 2" rgba="0.5 0 0 1" />
            <geom name="RoundNut_g3" size="0.0225 0.01125 0.01" pos="0 0.04245 0" type="box" condim="4" friction="0.95 0.3 0.1" solimp="0.998 0.998 0.001 0.5 2" rgba="0.5 0 0 1" />
            <geom name="RoundNut_g4" size="0.01125 0.0225 0.01" pos="-0.03 -0.03 0" quat="0.92388 0 0 0.382683" type="box" condim="4" friction="0.95 0.3 0.1" solimp="0.998 0.998 0.001 0.5 2" rgba="0.5 0 0 1" />
            <geom name="RoundNut_g5" size="0.01125 0.0225 0.01" pos="0.03 0.03 0" quat="0.92388 0 0 0.382683" type="box" condim="4" friction="0.95 0.3 0.1" solimp="0.998 0.998 0.001 0.5 2" rgba="0.5 0 0 1" />
            <geom name="RoundNut_g6" size="0.0225 0.01125 0.01" pos="0.03 -0.03 0" quat="0.92388 0 0 0.382683" type="box" condim="4" friction="0.95 0.3 0.1" solimp="0.998 0.998 0.001 0.5 2" rgba="0.5 0 0 1" />
            <geom name="RoundNut_g7" size="0.0225 0.01125 0.01" pos="-0.03 0.03 0" quat="0.92388 0 0 0.382683" type="box" condim="4" friction="0.95 0.3 0.1" solimp="0.998 0.998 0.001 0.5 2" rgba="0.5 0 0 1" />
            <geom name="RoundNut_g8" size="0.02525 0.015875 0.01" pos="0.06 0 0" type="box" condim="4" friction="0.95 0.3 0.1" solimp="0.998 0.998 0.001 0.5 2" rgba="0.5 0 0 1" />
            <geom name="RoundNut_g0_visual" size="0.01125 0.0225 0.01" pos="-0.04245 0 0" type="box" contype="0" conaffinity="0" condim="4" group="1" friction="0.95 0.3 0.1" solimp="0.998 0.998 0.001 0.5 2" material="RoundNut_smetal" />
            <geom name="RoundNut_g1_visual" size="0.01125 0.0225 0.01" pos="0.04245 0 0" type="box" contype="0" conaffinity="0" condim="4" group="1" friction="0.95 0.3 0.1" solimp="0.998 0.998 0.001 0.5 2" material="RoundNut_smetal" />
            <geom name="RoundNut_g2_visual" size="0.0225 0.01125 0.01" pos="0 -0.04245 0" type="box" contype="0" conaffinity="0" condim="4" group="1" friction="0.95 0.3 0.1" solimp="0.998 0.998 0.001 0.5 2" material="RoundNut_smetal" />
            <geom name="RoundNut_g3_visual" size="0.0225 0.01125 0.01" pos="0 0.04245 0" type="box" contype="0" conaffinity="0" condim="4" group="1" friction="0.95 0.3 0.1" solimp="0.998 0.998 0.001 0.5 2" material="RoundNut_smetal" />
            <geom name="RoundNut_g4_visual" size="0.01125 0.0225 0.01" pos="-0.03 -0.03 0" quat="0.92388 0 0 0.382683" type="box" contype="0" conaffinity="0" condim="4" group="1" friction="0.95 0.3 0.1" solimp="0.998 0.998 0.001 0.5 2" material="RoundNut_smetal" />
            <geom name="RoundNut_g5_visual" size="0.01125 0.0225 0.01" pos="0.03 0.03 0" quat="0.92388 0 0 0.382683" type="box" contype="0" conaffinity="0" condim="4" group="1" friction="0.95 0.3 0.1" solimp="0.998 0.998 0.001 0.5 2" material="RoundNut_smetal" />
            <geom name="RoundNut_g6_visual" size="0.0225 0.01125 0.01" pos="0.03 -0.03 0" quat="0.92388 0 0 0.382683" type="box" contype="0" conaffinity="0" condim="4" group="1" friction="0.95 0.3 0.1" solimp="0.998 0.998 0.001 0.5 2" material="RoundNut_smetal" />
            <geom name="RoundNut_g7_visual" size="0.0225 0.01125 0.01" pos="-0.03 0.03 0" quat="0.92388 0 0 0.382683" type="box" contype="0" conaffinity="0" condim="4" group="1" friction="0.95 0.3 0.1" solimp="0.998 0.998 0.001 0.5 2" material="RoundNut_smetal" />
            <geom name="RoundNut_g8_visual" size="0.02525 0.015875 0.01" pos="0.06 0 0" type="box" contype="0" conaffinity="0" condim="4" group="1" friction="0.95 0.3 0.1" solimp="0.998 0.998 0.001 0.5 2" material="RoundNut_smetal" />
            <site name="RoundNut_handle_site" pos="0.06 0 0" rgba="1 0 0 1" />
            <site name="RoundNut_center_site" pos="0 0 0" size="0.003" rgba="1 0 0 1" />
            <site name="RoundNut_default_site" pos="0 0 0" size="0.002" rgba="1 0 0 0" />
        </body>
    </worldbody>
    <actuator>
        <general name="robot0_torq_j1" joint="robot0_joint1" ctrllimited="true" ctrlrange="-80 80" />
        <general name="robot0_torq_j2" joint="robot0_joint2" ctrllimited="true" ctrlrange="-80 80" />
        <general name="robot0_torq_j3" joint="robot0_joint3" ctrllimited="true" ctrlrange="-80 80" />
        <general name="robot0_torq_j4" joint="robot0_joint4" ctrllimited="true" ctrlrange="-80 80" />
        <general name="robot0_torq_j5" joint="robot0_joint5" ctrllimited="true" ctrlrange="-80 80" />
        <general name="robot0_torq_j6" joint="robot0_joint6" ctrllimited="true" ctrlrange="-12 12" />
        <general name="robot0_torq_j7" joint="robot0_joint7" ctrllimited="true" ctrlrange="-12 12" />
        <general name="gripper0_gripper_finger_joint1" joint="gripper0_finger_joint1" ctrllimited="true" forcelimited="true" ctrlrange="0 0.04" forcerange="-20 20" biastype="affine" gainprm="1000 0 0 0 0 0 0 0 0 0" biasprm="0 -1000 0 0 0 0 0 0 0 0" />
        <general name="gripper0_gripper_finger_joint2" joint="gripper0_finger_joint2" ctrllimited="true" forcelimited="true" ctrlrange="-0.04 0" forcerange="-20 20" biastype="affine" gainprm="1000 0 0 0 0 0 0 0 0 0" biasprm="0 -1000 0 0 0 0 0 0 0 0" />
    </actuator>
    <sensor>
        <force site="gripper0_ft_frame" name="gripper0_force_ee" />
        <torque site="gripper0_ft_frame" name="gripper0_torque_ee" />
    </sensor>
</mujoco>
