<?xml version="1.0" ?>
<mujoco model="sawyer">
  <compiler angle="radian"/>
  <actuator>
    <motor ctrllimited="true" ctrlrange="-80.0 80.0" joint="right_j0" name="torq_right_j0"/>
    <motor ctrllimited="true" ctrlrange="-80.0 80.0" joint="right_j1" name="torq_right_j1"/>
    <motor ctrllimited="true" ctrlrange="-40.0 40.0" joint="right_j2" name="torq_right_j2"/>
    <motor ctrllimited="true" ctrlrange="-40.0 40.0" joint="right_j3" name="torq_right_j3"/>
    <motor ctrllimited="true" ctrlrange="-9.0 9.0" joint="right_j4" name="torq_right_j4"/>
    <motor ctrllimited="true" ctrlrange="-9.0 9.0" joint="right_j5" name="torq_right_j5"/>
    <motor ctrllimited="true" ctrlrange="-9.0 9.0" joint="right_j6" name="torq_right_j6"/>
  </actuator>
  <asset>
    <!-- base material and mesh -->
    <material name="Mtl1.017" specular="0.5" shininess="0.225" rgba="1.000000 0.000000 0.000000 1.000000"/>
    <material name="Mtl2.017" specular="0.5" shininess="0.225" rgba="0.286275 0.286275 0.286275 1.000000"/>
    <mesh name="base_0" file="obj_meshes/base/base_0.obj"/>
    <mesh name="base_1" file="obj_meshes/base/base_1.obj"/>
    <!-- head material and mesh -->
    <material name="Mtl1" specular="0.5" shininess="0.225" rgba="1.000000 0.000000 0.000000 1.000000"/>
    <material name="Mtl2" specular="0.5" shininess="0.225" rgba="0.000000 0.000000 0.000000 1.000000"/>
    <material name="Mtl4" specular="0.5" shininess="0.225" rgba="1.000000 1.000000 1.000000 1.000000"/>
    <material name="Mtl5" specular="0.5" shininess="0.225" rgba="0.870588 0.309804 0.086275 1.000000"/>
    <material name="Mtl6" specular="0.5" shininess="0.225" rgba="0.286275 0.286275 0.286275 1.000000"/>
    <material name="Mtl7" specular="0.5" shininess="0.225" rgba="0.698039 0.698039 0.698039 1.000000"/>
    <material name="Mtl8" specular="0.5" shininess="0.225" rgba="0.792157 0.819608 0.929412 1.000000"/>
    <material name="Mtl9" specular="0.5" shininess="0.225" rgba="0.250980 0.250980 0.250980 1.000000"/>
    <material name="Mtla" specular="0.5" shininess="0.225" rgba="0.000000 0.000000 1.000000 1.000000"/>
    <material name="Mtlb" specular="0.5" shininess="0.225" rgba="0.290196 0.290196 0.290196 1.000000"/>
    <mesh name="head_0" file="obj_meshes/head/head_0.obj"/>
    <mesh name="head_1" file="obj_meshes/head/head_1.obj"/>
    <mesh name="head_2" file="obj_meshes/head/head_2.obj"/>
    <mesh name="head_3" file="obj_meshes/head/head_3.obj"/>
    <mesh name="head_4" file="obj_meshes/head/head_4.obj"/>
    <mesh name="head_5" file="obj_meshes/head/head_5.obj"/>
    <mesh name="head_6" file="obj_meshes/head/head_6.obj"/>
    <mesh name="head_7" file="obj_meshes/head/head_7.obj"/>
    <mesh name="head_8" file="obj_meshes/head/head_8.obj"/>
    <mesh name="head_9" file="obj_meshes/head/head_9.obj"/>
    <!-- l0 material and mesh -->
    <material name="Mtl1.014" specular="0.5" shininess="0.225" rgba="0.286275 0.286275 0.286275 1.000000"/>
    <material name="Mtl2.014" specular="0.5" shininess="0.225" rgba="1.000000 1.000000 1.000000 1.000000"/>
    <material name="Mtl3.013" specular="0.5" shininess="0.225" rgba="0.168627 0.152941 0.141176 1.000000"/>
    <material name="Mtl4.012" specular="0.5" shininess="0.225" rgba="1.000000 0.403922 0.121569 1.000000"/>
    <material name="Mtl5.010" specular="0.5" shininess="0.225" rgba="1.000000 0.000000 0.000000 1.000000"/>
    <material name="Mtl6.008" specular="0.5" shininess="0.225" rgba="0.792157 0.819608 0.929412 1.000000"/>
    <material name="Mtl7.007" specular="0.5" shininess="0.225" rgba="0.250980 0.250980 0.250980 1.000000"/>
    <mesh name="l0_0" file="obj_meshes/l0/l0_0.obj"/>
    <mesh name="l0_1" file="obj_meshes/l0/l0_1.obj"/>
    <mesh name="l0_2" file="obj_meshes/l0/l0_2.obj"/>
    <mesh name="l0_3" file="obj_meshes/l0/l0_3.obj"/>
    <mesh name="l0_4" file="obj_meshes/l0/l0_4.obj"/>
    <mesh name="l0_5" file="obj_meshes/l0/l0_5.obj"/>
    <mesh name="l0_6" file="obj_meshes/l0/l0_6.obj"/>
    <!-- l1 material and mesh -->
    <material name="Mtl1.004" specular="0.5" shininess="0.225" rgba="1.000000 1.000000 1.000000 1.000000"/>
    <material name="Mtl2.004" specular="0.5" shininess="0.225" rgba="1.000000 0.000000 0.000000 1.000000"/>
    <material name="Mtl3.003" specular="0.5" shininess="0.225" rgba="0.286275 0.286275 0.286275 1.000000"/>
    <mesh name="l1_0" file="obj_meshes/l1/l1_0.obj"/>
    <mesh name="l1_1" file="obj_meshes/l1/l1_1.obj"/>
    <mesh name="l1_2" file="obj_meshes/l1/l1_2.obj"/>
    <!-- l2 material and mesh -->
    <material name="Mtl1.005" specular="0.5" shininess="0.225" rgba="1.000000 0.000000 0.000000 1.000000"/>
    <material name="Mtl2.005" specular="0.5" shininess="0.225" rgba="0.286275 0.286275 0.286275 1.000000"/>
    <material name="Mtl3.004" specular="0.5" shininess="0.225" rgba="1.000000 1.000000 1.000000 1.000000"/>
    <material name="Mtl4.003" specular="0.5" shininess="0.225" rgba="0.792157 0.819608 0.929412 1.000000"/>
    <material name="Mtl5.003" specular="0.5" shininess="0.225" rgba="0.105882 0.105882 0.105882 1.000000"/>
    <mesh name="l2_0" file="obj_meshes/l2/l2_0.obj"/>
    <mesh name="l2_1" file="obj_meshes/l2/l2_1.obj"/>
    <mesh name="l2_2" file="obj_meshes/l2/l2_2.obj"/>
    <mesh name="l2_3" file="obj_meshes/l2/l2_3.obj"/>
    <mesh name="l2_4" file="obj_meshes/l2/l2_4.obj"/>
    <!-- l3 material and mesh -->
    <material name="Mtl1.007" specular="0.5" shininess="0.225" rgba="0.290196 0.290196 0.290196 1.000000"/>
    <material name="Mtl2.007" specular="0.5" shininess="0.225" rgba="1.000000 1.000000 1.000000 1.000000"/>
    <material name="Mtl3.006" specular="0.5" shininess="0.225" rgba="1.000000 0.000000 0.000000 1.000000"/>
    <material name="Mtl4.005" specular="0.5" shininess="0.225" rgba="0.792157 0.819608 0.929412 1.000000"/>
    <mesh name="l3_0" file="obj_meshes/l3/l3_0.obj"/>
    <mesh name="l3_1" file="obj_meshes/l3/l3_1.obj"/>
    <mesh name="l3_2" file="obj_meshes/l3/l3_2.obj"/>
    <mesh name="l3_3" file="obj_meshes/l3/l3_3.obj"/>
    <!-- l4 material and mesh -->
    <material name="Mtl1.010" specular="0.5" shininess="0.225" rgba="0.286275 0.286275 0.286275 1.000000"/>
    <material name="Mtl2.010" specular="0.5" shininess="0.225" rgba="1.000000 0.000000 0.000000 1.000000"/>
    <material name="Mtl3.009" specular="0.5" shininess="0.225" rgba="0.000000 0.000000 0.000000 1.000000"/>
    <material name="Mtl4.008" specular="0.5" shininess="0.225" rgba="0.792157 0.819608 0.929412 1.000000"/>
    <material name="Mtl5.006" specular="0.5" shininess="0.225" rgba="1.000000 1.000000 1.000000 1.000000"/>
    <material name="Mtl6.004" specular="0.5" shininess="0.225" rgba="0.749020 0.749020 0.749020 1.000000"/>
    <material name="Mtl7.004" specular="0.5" shininess="0.225" rgba="0.290196 0.290196 0.290196 1.000000"/>
    <material name="Mtl8.002" specular="0.5" shininess="0.225" rgba="0.250980 0.250980 0.250980 1.000000"/>
    <mesh name="l4_0" file="obj_meshes/l4/l4_0.obj"/>
    <mesh name="l4_1" file="obj_meshes/l4/l4_1.obj"/>
    <mesh name="l4_2" file="obj_meshes/l4/l4_2.obj"/>
    <mesh name="l4_3" file="obj_meshes/l4/l4_3.obj"/>
    <mesh name="l4_4" file="obj_meshes/l4/l4_4.obj"/>
    <mesh name="l4_5" file="obj_meshes/l4/l4_5.obj"/>
    <mesh name="l4_6" file="obj_meshes/l4/l4_6.obj"/>
    <mesh name="l4_7" file="obj_meshes/l4/l4_7.obj"/>
    <!-- l5 material and mesh -->
    <material name="Mtl1_001" specular="0.5" shininess="0.225" rgba="1.000000 0.000000 0.000000 1.000000"/>
    <material name="Mtl2_001" specular="0.5" shininess="0.225" rgba="1.000000 1.000000 1.000000 1.000000"/>
    <material name="Mtl3_001" specular="0.5" shininess="0.225" rgba="0.286275 0.286275 0.286275 1.000000"/>
    <material name="Mtl4_001" specular="0.5" shininess="0.225" rgba="0.866667 0.905882 1.000000 1.000000"/>
    <material name="Mtl5_001" specular="0.5" shininess="0.225" rgba="0.501961 0.501961 0.501961 1.000000"/>
    <mesh name="l5_0" file="obj_meshes/l5/l5_0.obj"/>
    <mesh name="l5_1" file="obj_meshes/l5/l5_1.obj"/>
    <mesh name="l5_2" file="obj_meshes/l5/l5_2.obj"/>
    <mesh name="l5_3" file="obj_meshes/l5/l5_3.obj"/>
    <mesh name="l5_4" file="obj_meshes/l5/l5_4.obj"/>
    <!-- l6 material and mesh -->
    <material name="Mtl1.012" specular="0.5" shininess="0.225" rgba="0.298039 0.298039 0.298039 1.000000"/>
    <material name="Mtl2.012" specular="0.5" shininess="0.225" rgba="0.282353 0.282353 0.282353 1.000000"/>
    <material name="Mtl3.011" specular="0.5" shininess="0.225" rgba="0.286275 0.286275 0.286275 1.000000"/>
    <material name="Mtl4.010" specular="0.5" shininess="0.225" rgba="1.000000 0.000000 0.000000 1.000000"/>
    <material name="Mtl5.008" specular="0.5" shininess="0.225" rgba="1.000000 1.000000 1.000000 1.000000"/>
    <material name="Mtl6.006" specular="0.5" shininess="0.225" rgba="1.000000 0.403922 0.121569 1.000000"/>
    <mesh name="l6_0" file="obj_meshes/l6/l6_0.obj"/>
    <mesh name="l6_1" file="obj_meshes/l6/l6_1.obj"/>
    <mesh name="l6_2" file="obj_meshes/l6/l6_2.obj"/>
    <mesh name="l6_3" file="obj_meshes/l6/l6_3.obj"/>
    <mesh name="l6_4" file="obj_meshes/l6/l6_4.obj"/>
    <mesh name="l6_5" file="obj_meshes/l6/l6_5.obj"/>
  </asset>
  <worldbody>
    <body name="base" pos="0 0 0">
      <!-- robot view -->
      <camera mode="fixed" name="robotview" pos="1.0 0 0.4" quat="0.653 0.271 0.271 0.653"/>
      <inertial diaginertia="0 0 0" mass="0" pos="0 0 0"/>
      <!-- mount attached here -->
      <body name="right_arm_base_link" pos="0 0 0">
        <site name="right_center" pos="0 0 0" size="0.01" rgba="1 0.3 0.3 1" group="2"/>
        <inertial diaginertia="0.00740351 0.00681776 0.00672942" mass="2.0687" pos="-0.0006241 -2.8025e-05 0.065404" quat="-0.209285 0.674441 0.227335 0.670558"/>
        <geom mesh="base_0" material="Mtl2.017" type="mesh" contype="0" conaffinity="0" group="1"/>
        <geom mesh="base_1" material="Mtl1.017" type="mesh" contype="0" conaffinity="0" group="1"/>
        <geom pos="0 0 0.12" rgba="0.5 0.1 0.1 1" size="0.08 0.12" type="cylinder" name="base_col"/>
        <body name="right_l0" pos="0 0 0.08">
          <inertial diaginertia="0.0651588 0.0510944 0.0186218" mass="5.3213" pos="0.024366 0.010969 0.14363" quat="0.894823 0.00899958 -0.170275 0.412573"/>
          <joint axis="0 0 1" limited="true" name="right_j0" pos="0 0 0" range="-3.0503 3.0503"/>
          <geom mesh="l0_0" material="Mtl7.007" type="mesh" contype="0" conaffinity="0" group="1"/>
          <geom mesh="l0_1" material="Mtl6.008" type="mesh" contype="0" conaffinity="0" group="1"/>
          <geom mesh="l0_2" material="Mtl5.010" type="mesh" contype="0" conaffinity="0" group="1"/>
          <geom mesh="l0_3" material="Mtl4.012" type="mesh" contype="0" conaffinity="0" group="1"/>
          <geom mesh="l0_4" material="Mtl3.013" type="mesh" contype="0" conaffinity="0" group="1"/>
          <geom mesh="l0_5" material="Mtl2.014" type="mesh" contype="0" conaffinity="0" group="1"/>
          <geom mesh="l0_6" material="Mtl1.014" type="mesh" contype="0" conaffinity="0" group="1"/>
          <geom pos="0.08 0 0.23" rgba="0.5 0.1 0.1 1" size="0.07" name="link0_collision"/>
          <body name="head" pos="0 0 0.2965">
            <inertial diaginertia="0.0118334 0.00827089 0.00496574" mass="1.5795" pos="0.0053207 -2.6549e-05 0.1021" quat="0.999993 7.08405e-05 -0.00359857 -0.000626247"/>
            <!--Don't want to control the head joint so remove it from the kinematic tree-->
            <!--<joint axis="0 0 1" limited="true" name="head_pan" pos="0 0 0" range="-5.0952 0.9064"/>-->
            <geom mesh="head_0" material="Mtlb" type="mesh" contype="0" conaffinity="0" group="1"/>
            <geom mesh="head_1" material="Mtla" type="mesh" contype="0" conaffinity="0" group="1"/>
            <geom mesh="head_2" material="Mtl8" type="mesh" contype="0" conaffinity="0" group="1"/>
            <geom mesh="head_3" material="Mtl9" type="mesh" contype="0" conaffinity="0" group="1"/>
            <geom mesh="head_4" material="Mtl7" type="mesh" contype="0" conaffinity="0" group="1"/>
            <geom mesh="head_5" material="Mtl6" type="mesh" contype="0" conaffinity="0" group="1"/>
            <geom mesh="head_6" material="Mtl4" type="mesh" contype="0" conaffinity="0" group="1"/>
            <geom mesh="head_7" material="Mtl2" type="mesh" contype="0" conaffinity="0" group="1"/>
            <geom mesh="head_8" material="Mtl1" type="mesh" contype="0" conaffinity="0" group="1"/>
            <geom mesh="head_9" material="Mtl5" type="mesh" contype="0" conaffinity="0" group="1"/>
            <geom pos="0 0 0.08" rgba="0.5 0.1 0.1 1" size="0.018" name="head_collision"/>
            <body name="screen" pos="0.03 0 0.105" quat="0.5 0.5 0.5 0.5">
              <inertial diaginertia="1e-08 1e-08 1e-08" mass="0.0001" pos="0 0 0"/>
              <geom rgba="0.2 0.2 0.2 1" size="0.001" name="screen_collision"/>
            </body>
            <body name="head_camera" pos="0.0228027 0 0.216572" quat="0.342813 -0.618449 0.618449 -0.342813">
              <inertial diaginertia="0 0 0" mass="0" pos="0.0228027 0 0.216572" quat="0.342813 -0.618449 0.618449 -0.342813"/>
            </body>
          </body>
          <body name="right_torso_itb" pos="-0.055 0 0.22" quat="0.707107 0 -0.707107 0">
            <inertial diaginertia="1e-08 1e-08 1e-08" mass="0.0001" pos="0 0 0"/>
          </body>
          <body name="right_l1" pos="0.081 0.05 0.237" quat="0.5 -0.5 0.5 0.5">
            <inertial diaginertia="0.0224339 0.0221624 0.0097097" mass="4.505" pos="-0.0030849 -0.026811 0.092521" quat="0.424888 0.891987 0.132364 -0.0794296"/>
            <joint axis="0 0 1" limited="true" name="right_j1" pos="0 0 0" range="-3.8095 2.2736"/>
            <geom mesh="l1_0" material="Mtl3.003" type="mesh" contype="0" conaffinity="0" group="1"/>
            <geom mesh="l1_1" material="Mtl2.004" type="mesh" contype="0" conaffinity="0" group="1"/>
            <geom mesh="l1_2" material="Mtl1.004" type="mesh" contype="0" conaffinity="0" group="1"/>
            <geom pos="0 0 0.1225" rgba="0.5 0.1 0.1 1" size="0.07" name="link1_collision"/>
            <body name="right_l2" pos="0 -0.14 0.1425" quat="0.707107 0.707107 0 0">
              <inertial diaginertia="0.0257928 0.025506 0.00292515" mass="1.745" pos="-0.00016044 -0.014967 0.13582" quat="0.707831 -0.0524761 0.0516007 0.702537"/>
              <joint axis="0 0 1" limited="true" name="right_j2" pos="0 0 0" range="-3.0426 3.0426"/>
              <geom mesh="l2_0" material="Mtl4.003" type="mesh" contype="0" conaffinity="0" group="1"/>
              <geom mesh="l2_1" material="Mtl5.003" type="mesh" contype="0" conaffinity="0" group="1"/>
              <geom mesh="l2_2" material="Mtl3.004" type="mesh" contype="0" conaffinity="0" group="1"/>
              <geom mesh="l2_3" material="Mtl2.005" type="mesh" contype="0" conaffinity="0" group="1"/>
              <geom mesh="l2_4" material="Mtl1.005" type="mesh" contype="0" conaffinity="0" group="1"/>
              <geom pos="0 0 0.08" rgba="0.5 0.1 0.1 1" size="0.06 0.17" type="cylinder" name="link2_collision"/>
              <body name="right_l3" pos="0 -0.042 0.26" quat="0.707107 -0.707107 0 0">
                <inertial diaginertia="0.0102404 0.0096997 0.00369622" mass="2.5097" pos="-0.0048135 -0.0281 -0.084154" quat="0.902999 0.385391 -0.0880901 0.168247"/>
                <joint axis="0 0 1" limited="true" name="right_j3" pos="0 0 0" range="-3.0439 3.0439"/>
                <geom mesh="l3_0" material="Mtl4.005" type="mesh" contype="0" conaffinity="0" group="1"/>
                <geom mesh="l3_1" material="Mtl3.006" type="mesh" contype="0" conaffinity="0" group="1"/>
                <geom mesh="l3_2" material="Mtl2.007" type="mesh" contype="0" conaffinity="0" group="1"/>
                <geom mesh="l3_3" material="Mtl1.007" type="mesh" contype="0" conaffinity="0" group="1"/>
                <geom pos="0 -0.01 -0.12" rgba="0.5 0.1 0.1 1" size="0.06" name="link3_collision"/>
                <body name="right_l4" pos="0 -0.125 -0.1265" quat="0.707107 0.707107 0 0">
                  <inertial diaginertia="0.0136549 0.0135493 0.00127353" mass="1.1136" pos="-0.0018844 0.0069001 0.1341" quat="0.803612 0.031257 -0.0298334 0.593582"/>
                  <joint axis="0 0 1" limited="true" name="right_j4" pos="0 0 0" range="-2.9761 2.9761"/>
                  <geom mesh="l4_0" material="Mtl8.002" type="mesh" contype="0" conaffinity="0" group="1"/>
                  <geom mesh="l4_1" material="Mtl7.004" type="mesh" contype="0" conaffinity="0" group="1"/>
                  <geom mesh="l4_2" material="Mtl6.004" type="mesh" contype="0" conaffinity="0" group="1"/>
                  <geom mesh="l4_3" material="Mtl5.006" type="mesh" contype="0" conaffinity="0" group="1"/>
                  <geom mesh="l4_4" material="Mtl4.008" type="mesh" contype="0" conaffinity="0" group="1"/>
                  <geom mesh="l4_5" material="Mtl3.009" type="mesh" contype="0" conaffinity="0" group="1"/>
                  <geom mesh="l4_6" material="Mtl2.010" type="mesh" contype="0" conaffinity="0" group="1"/>
                  <geom mesh="l4_7" material="Mtl1.010" type="mesh" contype="0" conaffinity="0" group="1"/>
                  <geom pos="0 0 0.11" rgba="0.5 0.1 0.1 1" size="0.045 0.15" type="cylinder" name="link4_collision"/>
                  <body name="right_arm_itb" pos="-0.055 0 0.075" quat="0.707107 0 -0.707107 0">
                    <inertial diaginertia="1e-08 1e-08 1e-08" mass="0.0001" pos="0 0 0"/>
                  </body>
                  <body name="right_l5" pos="0 0.031 0.275" quat="0.707107 -0.707107 0 0">
                    <inertial diaginertia="0.00474131 0.00422857 0.00190672" mass="1.5625" pos="0.0061133 -0.023697 0.076416" quat="0.404076 0.9135 0.0473125 0.00158335"/>
                    <joint axis="0 0 1" limited="true" name="right_j5" pos="0 0 0" range="-2.9761 2.9761" damping="0.2"/>
                    <geom mesh="l5_0" material="Mtl5_001" type="mesh" contype="0" conaffinity="0" group="1"/>
                    <geom mesh="l5_1" material="Mtl4_001" type="mesh" contype="0" conaffinity="0" group="1"/>
                    <geom mesh="l5_2" material="Mtl2_001" type="mesh" contype="0" conaffinity="0" group="1"/>
                    <geom mesh="l5_3" material="Mtl1_001" type="mesh" contype="0" conaffinity="0" group="1"/>
                    <geom mesh="l5_4" material="Mtl3_001" type="mesh" contype="0" conaffinity="0" group="1"/>
                    <geom pos="0 0 0.1" rgba="0.5 0.1 0.1 1" size="0.06" name="link5_collision"/>
                    <body name="right_hand_camera" pos="0.039552 -0.033 0.0695" quat="0.707107 0 0.707107 0">
                      <inertial diaginertia="0 0 0" mass="0" pos="0.039552 -0.033 0.0695" quat="0.707107 0 0.707107 0"/>
                    </body>
                    <body name="right_wrist" pos="0 0 0.10541" quat="0.707107 0.707107 0 0">
                      <inertial diaginertia="0 0 0" mass="0" pos="0 0 0.10541" quat="0.707107 0.707107 0 0"/>
                    </body>
                    <body name="right_l6" pos="0 -0.11 0.1053" quat="0.0616248 0.06163 -0.704416 0.704416">
                      <inertial diaginertia="0.000360258 0.000311068 0.000214974" mass="0.3292" pos="-8.0726e-06 0.0085838 -0.0049566" quat="0.479044 0.515636 -0.513069 0.491322"/>
                      <joint axis="0 0 1" limited="true" name="right_j6" pos="0 0 0" range="-4.7124 4.7124" damping="0.1"/>
                      <geom mesh="l6_0" material="Mtl6.006" type="mesh" contype="0" conaffinity="0" group="1"/>
                      <geom mesh="l6_1" material="Mtl5.008" type="mesh" contype="0" conaffinity="0" group="1"/>
                      <geom mesh="l6_2" material="Mtl4.010" type="mesh" contype="0" conaffinity="0" group="1"/>
                      <geom mesh="l6_3" material="Mtl3.011" type="mesh" contype="0" conaffinity="0" group="1"/>
                      <geom mesh="l6_4" material="Mtl2.012" type="mesh" contype="0" conaffinity="0" group="1"/>
                      <geom mesh="l6_5" material="Mtl1.012" type="mesh" contype="0" conaffinity="0" group="1"/>
                      <geom pos="0 0.015 -0.01" rgba="0.5 0.1 0.1 1" size="0.055 0.025" type="cylinder" name="link6_collision"/>
                      <body name="right_hand" pos="0 0 0.024" quat="0.707105 0 0 0.707108">
                        <!-- This camera points out from the eef. -->
                        <camera mode="fixed" name="eye_in_hand" pos="0.05 0 0" quat="0 0.707108 0.707108 0" fovy="75"/>
                        <!-- To add gripper -->
                      </body>
                    </body>
                  </body>
                  <body name="right_l4_2" pos="0 0 0">
                    <inertial diaginertia="1e-08 1e-08 1e-08" mass="1e-08" pos="1e-08 1e-08 1e-08" quat="0.820473 0.339851 -0.17592 0.424708"/>
                    <geom pos="0 0.01 0.26" size="0.06" name="right_l4_2"/>
                  </body>
                </body>
              </body>
              <body name="right_l2_2" pos="0 0 0">
                <inertial diaginertia="1e-08 1e-08 1e-08" mass="1e-08" pos="1e-08 1e-08 1e-08" quat="0.820473 0.339851 -0.17592 0.424708"/>
                <geom pos="0 0 0.26" size="0.06" name="right_l2_2"/>
              </body>
            </body>
            <body name="right_l1_2" pos="0 0 0">
              <inertial diaginertia="1e-08 1e-08 1e-08" mass="1e-08" pos="1e-08 1e-08 1e-08" quat="0.820473 0.339851 -0.17592 0.424708"/>
              <geom pos="0 0 0.035" size="0.07 0.07" type="cylinder" name="right_l1_2"/>
            </body>
          </body>
        </body>
      </body>
    </body>
  </worldbody>
</mujoco>