<mujoco model="kinova3">
    <actuator>
        <!-- Physical limits of the actuator. This is hacky and not part of original urdf -->
        <motor ctrllimited="true" ctrlrange="-80.0 80.0" joint="Actuator1" name="torq_j1"/>
        <motor ctrllimited="true" ctrlrange="-80.0 80.0" joint="Actuator2" name="torq_j2"/>
        <motor ctrllimited="true" ctrlrange="-80.0 80.0" joint="Actuator3" name="torq_j3"/>
        <motor ctrllimited="true" ctrlrange="-80.0 80.0" joint="Actuator4" name="torq_j4"/>
        <motor ctrllimited="true" ctrlrange="-80.0 80.0" joint="Actuator5" name="torq_j5"/>
        <motor ctrllimited="true" ctrlrange="-12.0 12.0" joint="Actuator6" name="torq_j6"/>
        <motor ctrllimited="true" ctrlrange="-12.0 12.0" joint="Actuator7" name="torq_j7"/>
    </actuator>
    <asset>
        <mesh file="meshes/pedestal.stl" name="pedestal"/>
        <mesh name="base_link" file="meshes/base_link.STL" />
        <mesh name="Shoulder_Link" file="meshes/Shoulder_Link.STL" />
        <mesh name="Half_Arm_1_Link" file="meshes/Half_Arm_1_Link.STL" />
        <mesh name="Half_Arm_2_Link" file="meshes/Half_Arm_2_Link.STL" />
        <mesh name="ForeArm_Link" file="meshes/ForeArm_Link.STL" />
        <mesh name="Spherical_Wrist_1_Link" file="meshes/Spherical_Wrist_1_Link.STL" />
        <mesh name="Spherical_Wrist_2_Link" file="meshes/Spherical_Wrist_2_Link.STL" />
        <mesh name="Bracelet_with_vision_Link" file="meshes/Bracelet_with_vision_Link.STL" />
    </asset>
    <worldbody>
        <body name="base" pos="0 0 0">

            <!-- robot view -->
            <camera mode="fixed" name="robotview" pos="1.0 0 0.4" quat="0.653 0.271 0.271 0.653"/>
            <inertial diaginertia="0 0 0" mass="0" pos="0 0 0"/>
            <body name="controller_box" pos="0 0 0">
                <inertial diaginertia="1.71363 1.27988 0.809981" mass="46.64" pos="-0.325 0 -0.38"/>
                <geom pos="-0.325 0 -0.38" size="0.11 0.2 0.265" type="box" name="controller_box_col"/>
            </body>
            <body name="pedestal_feet" pos="0 0 0">
                <inertial diaginertia="8.16095 9.59375 15.0785" mass="167.09" pos="-0.1225 0 -0.758"/>
                <geom pos="-0.1225 0 -0.758" size="0.385 0.35 0.155" type="box" name="pedestal_feet_col"/>
            </body>
            <body name="torso" pos="0 0 0">
                <inertial diaginertia="1e-08 1e-08 1e-08" mass="0.0001" pos="0 0 0"/>
                <geom conaffinity="0" contype="0" group="1" rgba="0.2 0.2 0.2 1" size="0.05 0.05 0.05" type="box" name="torso_col"/>
            </body>
            <body name="pedestal" pos="0 0 0">
                <inertial diaginertia="6.0869 5.81635 4.20915" mass="60.864" pos="0 0 0" quat="0.659267 -0.259505 -0.260945 0.655692"/>
                <geom conaffinity="0" contype="0" group="1" mesh="pedestal" pos="0.26 0.345 -0.91488" quat="0.5 0.5 -0.5 -0.5" rgba="0.2 0.2 0.2 1" type="mesh" name="pedestal_col1"/>
                <geom pos="-0.02 0 -0.29" rgba="0.2 0.2 0.2 1" size="0.18 0.31" type="cylinder" name="pedestal_col2"/>
            </body>
            <geom type="mesh" contype="0" conaffinity="0" group="1" rgba="0.75294 0.75294 0.75294 1" mesh="base_link" />
            <geom type="mesh" rgba="0.75294 0.75294 0.75294 1" mesh="base_link" />
            <body name="Shoulder_Link" pos="0 0 0.15643" quat="-3.67321e-06 1 0 0">
                <inertial pos="-2.3e-05 -0.010364 -0.07336" quat="0.707051 0.0451246 -0.0453544 0.704263" mass="1.3773" diaginertia="0.00488868 0.00457 0.00135132" />
                <joint name="Actuator1" pos="0 0 0" axis="0 0 1" />
                <geom type="mesh" contype="0" conaffinity="0" group="1" rgba="0.75294 0.75294 0.75294 1" mesh="Shoulder_Link" />
                <geom type="mesh" rgba="0.75294 0.75294 0.75294 1" mesh="Shoulder_Link" name="s_collision"/>
                <body name="HalfArm1_Link" pos="0 0.005375 -0.12838" quat="0.707105 0.707108 0 0">
                    <inertial pos="-4.4e-05 -0.09958 -0.013278" quat="0.482348 0.516286 -0.516862 0.483366" mass="1.1636" diaginertia="0.0113017 0.011088 0.00102532" />
                    <joint name="Actuator2" pos="0 0 0" axis="0 0 1" limited="true" range="-2.41 2.41" />
                    <geom type="mesh" contype="0" conaffinity="0" group="1" rgba="0.75294 0.75294 0.75294 1" mesh="Half_Arm_1_Link" />
                    <geom type="mesh" rgba="0.75294 0.75294 0.75294 1" mesh="Half_Arm_1_Link" name="ha1_collision"/>
                    <body name="HalfArm2_Link" pos="0 -0.21038 -0.006375" quat="0.707105 -0.707108 0 0">
                        <inertial pos="-4.4e-05 -0.006641 -0.117892" quat="0.706144 0.0213722 -0.0209128 0.707437" mass="1.1636" diaginertia="0.0111633 0.010932 0.00100671" />
                        <joint name="Actuator3" pos="0 0 0" axis="0 0 1" />
                        <geom type="mesh" contype="0" conaffinity="0" group="1" rgba="0.75294 0.75294 0.75294 1" mesh="Half_Arm_2_Link" />
                        <geom type="mesh" rgba="0.75294 0.75294 0.75294 1" mesh="Half_Arm_2_Link" name="ha2_collision"/>
                        <body name="ForeArm_Link" pos="0 0.006375 -0.21038" quat="0.707105 0.707108 0 0">
                            <inertial pos="-1.8e-05 -0.075478 -0.015006" quat="0.483678 0.515961 -0.515859 0.483455" mass="0.9302" diaginertia="0.00834839 0.008147 0.000598606" />
                            <joint name="Actuator4" pos="0 0 0" axis="0 0 1" limited="true" range="-2.66 2.66" />
                            <geom type="mesh" contype="0" conaffinity="0" group="1" rgba="0.75294 0.75294 0.75294 1" mesh="ForeArm_Link" />
                            <geom type="mesh" rgba="0.75294 0.75294 0.75294 1" mesh="ForeArm_Link" name="f_collision"/>
                            <body name="SphericalWrist1_Link" pos="0 -0.20843 -0.006375" quat="0.707105 -0.707108 0 0">
                                <inertial pos="1e-06 -0.009432 -0.063883" quat="0.703558 0.0707492 -0.0707492 0.703558" mass="0.6781" diaginertia="0.00165901 0.001596 0.000346988" />
                                <joint name="Actuator5" pos="0 0 0" axis="0 0 1" />
                                <geom type="mesh" contype="0" conaffinity="0" group="1" rgba="0.75294 0.75294 0.75294 1" mesh="Spherical_Wrist_1_Link" />
                                <geom type="mesh" rgba="0.75294 0.75294 0.75294 1" mesh="Spherical_Wrist_1_Link" name="w1_collision"/>
                                <body name="SphericalWrist2_Link" pos="0 0.00017505 -0.10593" quat="0.707105 0.707108 0 0">
                                    <inertial pos="1e-06 -0.045483 -0.00965" quat="0.44426 0.550121 -0.550121 0.44426" mass="0.6781" diaginertia="0.00170087 0.001641 0.00035013" />
                                    <joint name="Actuator6" pos="0 0 0" axis="0 0 1" limited="true" range="-2.23 2.23" />
                                    <geom type="mesh" contype="0" conaffinity="0" group="1" rgba="0.75294 0.75294 0.75294 1" mesh="Spherical_Wrist_2_Link" />
                                    <geom type="mesh" rgba="0.75294 0.75294 0.75294 1" mesh="Spherical_Wrist_2_Link" name="w2_collision"/>
                                    <body name="Bracelet_Link" pos="0 -0.10593 -0.00017505" quat="0.707105 -0.707108 0 0">
                                        <inertial pos="-0.000281 -0.011402 -0.029798" quat="0.601961 0.40663 -0.381169 0.571843" mass="0.5006" diaginertia="0.000657515 0.000586793 0.000320693" />
                                        <joint name="Actuator7" pos="0 0 0" axis="0 0 1" />
                                        <geom type="mesh" contype="0" conaffinity="0" group="1" rgba="0.75294 0.75294 0.75294 1" mesh="Bracelet_with_vision_Link" />
                                        <geom type="mesh" rgba="0.75294 0.75294 0.75294 1" mesh="Bracelet_with_vision_Link" name="b_collision"/>
                                        <body name="right_hand" pos="0 0 0" quat="0 1 0 0">
                                            <!-- This sites were added for visualization. -->
                                            <site name="ee" pos="0 0 0" size="0.01 0.01 0.01" rgba="0 0 1 1" type="sphere" group="1"/>
                                            <site name="ee_x" pos="0 0 0" size="0.005 .1"  quat="0.707105 0.707108 0 0 " rgba="1 0 0 0" type="cylinder" group="1"/>
                                            <site name="ee_z" pos="0 0 0" size="0.005 .1" quat="0.707105 0 0 0.707108" rgba="0 0 1 0" type="cylinder" group="1"/>
                                            <site name="ee_y" pos="0 0 0" size="0.005 .1" quat="0.707105 0 0.707108 0 " rgba="0 1 0 0" type="cylinder" group="1"/>
                                              <!-- To add gripper -->
                                        </body>
                                    </body>
                                </body>
                            </body>
                        </body>
                    </body>
                </body>
            </body>
        </body>
    </worldbody>
</mujoco>
