<mujoco model="b1">
  <compiler angle="radian" autolimits="true" balanceinertia="true"/>
  <option gravity="0 0 0"/>
  <contact>
    <exclude name="exclude_two_front_hips" body1="FR_hip" body2="FL_hip"/>
    <exclude name="exclude_two_rear_hips" body1="RR_hip" body2="RL_hip"/>    
  </contact>
  <default>
    <default class="b1">
      <geom friction="0.6" margin="0.001"/>
      <joint axis="0 1 0" damping="2" armature="0.01" frictionloss="0.2"/>
      <motor forcerange="-33.5 33.5" ctrllimited="true"/>
    </default>
    <default class="abduction">
      <geom friction="0.6" margin="0.001"/>
      <!-- <joint axis="1 0 0" damping="0" range="-0.75 0.75" armature="0.01" frictionloss="0." limited="true"/> -->
      <joint axis="1 0 0" damping="100" range="-0.75 0.75" armature="0.01" frictionloss="0.2" limited="true"/>
      <motor ctrlrange="-33.5 33.5" ctrllimited="true"/>
    </default>
    <default class="hip">
      <geom friction="0.6" margin="0.001"/>
      <joint axis="0 1 0" range="-0.75 0.75" armature="0.01" frictionloss="0.2" limited="true"/>
      <motor ctrlrange="-100.0 100.0" ctrllimited="true"/>
    </default>
    <default class="knee">
      <geom friction="0.6" margin="0.001"/>
      <joint axis="0 1 0" range="-2.6 -0.6" armature="0.01" frictionloss="0.2" limited="true"/>
      <motor ctrlrange="-33.5 33.5"  ctrllimited="true"/>
    </default>
    <default class="visual">
      <geom type="mesh" contype="0" conaffinity="0" group="1" material="default_material"/>
    </default>
    <default class="collision">
      <geom group="0" type="capsule" rgba="0 1 0 0.8"/>
      <joint axis="0 1 0" damping="2" armature="0.01" frictionloss="0.2"/>
      <motor forcerange="-33.5 33.5" />
    </default>
    <default class="hip_left">
      <geom size="0.09" fromto="0.0 0.04 0 0.0 -0.06 0" group="0" type="capsule"/>
      <joint axis="0 1 0" damping="2" armature="0.01" frictionloss="0.2"/>
      <motor forcerange="-33.5 33.5"/>
    </default>
    <default class="hip_right">
      <geom size="0.09" fromto="0.0 0.04 0 0.0 -0.06 0" group="0" type="capsule"/>
      <joint axis="0 1 0" damping="2" armature="0.01" frictionloss="0.2"/>
      <motor forcerange="-33.5 33.5"/>
    </default>
    <default class="thigh1">
      <geom size="0.04 0.025 0.08" fromto="0.02 0 0 -0.01 0 -0.35" group="0" type="box"/>
      <joint axis="0 1 0" damping="2" armature="0.01" frictionloss="0.2"/>
      <motor forcerange="-33.5 33.5"/>
    </default>
    <default class="calf1">
      <geom size="0.02 0.015 0.08" fromto="0.0 0 0 0.03 0 -0.35" group="0" type="box"/>      
      <!-- <geom size="0.01" fromto="0 0 0 0.02 0 -0.13" group="0" type="capsule"/> -->
      <joint axis="0 1 0" damping="2" armature="0.01" frictionloss="0.2"/>
      <motor forcerange="-33.5 33.5"/>
    </default>
    <default class="foot">
      <geom type="sphere" size="0.03" pos="0 0 0" priority="1" solimp="0.015 1 0.031"
          condim="6" friction="0.8 0.02 0.01" group="0"/>
      <joint axis="0 1 0" damping="2" armature="0.01" frictionloss="0.2"/>
      <motor forcerange="-33.5 33.5"/>
    </default>
  </default>

  <asset>
    <material name="default_material" specular="0" shininess="0.1" rgba="0.4 0.4 0.4 1"/>

    <mesh name="calf" class="b1" file="meshes/calf.obj"/>
    <mesh name="hip" class="b1" file="meshes/hip.obj"/>
    <mesh name="thigh" class="b1" file="meshes/thigh.obj"/>
    <mesh name="thigh_mirror" class="b1" file="meshes/thigh_mirror.obj"/>
    <mesh name="trunk" class="b1" file="meshes/trunk.obj"/>
  </asset>

  <worldbody>
    <light name="spotlight" mode="targetbodycom" target="trunk" pos="0 -1 2"/>
    <body name="trunk" pos="0 0 0.43">
      <freejoint/>
      <inertial mass="9.041" pos="0.008465 0.004045 -0.000763"
	  fullinertia="0.033260231 0.16117211 0.17460442 -0.000451628
			0.000487603 4.8356e-05"/>
          <!-- fullinertia="0.0158533 0.0377999 0.0456542 -3.66e-05 -6.11e-05 -2.75e-05"/> -->
      <geom class="visual" mesh="trunk" material="default_material"/>
      <geom class="collision" size="0.47 0.15 0.075" type="box"/>
      <body name="FR_hip" pos="0.3455 -0.072 0">
        <inertial mass="1.993" pos="-0.022191 -0.015144 -1.5e-05"
            diaginertia="0.000807752 0.00055293 0.000468983"/>
            <!-- quat="0.507528 0.506268 0.491507 0.494499" -->
        <joint class="abduction" name="FR_hip_joint" pos="0 0 0"/>
        <geom class="visual" mesh="hip" quat="0 1 0 0"/>
        <geom class="hip_right"/>
        <body name="FR_thigh" pos="0 -0.12675 0">
          <inertial mass="0.639" pos="-0.005607 0.003877 -0.048199"
              quat="1 0 0 0"
              diaginertia="0.005666803 0.005847229 0.000369811"/>
          <joint class="hip" name="FR_thigh_joint"/>
          <geom class="visual" mesh="thigh_mirror"/>
          <geom class="thigh1"/>
          <body name="FR_calf" pos="0 0 -0.35">
            <inertial mass="0.207" pos="0.002781 6.3e-05 -0.142518"
                quat="1 0 0 0"
                diaginertia="0.006341369 0.006355157 3.9188e-05"/>
            <joint class="knee" name="FR_calf_joint"/>
            <geom class="visual" mesh="calf"/>
            <geom class="calf1"/>
	    <body name="FR_foot" pos="0 0 -0.35">
              <geom class="foot"/>
	    </body>
          </body>
        </body>
      </body>

      <body name="FL_hip" pos="0.3455 0.072 0">
        <inertial mass="1.993" pos="-0.022191 -0.015144 -1.5e-05"
            diaginertia="0.000807752 0.00055293 0.000468983"/>
        <joint class="abduction" name="FL_hip_joint" pos="0 0 0"/>
        <geom class="visual" mesh="hip" quat="0 1 0 0"/>
        <geom class="hip_right"/>
        <body name="FL_thigh" pos="0 0.12675 0">
          <inertial mass="0.639" pos="-0.005607 0.003877 -0.048199"
              quat="1 0 0 0"
               diaginertia="0.005666803 0.005847229 0.000369811"/>
          <joint class="hip" name="FL_thigh_joint"/>
          <geom class="visual" mesh="thigh"/>
          <geom class="thigh1"/>
          <body name="FL_calf" pos="0 0 -0.35">
            <inertial mass="0.207" pos="0.002781 6.3e-05 -0.142518"
                quat="1 0 0 0"
                diaginertia="0.006341369 0.006355157 3.9188e-05"/>
            <joint class="knee" name="FL_calf_joint"/>
            <geom class="visual" mesh="calf"/>
            <geom class="calf1"/>
	    <body name="FL_foot" pos="0 0 -0.35">
              <geom class="foot"/>
	    </body>
          </body>
        </body>
      </body>

      <body name="RR_hip" pos="-0.3455 -0.072 0">
        <inertial mass="1.993" pos="-0.022191 -0.015144 -1.5e-05"
            diaginertia="0.000807752 0.00055293 0.000468983"/>
            <!-- quat="0.507528 0.506268 0.491507 0.494499" -->
        <joint class="abduction" name="RR_hip_joint" pos="0 0 0"/>
        <geom class="visual" mesh="hip" quat="0 1 0 0"/>
        <geom class="hip_right"/>
        <body name="RR_thigh" pos="0 -0.12675 0">
          <inertial mass="0.639" pos="-0.005607 0.003877 -0.048199"
              quat="1 0 0 0"
              diaginertia="0.005666803 0.005847229 0.000369811"/>
          <joint class="hip" name="RR_thigh_joint"/>
          <geom class="visual" mesh="thigh_mirror"/>
          <geom class="thigh1"/>
          <body name="RR_calf" pos="0 0 -0.35">
            <inertial mass="0.207" pos="0.002781 6.3e-05 -0.142518"
                quat="1 0 0 0"
                diaginertia="0.006341369 0.006355157 3.9188e-05"/>
            <joint class="knee" name="RR_calf_joint"/>
            <geom class="visual" mesh="calf"/>
            <geom class="calf1"/>
	    <body name="RR_foot" pos="0 0 -0.35">
              <geom class="foot"/>
	    </body>
          </body>
        </body>
      </body>

      <body name="RL_hip" pos="-0.3455 0.072 0">
        <inertial mass="1.993" pos="-0.022191 -0.015144 -1.5e-05"
            diaginertia="0.000807752 0.00055293 0.000468983"/>
        <joint class="abduction" name="RL_hip_joint" pos="0 0 0"/>
        <geom class="visual" mesh="hip" quat="0 1 0 0"/>
        <geom class="hip_right"/>
        <body name="RL_thigh" pos="0 0.12675 0">
          <inertial mass="0.639" pos="-0.005607 0.003877 -0.048199"
              quat="1 0 0 0"
               diaginertia="0.005666803 0.005847229 0.000369811"/>
          <joint class="hip" name="RL_thigh_joint"/>
          <geom class="visual" mesh="thigh"/>
          <geom class="thigh1"/>
          <body name="RL_calf" pos="0 0 -0.35">
            <inertial mass="0.207" pos="0.002781 6.3e-05 -0.142518"
                quat="1 0 0 0"
                diaginertia="0.006341369 0.006355157 3.9188e-05"/>
            <joint class="knee" name="RL_calf_joint"/>
            <geom class="visual" mesh="calf"/>
            <geom class="calf1"/>
	    <body name="RL_foot" pos="0 0 -0.35">
              <geom class="foot"/>
	    </body>
          </body>
        </body>
      </body>      
    </body>
  </worldbody>

  <actuator>
    <motor class="abduction" name="FR_hip" joint="FR_hip_joint"/>
    <motor class="hip" name="FR_thigh" joint="FR_thigh_joint"/>
    <motor class="knee" name="FR_calf" joint="FR_calf_joint"/>
    <motor class="abduction" name="FL_hip" joint="FL_hip_joint"/>
    <motor class="hip" name="FL_thigh" joint="FL_thigh_joint"/>
    <motor class="knee" name="FL_calf" joint="FL_calf_joint"/>
    <motor class="abduction" name="RR_hip" joint="RR_hip_joint"/>
    <motor class="hip" name="RR_thigh" joint="RR_thigh_joint"/>
    <motor class="knee" name="RR_calf" joint="RR_calf_joint"/>
    <motor class="abduction" name="RL_hip" joint="RL_hip_joint"/>
    <motor class="hip" name="RL_thigh" joint="RL_thigh_joint"/>
    <motor class="knee" name="RL_calf" joint="RL_calf_joint"/>    
  </actuator>

  <keyframe>
    <key name="home" qpos="0 0 0.27 1 0 0 0 0 0.9 -1.8 0 0.9 -1.8 0 0.9 -1.8 0 0.9 -1.8"
        ctrl="0 0.9 -1.8 0 0.9 -1.8 0 0.9 -1.8 0 0.9 -1.8"/>
  </keyframe>
        
</mujoco>
