<?xml version="1.0" ?>
<mujoco model="hand">
  <compiler angle="radian" autolimits="true"/>
  <visual>
    <global ellipsoidinertia="true"/>
  </visual>
  <default>
    <default class="ability_right_hand_finger">
      <joint damping="0.001" frictionloss="0.001"/>
    </default>
  </default>
  <asset>
    <mesh name="visual_wristmesh" file="meshes/ability_hand/visual/wristmesh.obj"/>
    <mesh name="collision_wristmesh_C" file="meshes/ability_hand/collision/wristmesh_C.obj"/>
    <mesh name="visual_FB_palm_ref_MIR" file="meshes/ability_hand/visual/FB_palm_ref_MIR.obj"/>
    <mesh name="collision_FB_palm_ref_MIR" file="meshes/ability_hand/collision/FB_palm_ref_MIR.obj"/>
    <mesh name="visual_thumb-F1-MIR" file="meshes/ability_hand/visual/thumb-F1-MIR.obj"/>
    <mesh name="collision_thumb-F1-MIR_C" file="meshes/ability_hand/collision/thumb-F1-MIR_C.obj"/>
    <mesh name="visual_thumb-F2" file="meshes/ability_hand/visual/thumb-F2.obj"/>
    <mesh name="collision_thumb-F2_C" file="meshes/ability_hand/collision/thumb-F2_C.obj"/>
    <mesh name="visual_idx-F1" file="meshes/ability_hand/visual/idx-F1.obj"/>
    <mesh name="visual_idx-F2" file="meshes/ability_hand/visual/idx-F2.obj"/>
    <mesh name="collision_idx-F2_C" file="meshes/ability_hand/collision/idx-F2_C.obj"/>
  </asset>
  <actuator>
    <motor name="thumb_q1" joint="thumb_q1" ctrlrange="-50 50" ctrllimited="true"/>
    <motor name="thumb_q2" joint="thumb_q2" ctrlrange="-50 50" ctrllimited="true"/>
    <motor name="index_q1" joint="index_q1" ctrlrange="-50 50" ctrllimited="true"/>
    <motor name="index_q2" joint="index_q2" ctrlrange="-50 50" ctrllimited="true"/>
    <motor name="middle_q1" joint="middle_q1" ctrlrange="-50 50" ctrllimited="true"/>
    <motor name="middle_q2" joint="middle_q2" ctrlrange="-50 50" ctrllimited="true"/>
    <motor name="ring_q1" joint="ring_q1" ctrlrange="-50 50" ctrllimited="true"/>
    <motor name="ring_q2" joint="ring_q2" ctrlrange="-50 50" ctrllimited="true"/>
    <motor name="pinky_q1" joint="pinky_q1" ctrlrange="-50 50" ctrllimited="true"/>
    <motor name="pinky_q2" joint="pinky_q2" ctrlrange="-50 50" ctrllimited="true"/>
  </actuator>
  <worldbody>
    <body name="right_hand" pos="0 0 0" quat="1 0 0 0">
      <site name="ft_frame" pos="0 0 0" size="0.01 0.01 0.01" rgba="1 0 0 1" type="sphere" group="1"/>
      <inertial pos="0 0 0.17" quat="0.707107 0.707107 0 0" mass="0.3" diaginertia="0.09 0.07 0.05"/>
      <body name="eef" pos="0 0 0.097" quat="1 0 0 0">
        <site name="grip_site" pos="0 0 0" size="0.01 0.01 0.01" rgba="1 0 0 0.5" type="sphere" group="1"/>
        <site name="ee_x" pos="0.1 0 0" size="0.005 .1" quat="0.707105  0 0.707108 0 " rgba="1 0 0 0" type="cylinder" group="1"/>
        <site name="ee_y" pos="0 0.1 0" size="0.005 .1" quat="0.707105 0.707108 0 0" rgba="0 1 0 0" type="cylinder" group="1"/>
        <site name="ee_z" pos="0 0 0.1" size="0.005 .1" quat="1 0 0 0" rgba="0 0 1 0" type="cylinder" group="1"/>
        <site name="grip_site_cylinder" pos="0 0 0" size="0.005 10" rgba="0 1 0 0.3" type="cylinder" group="1"/>
      </body>
      <!--Start of base-->
      <body name="hand_mount" quat="0 0 -1 0">
        <!--Start of hand base-->
        <body name="base" pos="0.0 0.0 0.0" quat="0.7071090180427968 0.0 0.0 -0.7071045443232222">
          <inertial pos="22.41911e-3 -0.15798201e-3 -0.01319866e-3" quat="1.0 0.0 0.0 0.0" mass="0.200" diaginertia="978.26e-6 1244.78e-6 456.22e-6"/>
          <geom pos="0.0 0.0 0.0" quat="1.0 0.0 0.0 0.0" name="base_visual" group="1" contype="0" conaffinity="0" mesh="visual_wristmesh" type="mesh"/>
          <geom pos="0.0 0.0 0.0" quat="1.0 0.0 0.0 0.0" name="base_collision" group="0" mesh="collision_wristmesh_C" type="mesh"/>
          <!--Start of hand base-->
          <body name="thumb_base" pos="-0.0240476665 0.00378124745 0.03232964923" quat="0.04422965633392243 0.0006102695033793134 -0.9990212031492024 -2.701918460132315e-05">
            <inertial pos="22.41911e-3 -0.15798201e-3 -0.01319866e-3" quat="1.0 0.0 0.0 0.0" mass="0.200" diaginertia="978.26e-6 1244.78e-6 456.22e-6"/>
            <geom pos="0.0 0.0 0.0" quat="1.0 0.0 0.0 0.0" name="thumb_base_visual" group="1" contype="0" conaffinity="0" mesh="visual_FB_palm_ref_MIR" type="mesh"/>
            <geom pos="0.0 0.0 0.0" quat="1.0 0.0 0.0 0.0" name="thumb_base_collision" group="0" mesh="collision_FB_palm_ref_MIR" type="mesh"/>
            <!--Start of thumb_L1-->
            <body name="thumb_L1" pos="0.0 0.0 0.0" quat="6.095958279994181e-17 0.9955455375767813 -0.09428193151902146 -5.773103282609979e-18">
              <joint name="thumb_q1" type="hinge" class="ability_right_hand_finger" axis="0 0 1" range="-2.0943951 0"/>
              <inertial pos="14.606e-3 -1.890854e-3 -3.1155356e-3" quat="1.0 0.0 0.0 0.0" mass="0.00268342" diaginertia="0.16931e-4 0.77769934e-4 0.7249122e-4"/>
              <geom pos="0.0278283501 1.7436510745838653e-19 0.0147507" quat="0.608761429008721 0.7933533402912348 2.128773524066493e-18 1.6334653763113006e-18" name="thumb_L1_visual" group="1" contype="0" conaffinity="0" mesh="visual_thumb-F1-MIR" type="mesh"/>
              <geom pos="0.0278283501 1.7436510745838653e-19 0.0147507" quat="0.608761429008721 0.7933533402912348 2.128773524066493e-18 1.6334653763113006e-18" name="thumb_L1_collision" group="0" mesh="collision_thumb-F1-MIR_C" type="mesh"/>
              <!--Start of thumb_L2-->
              <body name="thumb_L2" pos="0.0278283501 1.7436510745838653e-19 0.0147507" quat="0.608761429008721 0.7933533402912348 2.128773524066493e-18 1.6334653763113006e-18">
                <joint name="thumb_q2" type="hinge" class="ability_right_hand_finger" axis="0 0 1" range="0 2.0943951"/>
                <inertial pos="30.020522e-3 5.59476e-3 -4.1504356e-3" quat="1.0 0.0 0.0 0.0" mass="0.0055" diaginertia="4.4789082e-4 15.600996e-4 17.908554e-4"/>
                <geom pos="0.06518669 0.02334021 0.00393483" quat="3.2197760503667046e-07 -0.9852589757290691 -0.1710694325272601 5.5904617503586985e-08" name="thumb_L2_visual" group="1" contype="0" conaffinity="0" mesh="visual_thumb-F2" type="mesh"/>
                <geom pos="0.06518669 0.02334021 0.00393483" quat="3.2197760503667046e-07 -0.9852589757290691 -0.1710694325272601 5.5904617503586985e-08" name="thumb_L2_collision" group="0" mesh="collision_thumb-F2_C" type="mesh"/>
                <body name="thumb_tip">
                  <site name="thumb_tip" pos="0.065 0.016 0" rgba="0 0 1 1" size="0.0025" group="2"/>
                </body>
              </body>
              <!--End of thumb_L2-->
            </body>
            <!--End of thumb_L1-->
            <!--Start of index_L1-->
            <body name="index_L1" pos="0.00949 -0.01304 -0.06295" quat="0.7441290289055105 -0.12811340794472753 0.6535561089151588 -0.052185779141515676">
              <joint name="index_q1" type="hinge" class="ability_right_hand_finger" axis="0 0 1" range="0 2.0943951"/>
              <inertial pos="22.41911e-3 -0.15798201e-3 -0.01319866e-3" quat="1.0 0.0 0.0 0.0" mass="0.00635888" diaginertia="0.29766e-4 3.6947967e-4 3.8176336e-4"/>
              <geom pos="0.038472723 0.003257695 0.0" quat="0.9991081505129547 0.0 0.0 0.04222444290435509" name="index_L1_visual" group="1" contype="0" conaffinity="0" mesh="visual_idx-F1" type="mesh"/>
              <geom pos="0.036 -0.00175 0.0" quat="1.0 0.0 0.0 0.0" name="index_L1_collision" group="0" type="sphere" size="0.0085"/>
              <geom pos="0.019 -0.0045 0.0" quat="0.9991076015107723 0.0 0.0 0.042237431306743435" name="index_L1_collision_1" group="0" type="box" size="0.014 0.006 0.008"/>
              <geom pos="0.018 0.006 0.0" quat="0.9991076015107723 0.0 0.0 0.042237431306743435" name="index_L1_collision_2" group="0" type="box" size="0.01 0.005 0.008"/>
              <geom pos="-0.001 0.0 0.007" quat="0.9991076015107723 0.0 0.0 0.042237431306743435" name="index_L1_collision_3" group="0" type="box" size="0.006 0.006 0.001"/>
              <geom pos="-0.001 0.0 -0.007" quat="0.9991076015107723 0.0 0.0 0.042237431306743435" name="index_L1_collision_4" group="0" type="box" size="0.006 0.006 0.001"/>
              <!--Start of index_L2-->
              <body name="index_L2" pos="0.038472723 0.003257695 0.0" quat="0.9991081505129547 0.0 0.0 0.04222444290435509">
                <joint name="index_q2" type="hinge" class="ability_right_hand_finger" axis="0 0 1" range="0.0 2.6586"/>
                <inertial pos="13.36818e-3 -8.75392e-3 -0.02886e-3" quat="1.0 0.0 0.0 0.0" mass="0.00645" diaginertia="0.82671e-4 1.98028e-4 2.64638e-4"/>
                <geom pos="0.0091241 0.0 0.0" quat="1.0 0.0 0.0 0.0" name="index_L2_visual" group="1" contype="0" conaffinity="0" mesh="visual_idx-F2" type="mesh"/>
                <geom pos="0.0 0.0 0.0" quat="1.0 0.0 0.0 0.0" name="index_L2_collision" group="0" mesh="collision_idx-F2_C" type="mesh"/>
                <geom pos="0.03 -0.016 0.0" quat="1.0 0.0 0.0 0.0" name="index_L2_collision_1" group="0" type="sphere" size="0.007"/>
                <body name="index_tip">
                  <site name="index_tip" pos="0.035  -0.018 0" rgba="0 0 1 1" size="0.0025" group="2"/>
                </body>
              </body>
              <!--End of index_L2-->
            </body>
            <!--End of index_L1-->
            <!--Start of middle_L1-->
            <body name="middle_L1" pos="-0.009653191 -0.015310271 -0.067853949" quat="0.7289207710104808 -0.1006523848250529 0.6729210218450563 -0.07563666688532023">
              <joint name="middle_q1" type="hinge" class="ability_right_hand_finger" axis="0 0 1" range="0 2.0943951"/>
              <inertial pos="22.41911e-3 -0.15798201e-3 -0.01319866e-3" quat="1.0 0.0 0.0 0.0" mass="0.00635888" diaginertia="0.29766e-4 3.6947967e-4 3.8176336e-4"/>
              <geom pos="0.038472723 0.003257695 0.0" quat="0.9991081505129547 0.0 0.0 0.04222444290435509" name="middle_L1_visual" group="1" contype="0" conaffinity="0" mesh="visual_idx-F1" type="mesh"/>
              <geom pos="0.036 -0.00175 0.0" quat="1.0 0.0 0.0 0.0" name="middle_L1_collision" group="0" type="sphere" size="0.0085"/>
              <geom pos="0.019 -0.0045 0.0" quat="0.9991076015107723 0.0 0.0 0.042237431306743435" name="middle_L1_collision_1" group="0" type="box" size="0.014 0.006 0.008"/>
              <geom pos="0.018 0.006 0.0" quat="0.9991076015107723 0.0 0.0 0.042237431306743435" name="middle_L1_collision_2" group="0" type="box" size="0.01 0.005 0.008"/>
              <geom pos="-0.001 0.0 0.007" quat="0.9991076015107723 0.0 0.0 0.042237431306743435" name="middle_L1_collision_3" group="0" type="box" size="0.006 0.006 0.001"/>
              <geom pos="-0.001 0.0 -0.007" quat="0.9991076015107723 0.0 0.0 0.042237431306743435" name="middle_L1_collision_4" group="0" type="box" size="0.006 0.006 0.001"/>
              <!--Start of middle_L2-->
              <body name="middle_L2" pos="0.038472723 0.003257695 0.0" quat="0.9991081505129547 0.0 0.0 0.04222444290435509">
                <joint name="middle_q2" type="hinge" class="ability_right_hand_finger" axis="0 0 1" range="0.0 2.6586"/>
                <inertial pos="13.36818e-3 -8.75392e-3 -0.02886e-3" quat="1.0 0.0 0.0 0.0" mass="0.00645" diaginertia="0.82671e-4 1.98028e-4 2.64638e-4"/>
                <geom pos="0.0091241 0.0 0.0" quat="1.0 0.0 0.0 0.0" name="middle_L2_visual" group="1" contype="0" conaffinity="0" mesh="visual_idx-F2" type="mesh"/>
                <geom pos="0.0 0.0 0.0" quat="1.0 0.0 0.0 0.0" name="middle_L2_collision" group="0" mesh="collision_idx-F2_C" type="mesh"/>
                <geom pos="0.03 -0.016 0.0" quat="1.0 0.0 0.0 0.0" name="middle_L2_collision_1" group="0" type="sphere" size="0.007"/>
                <body name="middle_tip">
                  <site name="middle_tip" pos="0.035  -0.018 0" rgba="0 0 1 1" size="0.0025" group="2"/>
                </body>
              </body>
              <!--End of middle_L2-->
            </body>
            <!--End of middle_L1-->
            <!--Start of ring_L1-->
            <body name="ring_L1" pos="-0.02995426 -0.014212492 -0.067286105" quat="0.7124733082016415 -0.07294795061211778 0.6904727568071236 -0.10152710824637612">
              <joint name="ring_q1" type="hinge" class="ability_right_hand_finger" axis="0 0 1" range="0 2.0943951"/>
              <inertial pos="22.41911e-3 -0.15798201e-3 -0.01319866e-3" quat="1.0 0.0 0.0 0.0" mass="0.00635888" diaginertia="0.29766e-4 3.6947967e-4 3.8176336e-4"/>
              <geom pos="0.038472723 0.003257695 0.0" quat="0.9991081505129547 0.0 0.0 0.04222444290435509" name="ring_L1_visual" group="1" contype="0" conaffinity="0" mesh="visual_idx-F1" type="mesh"/>
              <geom pos="0.036 -0.00175 0.0" quat="1.0 0.0 0.0 0.0" name="ring_L1_collision" group="0" type="sphere" size="0.0085"/>
              <geom pos="0.019 -0.0045 0.0" quat="0.9991076015107723 0.0 0.0 0.042237431306743435" name="ring_L1_collision_1" group="0" type="box" size="0.014 0.006 0.008"/>
              <geom pos="0.018 0.006 0.0" quat="0.9991076015107723 0.0 0.0 0.042237431306743435" name="ring_L1_collision_2" group="0" type="box" size="0.01 0.005 0.008"/>
              <geom pos="-0.001 0.0 0.007" quat="0.9991076015107723 0.0 0.0 0.042237431306743435" name="ring_L1_collision_3" group="0" type="box" size="0.006 0.006 0.001"/>
              <geom pos="-0.001 0.0 -0.007" quat="0.9991076015107723 0.0 0.0 0.042237431306743435" name="ring_L1_collision_4" group="0" type="box" size="0.006 0.006 0.001"/>
              <!--Start of ring_L2-->
              <body name="ring_L2" pos="0.038472723 0.003257695 0.0" quat="0.9991081505129547 0.0 0.0 0.04222444290435509">
                <joint name="ring_q2" type="hinge" class="ability_right_hand_finger" axis="0 0 1" range="0.0 2.6586"/>
                <inertial pos="13.36818e-3 -8.75392e-3 -0.02886e-3" quat="1.0 0.0 0.0 0.0" mass="0.00645" diaginertia="0.82671e-4 1.98028e-4 2.64638e-4"/>
                <geom pos="0.0091241 0.0 0.0" quat="1.0 0.0 0.0 0.0" name="ring_L2_visual" group="1" contype="0" conaffinity="0" mesh="visual_idx-F2" type="mesh"/>
                <geom pos="0.0 0.0 0.0" quat="1.0 0.0 0.0 0.0" name="ring_L2_collision" group="0" mesh="collision_idx-F2_C" type="mesh"/>
                <geom pos="0.03 -0.016 0.0" quat="1.0 0.0 0.0 0.0" name="ring_L2_collision_1" group="0" type="sphere" size="0.007"/>
                <body name="ring_tip">
                  <site name="ring_tip" pos="0.035  -0.018 0" rgba="0 0 1 1" size="0.0025" group="2"/>
                </body>
              </body>
              <!--End of ring_L2-->
            </body>
            <!--End of ring_L1-->
            <!--Start of pinky_L1-->
            <body name="pinky_L1" pos="-0.049521293 -0.011004583 -0.063029065" quat="0.7129681457596535 -0.0493647398401903 0.6883388097479964 -0.12421444596850761">
              <joint name="pinky_q1" type="hinge" class="ability_right_hand_finger" axis="0 0 1" range="0 2.0943951"/>
              <inertial pos="22.41911e-3 -0.15798201e-3 -0.01319866e-3" quat="1.0 0.0 0.0 0.0" mass="0.00635888" diaginertia="0.29766e-4 3.6947967e-4 3.8176336e-4"/>
              <geom pos="0.038472723 0.003257695 0.0" quat="0.9991081505129547 0.0 0.0 0.04222444290435509" name="pinky_L1_visual" group="1" contype="0" conaffinity="0" mesh="visual_idx-F1" type="mesh"/>
              <geom pos="0.036 -0.00175 0.0" quat="1.0 0.0 0.0 0.0" name="pinky_L1_collision" group="0" type="sphere" size="0.0085"/>
              <geom pos="0.019 -0.0045 0.0" quat="0.9991076015107723 0.0 0.0 0.042237431306743435" name="pinky_L1_collision_1" group="0" type="box" size="0.014 0.006 0.008"/>
              <geom pos="0.018 0.006 0.0" quat="0.9991076015107723 0.0 0.0 0.042237431306743435" name="pinky_L1_collision_2" group="0" type="box" size="0.01 0.005 0.008"/>
              <geom pos="-0.001 0.0 0.007" quat="0.9991076015107723 0.0 0.0 0.042237431306743435" name="pinky_L1_collision_3" group="0" type="box" size="0.006 0.006 0.001"/>
              <geom pos="-0.001 0.0 -0.007" quat="0.9991076015107723 0.0 0.0 0.042237431306743435" name="pinky_L1_collision_4" group="0" type="box" size="0.006 0.006 0.001"/>
              <!--Start of pinky_L2-->
              <body name="pinky_L2" pos="0.038472723 0.003257695 0.0" quat="0.9991081505129547 0.0 0.0 0.04222444290435509">
                <joint name="pinky_q2" type="hinge" class="ability_right_hand_finger" axis="0 0 1" range="0.0 2.6586"/>
                <inertial pos="13.36818e-3 -8.75392e-3 -0.02886e-3" quat="1.0 0.0 0.0 0.0" mass="0.00645" diaginertia="0.82671e-4 1.98028e-4 2.64638e-4"/>
                <geom pos="0.0091241 0.0 0.0" quat="1.0 0.0 0.0 0.0" name="pinky_L2_visual" group="1" contype="0" conaffinity="0" mesh="visual_idx-F2" type="mesh"/>
                <geom pos="0.0 0.0 0.0" quat="1.0 0.0 0.0 0.0" name="pinky_L2_collision" group="0" mesh="collision_idx-F2_C" type="mesh"/>
                <geom pos="0.03 -0.016 0.0" quat="1.0 0.0 0.0 0.0" name="pinky_L2_collision_1" group="0" type="sphere" size="0.007"/>
                <body name="pinky_tip">
                  <site name="pinky_tip" pos="0.035  -0.018 0" rgba="0 0 1 1" size="0.0025" group="2"/>
                </body>
              </body>
              <!--End of pinky_L2-->
            </body>
            <!--End of pinky_L1-->
          </body>
          <!--End of hand base-->
        </body>
        <!--End of hand base-->
      </body>
      <!--End of base-->
    </body>
  </worldbody>
  <contact>
    <exclude body1="thumb_base" body2="thumb_L1"/>
    <exclude body1="thumb_base" body2="index_L1"/>
    <exclude body1="thumb_base" body2="middle_L1"/>
    <exclude body1="thumb_base" body2="ring_L1"/>
    <exclude body1="thumb_base" body2="pinky_L1"/>
    <exclude body1="middle_L1" body2="index_L1"/>
    <exclude body1="ring_L1" body2="middle_L1"/>
    <exclude body1="pinky_L1" body2="ring_L1"/>
  </contact>
  <sensor>
    <force name="force_ee" site="ft_frame"/>
    <torque name="torque_ee" site="ft_frame"/>
  </sensor>
</mujoco>