<mujoco model="aloha_gripper">

    <asset>
      <material name="black" rgba="0.15 0.15 0.15 1" />
      <mesh name="vx300s_7_gripper_prop" file="meshes/aloha_gripper/vx300s_7_gripper_prop.stl" />
		  <mesh name="vx300s_7_gripper_bar" file="meshes/aloha_gripper/vx300s_7_gripper_bar.stl" />
		  <mesh name="vx300s_7_gripper_wrist_mount" file="meshes/aloha_gripper/vx300s_7_gripper_wrist_mount.stl" />
      <mesh name="vx300s_8_custom_finger_left" file="meshes/aloha_gripper/vx300s_8_custom_finger_left.stl" />
      <mesh name="vx300s_8_custom_finger_right" file="meshes/aloha_gripper/vx300s_8_custom_finger_right.stl" />
      <mesh name="d405_solid" file="meshes/aloha_gripper/d405_solid.stl" />
    </asset>

    <actuator>
        <position class="finger" name="left_finger" joint="left_finger" ctrlrange="0.002 0.037" forcelimited="true" forcerange="-20 20"/>
        <position class="finger" name="right_finger" joint="right_finger" ctrlrange="0.002 0.037" forcelimited="true" forcerange="-20 20"/>
    </actuator>

    <default>
        <default class="left_finger">
          <joint range="0 0.041" axis="0 0 -1" type="slide" armature="0.243" damping="40"/>
        </default>
        <default class="right_finger">
          <joint range="0 0.041" axis="0 0 -1"  type="slide" armature="0.243" damping="40"/>
        </default>
        <default class="finger">
            <joint type="slide" armature="0.243" damping="40" />
            <position ctrlrange="0.002 0.037" kp="2000" kv="124" />
        </default>
        <default class="visual">
            <geom type="mesh" contype="0" conaffinity="0" density="0" group="1" material="black" />
        </default>
        <default class="collision">
            <geom group="0" type="mesh" />
        </default>
    	  <default class="finger_collision">
          <geom group="0" condim="4" solimp="2 1 0.01" solref="0.01 1" friction="1 0.005 0.0001" />
        </default>
        <default class="sphere_collision">
          <geom group="0" type="sphere" size="0.0006" rgba="1 0 0 1" />
        </default>
    </default>

    <worldbody>
      <body name="gripper_base">
          <site name="ft_frame" pos="0 0 0" size="0.01 0.01 0.01" rgba="1 0 0 0" type="sphere" group="1"/>
          <inertial pos="0.000182154 -0.0341589 -0.0106026" quat="0.435286 0.557074 -0.551539 0.442718" mass="0.42158" diaginertia="0.00110438 0.000790537 0.000469727" />
          <geom class="visual" mesh="vx300s_7_gripper_prop" />
          <geom class="collision" mesh="vx300s_7_gripper_prop" />
          <geom class="visual" mesh="vx300s_7_gripper_bar" />
          <geom class="collision" mesh="vx300s_7_gripper_bar" />
          <geom class="visual" pos="0 -0.03525 -0.0227" quat="0 -0.707107 0 -0.707107" type="mesh" mesh="vx300s_7_gripper_wrist_mount" />
          <geom class="collision" pos="0 -0.03525 -0.0227" quat="0 -0.707107 0 -0.707107" type="mesh" mesh="vx300s_7_gripper_wrist_mount" />
          <geom class="visual" pos="0 -0.0824748 -0.0095955" quat="0 0 -0.21644 -0.976296" type="mesh" mesh="d405_solid" />
          <geom class="collision" pos="0 -0.0824748 -0.0095955" quat="0 0 -0.21644 -0.976296" type="mesh" mesh="d405_solid" />
          <camera name="wrist_cam_right" pos="0 -0.0824748 -0.0095955" fovy="58" mode="fixed" quat="0.21643999811115602 0.9762959219507387 0.0 0.0" />

          <body name="eef" pos="0 0 0.04" quat="1 0 0 0">
              <site name="grip_site" pos="0 0 0" size="0.01 0.01 0.01" rgba="1 0 0 0.5" type="sphere" group="1"/>
              <site name="ee_x" pos="0.1 0 0" size="0.005 .1"  quat="0.707105  0 0.707108 0 " rgba="1 0 0 0" type="cylinder" group="1"/>
              <site name="ee_y" pos="0 0.1 0" size="0.005 .1" quat="0.707105 0.707108 0 0" rgba="0 1 0 0" type="cylinder" group="1"/>
              <site name="ee_z" pos="0 0 0.1" size="0.005 .1" quat="1 0 0 0" rgba="0 0 1 0" type="cylinder" group="1"/>
              <!-- This site was added for visualization. -->
              <site name="grip_site_cylinder" pos="0 0 0" size="0.005 10" rgba="0 1 0 0.3" type="cylinder" group="1"/>
          </body>
          <body name="left_finger_link" pos="0.0191 -0.0141637 0.0211727" quat="1 -1 -1 1">
              <inertial pos="0.0143478 -0.0284791 0.0122897" quat="0.535486 0.458766 -0.450407 0.547651" mass="0.0862937" diaginertia="5.86848e-05 4.46887e-05 1.8397e-05" />
              <joint name="left_finger" class="left_finger" />
              <geom name="left_finger_g0" pos="0.0141637 0.0211727 0.06" class="visual" quat="1 1 1 -1" type="mesh" mesh="vx300s_8_custom_finger_left" />
              <geom name="left_finger_g1" pos="0.0141637 0.0211727 0.06" class="finger_collision" quat="1 1 1 -1" type="mesh" mesh="vx300s_8_custom_finger_left" />
              <geom name="left_finger_g2" pos="0.013  -0.0892 0.0268" class="sphere_collision" />
              <geom name="left_finger_g3" pos="0.0222 -0.0892 0.0268" class="sphere_collision" />
              <geom name="left_finger_g4" pos="0.0182 -0.0845 0.0266" class="sphere_collision" />
              <site name="left_finger" pos="0.015 -0.06 0.02" />
          </body>
          <body name="right_finger_link" pos="-0.0191 -0.0141637 0.0211727" quat="1 1 1 1">
              <inertial pos="0.0143711 0.0284792 0.0121421" quat="0.461317 0.537615 -0.545478 0.447894" mass="0.0862932" diaginertia="5.86828e-05 4.46887e-05 1.83949e-05" />
              <joint name="right_finger" class="right_finger" />
              <geom name="right_finger_g0" pos="0.0141637 -0.0211727 0.0597067" class="visual" quat="1 -1 -1 -1" type="mesh" mesh="vx300s_8_custom_finger_right" />
              <geom name="right_finger_g1" pos="0.0141637 -0.0211727 0.0597067" class="finger_collision" quat="1 -1 -1 -1" type="mesh" mesh="vx300s_8_custom_finger_right" />
              <geom name="right_finger_g2" pos="0.013  0.0892 0.0268" class="sphere_collision" />
              <geom name="right_finger_g3" pos="0.0222 0.0892 0.0268" class="sphere_collision" />
              <geom name="right_finger_g4" pos="0.0182 0.0845 0.0266" class="sphere_collision" />
              <site name="right_finger" pos="0.015 0.06 0.02" />
          </body>
      </body>

    </worldbody>
    <sensor>
        <force name="force_ee" site="ft_frame"/>
        <torque name="torque_ee" site="ft_frame"/>
    </sensor>
</mujoco>