<mujoco model="google_hand">
    <asset>
        <texture type="2d" name="robot_texture" file="meshes/google_gripper/robot_texture.png"/>
        <texture type="2d" name="finger_base_texture" file="meshes/google_gripper/finger_base_texture.png"/>
        <texture type="2d" name="finger_tip_texture" file="meshes/google_gripper/finger_tip_texture.png"/>
        <material name="robot_mtl" texture="robot_texture"/>
        <material name="finger_base_mtl" texture="finger_base_texture"/>
        <material name="finger_tip_mtl" texture="finger_tip_texture"/>

        <!-- Collision meshes -->
        <mesh name="link_gripper" file="meshes/google_gripper/link_gripper.stl"/>
        <mesh name="link_finger_base" file="meshes/google_gripper/link_finger_base.stl"/>
        <mesh name="link_finger_tip" file="meshes/google_gripper/link_finger_tip.stl"/>

        <!-- Visual meshes -->
        <mesh name="link_gripper_v" class="visual" file="meshes/google_gripper/link_gripper_v.obj"/>
        <mesh name="link_finger_base_v" class="visual" file="meshes/google_gripper/link_finger_base_v.obj"/>
        <mesh name="link_finger_tip_v" class="visual" file="meshes/google_gripper/link_finger_tip_v.obj"/>
    </asset>

    <actuator>
     <position joint="joint_finger_right" kp="20" ctrlrange="0.01 1.3"   forcerange="-30 30" name="torq_j8"/>
     <position joint="joint_finger_left"  kp="20" ctrlrange="0.01 1.3"   forcerange="-30 30" name="torq_j9"/>
   </actuator>

     <default>
    <default class="robot">
      <joint damping="10.0" frictionloss="1" armature=".1"/>
    </default>

    <default class="visual">
      <geom type="mesh" contype="0" conaffinity="0" group="1" material="robot_mtl"/>
    </default>
      
    <default class="collision">
      <geom type="mesh" rgba="1 1 1 1" group="0" contype="1" conaffinity="1"/>
    </default>
        
    <default class="finger_base">
      <geom type="capsule" rgba="1 1 1 1" size="0.015 0.01" quat="1 0 1 0" mass="0.0133245" pos="0 -0.005 0.03"/>
    </default>
        
    <default class="finger_tip">
      <geom type="capsule" rgba="1 1 1 1" size="0.01 0.008" quat="1 0 1 0" mass="0.0161862"/>
    </default>
  </default>
    <worldbody>
        <body name="right_gripper" pos="0 0 0">
            <site name="ft_frame" pos="0 0 0" size="0.01 0.01 0.01" rgba="1 0 0 1" type="sphere" group="1"/>
            <inertial pos="0 0 0" mass="3e-1" diaginertia="1e-2 1e-2 1e-2" />
            <!-- This site was added for visualization. -->
            <body name="eef" pos="0 0 0" quat="0.707105 0 0 -0.707105">
                <site name="grip_site" pos="0 0 0" size="0.01 0.01 0.01" rgba="1 0 0 0.5" type="sphere" group="1"/>
                <site name="ee_x" pos="0.1 0 0" size="0.005 .1"  quat="0.707105  0 0.707108 0 " rgba="1 0 0 0" type="cylinder" group="1"/>
                <site name="ee_y" pos="0 0.1 0" size="0.005 .1" quat="0.707105 0.707108 0 0" rgba="0 1 0 0" type="cylinder" group="1"/>
                <site name="ee_z" pos="0 0 0.1" size="0.005 .1" quat="1 0 0 0" rgba="0 0 1 0" type="cylinder" group="1"/>
                <!-- This site was added for visualization. -->
                <site name="grip_site_cylinder" pos="0 0 0" size="0.005 10" rgba="0 1 0 0.3" type="cylinder" group="1"/>
            </body>

            <site name="gripper" pos="0 0 0.13" group="5"/>
            <!-- <inertial pos="-3.20302e-05 0.000371384 0.0387883" quat="0.997934 0.0574504 -0.0278948 -0.00699571" mass="0.41474" diaginertia="0.000327698 0.000308611 0.000272392"/> -->
            
            <!-- <joint name="joint_gripper" axis="0 0 1" range="-4.49 1.35"/> -->
            <geom class="visual" mesh="link_gripper_v"/>
            <geom class="collision" name="gripper" quat="1 0 0 -1" type="mesh" mesh="link_gripper"/>

            <!-- right finger -->
            <body name="link_finger_right" pos="0 0.025 0.05886" quat="0.879969 -0.475032 0 0" gravcomp="1">
            <joint name="joint_finger_right" axis="1 0 0" range="0.01 1.3" damping="2.0" frictionloss="1" armature=".1"/>
            <geom class="visual" mesh="link_finger_base_v" material="finger_base_mtl"/>
            <geom class="collision" mesh="link_finger_base" mass="0.0333245"/>
            <geom class="finger_base"/>
            <geom class="finger_base" pos="0 -0.005 0.04"/>
            <geom class="finger_base" pos="0 -0.005 0.05"/>
            <body name="link_finger_tip_right" pos="0 -0.0103567 0.0641556" quat="0.995004 0.0998334 0 0" gravcomp="1">
                <geom class="visual" mesh="link_finger_tip_v" material="finger_tip_mtl"/>
                <geom class="collision" mesh="link_finger_tip_v" mass="0.0161862"/>
                <geom class="finger_tip"/>
                <geom class="finger_tip" pos="0 0 0.01"/>
                <geom class="finger_tip" pos="0 0 0.02"/>
                <geom class="finger_tip" pos="0 0 0.03"/>
                <geom class="finger_tip" pos="0 0 0.04"/>
            </body>
            </body>
            <!-- left finger -->
            <body name="link_finger_left" pos="0 -0.025 0.05886" quat="0 0 -0.475032 0.879969" gravcomp="1">
            <joint name="joint_finger_left" axis="1 0 0" range="0.01 1.3" damping="2.0" frictionloss="1" armature=".1"/>
            <geom class="visual" mesh="link_finger_base_v" material="finger_base_mtl"/>
            <geom class="collision" mesh="link_finger_base_v" mass="0.0333245" />
                <geom class="finger_base"/>
                <geom class="finger_base" pos="0 -0.005 0.04"/>
                <geom class="finger_base" pos="0 -0.005 0.05"/>
            <body name="link_finger_tip_left" pos="0 -0.0103567 0.0641556" quat="0.995004 0.0998334 0 0" gravcomp="1">
                <geom class="visual" mesh="link_finger_tip_v" material="finger_tip_mtl"/>
                <geom class="collision" mesh="link_finger_tip" mass="0.0161862"/>
                <geom class="finger_tip"/>
                <geom class="finger_tip" pos="0 0 0.01"/>
                <geom class="finger_tip" pos="0 0 0.02"/>
                <geom class="finger_tip" pos="0 0 0.03"/>
                <geom class="finger_tip" pos="0 0 0.04"/>
            </body>
            </body>
        </body>
    </worldbody>
    <sensor>
        <force name="force_ee" site="ft_frame"/>
        <torque name="torque_ee" site="ft_frame"/>
    </sensor>
</mujoco>
