<mujoco model="inspire left hand">
    <statistic center="0.3 0 0.4" extent="1"/>
    <compiler angle="radian" meshdir="./" autolimits="true"/>

    <visual>
        <headlight diffuse="0.6 0.6 0.6" ambient="0.3 0.3 0.3" specular="0 0 0"/>
        <rgba haze="0.15 0.25 0.35 1"/>
        <global azimuth="120" elevation="20"/>
    </visual>

    <default>
        <joint damping="1"/>
        <muscle ctrllimited="true" ctrlrange="0 100"/>
        <motor ctrllimited="true" ctrlrange="-3 3" gear="1"/>
        <position ctrllimited="true" kp="10"/>
    </default>

    <asset>
        <mesh name="l_palm_vis" file="meshes/inspire_hands/lh_base_link.STL"/>
        <mesh name="l_palm_col" file="meshes/inspire_hands/lh_base_link.STL"/>

        <mesh name="l_thumb_proximal_1_vis" file="meshes/inspire_hands/lh_Link11.STL"/>
        <mesh name="l_thumb_proximal_1_col" file="meshes/inspire_hands/lh_Link11.STL"/>

        <mesh name="l_thumb_proximal_2_vis" file="meshes/inspire_hands/lh_Link12.STL"/>
        <mesh name="l_thumb_proximal_2_col" file="meshes/inspire_hands/lh_Link12.STL"/>

        <mesh name="l_thumb_middle_vis" file="meshes/inspire_hands/lh_Link13.STL"/>
        <mesh name="l_thumb_middle_col" file="meshes/inspire_hands/lh_Link13.STL"/>


        <mesh name="l_thumb_distal_vis" file="meshes/inspire_hands/lh_Link14.STL"/>
        <mesh name="l_thumb_distal_col" file="meshes/inspire_hands/lh_Link14.STL"/>

        <mesh name="l_index_proximal_vis" file="meshes/inspire_hands/lh_Link15.STL"/>
        <mesh name="l_index_proximal_col" file="meshes/inspire_hands/lh_Link15.STL"/>

        <mesh name="l_index_distal_vis" file="meshes/inspire_hands/lh_Link16.STL"/>
        <mesh name="l_index_distal_col" file="meshes/inspire_hands/lh_Link16.STL"/>

        <mesh name="l_middle_proximal_vis" file="meshes/inspire_hands/lh_Link17.STL"/>
        <mesh name="l_middle_proximal_col" file="meshes/inspire_hands/lh_Link17.STL"/>

        <mesh name="l_middle_distal_vis" file="meshes/inspire_hands/lh_Link18.STL"/>
        <mesh name="l_middle_distal_col" file="meshes/inspire_hands/lh_Link18.STL"/>


        <mesh name="l_ring_proximal_vis" file="meshes/inspire_hands/lh_Link19.STL"/>
        <mesh name="l_ring_proximal_col" file="meshes/inspire_hands/lh_Link19.STL"/>

        <mesh name="l_ring_distal_vis" file="meshes/inspire_hands/lh_Link20.STL"/>
        <mesh name="l_ring_distal_col" file="meshes/inspire_hands/lh_Link20.STL"/>


        <mesh name="l_pinky_proximal_vis" file="meshes/inspire_hands/lh_Link21.STL"/>
        <mesh name="l_pinky_proximal_col" file="meshes/inspire_hands/lh_Link21.STL"/>

        <mesh name="l_pinky_distal_vis" file="meshes/inspire_hands/lh_Link22.STL"/>
        <mesh name="l_pinky_distal_col" file="meshes/inspire_hands/lh_Link22.STL"/>




        <material name="site_left_hand" rgba="0.1882 0.1882 0.1882 0"/>

        <material name="l_base_material" rgba="0 0 0 1"/>
        <material name="l_thumb_material" rgba="0 0 0 1"/>
        <material name="l_index_material" rgba="0 0 0 1"/>
        <material name="l_middle_material" rgba="0 0 0 1"/>
        <material name="l_ring_material" rgba="0 0 0 1"/>
        <material name="l_pinky_material" rgba="0 0 0 1"/>

        <material name="l_thumb_distal_material" rgba="0 0 0 1"/>

    </asset>

    <worldbody>
        <body name="left_hand" pos="0 0 0" quat="0.7071068 0.7071068 0 0">
            <site name="ft_frame" pos="0 0 0" size="0.01 0.01 0.01" rgba="1 0 0 0" type="sphere" group="1"/>
            <inertial diaginertia="0 0 0" mass="0" pos="0 0 0"/>
            <body name="eef" pos="0 0 0" quat="0.707 0. -0.707 0.">
                <site name="grip_site" pos="0 0 0" size="0.01 0.01 0.01" rgba="1 1 0 0" type="sphere" group="2"/>
                <site name="ee_x" pos="0.1 0 0" size="0.005 .1"  quat="0.707105  0 0.707108 0 " rgba="1 0 0 0" type="cylinder" group="1"/>
                <site name="ee_y" pos="0 0.1 0" size="0.005 .1" quat="0.707105 0.707108 0 0" rgba="0 1 0 0" type="cylinder" group="1"/>
                <site name="ee_z" pos="0 0 0.1" size="0.005 .1" quat="1 0 0 0" rgba="0 0 1 0" type="cylinder" group="1"/>
                <!-- This site was added for visualization. -->
                <site name="grip_site_cylinder" pos="0 0 0" quat="-0.5 -0.5 -0.5 0.5" size="0.005 0.5" rgba="0 1 0 0" type="cylinder" group="1"/>
            </body>


            <!-- Palm  -->
            <body name="l_palm" pos="0 0 0">
                <!-- Palm Visual -->
                <geom name="l_palm_vis" type="mesh" mesh="l_palm_vis" material="l_base_material" group="1" contype="0" conaffinity="0"/>
                <!-- Palm Collision -->
                <geom name="l_palm_col" type="mesh" mesh="l_palm_col" mass="0.1" />
                <site name="l_pinch_sphere" pos="-0.06 -0.12 0.03" size="0.01 0.01 0.01" rgba="1 0 0 1" type="sphere" group="1"/>

                <!-- Thumb -->
                <body name="l_thumb" pos="0. 0. 0.">
                    <!-- Thumb Proximal 1 -->
                    <body name="l_thumb_proximal_1" pos="-0.01496 -0.0375 0.02045" quat="0.5 0.5 -0.5 0.5">
                        <joint name="joint_l_thumb_proximal_1" type="hinge" pos="0 0 0" axis="0 0 1" range="0 1.30" limited="true" damping="1"/>
                        <geom name="l_thumb_proximal_vis" type="mesh" mesh="l_thumb_proximal_1_vis" material="l_thumb_material" group="1" contype="0" conaffinity="0"> </geom>
                        <geom name="l_thumb_proximal_col" type="mesh" mesh="l_thumb_proximal_1_col" mass="0.1" />

                        <!-- Thumb Proximal 2 -->
                        <body name="l_thumb_proximal_2" pos="0.0099867 0.0098242 -0.0089" quat="0.705 -0.705 -0.060 0.060">
                            <joint name="joint_l_thumb_proximal_2" type="hinge" pos="0 0 0" axis="0 0 -1" range="0 0.68" limited="true" damping="1"/>
                            <geom name="l_thumb_proximal_2_vis" type="mesh" mesh="l_thumb_proximal_2_vis" material="l_thumb_material" group="1" contype="0" conaffinity="0"> </geom>
                            <geom name="l_thumb_proximal_2_col" type="mesh" mesh="l_thumb_proximal_2_col" mass="0.1" />

                            <site name="site_l_thumb_proximal_2" size="0.01" material="site_left_hand"/>

                            <!-- Thumb Middle -->
                            <body name="l_thumb_middle" pos="0.04407 -0.034553 -0.0008" quat="1 0 0 0">
                                <joint name="joint_l_thumb_middle" type="hinge" pos="0 0 0" axis="0 0 -1" range="0 0.68" limited="true" damping="1"/>
                                <geom name="l_thumb_middle_vis" type="mesh" mesh="l_thumb_middle_vis" material="l_thumb_material" group="1" contype="0" conaffinity="0"/>
                                <geom name="l_thumb_middle_col" type="mesh" mesh="l_thumb_middle_col" mass="0.1" />
                                <site name="site_l_thumb_middle" size="0.01" material="site_left_hand"/>

                                <!-- Thumb Distal -->
                                <body name="l_thumb_distal" pos="0.020248 -0.010156 -0.0012" quat="1 0 0 0">
                                    <joint name="joint_l_thumb_distal" type="hinge" pos="0 0 0" axis="0 0 -1" range="0 0.77" limited="true" damping="1"/>
                                    <geom name="l_thumb_distal_vis" type="mesh" mesh="l_thumb_distal_vis" material="l_thumb_distal_material" group="1" contype="0" conaffinity="0"> </geom>
                                    <geom name="l_thumb_distal_col" type="mesh" mesh="l_thumb_distal_col" mass="0.1" />
                                    <site name="site_l_thumb_distal" size="0.01" material="site_left_hand"/>
                                    <site name="l_thumb_distal_site_cylinder" pos="0.04242 -0.04242 -0.006" quat="0.7071 0.5 0.5 0" size="0.002 0.06" rgba="0 1 0 0.3" type="cylinder" group="1"/>
                                </body>
                                <!-- End of Thumb Distal -->
                            </body>
                            <!-- End of Thumb Middle -->
                        </body>
                        <!-- End of Thumb Proximal 2 -->
                    </body>
                    <!-- End of Thumb Proximal 1 -->
                </body>
                <!-- End of Thumb -->

                <!-- Index finger -->
                <body name="l_index" pos="0 0 0">
                    <!-- Index Proximal -->
                    <body name="l_index_proximal" pos="0.0022853 -0.10493 0.032268" quat="0.99985 -0.01745 0.0 0.0">
                        <joint name="joint_l_index_proximal" type="hinge" pos="0 0 0" axis="0 0 -1" range="0 1.62" limited="true" damping="1"/>
                        <site name="site_l_index_proximal" size="0.01" material="site_left_hand"/>
                        <geom name="l_index_proximal_vis" type="mesh" mesh="l_index_proximal_vis" material="l_index_material" group="1" contype="0" conaffinity="0"/>
                        <geom name="l_index_proximal_col" type="mesh" mesh="l_index_proximal_col" mass="0.1" />
                        <!-- Index Distal -->
                        <body name="l_index_distal" pos="-0.0024229 -0.032041 -0.001" quat="1 0 0 0">
                            <joint name="joint_l_index_distal" type="hinge" pos="0 0 0" axis="0 0 -1" range="0 1.82" limited="true" damping="1"/>
                            <site name="site_l_index_distal" size="0.01" material="site_left_hand"/>
                            <geom name="l_index_distal_vis" type="mesh" mesh="l_index_distal_vis" material="l_index_material" group="1" contype="0" conaffinity="0"/>
                            <geom name="l_index_distal_col" type="mesh" mesh="l_index_distal_col" mass="0.1" />
                            <site name="l_index_distal_site_cylinder" pos="0 -0.06 -0.005" quat="0.7071 0.7071 0 0" size="0.002 0.06" rgba="0 1 0 0.3" type="cylinder" group="1"/>
                        </body>
                        <!-- End of Index Distal -->
                    </body>
                    <!-- End of Index Proximal -->
                </body>
                <!-- End of Index finger -->
                <!-- Middle finger -->
                <body name="l_middle" pos="0 0 0">
                    <!-- Middle Proximal -->
                    <body name="l_middle_proximal" pos="0.0022853 -0.1055 0.01295" quat="1 0 0 0">
                        <joint name="joint_l_middle_proximal" type="hinge" pos="0 0 0" axis="0 0 -1" range="0 1.62" limited="true" damping="1"/>
                        <site name="site_l_middle_proximal" size="0.01" material="site_left_hand"/>
                        <geom name="l_middle_proximal_vis" type="mesh" mesh="l_middle_proximal_vis" material="l_middle_material" group="1" contype="0" conaffinity="0"/>
                        <geom name="l_middle_proximal_col" type="mesh" mesh="l_middle_proximal_col" mass="0.1" />
                        <!-- Middle Distal -->
                        <body name="l_middle_distal" pos="-0.0024229 -0.032041 -0.001" quat="1 0 0 0">
                            <joint name="joint_l_middle_distal" type="hinge" pos="0 0 0" axis="0 0 -1" range="0 1.82" limited="true" damping="1"/>
                            <site name="site_l_middle_distal" size="0.01" material="site_left_hand"/>
                            <geom name="l_middle_distal_vis" type="mesh" mesh="l_middle_distal_vis" material="l_middle_material" group="1" contype="0" conaffinity="0"/>
                            <geom name="l_middle_distal_col" type="mesh" mesh="l_middle_distal_col" mass="0.1" />
                            <site name="l_middle_distal_site_cylinder" pos="0 -0.06 -0.005" quat="0.7071 0.7071 0 0" size="0.002 0.06" rgba="0 1 0 0.3" type="cylinder" group="1"/>
                        </body>
                        <!-- End of Middle Distal -->
                    </body>
                    <!-- End of Middle Proximal -->
                </body>
                <!-- End of Middle finger -->

                <!-- Ring finger -->
                <body name="l_ring" pos="0 0 0">
                    <!-- Ring Proximal -->
                    <body name="l_ring_proximal" pos="0.0022853 -0.10531 -0.0062872" quat="0.99966 0.02618 0.0 0.0">
                        <joint name="joint_l_ring_proximal" type="hinge" pos="0 0 0" axis="0 0 -1" range="0 1.62" limited="true" damping="1"/>
                        <site name="site_l_ring_proximal" size="0.01" material="site_left_hand"/>
                        <geom name="l_ring_proximal_vis" type="mesh" mesh="l_ring_proximal_vis" material="l_ring_material" group="1" contype="0" conaffinity="0"/>
                        <geom name="l_ring_proximal_col" type="mesh" mesh="l_ring_proximal_col" mass="0.1" />
                        <!-- Ring Distal -->
                        <body name="l_ring_distal" pos="-0.0024229 -0.032041 -0.001" quat="1 0 0 0">
                            <joint name="joint_l_ring_distal" type="hinge" pos="0 0 0" axis="0 0 -1" range="0 1.75" limited="true" damping="1"/>
                            <site name="site_l_ring_distal" size="0.01" material="site_left_hand"/>
                            <geom name="l_ring_distal_vis" type="mesh" mesh="l_ring_distal_vis" material="l_ring_material" group="1" contype="0" conaffinity="0"/>
                            <geom name="l_ring_distal_col" type="mesh" mesh="l_ring_distal_col" mass="0.1" />
                            <site name="l_ring_distal_site_cylinder" pos="0 -0.06 -0.005" quat="0.7071 0.7071 0 0" size="0.002 0.06" rgba="0 1 0 0.3" type="cylinder" group="1"/>
                        </body>
                        <!-- End of Ring Distal -->
                    </body>
                    <!-- End of Ring Proximal -->
                </body>
                <!-- End of Ring finger -->

                <!-- Pinky finger -->
                <body name="l_pinky" pos="0 0 0">
                    <!-- Pinky Proximal -->
                    <body name="l_pinky_proximal" pos="0.0022853 -0.10411 -0.025488" quat="0.99863 0.05234 0.0 0.0">
                        <joint name="joint_l_pinky_proximal" type="hinge" pos="0 0 0" axis="0 0 -1" range="0 1.62" limited="true" damping="1"/>
                        <site name="site_l_pinky_proximal" size="0.01" material="site_left_hand"/>
                        <geom name="l_pinky_proximal_vis" type="mesh" mesh="l_pinky_proximal_vis" material="l_pinky_material" group="1" contype="0" conaffinity="0"/>
                        <geom name="l_pinky_proximal_col" type="mesh" mesh="l_pinky_proximal_col" mass="0.1" />
                        <!-- Pinky Distal -->
                        <body name="l_pinky_distal" pos="-0.0024229 -0.032041 -0.001" quat="1 0 0 0">
                            <joint name="joint_l_pinky_distal" type="hinge" pos="0 0 0" axis="0 0 -1" range="0 1.87" limited="true" damping="1"/>
                            <site name="site_l_pinky_distal" size="0.01" material="site_left_hand"/>
                            <geom name="l_pinky_distal_vis" type="mesh" mesh="l_pinky_distal_vis" material="l_pinky_material" group="1" contype="0" conaffinity="0"/>
                            <geom name="l_pinky_distal_col" type="mesh" mesh="l_pinky_distal_col" mass="0.1" />
                            <site name="l_pinky_distal_site_cylinder_5" pos="0 -0.06 -0.005" quat="0.7071 0.7071 0 0" size="0.002 0.06" rgba="0 1 0 0.3" type="cylinder" group="1"/>
                        </body>
                        <!-- End of Pinky Distal -->
                    </body>
                    <!-- End of Pinky Proximal -->
                </body>
                <!-- End of Pinky finger -->

            </body>
            <!-- End of Palm -->
        </body>
    </worldbody>
    <contact>
      <exclude name="exclude_lh_palm_thumb_proximal_1" body1="l_thumb_proximal_1" body2="l_palm"/>
      <exclude name="exclude_lh_palm_thumb_proximal_1_proximal_2" body1="l_thumb_proximal_1" body2="l_thumb_proximal_2"/>
      <exclude name="exclude_lh_palm_thumb_proximal_2" body1="l_thumb_proximal_2" body2="l_palm"/>
      <exclude name="exclude_lh_palm_thumb_middle_2" body1="l_thumb_middle" body2="l_palm"/>
      <exclude name="exclude_lh_thumb_proximal_2_middle" body1="l_thumb_proximal_2" body2="l_thumb_middle"/>
      <exclude name="exclude_lh_thumb_middle_distal" body1="l_thumb_middle" body2="l_thumb_distal"/>
      <exclude name="exclude_lh_palm_index_proximal" body1="l_index_proximal" body2="l_palm"/>
      <exclude name="exclude_lh_palm_middle_proximal" body1="l_middle_proximal" body2="l_palm"/>
      <exclude name="exclude_lh_palm_ring_proximal" body1="l_ring_proximal" body2="l_palm"/>
      <exclude name="exclude_lh_palm_pinky_proximal" body1="l_pinky_proximal" body2="l_palm"/>
    </contact>

  <actuator>
    <position joint="joint_l_pinky_distal" name="pinky_distal_drive" ctrlrange="0 1.87" kp="2" forcelimited="true" forcerange="-20 20"/>
    <position joint="joint_l_pinky_proximal" name="pinky_proximal_drive" ctrlrange="0 1.62" kp="2" forcelimited="true" forcerange="-20 20"/>
    <position joint="joint_l_ring_distal" name="ring_distal_drive" ctrlrange="0 1.75" kp="2" forcelimited="true" forcerange="-20 20"/>
    <position joint="joint_l_ring_proximal" name="ring_proximal_drive" ctrlrange="0 1.62" kp="2" forcelimited="true" forcerange="-20 20"/>
    <position joint="joint_l_middle_distal" name="middle_distal_drive" ctrlrange="0 1.82" kp="2" forcelimited="true" forcerange="-20 20"/>
    <position joint="joint_l_middle_proximal" name="middle_proximal_drive" ctrlrange="0 1.62" kp="2" forcelimited="true" forcerange="-20 20"/>
    <position joint="joint_l_index_distal" name="index_distal_drive" ctrlrange="0 1.82" kp="2" forcelimited="true" forcerange="-20 20"/>
    <position joint="joint_l_index_proximal" name="index_proximal_drive" ctrlrange="0 1.62"  kp="2" forcelimited="true" forcerange="-20 20"/>
    <position joint="joint_l_thumb_distal" name="thumb_distal_drive" ctrlrange="0 0.77" kp="2" forcelimited="true" forcerange="-20 20"/>
    <position joint="joint_l_thumb_middle" name="thumb_middle_drive" ctrlrange="0 0.68" kp="2" forcelimited="true" forcerange="-20 20"/>
    <position joint="joint_l_thumb_proximal_2" name="thumb_proximal_2_drive" ctrlrange="0 0.68" kp="2" forcelimited="true" forcerange="-20 20"/>
    <position joint="joint_l_thumb_proximal_1" name="thumb_proximal_1_drive" ctrlrange="0 1.3"  kp="4" forcelimited="true" forcerange="-20 20"/>
  </actuator>

  <sensor>
        <force name="force_ee" site="ft_frame"/>
        <torque name="torque_ee" site="ft_frame"/>
  </sensor>

</mujoco>