<mujoco model="pr2 gripper">
  <compiler angle="radian" />
  <option gravity="0 0 0"/>
  <option integrator="implicitfast" cone="elliptic" impratio="100"/>
  <visual>
    <global ellipsoidinertia="true"/>
  </visual>

<asset>
    <mesh name="gripper_v0_gripper_palm_vis" file="meshes/pr2_gripper/gripper_palm.obj" />
      <mesh name="gripper_v0_gripper_palm" file="meshes/pr2_gripper/gripper_palm.stl" />
      <mesh name="gripper_v0_l_finger_vis" file="meshes/pr2_gripper/l_finger.stl" />
      <mesh name="gripper_v0_l_finger" file="meshes/pr2_gripper/l_finger.stl" />
      <mesh name="gripper_v0_l_finger_tip_vis" file="meshes/pr2_gripper/l_finger_tip.stl" />
      <mesh name="gripper_v0_l_finger_tip" file="meshes/pr2_gripper/l_finger_tip.stl" />

      <material name="gripper_v0_gripper_palm_mat" texture="gripper_v0_gripper_palm_tex"/>
      <texture type="2d" name="gripper_v0_gripper_palm_tex" file="meshes/pr2_gripper/gripper_palm_color.png"/>
  </asset>

  <worldbody>
    <body name="right_gripper" pos="0 0 0" quat="1 0 0 0">
        <site name="ft_frame" pos="0.15 0 0" size="0.01 0.01 0.01" rgba="1 0 0 1" type="sphere" group="1"/>
        <inertial pos="0 0 0.0" quat="0.707107 0.707107 0 0" mass="0.3" diaginertia="0.09 0.07 0.05" />
        <!-- This site was added for visualization. -->
        <body name="eef" pos="0 0 0.0" quat="0.5 0.5 -0.5 -0.5">
            <site name="grip_site" pos="0 0 -0.15" size="0.01 0.01 0.01" rgba="0 0 1 0.5" type="sphere" group="1"/>
            <site name="ee_x" pos="0.1 0 0" size="0.005 .1"  quat="0.707105  0 0.707108 0 " rgba="1 0 0 0" type="cylinder" group="1"/>
            <site name="ee_y" pos="0 0.1 0" size="0.005 .1" quat="0.707105 0.707108 0 0" rgba="0 1 0 0" type="cylinder" group="1"/>
            <site name="ee_z" pos="0 0 0.1" size="0.005 .1" quat="1 0 0 0" rgba="0 0 1 0" type="cylinder" group="1"/>
            <!-- This site was added for visualization. -->
            <site name="grip_site_cylinder" pos="0 0 0" size="0.005 10" rgba="0 1 0 0.3" type="cylinder" group="1"/>
        </body>

        <!-- The following is the actual gripper content -->
        <!--Start of gripper_l_base-->
        <body name="gripper_palm_link" pos="0.0 0.0 0.0" quat="1.0 0.0 0.0 0.0">
            <inertial pos="0.06623 0.00053 -0.00119" quat="1.0 0.0 0.0 0.0" mass="0.58007" diaginertia="0.00035223921 0.00067741312 0.00086563316" />
            <geom pos="0.0 0.0 0.0" quat="1.0 0.0 0.0 0.0" name="gripper_palm_link_visual" group="1" contype="0" conaffinity="0" mesh="gripper_v0_gripper_palm_vis" material="gripper_v0_gripper_palm_mat" type="mesh" />
            <geom pos="0.0 0.0 0.0" quat="1.0 0.0 0.0 0.0" name="gripper_palm_link_collision" group="0" mesh="gripper_v0_gripper_palm" type="mesh" />

            <!--Start of gripper_l_finger_link-->
            <body name="gripper_l_finger_link" pos="0.07691 0.01 0.0" quat="1.0 0.0 0.0 0.0">
                    <joint name="gripper_l_finger_joint" type="hinge" frictionloss="0.5" damping="30" stiffness="0.3" axis="0 0 1" range="0.0 0.548" />
                    <inertial pos="0.03598 0.01730 -0.00164" quat="1.0 0.0 0.0 0.0" mass="0.17126" diaginertia="0.00007756198 0.00019708305 0.00018105446" />
                    <geom pos="0.0 0.0 0.0" quat="1.0 0.0 0.0 0.0" name="gripper_l_finger_link_visual" group="1" contype="0" conaffinity="0" mesh="gripper_v0_l_finger_vis" type="mesh" />
                    <geom pos="0.0 0.0 0.0" quat="1.0 0.0 0.0 0.0" name="gripper_l_finger_link_collision" group="0" mesh="gripper_v0_l_finger" type="mesh" />

                    <!--Start of gripper_l_finger_tip_link-->
                    <body name="gripper_l_finger_tip_link" pos="0.09137 0.00495 0.0" quat="1.0 0.0 0.0 0.0">
                        <joint name="gripper_l_finger_tip_joint" type="hinge" frictionloss="0.5" damping="30" stiffness="0.3" axis="0 0 -1" range="0.0 0.548" />
                        <inertial pos="0.00423 0.00284 0.0" quat="1.0 0.0 0.0 0.0" mass="0.04419" diaginertia="0.00000837047 0.00000987067 0.00001541768" />
                        <geom pos="0.0 0.0 0.0" quat="1.0 0.0 0.0 0.0" name="gripper_l_finger_tip_link_visual" group="1" contype="0" conaffinity="0" mesh="gripper_v0_l_finger_tip_vis" type="mesh" />
                        <geom pos="0.0 0.0 0.0" quat="1.0 0.0 0.0 0.0" name="gripper_l_finger_tip_link_collision" group="0" mesh="gripper_v0_l_finger_tip" type="mesh" />
                    </body>
            <!--End of gripper_l_finger_tip_link-->
            </body>
            <!--End of gripper_l_finger_link-->
            <!--Start of gripper_r_finger_link-->
            <body name="gripper_r_finger_link" pos="0.07691 -0.01 0.0" quat="1.0 0.0 0.0 0.0">
                <joint name="gripper_r_finger_joint" type="hinge" frictionloss="0.5" damping="30" stiffness="0.3" axis="0 0 -1" range="0.0 0.548" />
                <inertial pos="0.03576 -0.01736 -0.00095" quat="1.0 0.0 0.0 0.0" mass="0.17389" diaginertia="0.00007738410 0.00019847383 0.00018106988" />
                <geom pos="0.0 0.0 0.0" quat="-1.0341155355510722e-13 1.0 0.0 -0.0" name="gripper_r_finger_link_visual" group="1" contype="0" conaffinity="0" mesh="gripper_v0_l_finger_vis" type="mesh" />
                <geom pos="0.0 0.0 0.0" quat="-1.0341155355510722e-13 1.0 0.0 -0.0" name="gripper_r_finger_link_collision" group="0" mesh="gripper_v0_l_finger" type="mesh" />
                
                <!--Start of gripper_r_finger_tip_link-->
                <body name="gripper_r_finger_tip_link" pos="0.09137 -0.00495 0.0" quat="1.0 0.0 0.0 0.0">
                    <joint name="gripper_r_finger_tip_joint" type="hinge" frictionloss="0.5" damping="30" stiffness="0.3" axis="0 0 1" range="0.0 0.548" />
                    <inertial pos="0.00423 -0.00284 0.0" quat="1.0 0.0 0.0 0.0" mass="0.04419" diaginertia="0.00000837047 0.00000987067 0.00001541768" />
                    <geom pos="0.0 0.0 0.0" quat="-1.0341155355510722e-13 1.0 0.0 -0.0" name="gripper_r_finger_tip_link_visual" group="1" contype="0" conaffinity="0" mesh="gripper_v0_l_finger_tip_vis" type="mesh" />
                    <geom pos="0.0 0.0 0.0" quat="-1.0341155355510722e-13 1.0 0.0 -0.0" name="gripper_r_finger_tip_link_collision" group="0" mesh="gripper_v0_l_finger_tip" type="mesh" />
                </body>
                <!--End of gripper_r_finger_tip_link-->
            </body>
            <!--End of gripper_r_finger_link-->
        </body>
        <!--End of gripper_l_base-->
    </body>

  </worldbody>

  <actuator>
    <position name="gripper_l_finger_actuator" joint="gripper_l_finger_joint" ctrlrange="0.0 0.548" kp="1000" forcelimited="true" forcerange="-20 20"/>
    <position name="gripper_l_finger_tip_actuator" joint="gripper_l_finger_tip_joint" ctrlrange="0.0 0.548"  kp="1000" forcelimited="true" forcerange="-20 20"/>
    <position name="gripper_r_finger_actuator" joint="gripper_r_finger_joint" ctrlrange="0.0 0.548"  kp="1000" forcelimited="true" forcerange="-20 20"/>
    <position name="gripper_r_finger_tip_actuator" joint="gripper_r_finger_tip_joint" ctrlrange="0.0 0.548"  kp="1000" forcelimited="true" forcerange="-20 20"/>
  </actuator>

  <contact>
    <exclude body1="gripper_palm_link" body2="gripper_l_finger_link"/>
    <exclude body1="gripper_palm_link" body2="gripper_r_finger_tip_link"/>
    <exclude body1="gripper_palm_link" body2="gripper_l_finger_link"/>
    <exclude body1="gripper_palm_link" body2="gripper_r_finger_tip_link"/>
  </contact>

  <sensor>
    <force name="force_ee" site="ft_frame"/>
    <torque name="torque_ee" site="ft_frame"/>
  </sensor>
</mujoco>
