<mujoco model="robotiq_gripper_140_model">
    <compiler angle="radian"/>
    <option impratio="10"/>

    <asset>
        <mesh name="robotiq_arg2f_coupling" file="meshes/robotiq_140_gripper/robotiq_arg2f_coupling.stl" scale="0.001 0.001 0.001"/>
        <mesh name="robotiq_arg2f_base_link" file="meshes/robotiq_140_gripper/robotiq_arg2f_base_link.stl" />
        <mesh name="robotiq_arg2f_140_outer_knuckle" file="meshes/robotiq_140_gripper/robotiq_arg2f_140_outer_knuckle.stl" />
        <mesh name="robotiq_arg2f_140_outer_finger" file="meshes/robotiq_140_gripper/robotiq_arg2f_140_outer_finger.stl" />
        <mesh name="robotiq_arg2f_140_inner_finger" file="meshes/robotiq_140_gripper/robotiq_arg2f_140_inner_finger.stl" />
        <mesh name="robotiq_arg2f_140_inner_knuckle" file="meshes/robotiq_140_gripper/robotiq_arg2f_140_inner_knuckle.stl" />
        <mesh name="robotiq_arg2f_coupling_vis" file="meshes/robotiq_140_gripper/robotiq_arg2f_coupling_vis.stl" scale="0.001 0.001 0.001"/>
        <mesh name="robotiq_arg2f_base_link_vis" file="meshes/robotiq_140_gripper/robotiq_arg2f_base_link_vis.stl" />
        <mesh name="robotiq_arg2f_140_outer_knuckle_vis" file="meshes/robotiq_140_gripper/robotiq_arg2f_140_outer_knuckle_vis.stl" />
        <mesh name="robotiq_arg2f_140_outer_finger_vis" file="meshes/robotiq_140_gripper/robotiq_arg2f_140_outer_finger_vis.stl" />
        <mesh name="robotiq_arg2f_140_inner_finger_vis" file="meshes/robotiq_140_gripper/robotiq_arg2f_140_inner_finger_vis.stl" />
        <mesh name="robotiq_arg2f_140_inner_knuckle_vis" file="meshes/robotiq_140_gripper/robotiq_arg2f_140_inner_knuckle_vis.stl" />
        <mesh name="silicone_pad" file="meshes/robotiq_140_gripper/silicone_pad.stl" scale="0.0012 0.001 0.0017"/>
        <mesh name="pad" file="meshes/robotiq_140_gripper/pad.stl" scale="0.0012 0.0012 0.0017"/>
    </asset>

    <worldbody>
        <body name="base_mount" pos="0 0 0">
            <site name="ft_frame" pos="0 0 0" size="0.01 0.01 0.01" rgba="1 0 0 1" type="sphere" group="1" />

            <!-- This site was added for visualization. -->
            <body name="eef" pos="0 0 0.22" quat="0 1 0 0">
                <site name="grip_site" pos="0 0 0" size="0.01 0.01 0.01" rgba="1 0 0 0.5" type="sphere" group="1"/>
                <site name="ee_x" pos="0.1 0 0" size="0.005 .1" quat="0.707105  0 0.707108 0 " rgba="1 0 0 0" type="cylinder" group="1"/>
                <site name="ee_y" pos="0 0.1 0" size="0.005 .1" quat="0.707105 0.707108 0 0" rgba="0 1 0 0" type="cylinder" group="1"/>
                <site name="ee_z" pos="0 0 0.1" size="0.005 .1" quat="1 0 0 0" rgba="0 0 1 0" type="cylinder" group="1"/>
                <!-- This site was added for visualization. -->
                <site name="grip_site_cylinder" pos="0 0 0" size="0.005 10" rgba="0 1 0 0.3" type="cylinder" group="1"/>
            </body>
            <geom type="mesh" contype="0" conaffinity="0" group="1" mesh="robotiq_arg2f_coupling_vis"/>
            <geom type="mesh" group="0" mesh="robotiq_arg2f_coupling"/>
            <!-- Right-hand side 4-bar linkage -->
            <body name="robotiq_arg2f_base" pos="0 0 0.0038">
                <geom type="mesh" contype="0" conaffinity="0" group="1" density="0" rgba="0.1 0.1 0.1 1" mesh="robotiq_arg2f_base_link_vis"/>
                <geom type="mesh" rgba="0.1 0.1 0.1 1" mesh="robotiq_arg2f_base_link"/>
                <body name="right_outer_knuckle" pos="0 0.030601 0.054905" quat="0 0 0.911903 0.410405">
                    <inertial pos="0.000163875 0.0458404 0.0117804" quat="0.881368 0.472423 -0.0024451 -0.000996122" mass="0.0311462" diaginertia="2.96023e-05 2.79814e-05 4.39017e-06"/>
                    <joint name="right_outer_knuckle_joint" limited="true" pos="0 0 0" axis="1 0 0" range="-0.7 0.0" armature="0.005" damping="0.1" solimplimit="0.95 0.99 0.001" solreflimit="0.005 1"/>
                    <geom type="mesh" contype="0" conaffinity="0" group="1" density="0" rgba="0.792157 0.819608 0.933333 1" mesh="robotiq_arg2f_140_outer_knuckle_vis"/>
                    <geom type="mesh" rgba="0.792157 0.819608 0.933333 1" mesh="robotiq_arg2f_140_outer_knuckle"/>
                    <body name="right_coupler" pos="0 0.01822 0.0260018">
                        <inertial mass="0.0140974" pos="0 0.00301209 0.0232175" quat="0.705636 -0.0455904 0.0455904 0.705636" diaginertia="4.16206e-06 3.52216e-06 8.88131e-07"/>
                        <joint name="right_coupler_joint" limited="true" range="-1.57 0" solimplimit="0.95 0.99 0.001" solreflimit="0.005 1" axis="1 0 0"/>
                        <geom type="mesh" contype="0" conaffinity="0" group="1" density="0" rgba="0.1 0.1 0.1 1" mesh="robotiq_arg2f_140_outer_finger_vis"/>
                        <geom type="mesh" rgba="0.1 0.1 0.1 1" mesh="robotiq_arg2f_140_outer_finger"/>
                    </body>
                </body>
                <body name="right_inner_knuckle" pos="0 0.0127 0.06142" quat="0 0 -0.911903 -0.410405">
                    <inertial pos="0.000123012 0.0507851 0.00103969" quat="0.497203 0.502496 -0.507943 0.492221" mass="0.0271177" diaginertia="2.83809e-05 2.61936e-05 2.81319e-06"/>
                    <joint name="right_inner_knuckle_joint" limited="true" pos="0 0 0" axis="1 0 0" range="-0.8757 0.8757" stiffness="0.05" springref="2.62" damping="0.00125"/>
                    <geom type="mesh" contype="0" conaffinity="0" group="1" density="0" rgba="0.1 0.1 0.1 1" mesh="robotiq_arg2f_140_inner_knuckle_vis"/>
                    <geom type="mesh" rgba="0.1 0.1 0.1 1" mesh="robotiq_arg2f_140_inner_knuckle"/>
                    <body name="right_inner_finger" pos="0 0.10697 0.015501" quat="0.935013 -0.354613 0 0">
                        <inertial pos="0.000119314 0.0339244 -0.021841" quat="0.545437 0.430197 -0.442938 0.566776" mass="0.0261503" diaginertia="1.62408e-05 1.59131e-05 2.38936e-06"/>
                        <joint name="right_inner_finger_joint" limited="true" pos="0 0.006515 -0.017901" axis="1 0 0" range="-0.8757 0.8757" solimplimit="0.95 0.99 0.001" solreflimit="0.005 1"/>
                        <geom type="mesh" contype="0" conaffinity="0" group="1" density="0" rgba="0.1 0.1 0.1 1" mesh="robotiq_arg2f_140_inner_finger_vis"/>
                        <geom type="mesh" rgba="0.1 0.1 0.1 1" mesh="robotiq_arg2f_140_inner_finger"/>

                        <body name="right_pad" pos="0 0.0457554 -0.0252203">
                            <geom pos="0 0 0" size="0.0135 0.0325 0.001875" type="box" friction="0.7" solimp="0.95 0.99 0.001" solref="0.004 1" priority="1" rgba="1 0 0 0.2" name="right_pad1"/>
                            <geom pos="0 0 -0.00375" size="0.0135 0.0325 0.001875" type="box" friction="0.6" solimp="0.95 0.99 0.001" solref="0.004 1" priority="1" rgba="0.45 0.45 0.45 0.5" name="right_pad2"/>

                            <inertial mass="0.0035" pos="0 -0.0025 0.0185" quat="1 0 0 1" diaginertia="4.73958e-07 3.64583e-07 1.23958e-07"/>
                            <geom type="mesh" pos="0 -0.0325 -0.004" euler="-1.5707 0 0" contype="0" conaffinity="0" group="1" mesh="pad"/>
                            <body name="right_silicone_pad">
                                <geom type="mesh" pos="0 -0.0325 -0.0105" euler="-1.5707 0 0" contype="0" conaffinity="0" group="1" mesh="silicone_pad" rgba="0.149 0.149 0.149 1"/>
                            </body>
                        </body>
                    </body>
                </body>
                <!-- Left-hand side 4-bar linkage -->
                <body name="left_outer_knuckle" pos="0 -0.030601 0.054905" quat="0.410405 0.911903 0 0">
                    <inertial pos="0.000163875 0.0458404 0.0117804" quat="0.881368 0.472423 -0.0024451 -0.000996122" mass="0.0311462" diaginertia="2.96023e-05 2.79814e-05 4.39017e-06"/>
                    <joint name="left_outer_knuckle_joint" limited="true" pos="0 0 0" axis="1 0 0" range="-0.7 0.0" armature="0.005" damping="0.1" solimplimit="0.95 0.99 0.001" solreflimit="0.005 1"/>
                    <geom type="mesh" contype="0" conaffinity="0" group="1" density="0" rgba="0.792157 0.819608 0.933333 1" mesh="robotiq_arg2f_140_outer_knuckle_vis"/>
                    <geom type="mesh" rgba="0.792157 0.819608 0.933333 1" mesh="robotiq_arg2f_140_outer_knuckle"/>
                    <body name="left_coupler" pos="0 0.01822 0.0260018">
                        <inertial mass="0.0140974" pos="0 0.00301209 0.0232175" quat="0.705636 -0.0455904 0.0455904 0.705636" diaginertia="4.16206e-06 3.52216e-06 8.88131e-07"/>
                        <joint name="left_coupler_joint" limited="true" range="-1.57 0" solimplimit="0.95 0.99 0.001" solreflimit="0.005 1" axis="1 0 0"/>
                        <geom type="mesh" contype="0" conaffinity="0" group="1" density="0" rgba="0.1 0.1 0.1 1" mesh="robotiq_arg2f_140_outer_finger_vis"/>
                        <geom type="mesh" rgba="0.1 0.1 0.1 1" mesh="robotiq_arg2f_140_outer_finger"/>
                    </body>
                </body>
                <body name="left_inner_knuckle" pos="0 -0.0127 0.06142" quat="0.410405 0.911903 0 0">
                    <inertial pos="0.000123012 0.0507851 0.00103969" quat="0.497203 0.502496 -0.507943 0.492221" mass="0.0271177" diaginertia="2.83809e-05 2.61936e-05 2.81319e-06"/>
                    <joint name="left_inner_knuckle_joint" limited="true" pos="0 0 0" axis="1 0 0" range="-0.8757 0.8757" stiffness="0.05" springref="2.62" damping="0.00125"/>
                    <geom type="mesh" contype="0" conaffinity="0" group="1" density="0" rgba="0.1 0.1 0.1 1" mesh="robotiq_arg2f_140_inner_knuckle_vis"/>
                    <geom type="mesh" rgba="0.1 0.1 0.1 1" mesh="robotiq_arg2f_140_inner_knuckle"/>
                    <body name="left_inner_finger" pos="0 0.10697  0.015501" quat="0.935013 -0.354613 0 0">
                        <inertial pos="0.  0.10697  0.015501" quat="0.545437 0.430197 -0.442938 0.566776" mass="0.0261503" diaginertia="1.62408e-05 1.59131e-05 2.38936e-06"/>
                        <joint name="left_inner_finger_joint" limited="true" pos="0 0.006515 -0.017901" axis="1 0 0" range="-0.8757 0.8757" solimplimit="0.95 0.99 0.001" solreflimit="0.005 1"/>
                        <geom type="mesh" contype="0" conaffinity="0" group="1" density="0" rgba="0.1 0.1 0.1 1" mesh="robotiq_arg2f_140_inner_finger_vis"/>
                        <geom type="mesh" rgba="0.1 0.1 0.1 1" mesh="robotiq_arg2f_140_inner_finger"/>

                        <body name="left_pad" pos="0 0.0457554 -0.0252203">
                            <geom pos="0 0 0" size="0.0135 0.0325 0.001875" type="box" friction="0.7" solimp="0.95 0.99 0.001" solref="0.004 1" priority="1" rgba="0.55 0.55 0.55 1" name="left_pad1"/>
                            <geom pos="0 0 -0.00375" size="0.0135 0.0325 0.001875" type="box" friction="0.6" solimp="0.95 0.99 0.001" solref="0.004 1" priority="1" rgba="0.45 0.45 0.45 1" name="left_pad2"/>

                            <inertial mass="0.0035" pos="0 -0.0025 0.0185" quat="1 0 0 1" diaginertia="4.73958e-07 3.64583e-07 1.23958e-07"/>
                            <geom type="mesh" pos="0 -0.0325 -0.004" euler="-1.5707 0 0" contype="0" conaffinity="0" group="1" mesh="pad"/>
                            <body name="left_silicone_pad">
                                <geom type="mesh" pos="0 -0.0325 -0.0105" euler="-1.5707 0 0" contype="0" conaffinity="0" group="1" mesh="silicone_pad" rgba="0.149 0.149 0.149 1"/>
                            </body>
                        </body>
                    </body>
                </body>
            </body>
        </body>
    </worldbody>


    <contact>
        <exclude body1="robotiq_arg2f_base" body2="left_outer_knuckle"/>
        <exclude body1="robotiq_arg2f_base" body2="left_inner_knuckle"/>
        <exclude body1="left_outer_knuckle" body2="left_coupler"/>
        <exclude body1="left_outer_knuckle" body2="left_inner_knuckle"/>
        <exclude body1="left_inner_knuckle" body2="left_coupler"/>
        <exclude body1="left_coupler" body2="left_inner_finger"/>

        <exclude body1="robotiq_arg2f_base" body2="right_outer_knuckle"/>
        <exclude body1="robotiq_arg2f_base" body2="right_inner_knuckle"/>
        <exclude body1="right_outer_knuckle" body2="right_coupler"/>
        <exclude body1="right_outer_knuckle" body2="right_inner_knuckle"/>
        <exclude body1="right_inner_knuckle" body2="right_coupler"/>
        <exclude body1="right_coupler" body2="right_inner_finger"/>
    </contact>

    <!--
    This adds stability to the model by having a tendon that distributes the forces between both
    joints, such that the equality constraint doesn't have to do that much work in order to equalize
    both joints. Since both joints share the same sign, we split the force between both equally by
    setting coef=0.5
    -->

    <tendon>
        <fixed name="split">
            <joint joint="left_outer_knuckle_joint" coef="-0.5"/>
            <joint joint="right_outer_knuckle_joint" coef="-0.5"/>
        </fixed>
    </tendon>
    <!--
    The general actuator below is a customized position actuator (with some damping) where
    gainprm[0] != kp (see http://mujoco.org/book/modeling.html#position).
    The reason why gainprm[0] != kp is because the control input range has to be re-scaled to
    [0, 255]. The joint range is currently set at [0, 0.8], the control range is [0, 255] and
    kp = 100. Tau = Kp * scale * control_input - Kp * error, max(Kp * scale * control_input) = 0.8,
    hence scale = 0.8 * 100 / 255
    -->
    <equality>
        <connect anchor="0 0 0" body1="left_inner_finger" body2="left_coupler" solimp="0.95 0.99 0.001" solref="0.005 1"/>
        <connect anchor="0 0 0" body1="right_inner_finger" body2="right_coupler" solimp="0.95 0.99 0.001" solref="0.005 1"/>
        <joint joint1="left_outer_knuckle_joint" joint2="right_outer_knuckle_joint" polycoef="0 1 0 0 0" solimp="0.95 0.99 0.001" solref="0.005 1"/>
    </equality>
    <actuator>
        <general name="fingers_actuator" tendon="split" forcerange="-5 5" ctrlrange="0 255" gainprm="0.3137255 0 0" biasprm="0 -100 -10" biastype="affine"/>
    </actuator>

    <sensor>
        <force name="force_ee" site="ft_frame"/>
        <torque name="torque_ee" site="ft_frame"/>
    </sensor>
</mujoco>
