<?xml version="1.0" ?>
<mujoco model="hand">
  <compiler angle="radian" autolimits="true"/>
  <visual>
    <global ellipsoidinertia="true"/>
  </visual>
  <default>
    <default class="schunk_svh_right_hand_finger">
      <joint damping="0.001" frictionloss="0.001"/>
    </default>
  </default>
  <asset>

    <material name="Metall_Alu_final" rgba="0.799102 0.806952 0.846873 1.0" specular="0.8" metallic="0.3"/>

    <material name="Metall_Daumen" rgba="0.350000 0.350000 0.350000 1.0" specular="0.7" />

    <mesh name="visual_base10" file="meshes/schunk_svh_hand/visual/base10.obj"/>
    <mesh name="visual_h10" file="meshes/schunk_svh_hand/visual/h10.obj"/>
    <mesh name="visual_h11" file="meshes/schunk_svh_hand/visual/h11.obj"/>
    <mesh name="visual_d10" file="meshes/schunk_svh_hand/visual/d10.obj"/>
    <mesh name="visual_d11" file="meshes/schunk_svh_hand/visual/d11.obj"/>
    <mesh name="collision_d11" file="meshes/schunk_svh_hand/collision/d11.obj"/>
    <mesh name="visual_d12" file="meshes/schunk_svh_hand/visual/d12.obj"/>
    <mesh name="collision_d12" file="meshes/schunk_svh_hand/collision/d12.obj"/>
    <mesh name="visual_d13" file="meshes/schunk_svh_hand/visual/d13.obj"/>
    <mesh name="collision_d13" file="meshes/schunk_svh_hand/collision/d13.obj"/>
    <mesh name="visual_f10_f20" file="meshes/schunk_svh_hand/visual/f10_f20.obj"/>
    <mesh name="visual_f11" file="meshes/schunk_svh_hand/visual/f11.obj"/>
    <mesh name="collision_f11" file="meshes/schunk_svh_hand/collision/f11.obj"/>
    <mesh name="visual_f12" file="meshes/schunk_svh_hand/visual/f12.obj"/>
    <mesh name="collision_f12" file="meshes/schunk_svh_hand/collision/f12.obj"/>
    <mesh name="visual_finger_tip" file="meshes/schunk_svh_hand/visual/finger_tip.obj"/>
    <mesh name="collision_finger_tip" file="meshes/schunk_svh_hand/collision/finger_tip.obj"/>
    <mesh name="visual_f21" file="meshes/schunk_svh_hand/visual/f21.obj"/>
    <mesh name="collision_f21" file="meshes/schunk_svh_hand/collision/f21.obj"/>
    <mesh name="visual_f22_f32" file="meshes/schunk_svh_hand/visual/f22_f32.obj"/>
    <mesh name="collision_f22_f32" file="meshes/schunk_svh_hand/collision/f22_f32.obj"/>
    <mesh name="visual_f30_f40" file="meshes/schunk_svh_hand/visual/f30_f40.obj"/>
    <mesh name="visual_f31" file="meshes/schunk_svh_hand/visual/f31.obj"/>
    <mesh name="collision_f31" file="meshes/schunk_svh_hand/collision/f31.obj"/>
    <mesh name="visual_f41" file="meshes/schunk_svh_hand/visual/f41.obj"/>
    <mesh name="collision_f41" file="meshes/schunk_svh_hand/collision/f41.obj"/>
    <mesh name="visual_f42" file="meshes/schunk_svh_hand/visual/f42.obj"/>
    <mesh name="collision_f42" file="meshes/schunk_svh_hand/collision/f42.obj"/>
  </asset>
  <actuator>
    <motor name="right_hand_Thumb_Flexion" joint="right_hand_Thumb_Flexion" ctrlrange="-50 50" ctrllimited="true"/>
    <motor name="right_hand_Thumb_Opposition" joint="right_hand_Thumb_Opposition" ctrlrange="-50 50" ctrllimited="true"/>
    <motor name="right_hand_j5" joint="right_hand_j5" ctrlrange="-50 50" ctrllimited="true"/>
    <motor name="right_hand_j3" joint="right_hand_j3" ctrlrange="-50 50" ctrllimited="true"/>
    <motor name="right_hand_j4" joint="right_hand_j4" ctrlrange="-50 50" ctrllimited="true"/>
    <motor name="right_hand_Index_Finger_Distal" joint="right_hand_Index_Finger_Distal" ctrlrange="-50 50" ctrllimited="true"/>
    <motor name="right_hand_Index_Finger_Proximal" joint="right_hand_Index_Finger_Proximal" ctrlrange="-50 50" ctrllimited="true"/>
    <motor name="right_hand_j14" joint="right_hand_j14" ctrlrange="-50 50" ctrllimited="true"/>
    <motor name="right_hand_Middle_Finger_Proximal" joint="right_hand_Middle_Finger_Proximal" ctrlrange="-50 50" ctrllimited="true"/>
    <motor name="right_hand_Middle_Finger_Distal" joint="right_hand_Middle_Finger_Distal" ctrlrange="-50 50" ctrllimited="true"/>
    <motor name="right_hand_j15" joint="right_hand_j15" ctrlrange="-50 50" ctrllimited="true"/>
    <motor name="right_hand_Ring_Finger" joint="right_hand_Ring_Finger" ctrlrange="-50 50" ctrllimited="true"/>
    <motor name="right_hand_j12" joint="right_hand_j12" ctrlrange="-50 50" ctrllimited="true"/>
    <motor name="right_hand_j16" joint="right_hand_j16" ctrlrange="-50 50" ctrllimited="true"/>
    <motor name="right_hand_Pinky" joint="right_hand_Pinky" ctrlrange="-50 50" ctrllimited="true"/>
    <motor name="right_hand_j13" joint="right_hand_j13" ctrlrange="-50 50" ctrllimited="true"/>
    <motor name="right_hand_j17" joint="right_hand_j17" ctrlrange="-50 50" ctrllimited="true"/>
    <motor name="right_hand_index_spread" joint="right_hand_index_spread" ctrlrange="-50 50" ctrllimited="true"/>
    <motor name="right_hand_ring_spread" joint="right_hand_ring_spread" ctrlrange="-50 50" ctrllimited="true"/>
    <motor name="right_hand_Finger_Spread" joint="right_hand_Finger_Spread" ctrlrange="-50 50" ctrllimited="true"/>
  </actuator>
  <worldbody>
    <body name="right_gripper" pos="0 0 0" quat="0 0 -1 0">
      <site name="ft_frame" pos="0 0 0" size="0.01 0.01 0.01" rgba="1 0 0 1" type="sphere" material="Metall_Alu_final"  group="1"/>
      <inertial pos="0 0 0.17" quat="0.707107 0.707107 0 0" mass="0.3" diaginertia="0.09 0.07 0.05"/>
      <body name="eef" pos="0 0 0.097" quat="1 0 0 0">
        <site name="grip_site" pos="0 0 0" size="0.01 0.01 0.01" rgba="1 0 0 0.5" type="sphere" group="1"/>
        <site name="ee_x" pos="0.1 0 0" size="0.005 .1" quat="0.707105  0 0.707108 0 " rgba="1 0 0 0" type="cylinder" group="1"/>
        <site name="ee_y" pos="0 0.1 0" size="0.005 .1" quat="0.707105 0.707108 0 0" rgba="0 1 0 0" type="cylinder" material="Metall_Daumen"  group="1"/>
        <site name="ee_z" pos="0 0 0.1" size="0.005 .1" quat="1 0 0 0" rgba="0 0 1 0" type="cylinder" group="1"/>
        <site name="grip_site_cylinder" pos="0 0 0" size="0.005 10" rgba="0 1 0 0.3" type="cylinder" group="1"/>
      </body>
      <!--Start of base-->
      <body name="hand_mount">
      <!--Start of hand base-->
      <body name="right_hand_base_link" pos="0.0 0.0 0.0" quat="0.7071090180427968 0.0 0.0 -0.7071045443232222">
        <inertial pos="0 0 0" quat="1.0 0.0 0.0 0.0" mass="0.001" diaginertia="1.0e-08 1.0e-08 1.0e-08"/>
        <geom pos="0.0 0.0 -0.032" quat="1.0 0.0 0.0 0.0" name="right_hand_base_link_visual" material="Metall_Daumen"  group="1" contype="0" conaffinity="0" mesh="visual_base10" type="mesh"/>
        <geom pos="0.0 0.0 -0.009" quat="1.0 0.0 0.0 0.0" name="right_hand_base_link_collision" group="0" type="box" size="0.045 0.045 0.0225"/>
        <!--Start of hand base-->
        <body name="right_hand_e1" pos="0.0 -0.01313 0.0" quat="1.0 0.0 0.0 0.0">
          <inertial pos="0 0 0" quat="1.0 0.0 0.0 0.0" mass="0.001" diaginertia="1.0e-08 1.0e-08 1.0e-08"/>
          <geom pos="0.0 0.01313 0.0" quat="1.0 0.0 0.0 0.0" name="right_hand_e1_visual" material="Metall_Daumen"  group="1" contype="0" conaffinity="0" mesh="visual_h10" type="mesh"/>
          <geom pos="0.0 0.01313 0.013" quat="1.0 0.0 0.0 0.0" name="right_hand_e1_collision" group="0" type="box" size="0.025 0.025 0.013"/>
          <geom pos="-0.00573 0.0035 0.05747" quat="1.0 0.0 0.0 0.0" name="right_hand_e1_collision_1" group="0" type="box" size="0.0292 0.019 0.03205"/>
          <geom pos="-0.01 0.0035 0.096" quat="1.0 0.0 0.0 0.0" name="right_hand_e1_collision_2" group="0" type="box" size="0.021 0.019 0.0075"/>
          <!--Start of right_hand_z-->
          <body name="right_hand_z" pos="-0.0169 0.02626 0.0" quat="0.7009859594636422 -0.09230556888501792 0.09228677062823984 0.7011287460621343">
            <joint name="right_hand_Thumb_Opposition" type="hinge" class="schunk_svh_right_hand_finger" axis="0 0 -1" range="0.0 0.9879"/>
            <inertial pos="0 0 0" quat="1.0 0.0 0.0 0.0" mass="0.001" diaginertia="1.0e-08 1.0e-08 1.0e-08"/>
            <geom pos="0.0 0.0 0.02442" quat="1.0 0.0 0.0 0.0" name="right_hand_z_visual" material="Metall_Alu_final"  group="1" contype="0" conaffinity="0" mesh="visual_d10" type="mesh"/>
            <geom pos="0.0 0.0 0.02842" quat="1.0 0.0 0.0 0.0" name="right_hand_z_collision" group="0" type="box" size="0.012 0.0094 0.004"/>
            <geom pos="0.0125 0.0 0.04292" quat="1.0 0.0 0.0 0.0" name="right_hand_z_collision_1" group="0" type="box" size="0.003 0.012 0.0165"/>
            <geom pos="-0.0125 0.0 0.04292" quat="1.0 0.0 0.0 0.0" name="right_hand_z_collision_2" group="0" type="box" size="0.003 0.012 0.0165"/>
            <!--Start of right_hand_a-->
            <body name="right_hand_a" pos="0.0 0.0 0.04596" quat="0.3297870063394784 0.6254943170001938 0.32977909159097296 0.6254943170001938">
              <joint name="right_hand_Thumb_Flexion" type="hinge" class="schunk_svh_right_hand_finger" axis="0 0 1" range="0.0 0.9704"/>
              <inertial pos="0 0 0" quat="1.0 0.0 0.0 0.0" mass="0.001" diaginertia="1.0e-08 1.0e-08 1.0e-08"/>
              <geom pos="0.0 0.0 0.0" quat="1.0 0.0 0.0 0.0" name="right_hand_a_visual" material="Metall_Alu_final"  group="1" contype="0" conaffinity="0" mesh="visual_d11" type="mesh"/>
              <geom pos="0.0 0.0 0.0" quat="1.0 0.0 0.0 0.0" name="right_hand_a_collision" group="0" mesh="collision_d11" type="mesh"/>
              <!--Start of right_hand_b-->
              <body name="right_hand_b" pos="0.0485 0.0 0.0" quat="1.0 0.0 0.0 0.0">
                <joint name="right_hand_j3" type="hinge" class="schunk_svh_right_hand_finger" axis="0 0 1" range="0.0 0.98506"/>
                <inertial pos="0 0 0" quat="1.0 0.0 0.0 0.0" mass="0.001" diaginertia="1.0e-08 1.0e-08 1.0e-08"/>
                <geom pos="0.0 0.0 0.0" quat="1.0 0.0 0.0 0.0" name="right_hand_b_visual" material="Metall_Alu_final"  group="1" contype="0" conaffinity="0" mesh="visual_d12" type="mesh"/>
                <geom pos="0.0 0.0 0.0" quat="1.0 0.0 0.0 0.0" name="right_hand_b_collision" group="0" mesh="collision_d12" type="mesh"/>
                <!--Start of right_hand_c-->
                <body name="right_hand_c" pos="0.03 0.0 0.0" quat="1.0 0.0 0.0 0.0">
                  <joint name="right_hand_j4" type="hinge" class="schunk_svh_right_hand_finger" axis="0 0 1" range="0.0 1.406"/>
                  <inertial pos="0.007 0.000 0.000" quat="1.0 0.0 0.0 0.0" mass="0.02" diaginertia="1e-5 2e-5 2e-5"/>
                  <geom pos="0.0 0.0 0.0" quat="1.0 0.0 0.0 0.0" name="right_hand_c_visual" material="Metall_Daumen"  group="1" contype="0" conaffinity="0" mesh="visual_d13" type="mesh"/>
                  <geom pos="0.0 0.0 0.0" quat="1.0 0.0 0.0 0.0" name="right_hand_c_collision" group="0" mesh="collision_d13" type="mesh"/>
                  <body name="thumb_tip">
                      <site name="thumb_tip" pos="0.014 0.000 0.000" rgba="0 0 1 1" size="0.0025" group="2"/>
                  </body>
                </body>
                <!--End of right_hand_c-->
              </body>
              <!--End of right_hand_b-->
            </body>
            <!--End of right_hand_a-->
          </body>
          <!--End of right_hand_z-->
          <!--Start of right_hand_virtual_l-->
          <body name="right_hand_virtual_l" pos="-0.025 0.0 0.11" quat="0.5000481633973738 0.49995183660262615 -0.49999999768028713 0.49999999768028713">
            <joint name="right_hand_index_spread" type="hinge" class="schunk_svh_right_hand_finger" axis="0 0 1" range="0.0 0.28833"/>
            <inertial pos="0 0 0" quat="1.0 0.0 0.0 0.0" mass="0.001" diaginertia="1.0e-08 1.0e-08 1.0e-08"/>
            <geom pos="0.0 0.0 0.01321" quat="1.0 0.0 0.0 0.0" name="right_hand_virtual_l_visual" material="Metall_Alu_final"  group="1" contype="0" conaffinity="0" mesh="visual_f10_f20" type="mesh"/>
            <geom pos="0.0 0.0 0.00121" quat="1.0 0.0 0.0 0.0" name="right_hand_virtual_l_collision" group="0" type="sphere" size="0.01"/>
            <!--Start of right_hand_l-->
            <body name="right_hand_l" pos="0.0 0.0 0.0" quat="0.7071408370313327 -0.7070727237014777 0.0 0.0">
              <joint name="right_hand_Index_Finger_Proximal" type="hinge" class="schunk_svh_right_hand_finger" axis="0 0 1" range="0.0 0.79849"/>
              <inertial pos="0 0 0" quat="1.0 0.0 0.0 0.0" mass="0.001" diaginertia="1.0e-08 1.0e-08 1.0e-08"/>
              <geom pos="0.0 0.0 0.0" quat="1.0 0.0 0.0 0.0" name="right_hand_l_visual" material="Metall_Alu_final"  group="1" contype="0" conaffinity="0" mesh="visual_f11" type="mesh"/>
              <geom pos="0.0 0.0 0.0" quat="1.0 0.0 0.0 0.0" name="right_hand_l_collision" group="0" mesh="collision_f11" type="mesh"/>
              <!--Start of right_hand_p-->
              <body name="right_hand_p" pos="0.04804 0.0 0.0" quat="1.0 0.0 0.0 0.0">
                <joint name="right_hand_Index_Finger_Distal" type="hinge" class="schunk_svh_right_hand_finger" axis="0 0 1" range="0 1.334"/>
                <inertial pos="0.01 0.000 0.000" quat="1.0 0.0 0.0 0.0" mass="0.024" diaginertia="1e-6 3e-6 2e-6"/>
                <geom pos="0.0 0.0 0.0" quat="1.0 0.0 0.0 0.0" name="right_hand_p_visual" material="Metall_Alu_final"  group="1" contype="0" conaffinity="0" mesh="visual_f12" type="mesh"/>
                <geom pos="0.0 0.0 0.0" quat="1.0 0.0 0.0 0.0" name="right_hand_p_collision" group="0" mesh="collision_f12" type="mesh"/>
                <!--Start of right_hand_t-->
                <body name="right_hand_t" pos="0.026 0.0 0.0" quat="1.0 0.0 0.0 0.0">
                  <joint name="right_hand_j14" type="hinge" class="schunk_svh_right_hand_finger" axis="0 0 1" range="0 1.394"/>
                  <inertial pos="0.007 0.000 0.000" quat="1.0 0.0 0.0 0.0" mass="0.02" diaginertia="1e-5 2e-5 2e-5"/>
                  <geom pos="0.0 0.0 0.0" quat="1.0 0.0 0.0 0.0" name="right_hand_t_visual" material="Metall_Daumen"  group="1" contype="0" conaffinity="0" mesh="visual_finger_tip" type="mesh"/>
                  <geom pos="0.0 0.0 0.0" quat="1.0 0.0 0.0 0.0" name="right_hand_t_collision" group="0" mesh="collision_finger_tip" type="mesh"/>
                  <body name="index_tip">
                      <site name="index_tip" pos="0.014 0.000 0.000" rgba="0 0 1 1" size="0.0025" group="2"/>
                  </body>
                </body>
                <!--End of right_hand_t-->
              </body>
              <!--End of right_hand_p-->
            </body>
            <!--End of right_hand_l-->
          </body>
          <!--End of right_hand_virtual_l-->
          <!--Start of right_hand_virtual_k-->
          <body name="right_hand_virtual_k" pos="0.0 0.0 0.11" quat="0.5000481633973738 0.49995183660262615 -0.49999999768028713 0.49999999768028713">
            <inertial pos="0 0 0" quat="1.0 0.0 0.0 0.0" mass="0.001" diaginertia="1.0e-08 1.0e-08 1.0e-08"/>
            <geom pos="0.0 0.0 0.01321" quat="1.0 0.0 0.0 0.0" name="right_hand_virtual_k_visual" material="Metall_Alu_final"  group="1" contype="0" conaffinity="0" mesh="visual_f10_f20" type="mesh"/>
            <geom pos="0.0 0.0 0.00321" quat="1.0 0.0 0.0 0.0" name="right_hand_virtual_k_collision" group="0" type="sphere" size="0.01"/>
            <!--Start of right_hand_k-->
            <body name="right_hand_k" pos="0.0 0.0 0.0" quat="0.7071408370313327 -0.7070727237014777 0.0 0.0">
              <joint name="right_hand_Middle_Finger_Proximal" type="hinge" class="schunk_svh_right_hand_finger" axis="0 0 1" range="0.0 0.79849"/>
              <inertial pos="0 0 0" quat="1.0 0.0 0.0 0.0" mass="0.001" diaginertia="1.0e-08 1.0e-08 1.0e-08"/>
              <geom pos="0.0 0.0 0.0" quat="1.0 0.0 0.0 0.0" name="right_hand_k_visual" material="Metall_Alu_final"  group="1" contype="0" conaffinity="0" mesh="visual_f21" type="mesh"/>
              <geom pos="0.0 0.0 0.0" quat="1.0 0.0 0.0 0.0" name="right_hand_k_collision" group="0" mesh="collision_f21" type="mesh"/>
              <!--Start of right_hand_o-->
              <body name="right_hand_o" pos="0.05004 0.0 0.0" quat="1.0 0.0 0.0 0.0">
                <joint name="right_hand_Middle_Finger_Distal" type="hinge" class="schunk_svh_right_hand_finger" axis="0 0 1" range="0 1.334"/>
                <inertial pos="0 0 0" quat="1.0 0.0 0.0 0.0" mass="0.001" diaginertia="1.0e-08 1.0e-08 1.0e-08"/>
                <geom pos="0.0 0.0 0.0" quat="1.0 0.0 0.0 0.0" name="right_hand_o_visual" material="Metall_Alu_final"  group="1" contype="0" conaffinity="0" mesh="visual_f22_f32" type="mesh"/>
                <geom pos="0.0 0.0 0.0" quat="1.0 0.0 0.0 0.0" name="right_hand_o_collision" group="0" mesh="collision_f22_f32" type="mesh"/>
                <!--Start of right_hand_s-->
                <body name="right_hand_s" pos="0.032 0.0 0.0" quat="1.0 0.0 0.0 0.0">
                  <joint name="right_hand_j15" type="hinge" class="schunk_svh_right_hand_finger" axis="0 0 1" range="0 1.334"/>
                  <inertial pos="0.007 0.000 0.000" quat="1.0 0.0 0.0 0.0" mass="0.02" diaginertia="1e-5 2e-5 2e-5"/>
                  <geom pos="0.0 0.0 0.0" quat="1.0 0.0 0.0 0.0" name="right_hand_s_visual" material="Metall_Daumen"  group="1" contype="0" conaffinity="0" mesh="visual_finger_tip" type="mesh"/>
                  <geom pos="0.0 0.0 0.0" quat="1.0 0.0 0.0 0.0" name="right_hand_s_collision" group="0" mesh="collision_finger_tip" type="mesh"/>
                  <body name="middle_tip">
                      <site name="middle_tip" pos="0.014 0.000 0.000" rgba="0 0 1 1" size="0.0025" group="2"/>
                  </body>
                </body>
                <!--End of right_hand_s-->
              </body>
              <!--End of right_hand_o-->
            </body>
            <!--End of right_hand_k-->
          </body>
          <!--End of right_hand_virtual_k-->
          <!--Start of right_hand_e2-->
          <body name="right_hand_e2" pos="0.0184 0.006 0.0375" quat="1.0 0.0 0.0 0.0">
            <joint name="right_hand_j5" type="hinge" class="schunk_svh_right_hand_finger" axis="0 0 1" range="0.0 0.98786"/>
            <inertial pos="0 0 0" quat="1.0 0.0 0.0 0.0" mass="0.001" diaginertia="1.0e-08 1.0e-08 1.0e-08"/>
            <geom pos="-0.0007 0.0 -0.01002" quat="1.0 0.0 0.0 0.0" name="right_hand_e2_visual" material="Metall_Alu_final"  group="1" contype="0" conaffinity="0" mesh="visual_h11" type="mesh"/>
            <geom pos="0.016 0.0 0.02" quat="1.0 0.0 0.0 0.0" name="right_hand_e2_collision" group="0" type="box" size="0.0123 0.0175 0.0282"/>
            <geom pos="0.0032 -0.0083 0.048" quat="1.0 0.0 0.0 0.0" name="right_hand_e2_collision_1" group="0" type="box" size="0.006 0.009 0.0105"/>
            <!--Start of right_hand_virtual_j-->
            <body name="right_hand_virtual_j" pos="0.003855 -0.006 0.0655" quat="0.5000481633973738 -0.49999999768028713 -0.49999999768028713 -0.49995183660262615">
              <joint name="right_hand_ring_spread" type="hinge" class="schunk_svh_right_hand_finger" axis="0 0 1" range="0.0 0.28833"/>
              <inertial pos="0 0 0" quat="1.0 0.0 0.0 0.0" mass="0.001" diaginertia="1.0e-08 1.0e-08 1.0e-08"/>
              <geom pos="0.0 0.0 -0.01321" quat="1.0 0.0 0.0 0.0" name="right_hand_virtual_j_visual" material="Metall_Alu_final"  group="1" contype="0" conaffinity="0" mesh="visual_f30_f40" type="mesh"/>
              <geom pos="0.0 0.0 -0.00321" quat="1.0 0.0 0.0 0.0" name="right_hand_virtual_j_collision" group="0" type="sphere" size="0.01"/>
              <!--Start of right_hand_j-->
              <body name="right_hand_j" pos="0.0 0.0 0.0" quat="0.7071408370313327 0.7070727237014777 0.0 0.0">
                <joint name="right_hand_Ring_Finger" type="hinge" class="schunk_svh_right_hand_finger" axis="0 0 1" range="0.0 0.98175"/>
                <inertial pos="0 0 0" quat="1.0 0.0 0.0 0.0" mass="0.001" diaginertia="1.0e-08 1.0e-08 1.0e-08"/>
                <geom pos="0.0 0.0 0.0" quat="1.0 0.0 0.0 0.0" name="right_hand_j_visual" material="Metall_Alu_final"  group="1" contype="0" conaffinity="0" mesh="visual_f31" type="mesh"/>
                <geom pos="0.0 0.0 0.0" quat="1.0 0.0 0.0 0.0" name="right_hand_j_collision" group="0" mesh="collision_f31" type="mesh"/>
                <!--Start of right_hand_n-->
                <body name="right_hand_n" pos="0.05004 0.0 0.0" quat="1.0 0.0 0.0 0.0">
                  <joint name="right_hand_j12" type="hinge" class="schunk_svh_right_hand_finger" axis="0 0 1" range="0 1.334"/>
                  <inertial pos="0 0 0" quat="1.0 0.0 0.0 0.0" mass="0.001" diaginertia="1.0e-08 1.0e-08 1.0e-08"/>
                  <geom pos="0.0 0.0 0.0" quat="1.0 0.0 0.0 0.0" name="right_hand_n_visual" material="Metall_Alu_final"  group="1" contype="0" conaffinity="0" mesh="visual_f22_f32" type="mesh"/>
                  <geom pos="0.0 0.0 0.0" quat="1.0 0.0 0.0 0.0" name="right_hand_n_collision" group="0" mesh="collision_f22_f32" type="mesh"/>
                  <!--Start of right_hand_r-->
                  <body name="right_hand_r" pos="0.032 0.0 0.0" quat="1.0 0.0 0.0 0.0">
                    <joint name="right_hand_j16" type="hinge" class="schunk_svh_right_hand_finger" axis="0 0 1" range="0 1.395"/>
                    <inertial pos="0.007 0.000 0.000" quat="1.0 0.0 0.0 0.0" mass="0.02" diaginertia="1e-5 2e-5 2e-5"/>
                    <geom pos="0.0 0.0 0.0" quat="1.0 0.0 0.0 0.0" name="right_hand_r_visual" material="Metall_Daumen"  group="1" contype="0" conaffinity="0" mesh="visual_finger_tip" type="mesh"/>
                    <geom pos="0.0 0.0 0.0" quat="1.0 0.0 0.0 0.0" name="right_hand_r_collision" group="0" mesh="collision_finger_tip" type="mesh"/>
                    <body name="ring_tip">
                        <site name="ring_tip" pos="0.014 0.000 0.000" rgba="0 0 1 1" size="0.0025" group="2"/>
                    </body>
                  </body>
                  <!--End of right_hand_r-->
                </body>
                <!--End of right_hand_n-->
              </body>
              <!--End of right_hand_j-->
            </body>
            <!--End of right_hand_virtual_j-->
            <!--Start of right_hand_virtual_i-->
            <body name="right_hand_virtual_i" pos="0.025355 -0.006 0.056" quat="0.5000481633973738 -0.49999999768028713 -0.49999999768028713 -0.49995183660262615">
              <joint name="right_hand_Finger_Spread" type="hinge" class="schunk_svh_right_hand_finger" axis="0 0 1" range="0.0 0.5829"/>
              <inertial pos="0 0 0" quat="1.0 0.0 0.0 0.0" mass="0.001" diaginertia="1.0e-08 1.0e-08 1.0e-08"/>
              <geom pos="0.0 0.0 -0.01321" quat="1.0 0.0 0.0 0.0" name="right_hand_virtual_i_visual" material="Metall_Alu_final"  group="1" contype="0" conaffinity="0" mesh="visual_f30_f40" type="mesh"/>
              <geom pos="0.0 0.0 -0.00321" quat="1.0 0.0 0.0 0.0" name="right_hand_virtual_i_collision" group="0" type="sphere" size="0.01"/>
              <!--Start of right_hand_i-->
              <body name="right_hand_i" pos="0.0 0.0 0.0" quat="0.7071408370313327 0.7070727237014777 0.0 0.0">
                <joint name="right_hand_Pinky" type="hinge" class="schunk_svh_right_hand_finger" axis="0 0 1" range="0.0 0.98175"/>
                <inertial pos="0 0 0" quat="1.0 0.0 0.0 0.0" mass="0.001" diaginertia="1.0e-08 1.0e-08 1.0e-08"/>
                <geom pos="0.0 0.0 0.0" quat="1.0 0.0 0.0 0.0" name="right_hand_i_visual" material="Metall_Alu_final"  group="1" contype="0" conaffinity="0" mesh="visual_f41" type="mesh"/>
                <geom pos="0.0 0.0 0.0" quat="1.0 0.0 0.0 0.0" name="right_hand_i_collision" group="0" mesh="collision_f41" type="mesh"/>
                <!--Start of right_hand_m-->
                <body name="right_hand_m" pos="0.04454 0.0 0.0" quat="1.0 0.0 0.0 0.0">
                  <joint name="right_hand_j13" type="hinge" class="schunk_svh_right_hand_finger" axis="0 0 1" range="0 1.334"/>
                  <inertial pos="0.007 0.000 0.000" quat="1.0 0.0 0.0 0.0" mass="0.02" diaginertia="8e-7 2e-6 2e-6"/>
                  <geom pos="0.0 0.0 0.0" quat="1.0 0.0 0.0 0.0" name="right_hand_m_visual" material="Metall_Alu_final"  group="1" contype="0" conaffinity="0" mesh="visual_f42" type="mesh"/>
                  <geom pos="0.0 0.0 0.0" quat="1.0 0.0 0.0 0.0" name="right_hand_m_collision" group="0" mesh="collision_f42" type="mesh"/>
                  <!--Start of right_hand_q-->
                  <body name="right_hand_q" pos="0.022 0.0 0.0" quat="1.0 0.0 0.0 0.0">
                    <joint name="right_hand_j17" type="hinge" class="schunk_svh_right_hand_finger" axis="0 0 1" range="0 1.3971"/>
                    <inertial pos="0.007 0.000 0.000" quat="1.0 0.0 0.0 0.0" mass="0.02" diaginertia="1e-5 2e-5 2e-5"/>
                    <geom pos="0.0 0.0 0.0" quat="1.0 0.0 0.0 0.0" name="right_hand_q_visual" material="Metall_Daumen"  group="1" contype="0" conaffinity="0" mesh="visual_finger_tip" type="mesh"/>
                    <geom pos="0.0 0.0 0.0" quat="1.0 0.0 0.0 0.0" name="right_hand_q_collision" group="0" mesh="collision_finger_tip" type="mesh"/>
                    <body name="pinky_tip">
                        <site name="pinky_tip" pos="0.014 0.000 0.000" rgba="0 0 1 1" size="0.0025" group="2"/>
                    </body>
                  </body>
                  <!--End of right_hand_q-->
                </body>
                <!--End of right_hand_m-->
              </body>
              <!--End of right_hand_i-->
            </body>
            <!--End of right_hand_virtual_i-->
          </body>
          <!--End of right_hand_e2-->
        </body>
        <!--End of hand base-->
      </body>
      <!--End of hand base-->
    </body>
    <!--End of base-->
    </body>
  </worldbody>
  <contact>
    <exclude body1="right_hand_e1" body2="right_hand_z"/>
    <exclude body1="right_hand_base_link" body2="right_hand_e1"/>
    <exclude body1="right_hand_e1" body2="right_hand_a"/>
    <exclude body1="right_hand_e1" body2="right_hand_b"/>
    <exclude body1="right_hand_e1" body2="right_hand_e2"/>
    <exclude body1="right_hand_e1" body2="right_hand_virtual_l"/>
    <exclude body1="right_hand_e1" body2="right_hand_virtual_k"/>
    <exclude body1="right_hand_e1" body2="right_hand_virtual_i"/>
    <exclude body1="right_hand_e1" body2="right_hand_virtual_j"/>
    <exclude body1="right_hand_virtual_l" body2="right_hand_l"/>
    <exclude body1="right_hand_virtual_k" body2="right_hand_k"/>
    <exclude body1="right_hand_virtual_i" body2="right_hand_i"/>
    <exclude body1="right_hand_virtual_j" body2="right_hand_j"/>
    <exclude body1="right_hand_virtual_l" body2="right_hand_virtual_k"/>
    <exclude body1="right_hand_virtual_k" body2="right_hand_virtual_i"/>
    <exclude body1="right_hand_virtual_i" body2="right_hand_virtual_j"/>
  </contact>
  <sensor>
    <force name="force_ee" site="ft_frame"/>
    <torque name="torque_ee" site="ft_frame"/>
  </sensor>
</mujoco>