<mujoco model="g1">
    <compiler angle="radian" autolimits="true"/>

  <visual>
    <global ellipsoidinertia="true"/>
  </visual>

  <default>
    <default class="visual">
        <geom group="1" type="mesh" contype="0" conaffinity="0" density="0" material="metallic"/>
    </default>
    <default class="collision">
        <geom group="0" type="mesh"/>
    </default>
    <default class="foot">
        <geom group="0" type="sphere" size="0.001"/>
    </default>
    <default class="arm_joint">
        <motor ctrllimited="true" ctrlrange="-1000 1000"/>
        <!-- <joint damping="7.7" armature="1.0" frictionloss="0.2"/> -->
    </default>
    <default class="hand_joint">
      <site rgba="1 0 0 1" size="0.01" group="5"/>
      <joint damping="7.7" armature="1.0" frictionloss="0.2"/>
      <motor ctrllimited="true" ctrlrange="-0.7 0.7"/>
    </default>
    <default class="g1">
      <site rgba="1 0 0 1" size="0.01" group="5"/>
      <joint damping="7.7" armature="1.0" frictionloss="0.2"/>
    </default>
  </default>

  <asset>
    <material name="metallic" rgba="0.7 0.7 0.7 1"/>
    <material name="black" rgba="0.2 0.2 0.2 1"/>

    <mesh name="pelvis" file="./meshes/pelvis.STL"/>
    <mesh name="pelvis_contour_link" file="./meshes/pelvis_contour_link.STL"/>
    <mesh name="l_hip_pitch_link" file="./meshes/left_hip_pitch_link.STL"/>
    <mesh name="l_hip_roll_link" file="./meshes/left_hip_roll_link.STL"/>
    <mesh name="l_hip_yaw_link" file="./meshes/left_hip_yaw_link.STL"/>
    <mesh name="l_knee_link" file="./meshes/left_knee_link.STL"/>
    <mesh name="l_ankle_pitch_link" file="./meshes/left_ankle_pitch_link.STL"/>
    <mesh name="l_ankle_roll_link" file="./meshes/left_ankle_roll_link.STL"/>
    <mesh name="r_hip_pitch_link" file="./meshes/right_hip_pitch_link.STL"/>
    <mesh name="r_hip_roll_link" file="./meshes/right_hip_roll_link.STL"/>
    <mesh name="r_hip_yaw_link" file="./meshes/right_hip_yaw_link.STL"/>
    <mesh name="r_knee_link" file="./meshes/right_knee_link.STL"/>
    <mesh name="r_ankle_pitch_link" file="./meshes/right_ankle_pitch_link.STL"/>
    <mesh name="r_ankle_roll_link" file="./meshes/right_ankle_roll_link.STL"/>
    <mesh name="torso_link" file="./meshes/torso_link.STL"/>
    <mesh name="head_link" file="./meshes/head_link.STL"/>
    <mesh name="l_shoulder_pitch_link" file="./meshes/left_shoulder_pitch_link.STL"/>
    <mesh name="l_shoulder_roll_link" file="./meshes/left_shoulder_roll_link.STL"/>
    <mesh name="l_shoulder_yaw_link" file="./meshes/left_shoulder_yaw_link.STL"/>
    <mesh name="l_elbow_pitch_link" file="./meshes/left_elbow_pitch_link.STL"/>
    <mesh name="l_elbow_roll_link" file="./meshes/left_elbow_roll_link.STL"/>
    <mesh name="r_shoulder_pitch_link" file="./meshes/right_shoulder_pitch_link.STL"/>
    <mesh name="r_shoulder_roll_link" file="./meshes/right_shoulder_roll_link.STL"/>
    <mesh name="r_shoulder_yaw_link" file="./meshes/right_shoulder_yaw_link.STL"/>
    <mesh name="r_elbow_pitch_link" file="./meshes/right_elbow_pitch_link.STL"/>
    <mesh name="r_elbow_roll_link" file="./meshes/right_elbow_roll_link.STL"/>
    <mesh name="logo_link" file="./meshes/logo_link.STL"/>
  </asset>

  <worldbody>
    <light name="spotlight" mode="targetbodycom" target="pelvis" pos="0 -6 4" cutoff="30"/>

    <body name="base">
    <freejoint/>
    <!-- Pelvis -->
    <body name="pelvis" pos="0 0 0.755">
      <inertial pos="0 0 -0.07605" quat="1 0 -0.000405289 0" mass="2.86" diaginertia="0.0079143 0.0069837 0.0059404"/>
      <!-- <freejoint name="floating_base_joint"/> -->
      <light name="tracking" mode="trackcom" pos="0 0 2"/>
      <geom type="mesh" class="visual" mesh="pelvis"/>
      <geom type="mesh" mesh="pelvis" class="collision"/>
      <geom type="mesh" class="visual" material="black" mesh="pelvis_contour_link"/>
      <!-- Torso -->
      <body name="torso_link">
        <inertial pos="0.00187791 0.00229457 0.208747" quat="0.999957 0.00624375 -0.00636707 -0.0026338" mass="7.52036"
          diaginertia="0.12848 0.111753 0.0350394"/>
        <site name="imu" pos="-0.04233868314 0.00166 0.152067"/>
        <site name="head" pos="0 0 0.5"/>
        <joint name="torso_joint" axis="0 0 1" range="-2.618 2.618"/>
        <geom type="mesh" class="visual" mesh="torso_link"/>
        <geom type="mesh" mesh="torso_link" class="collision"/>
        <geom type="mesh" class="visual" material="black" mesh="head_link"/>
        <geom type="mesh" mesh="head_link" class="collision"/>
        <geom type="mesh" class="visual" material="black" mesh="logo_link"/>
        <geom type="mesh" mesh="logo_link" class="collision"/>
        <!-- Start of right arm -->
        <body name="right_arm_mount">
        <site name="right_center" pos="0 0 0" size="0.01" rgba="1 0.3 0.3 1" group="2"/>
            <body name="r_shoulder_pitch_link" pos="-0.0025 -0.10396 0.25928" quat="0.990268 -0.139172 0 0">
            <inertial pos="-0.001431 -0.048811 0.001304" quat="0.588396 0.786417 -0.0523639 0.180543" mass="0.713"
                diaginertia="0.000466421 0.000440181 0.000410999"/>
            <joint class="arm_joint" name="r_shoulder_pitch_joint" axis="0 1 0" range="-2.9671 2.7925"/>
            <geom type="mesh" class="visual" mesh="r_shoulder_pitch_link"/>
            <geom type="mesh" mesh="r_shoulder_pitch_link" class="collision"/>
            <body name="r_shoulder_roll_link" pos="0 -0.052 0" quat="0.990268 0.139172 0 0">
                <inertial pos="-0.003415 -0.006955 -0.064598" quat="0.707282 0.00575207 0.0105364 0.70683" mass="0.642"
                diaginertia="0.000683514 0.000616029 0.000372857"/>
                <joint class="arm_joint"  name="r_shoulder_roll_joint" axis="1 0 0" range="-2.2515 1.5882"/>
                <geom type="mesh" class="visual" mesh="r_shoulder_roll_link"/>
                <geom size="0.03 0.015" pos="-0.004 -0.006 -0.053" type="cylinder" class="collision"/>
                <body name="r_shoulder_yaw_link" pos="-0.00354 -0.0062424 -0.1032">
                <inertial pos="0.000375 0.00444 -0.072374" quat="0.42613 0.00985482 -0.0374183 0.903834" mass="0.713"
                    diaginertia="0.000977874 0.000964661 0.000379065"/>
                <joint class="arm_joint"  name="r_shoulder_yaw_joint" axis="0 0 1" range="-2.618 2.618"/>
                <geom type="mesh" class="visual" mesh="r_shoulder_yaw_link"/>
                <geom type="mesh" mesh="r_shoulder_yaw_link" class="collision"/>
                <body name="r_elbow_pitch_link" pos="0 -0.00189 -0.0855">
                    <inertial pos="0.064497 -0.002873 0" quat="0.401069 0.400893 0.582495 0.582347" mass="0.601"
                    diaginertia="0.00049549 0.0004712 0.00025371"/>
                    <joint class="arm_joint"  name="r_elbow_pitch_joint" axis="0 1 0" range="-0.2268 3.4208"/>
                    <geom type="mesh" class="visual" mesh="r_elbow_pitch_link"/>
                    <geom type="mesh" mesh="r_elbow_pitch_link" class="collision"/>
                    <body name="r_elbow_roll_link" pos="0.1 0 0">
                    <inertial pos="0.133814 -0.00147121 0.000265832" quat="0.506502 0.498782 0.497877 0.496781"
                        mass="0.50826" diaginertia="0.00239763 0.00226639 0.000285577"/>
                    <joint class="arm_joint" name="r_elbow_roll_joint" axis="1 0 0" range="-2.0943 2.0943"/>
                    <geom type="mesh" class="visual" mesh="r_elbow_roll_link"/>
                    <geom type="mesh" mesh="r_elbow_roll_link" class="collision"/>

                    <!-- right eef -->
                    <body name="right_eef" pos="0 0 0" quat="1 0 0 0">
                        <body name="right_mount" quat="0 0 1 0"/>
                        <body name="right_hand_eef" pos="0 0 0"/>
                    </body>
                    </body>
                </body>
                </body>
            </body>
            </body>
        </body>
        <!-- End of right arm -->
        <!-- Left arm -->
        <body name="left_arm_mount">
        <site name="left_center" pos="0 0 0" size="0.01" rgba="1 0.3 0.3 1" group="2"/>
            <body name="l_shoulder_pitch_link" pos="-0.0025 0.10396 0.25928" quat="0.990268 0.139172 0 0">
            <inertial pos="-0.001431 0.048811 0.001304" quat="0.786417 0.588396 -0.180543 0.0523639" mass="0.713"
                diaginertia="0.000466421 0.000440181 0.000410999"/>
            <joint class="arm_joint" name="l_shoulder_pitch_joint" axis="0 1 0" range="-2.9671 2.7925"/>
            <geom type="mesh" class="visual" mesh="l_shoulder_pitch_link"/>
            <geom type="mesh" mesh="l_shoulder_pitch_link" class="collision"/>
            <body name="l_shoulder_roll_link" pos="0 0.052 0" quat="0.990268 -0.139172 0 0">
                <inertial pos="-0.003415 0.006955 -0.064598" quat="0.70683 0.0105364 0.00575207 0.707282" mass="0.642"
                diaginertia="0.000683514 0.000616029 0.000372857"/>
                <joint class="arm_joint" name="l_shoulder_roll_joint" axis="1 0 0" range="-1.5882 2.2515"/>
                <geom type="mesh" class="visual" mesh="l_shoulder_roll_link"/>
                <geom size="0.03 0.015" pos="-0.004 0.006 -0.053" type="cylinder" class="collision"/>
                <body name="l_shoulder_yaw_link" pos="-0.00354 0.0062424 -0.1032">
                <inertial pos="0.000375 -0.00444 -0.072374" quat="0.903834 -0.0374183 0.00985482 0.42613" mass="0.713"
                    diaginertia="0.000977874 0.000964661 0.000379065"/>
                <joint class="arm_joint" name="l_shoulder_yaw_joint" axis="0 0 1" range="-2.618 2.618"/>
                <geom type="mesh" class="visual" mesh="l_shoulder_yaw_link"/>
                <geom type="mesh" mesh="l_shoulder_yaw_link" class="collision"/>
                <body name="l_elbow_pitch_link" pos="0 0.00189 -0.0855">
                    <inertial pos="0.064497 0.002873 0" quat="0.582347 0.582495 0.400893 0.401069" mass="0.601"
                    diaginertia="0.00049549 0.0004712 0.00025371"/>
                    <joint class="arm_joint" name="l_elbow_pitch_joint" axis="0 1 0" range="-0.2268 3.4208"/>
                    <geom type="mesh" class="visual" mesh="l_elbow_pitch_link"/>
                    <geom type="mesh" mesh="l_elbow_pitch_link" class="collision"/>
                    <body name="l_elbow_roll_link" pos="0.1 0 0">
                    <inertial pos="0.133814 0.00147121 0.000265832" quat="0.496781 0.497877 0.498782 0.506502"
                        mass="0.50826" diaginertia="0.00239763 0.00226639 0.000285577"/>
                    <joint class="arm_joint" name="l_elbow_roll_joint" axis="1 0 0" range="-2.0943 2.0943"/>
                    <geom type="mesh" class="visual" mesh="l_elbow_roll_link"/>
                    <geom type="mesh" mesh="l_elbow_roll_link" class="collision"/>
                    <!-- left eef -->
                    <body name="left_eef" pos="0 0 0" quat="1 0 0 0">
                        <body name="left_mount" quat="0 0 1 0"/>
                        <body name="left_hand_eef" pos="0 0 0"/>
                    </body>
                    </body>
                </body>
                </body>
            </body>
            </body>
        </body>

        <!-- End of left arm -->
      </body>
      <!-- End of torso -->
 <body name="lower_body">
      <!-- Left hip -->
      <body name="l_hip_pitch_link" pos="0 0.06445 -0.1027" quat="0.984807 0 -0.17365 0">
        <inertial pos="0.001962 0.049392 -0.000941" quat="0.420735 0.907025 -0.0155675 -0.00670646" mass="1.299"
          diaginertia="0.00138785 0.000955478 0.00086947"/>
        <joint name="l_leg_hip_pitch_joint" axis="0 1 0" range="-2.35 3.05"/>
        <geom type="mesh" class="visual" material="black" mesh="l_hip_pitch_link"/>
        <geom type="mesh" mesh="l_hip_pitch_link" class="collision"/>
        <body name="l_hip_roll_link" pos="0 0.0523 0">
          <inertial pos="0.024757 -0.001036 -0.086323" quat="0.977498 -0.00692636 0.210181 0.0165269" mass="1.446"
            diaginertia="0.00244106 0.00230425 0.00142899"/>
          <joint name="l_leg_hip_roll_joint" axis="1 0 0" range="-0.26 2.53"/>
          <geom type="mesh" class="visual" mesh="l_hip_roll_link"/>
          <geom type="mesh" mesh="l_hip_roll_link" class="collision"/>
          <body name="l_hip_yaw_link" pos="0.01966 -0.0012139 -0.1241">
            <inertial pos="-0.053554 -0.011477 -0.14067" quat="0.645099 0.15885 0.202109 0.71956" mass="2.052"
              diaginertia="0.0114475 0.0107868 0.00214501"/>
            <joint name="l_leg_hip_yaw_joint" axis="0 0 1" range="-2.75 2.75"/>
            <geom type="mesh" class="visual" mesh="l_hip_yaw_link"/>
            <geom type="mesh" mesh="l_hip_yaw_link" class="collision"/>
            <body name="l_knee_link" pos="-0.078292 -0.0017335 -0.177225" quat="0.967714 0 0.252052 0">
              <inertial pos="0.005505 0.006534 -0.116629" quat="0.799234 -0.0128894 0.0354278 0.599836" mass="2.252"
                diaginertia="0.0127418 0.0124382 0.00192524"/>
              <joint name="l_leg_knee_joint" axis="0 1 0" range="-0.33489 2.5449"/>
              <geom type="mesh" class="visual" mesh="l_knee_link"/>
              <geom size="0.015 0.075" pos="0.007 0.005 -0.15" type="cylinder" class="collision"/>
              <body name="l_ankle_pitch_link" pos="0 0.0040687 -0.30007" quat="0.99678 0 -0.0801788 0">
                <inertial pos="-0.007269 0 0.011137" quat="0.603053 0.369225 0.369225 0.603053" mass="0.074"
                  diaginertia="1.89e-05 1.40805e-05 6.9195e-06"/>
                <joint name="l_leg_ankle_pitch_joint" axis="0 1 0" range="-0.68 0.73"/>
                <geom type="mesh" class="visual" mesh="l_ankle_pitch_link"/>
                <geom type="mesh" mesh="l_ankle_pitch_link" class="collision"/>
                <body name="l_ankle_roll_link" pos="0 0 -0.017558">
                  <site name="l_foot" pos="0 0 0"/>
                  <inertial pos="0.024762 2e-05 -0.012526" quat="0.000771333 0.734476 0.000921291 0.678634" mass="0.391"
                    diaginertia="0.00110394 0.0010657 0.000149255"/>
                  <joint name="l_leg_ankle_roll_joint" axis="1 0 0" range="-0.2618 0.2618"/>
                  <geom type="mesh" class="visual" material="black" mesh="l_ankle_roll_link"/>
                  <geom pos="-0.06 0.02 -0.03" class="foot"/>
                  <geom pos="-0.06 -0.02 -0.03" class="foot"/>
                  <geom pos="0.13 0.02 -0.03" class="foot"/>
                  <geom pos="0.13 -0.02 -0.03" class="foot"/>
                </body>
              </body>
            </body>
          </body>
        </body>
      </body>
      <!-- Right hip -->
      <body name="r_hip_pitch_link" pos="0 -0.06445 -0.1027" quat="0.984807 0 -0.17365 0">
        <inertial pos="0.001962 -0.049392 -0.000941" quat="0.907025 0.420735 0.00670646 0.0155675" mass="1.299"
          diaginertia="0.00138785 0.000955478 0.00086947"/>
        <joint name="r_leg_hip_pitch_joint" axis="0 1 0" range="-2.35 3.05"/>
        <geom type="mesh" class="visual" material="black" mesh="r_hip_pitch_link"/>
        <geom type="mesh" mesh="r_hip_pitch_link" class="collision"/>
        <body name="r_hip_roll_link" pos="0 -0.0523 0">
          <inertial pos="0.024757 0.001036 -0.086323" quat="0.977498 0.00692636 0.210181 -0.0165269" mass="1.446"
            diaginertia="0.00244106 0.00230425 0.00142899"/>
          <joint name="r_leg_hip_roll_joint" axis="1 0 0" range="-2.53 0.26"/>
          <geom type="mesh" class="visual" mesh="r_hip_roll_link"/>
          <geom type="mesh" mesh="r_hip_roll_link" class="collision"/>
          <body name="r_hip_yaw_link" pos="0.01966 0.0012139 -0.1241">
            <inertial pos="-0.053554 0.011477 -0.14067" quat="0.71956 0.202109 0.15885 0.645099" mass="2.052"
              diaginertia="0.0114475 0.0107868 0.00214501"/>
            <joint name="r_leg_hip_yaw_joint" axis="0 0 1" range="-2.75 2.75"/>
            <geom type="mesh" class="visual" mesh="r_hip_yaw_link"/>
            <geom type="mesh" mesh="r_hip_yaw_link" class="collision"/>
            <body name="r_knee_link" pos="-0.078292 0.0017335 -0.177225" quat="0.967714 0 0.252052 0">
              <inertial pos="0.005505 -0.006534 -0.116629" quat="0.599836 0.0354278 -0.0128894 0.799234" mass="2.252"
                diaginertia="0.0127418 0.0124382 0.00192524"/>
              <joint name="r_leg_knee_joint" axis="0 1 0" range="-0.33489 2.5449"/>
              <geom type="mesh" class="visual" mesh="r_knee_link"/>
              <geom size="0.015 0.075" pos="0.007 -0.005 -0.15" type="cylinder" class="collision"/>
              <body name="r_ankle_pitch_link" pos="0 -0.0040687 -0.30007" quat="0.99678 0 -0.0801788 0">
                <inertial pos="-0.007269 0 0.011137" quat="0.603053 0.369225 0.369225 0.603053" mass="0.074"
                  diaginertia="1.89e-05 1.40805e-05 6.9195e-06"/>
                <joint name="r_leg_ankle_pitch_joint" axis="0 1 0" range="-0.68 0.73"/>
                <geom type="mesh" class="visual" mesh="r_ankle_pitch_link"/>
                <geom type="mesh" mesh="r_ankle_pitch_link" class="collision"/>
                <body name="r_ankle_roll_link" pos="0 0 -0.017558">
                  <site name="r_foot" pos="0 0 0"/>
                  <inertial pos="0.024762 -2e-05 -0.012526" quat="-0.000771333 0.734476 -0.000921291 0.678634"
                    mass="0.391" diaginertia="0.00110394 0.0010657 0.000149255"/>
                  <joint name="r_leg_ankle_roll_joint" axis="1 0 0" range="-0.2618 0.2618"/>
                  <geom type="mesh" class="visual" material="black" mesh="r_ankle_roll_link"/>
                  <geom pos="-0.06 0.02 -0.03" class="foot"/>
                  <geom pos="-0.06 -0.02 -0.03" class="foot"/>
                  <geom pos="0.13 0.02 -0.03" class="foot"/>
                  <geom pos="0.13 -0.02 -0.03" class="foot"/>
                </body>
              </body>
            </body>
          </body>
        </body>
      </body>
      </body>
      <!-- Lower  -->
    </body>
    <!-- End of pelvis -->
    </body>
  </worldbody>

  <actuator>
    <motor class="g1" name="l_leg_hip_pitch_joint" joint="l_leg_hip_pitch_joint" ctrllimited="true" ctrlrange="-20 20"/>
    <motor class="g1" name="l_leg_hip_roll_joint" joint="l_leg_hip_roll_joint" ctrllimited="true" ctrlrange="-20 20"/>
    <motor class="g1" name="l_leg_hip_yaw_joint" joint="l_leg_hip_yaw_joint" ctrllimited="true" ctrlrange="-20 20"/>
    <motor class="g1" name="l_leg_knee_joint" joint="l_leg_knee_joint" ctrllimited="true" ctrlrange="-139 139"/>
    <motor class="g1" name="l_leg_ankle_pitch_joint" joint="l_leg_ankle_pitch_joint" ctrllimited="true" ctrlrange="-40 40"/>
    <motor class="g1" name="l_leg_ankle_roll_joint" joint="l_leg_ankle_roll_joint" ctrllimited="true" ctrlrange="-40 40"/>

    <motor class="g1" name="r_leg_hip_pitch_joint" joint="r_leg_hip_pitch_joint" ctrllimited="true" ctrlrange="-20 20"/>
    <motor class="g1" name="r_leg_hip_roll_joint" joint="r_leg_hip_roll_joint" ctrllimited="true" ctrlrange="-20 20"/>
    <motor class="g1" name="r_leg_hip_yaw_joint" joint="r_leg_hip_yaw_joint" ctrllimited="true" ctrlrange="-20 20"/>
    <motor class="g1" name="r_leg_knee_joint" joint="r_leg_knee_joint" ctrllimited="true" ctrlrange="-139 139"/>
    <motor class="g1" name="r_leg_ankle_pitch_joint" joint="r_leg_ankle_pitch_joint" ctrllimited="true" ctrlrange="-40 40"/>
    <motor class="g1" name="r_leg_ankle_roll_joint" joint="r_leg_ankle_roll_joint" ctrllimited="true" ctrlrange="-40 40"/>

    <motor class="g1" name="torso_joint" joint="torso_joint" ctrllimited="true" ctrlrange="-20 20"/>


    <motor class="arm_joint" name="r_shoulder_pitch_joint" joint="r_shoulder_pitch_joint"/>
    <motor class="arm_joint" name="r_shoulder_roll_joint" joint="r_shoulder_roll_joint"/>
    <motor class="arm_joint" name="r_shoulder_yaw_joint" joint="r_shoulder_yaw_joint"/>
    <motor class="arm_joint" name="r_elbow_pitch_joint" joint="r_elbow_pitch_joint"/>
    <motor class="arm_joint" name="r_elbow_roll_joint" joint="r_elbow_roll_joint"/>

    <motor class="arm_joint" name="l_shoulder_pitch_joint" joint="l_shoulder_pitch_joint"/>
    <motor class="arm_joint" name="l_shoulder_roll_joint" joint="l_shoulder_roll_joint"/>
    <motor class="arm_joint" name="l_shoulder_yaw_joint" joint="l_shoulder_yaw_joint"/>
    <motor class="arm_joint" name="l_elbow_pitch_joint" joint="l_elbow_pitch_joint"/>
    <motor class="arm_joint" name="l_elbow_roll_joint" joint="l_elbow_roll_joint"/>

  </actuator>

  <sensor>
    <gyro name="imu-angular-velocity" site="imu" cutoff="34.9"/>
    <accelerometer name="imu-linear-acceleration" site="imu" cutoff="157"/>
    <framequat name="imu-body-quat" objtype="site" objname="imu"/>
  </sensor>
</mujoco>
