<mujoco model="jaco_v2">
    <actuator>
        <!-- Physical limits of the actuator.  This is hacky and not part of original urdf -->
        <motor ctrllimited="true" ctrlrange="-80.0 80.0" joint="j2s7s300_joint_1" name="torq_j1"/>
        <motor ctrllimited="true" ctrlrange="-80.0 80.0" joint="j2s7s300_joint_2" name="torq_j2"/>
        <motor ctrllimited="true" ctrlrange="-80.0 80.0" joint="j2s7s300_joint_3" name="torq_j3"/>
        <motor ctrllimited="true" ctrlrange="-80.0 80.0" joint="j2s7s300_joint_4" name="torq_j4"/>
        <motor ctrllimited="true" ctrlrange="-80.0 80.0" joint="j2s7s300_joint_5" name="torq_j5"/>
        <motor ctrllimited="true" ctrlrange="-12.0 12.0" joint="j2s7s300_joint_6" name="torq_j6"/>
        <motor ctrllimited="true" ctrlrange="-12.0 12.0" joint="j2s7s300_joint_7" name="torq_j7"/>
    </actuator>
    <asset>
        <mesh file="meshes/pedestal.stl" name="pedestal"/>
        <mesh name="base" file="meshes/base.stl" />
        <mesh name="shoulder" file="meshes/shoulder.stl" />
        <mesh name="ring_big" file="meshes/ring_big.stl" />
        <mesh name="arm_half_1" file="meshes/arm_half_1.stl" />
        <mesh name="arm_half_2" file="meshes/arm_half_2.stl" />
        <mesh name="forearm" file="meshes/forearm.stl" />
        <mesh name="ring_small" file="meshes/ring_small.stl" />
        <mesh name="wrist_spherical_1" file="meshes/wrist_spherical_1.stl" />
        <mesh name="wrist_spherical_2" file="meshes/wrist_spherical_2.stl" />
    </asset>
    <worldbody>
        <body name="base" pos="0 0 0">

            <!-- robot view -->
            <camera mode="fixed" name="robotview" pos="1.0 0 0.4" quat="0.653 0.271 0.271 0.653"/>
            <inertial diaginertia="0 0 0" mass="0" pos="0 0 0"/>
            <body name="controller_box" pos="0 0 0">
                <inertial diaginertia="1.71363 1.27988 0.809981" mass="46.64" pos="-0.325 0 -0.38"/>
                <geom pos="-0.325 0 -0.38" size="0.11 0.2 0.265" type="box" name="controller_box_col"/>
            </body>
            <body name="pedestal_feet" pos="0 0 0">
                <inertial diaginertia="8.16095 9.59375 15.0785" mass="167.09" pos="-0.1225 0 -0.758"/>
                <geom pos="-0.1225 0 -0.758" size="0.385 0.35 0.155" type="box" name="pedestal_feet_col"/>
            </body>
            <body name="torso" pos="0 0 0">
                <inertial diaginertia="1e-08 1e-08 1e-08" mass="0.0001" pos="0 0 0"/>
                <geom conaffinity="0" contype="0" group="1" rgba="0.2 0.2 0.2 1" size="0.05 0.05 0.05" type="box" name="torso_col"/>
            </body>
            <body name="pedestal" pos="0 0 0">
                <inertial diaginertia="6.0869 5.81635 4.20915" mass="60.864" pos="0 0 0" quat="0.659267 -0.259505 -0.260945 0.655692"/>
                <geom conaffinity="0" contype="0" group="1" mesh="pedestal" pos="0.26 0.345 -0.91488" quat="0.5 0.5 -0.5 -0.5" rgba="0.2 0.2 0.2 1" type="mesh" name="pedestal_col1"/>
                <geom pos="-0.02 0 -0.29" rgba="0.2 0.2 0.2 1" size="0.18 0.31" type="cylinder" name="pedestal_col2"/>
            </body>
            <!--<inertial pos="0 0 0.05" mass="4" diaginertia="0.4 0.4 0.4" />-->
            <geom type="mesh" contype="0" conaffinity="0" group="1" rgba="0 0 0 1" mesh="base" />
            <geom type="mesh" rgba="0 0 0 1" mesh="base" />
            <body name="j2s7s300_link_1" pos="0 0 0.15675" quat="0 0 1 0">
                <inertial pos="0 -0.002 -0.0605" mass="0.7477" diaginertia="0.00152032 0.00152032 0.00059816" />
                <joint name="j2s7s300_joint_1" pos="0 0 0" axis="0 0 1" limited="true" range="-6.28319 6.28319" damping="0.1"/>
                <geom type="mesh" contype="0" conaffinity="0" group="1" rgba="0 0 0 1" mesh="shoulder" />
                <geom type="mesh" contype="0" conaffinity="0" group="1" rgba="1 1 1 1" mesh="ring_big" />
                <geom type="mesh" rgba="0 0 0 1" mesh="shoulder" name="s_collision"/>
                <body name="j2s7s300_link_2" pos="0 0.0016 -0.11875" quat="0 0 -0.707107 0.707107">
                    <inertial pos="0 -0.103563 0" quat="0.707107 0.707107 0 0" mass="0.8447" diaginertia="0.00247074 0.00247074 0.000380115" />
                    <joint name="j2s7s300_joint_2" pos="0 0 0" axis="0 0 1" limited="true" range="0.820305 5.46288" damping="0.1"/>
                    <geom type="mesh" contype="0" conaffinity="0" group="1" rgba="0 0 0 1" mesh="arm_half_1" />
                    <geom type="mesh" contype="0" conaffinity="0" group="1" rgba="1 1 1 1" mesh="ring_big" />
                    <geom type="mesh" rgba="0 0 0 1" mesh="arm_half_1" name="ah1_collision"/>
                    <body name="j2s7s300_link_3" pos="0 -0.205 0" quat="0.707107 -0.707107 0 0">
                        <inertial pos="0 0 -0.102245" mass="0.8447" diaginertia="0.00247074 0.00247074 0.000380115" />
                        <joint name="j2s7s300_joint_3" pos="0 0 0" axis="0 0 1" limited="true" range="-6.28319 6.28319" damping="0.1"/>
                        <geom type="mesh" contype="0" conaffinity="0" group="1" rgba="0 0 0 1" mesh="arm_half_2" />
                        <geom type="mesh" contype="0" conaffinity="0" group="1" rgba="1 1 1 1" mesh="ring_big" />
                        <geom type="mesh" rgba="0 0 0 1" mesh="arm_half_2" name="ah2_collision"/>
                        <body name="j2s7s300_link_4" pos="0 0 -0.205" quat="0 0 0.707107 0.707107">
                            <inertial pos="0 0.081 -0.0086" quat="0.707107 0.707107 0 0" mass="0.6763" diaginertia="0.00142022 0.00142022 0.000304335" />
                            <joint name="j2s7s300_joint_4" pos="0 0 0" axis="0 0 1" limited="true" range="0.523599 5.75959" damping="0.1"/>
                            <geom type="mesh" contype="0" conaffinity="0" group="1" rgba="0 0 0 1" mesh="forearm" />
                            <geom type="mesh" contype="0" conaffinity="0" group="1" rgba="1 1 1 1" mesh="ring_small" />
                            <geom type="mesh" rgba="0 0 0 1" mesh="forearm" name="f_collision"/>
                            <body name="j2s7s300_link_5" pos="0 0.2073 -0.0114" quat="0 0 -0.707107 0.707107">
                                <inertial pos="0 0.00288489 -0.0541933" mass="0.463" diaginertia="0.000432132 0.000432132 9.26e-05" />
                                <joint name="j2s7s300_joint_5" pos="0 0 0" axis="0 0 1" limited="true" range="-6.28319 6.28319" damping="0.1"/>
                                <geom type="mesh" contype="0" conaffinity="0" group="1" rgba="0 0 0 1" mesh="wrist_spherical_1" />
                                <geom type="mesh" contype="0" conaffinity="0" group="1" rgba="1 1 1 1" mesh="ring_small" />
                                <geom type="mesh" rgba="0 0 0 1" mesh="wrist_spherical_1" name="ws1_collision"/>
                                <body name="j2s7s300_link_6" pos="0 0 -0.10375" quat="0 0 0.707107 0.707107">
                                    <inertial pos="0 0.0497209 -0.00285628" quat="0.707107 0.707107 0 0" mass="0.463" diaginertia="0.000432132 0.000432132 9.26e-05" />
                                    <joint name="j2s7s300_joint_6" pos="0 0 0" axis="0 0 1" limited="true" range="1.13446 5.14872" damping="0.01"/>
                                    <geom type="mesh" contype="0" conaffinity="0" group="1" rgba="0 0 0 1" mesh="wrist_spherical_2" />
                                    <geom type="mesh" contype="0" conaffinity="0" group="1" rgba="1 1 1 1" mesh="ring_small" />
                                    <geom type="mesh" rgba="0 0 0 1" mesh="wrist_spherical_2" name="ws2_collision"/>
                                    <body name="j2s7s300_link_7" pos="0 0.10375 0" quat="0 0 -0.707107 0.707107">
                                        <inertial pos="0 0 -0.06" quat="0.5 0.5 -0.5 0.5" mass="0.99" diaginertia="0.0005816 0.000345324 0.000345324" />
                                        <joint name="j2s7s300_joint_7" pos="0 0 0" axis="0 0 1" limited="true" range="-6.28319 6.28319" damping="0.01"/>
                                        <!--<geom type="mesh" contype="0" conaffinity="0" group="1" rgba="0.792157 0.819608 0.933333 1" mesh="hand_3finger" />
                                        <geom type="mesh" contype="0" conaffinity="0" group="1" rgba="0.792157 0.819608 0.933333 1" mesh="ring_small" />
                                        <geom type="mesh" rgba="0.792157 0.819608 0.933333 1" mesh="hand_3finger" />-->
                                        <body name="right_hand" pos="0 0 0" quat="0 1 0 0">
                                                <!-- This sites were added for visualization. -->
                                                <site name="ee" pos="0 0 0" size="0.01 0.01 0.01" rgba="0 0 1 1" type="sphere" group="1"/>
                                                <site name="ee_x" pos="0 0 0" size="0.005 .1"  quat="0.707105 0.707108 0 0 " rgba="1 0 0 0" type="cylinder" group="1"/>
                                                <site name="ee_z" pos="0 0 0" size="0.005 .1" quat="0.707105 0 0 0.707108" rgba="0 0 1 0" type="cylinder" group="1"/>
                                                <site name="ee_y" pos="0 0 0" size="0.005 .1" quat="0.707105 0 0.707108 0 " rgba="0 1 0 0" type="cylinder" group="1"/>
                                                  <!-- To add gripper -->
                                              </body>
                                        <!--
                                        <body name="j2s7s300_link_finger_1" pos="0.00279 0.03126 -0.11467" quat="0.379408 -0.662973 -0.245899 0.596699">
                                            <inertial pos="0.022 0 0" mass="0.01" diaginertia="7.89997e-07 7.89997e-07 8e-08" />
                                            <joint name="j2s7s300_joint_finger_1" pos="0 0 0" axis="0 0 1" limited="true" range="0 1.51" />
                                            <geom type="mesh" contype="0" conaffinity="0" group="1" rgba="0.792157 0.819608 0.933333 1" mesh="finger_proximal" />
                                            <geom type="mesh" rgba="0.792157 0.819608 0.933333 1" mesh="finger_proximal" />
                                            <body name="j2s7s300_link_finger_tip_1" pos="0.044 -0.003 0">
                                                <inertial pos="0.022 0 0" mass="0.01" diaginertia="7.89997e-07 7.89997e-07 8e-08" />
                                                <joint name="j2s7s300_joint_finger_tip_1" pos="0 0 0" axis="0 0 1" limited="true" range="0 2" />
                                                <geom type="mesh" contype="0" conaffinity="0" group="1" rgba="0.792157 0.819608 0.933333 1" mesh="finger_distal" />
                                                <geom type="mesh" rgba="0.792157 0.819608 0.933333 1" mesh="finger_distal" />
                                            </body>
                                        </body>
                                        <body name="j2s7s300_link_finger_2" pos="0.02226 -0.02707 -0.11482" quat="0.659653 -0.37146 0.601679 -0.254671">
                                            <inertial pos="0.022 0 0" mass="0.01" diaginertia="7.89997e-07 7.89997e-07 8e-08" />
                                            <joint name="j2s7s300_joint_finger_2" pos="0 0 0" axis="0 0 1" limited="true" range="0 1.51" />
                                            <geom type="mesh" contype="0" conaffinity="0" group="1" rgba="0.792157 0.819608 0.933333 1" mesh="finger_proximal" />
                                            <geom type="mesh" rgba="0.792157 0.819608 0.933333 1" mesh="finger_proximal" />
                                            <body name="j2s7s300_link_finger_tip_2" pos="0.044 -0.003 0">
                                                <inertial pos="0.022 0 0" mass="0.01" diaginertia="7.89997e-07 7.89997e-07 8e-08" />
                                                <joint name="j2s7s300_joint_finger_tip_2" pos="0 0 0" axis="0 0 1" limited="true" range="0 2" />
                                                <geom type="mesh" contype="0" conaffinity="0" group="1" rgba="0.792157 0.819608 0.933333 1" mesh="finger_distal" />
                                                <geom type="mesh" rgba="0.792157 0.819608 0.933333 1" mesh="finger_distal" />
                                            </body>
                                        </body>
                                        <body name="j2s7s300_link_finger_3" pos="-0.02226 -0.02707 -0.11482" quat="0.601679 -0.254671 0.659653 -0.37146">
                                            <inertial pos="0.022 0 0" mass="0.01" diaginertia="7.89997e-07 7.89997e-07 8e-08" />
                                            <joint name="j2s7s300_joint_finger_3" pos="0 0 0" axis="0 0 1" limited="true" range="0 1.51" />
                                            <geom type="mesh" contype="0" conaffinity="0" group="1" rgba="0.792157 0.819608 0.933333 1" mesh="finger_proximal" />
                                            <geom type="mesh" rgba="0.792157 0.819608 0.933333 1" mesh="finger_proximal" />
                                            <body name="j2s7s300_link_finger_tip_3" pos="0.044 -0.003 0">
                                                <inertial pos="0.022 0 0" mass="0.01" diaginertia="7.89997e-07 7.89997e-07 8e-08" />
                                                <joint name="j2s7s300_joint_finger_tip_3" pos="0 0 0" axis="0 0 1" limited="true" range="0 2" />
                                                <geom type="mesh" contype="0" conaffinity="0" group="1" rgba="0.792157 0.819608 0.933333 1" mesh="finger_distal" />
                                                <geom type="mesh" rgba="0.792157 0.819608 0.933333 1" mesh="finger_distal" />
                                            </body>
                                        </body>
                                        -->
                                    </body>
                                </body>
                            </body>
                        </body>
                    </body>
                </body>
            </body>
        </body>
    </worldbody>
</mujoco>
