<mujoco model="onshape">
  <compiler angle="radian" meshdir="assets/"/>

  <size nkey="2"/>

  <visual>
    <global azimuth="120" elevation="-20" offwidth="1920" offheight="1080"/>
    <headlight ambient="0.3 0.3 0.3" diffuse="0.6 0.6 0.6" specular="0 0 0"/>
    <scale forcewidth="0.05" contactwidth="0.075" contactheight="0.025" com="0.05" framelength="0.2" framewidth="0.01"/>
    <rgba haze="0.15 0.25 0.35 1"/>
  </visual>

  <default>
    <default class="camera_visual">
      <geom type="mesh" contype="0" conaffinity="0" group="2"/>
    </default>
    <default class="camera_collision">
      <geom type="mesh" condim="6" group="3" friction="1 0.005 0.0005" solref="0.01"/>
    </default>
    <default class="yam">
      <joint frictionloss="0.1"/>
      <general biastype="affine" biasprm="0 -1"/>
      <default class="dm4340">
        <joint armature="0.032"/>
        <general forcerange="-28 28" gainprm="40" biasprm="0 -40 -2.5"/>
      </default>
      <default class="dm4310">
        <joint armature="0.0018"/>
        <general forcerange="-10 10" gainprm="10" biasprm="0 -10 -1"/>
      </default>
      <default class="visual">
        <geom type="mesh" contype="0" conaffinity="0" group="2" density="0" material="black"/>
      </default>
      <default class="collision">
        <geom type="capsule" group="3"/>
        <default class="sphere_collision">
          <geom size="0.0006 0 0" type="sphere" rgba="1 0 0 1"/>
        </default>
      </default>
      <default class="finger">
        <joint type="slide" armature="0.1"/>
        <general ctrlrange="0 0.041" gainprm="100" biasprm="0 -100 -10"/>
      </default>
    </default>
  </default>

  <asset>
    <texture type="skybox" colorspace="auto" builtin="gradient" rgb1="0.3 0.5 0.7" rgb2="0 0 0" width="512" height="3072"/>
    <texture type="2d" colorspace="auto" name="groundplane" builtin="checker" mark="edge" rgb1="0.2 0.3 0.4" rgb2="0.1 0.2 0.3" markrgb="0.8 0.8 0.8" width="300" height="300"/>
    <material name="groundplane" texture="groundplane" texuniform="true" texrepeat="5 5" reflectance="0.2"/>
    <material name="black" rgba="0.25 0.25 0.25 1"/>
    <material name="white" rgba="0.9 0.9 0.9 1"/>
    <mesh name="base_visual_gate" file="base_visual_gate.stl"/>
    <mesh name="camera_d405" file="d405.stl"/>
    <mesh name="model2" file="model2.stl"/>
    <mesh name="model2__2" file="model2__2.stl"/>
    <mesh name="model2__3" file="model2__3.stl"/>
    <mesh name="model2__4" file="model2__4.stl"/>
    <mesh name="model2__5" file="model2__5.stl"/>
    <mesh name="model2__6" file="model2__6.stl"/>
    <mesh name="model2__7" file="model2__7.stl"/>
    <mesh name="model2__8" file="model2__8.stl"/>
    <mesh name="model2__9" file="model2__9.stl"/>
    <mesh name="model2__10" file="model2__10.stl"/>
    <mesh name="model2__11" file="model2__11.stl"/>
    <mesh name="model2__12" file="model2__12.stl"/>
    <mesh name="model2__13" file="model2__13.stl"/>
    <mesh name="model2__14" file="model2__14.stl"/>
    <mesh name="model2__15" file="model2__15.stl"/>
    <mesh name="model2__16" file="model2__16.stl"/>
    <mesh name="model2__17" file="model2__17.stl"/>
  </asset>

  <worldbody>
    <geom name="floor" size="0 0 0.05" type="plane" material="groundplane"/>
    <light pos="0 0 1.5" dir="0 0 -1" type="directional"/>
    <geom type="mesh" contype="0" conaffinity="0" group="2" density="0" rgba="0.792157 0.819608 0.933333 1" mesh="base_visual_gate"/>
    <geom size="0.2975 0.65 0.375" pos="0 0 0.375" type="box" group="3" rgba="1 0 0 0.1"/>
    <body name="gate_collision" pos="0 0 0.75">
      <geom size="0.015 0.015 0.45" pos="0 0.575 0.45" type="box" group="3" rgba="1 0 0 0.1"/>
      <geom size="0.015 0.015 0.45" pos="0 -0.575 0.45" type="box" group="3" rgba="1 0 0 0.1"/>
      <geom size="0.015 0.015 0.59" pos="0 0 0.915" quat="0.707107 0.707107 0 0" type="box" group="3" rgba="1 0 0 0.1"/>
      <body name="top_bar_center" pos="0 0 0.915">
        <body name="top_camera_d405" pos="0.08600512 -0.009 0.03932053" quat="0.183012 0.683013 0.683013 0.183012">
          <geom class="camera_visual" mass="0" rgba="0.792157 0.819608 0.933333 1" mesh="camera_d405"/>
          <geom class="camera_collision" mesh="camera_d405"/>
          <body name="top_camera_frame" pos="0.009 0 0" quat="0 0 0 1">
              <camera name="top_camera_d405" pos="0 0 0" quat="0 1 0 0" resolution="1280 720" sensorsize="0.003896 0.00214" focal="0.00193 0.00193"/>
          </body>
        </body>
      </body>
    </body>
    <body name="play_table">
      <geom size="0.2975 0.65 0.005" pos="0.6 0 0.745" type="box" group="2" rgba="1 1 1 1"/>
    </body>
    <body name="left_arm" childclass="yam" pos="0.2525 0.31 0.75">
      <geom class="visual" pos="0 0 -0.0006" quat="0.707107 0 0 0.707107" material="black" mesh="model2"/>
      <geom class="collision" size="0.033 0.01" pos="0 0 0.026"/>
      <body name="left_link_1" pos="0 0 0.0631" quat="0.707107 0 0 0.707107">
        <inertial pos="-0.00192861 -0.00795735 0.0208176" quat="0.297851 0.642634 0.360045 0.607185" mass="0.12415" diaginertia="0.000180751 0.000145532 5.89179e-05"/>
        <joint name="left_joint1" class="dm4340" pos="0 0 0" axis="0 0 1" range="-2.61799 3.05433"/>
        <geom class="visual" pos="5.26159e-07 2.34355e-07 -0.0632" quat="1 0 0 0" material="black" mesh="model2__2"/>
        <body name="left_link_2" pos="2.5e-05 -0.02 0.0409" quat="0.5 0.5 0.5 0.5" gravcomp="1">
          <inertial pos="0.132008 2.10599e-06 0.000293073" quat="0.5 0.5 0.5 0.5" mass="1.24434" diaginertia="0.0121902 0.0121318 0.000683304"/>
          <joint name="left_joint2" class="dm4340" pos="0 0 0" axis="0 0 1" range="0 3.66519"/>
          <geom class="visual" pos="0.0199992 -0.1041 -2.44738e-05" quat="0.5 -0.5 -0.5 -0.5" material="black" mesh="model2__3"/>
          <geom class="visual" pos="0.0199992 -0.1041 -2.44738e-05" quat="0.5 -0.5 -0.5 -0.5" material="black" mesh="model2__4"/>
          <geom class="visual" pos="0.0199992 -0.1041 -2.44738e-05" quat="0.5 -0.5 -0.5 -0.5" material="white" mesh="model2__5"/>
          <geom class="collision" size="0.032 0.11" pos="0.13 0 0" quat="0.707107 0 0.707107 0"/>
          <geom class="collision" size="0.033 0.02"/>
          <geom class="collision" size="0.033 0.025" pos="0.265 0 0"/>
          <body name="left_link_3" pos="0.264 0 0" quat="0 1 0 0" gravcomp="1">
            <inertial pos="-0.121816 -0.054846 -0.000111108" quat="0.5 0.5 0.5 0.5" mass="0.853698" diaginertia="0.00699732 0.00696112 0.000788244"/>
            <joint name="left_joint3" class="dm4340" pos="0 0 0" axis="0 0 1" range="0 3.66519"/>
            <geom class="visual" pos="-0.244001 0.104101 2.44738e-05" quat="0.5 0.5 0.5 -0.5" material="black" mesh="model2__6"/>
            <geom class="visual" pos="-0.244001 0.104101 2.44738e-05" quat="0.5 0.5 0.5 -0.5" material="black" mesh="model2__7"/>
            <geom class="visual" pos="-0.244001 0.104101 2.44738e-05" quat="0.5 0.5 0.5 -0.5" material="white" mesh="model2__8"/>
            <geom class="visual" pos="-0.244001 0.104101 2.44738e-05" quat="0.5 0.5 0.5 -0.5" material="black" mesh="model2__9"/>
            <geom class="collision" size="0.034 0.12" pos="-0.14 -0.06 0" quat="0.707107 0 0.707107 0"/>
            <geom class="collision" size="0.034 0.015" pos="-0.24 -0.06 0"/>
            <body name="left_link_4" pos="-0.245 -0.06 0" gravcomp="1">
              <inertial pos="-0.0769778 -0.0527104 0.000154878" quat="0.66661 0.66661 -0.235862 -0.235862" mass="0.463511" diaginertia="0.000791532 0.000744733 0.000282116"/>
              <joint name="left_joint4" class="dm4310" pos="0 0 0" axis="0 0 1" range="-1.5708 1.5708"/>
              <geom class="visual" pos="0.00100023 0.164101 2.44738e-05" quat="0.5 0.5 0.5 -0.5" material="black" mesh="model2__10"/>
              <geom class="collision" size="0.03 0.015" pos="-0.073 -0.06 0" quat="0.707107 0.707107 0 0"/>
              <body name="left_link_5" pos="-0.074 -0.0395 2.5e-05" quat="0.5 -0.5 0.5 0.5" gravcomp="1">
                <inertial pos="3.64861e-05 0.00025665 0.0353526" mass="0.350962" diaginertia="0.000197802 0.0001775 0.000147402"/>
                <joint name="left_joint5" class="dm4310" pos="0 0 0" axis="0 0 1" range="-1.5708 1.5708"/>
                <geom class="visual" pos="0 -0.0749971 0.203601" quat="1.32679e-06 1 0 0" material="black" mesh="model2__11"/>
                <geom class="collision" size="0.03 0.015" pos="0 0.025 0.0395" quat="0.707107 0.707107 0 0"/>
                <body name="left_link_6" pos="0 0.0353 0.0395" quat="0.707107 -0.707107 0 0" gravcomp="1">
                  <inertial pos="-0.000217767 7.37059e-05 0.0270545" quat="0.707107 0.707107 0 0" mass="0.367476" diaginertia="0.000265958 0.000242686 0.000227409"/>
                  <joint name="left_joint6" class="dm4310" pos="0 0 0" axis="0 0 1" range="-2.0944 2.0944"/>
                  <geom class="visual" pos="0 -0.164101 -0.110597" quat="0.707107 -0.707107 0 0" material="black" mesh="model2__12"/>
                  <geom class="visual" pos="0 -0.164101 -0.110597" quat="0.707107 -0.707107 0 0" material="black" mesh="model2__13"/>
                  <geom class="collision" size="0.01 0.035" pos="0 0.039 0.052" quat="0.707107 0 0.707107 0"/>
                  <geom class="collision" size="0.03 0.005" pos="0 0 0.03" quat="0.707107 0 0 0.707107"/>
                  <geom class="collision" size="0.01 0.035" pos="0 -0.039 0.052" quat="0.707107 0 0.707107 0"/>
                  <body name="left_tcp" pos="0 0 0" quat="0 0 0 -1">
                    <site name="left_tcp_site" pos="0 0 0" rgba="1 0 0 1"/>
                    <site name="left_grasp_site" pos="0 0 0.1347" rgba="0 1 0 1"/>
                  </body>
                  <body name="left_left_link_finger" pos="-0.037 0.0392 0.0605" quat="0.707107 0 0.707107 0" gravcomp="1">
                    <inertial pos="-0.0192995 -0.0365902 0.039774" quat="0.757517 0.569023 -0.31997 0" mass="0.118" diaginertia="0.000159084 0.000154909 4.63655e-05"/>
                    <joint name="left_left_finger" class="finger" pos="0 0 0" axis="0 0 1" range="-0.00205 0.037524"/>
                    <geom class="visual" pos="0.171097 -0.203301 0.037" quat="0.5 -0.5 -0.5 -0.5" material="black" mesh="model2__14"/>
                    <geom class="visual" pos="0.171097 -0.203301 0.037" quat="0.5 -0.5 -0.5 -0.5" material="black" mesh="model2__15"/>
                    <body name="left_lf_rot" pos="0 -0.0392 0.037" quat="0.5 -0.5 -0.5 0.5" gravcomp="1">
                      <geom class="collision" size="0.01 0.03" pos="0 -0.02 0.012" quat="0.707107 0 0.707107 0" rgba="0.381493 0.492734 0.780446 1"/>
                      <geom class="collision" size="0.01 0.02" pos="-0.02 -0.01 0.032" quat="0.371391 0 0.928477 0" rgba="0.381493 0.492734 0.780446 1"/>
                      <body name="left_lf_down" pos="-0.044 0 0" gravcomp="1">
                        <geom class="collision" size="0.01 0.01" pos="0 -0.02 0.012" quat="0.995037 -0.0995037 0 0" rgba="0.381493 0.492734 0.780446 1"/>
                        <geom class="collision" size="0.003 0.022" pos="0.005 -0.014 0.04" quat="0.980581 -0.196116 0 0" rgba="0.381493 0.492734 0.780446 1"/>
                        <geom class="collision" size="0.003 0.022" pos="-0.005 -0.014 0.04" quat="0.980581 -0.196116 0 0" rgba="0.381493 0.492734 0.780446 1"/>
                        <geom class="collision" size="0.006 0.002 0.04" pos="0 -0.0024 0.046" type="box" rgba="0.381493 0.492734 0.780446 1"/>
                        <geom class="collision" size="0.006 0.002 0.039" pos="0.027 -0.0024 0.053" quat="0.371391 0 0.928477 0" type="box" rgba="0.381493 0.492734 0.780446 1"/>
                        <geom class="sphere_collision" pos="0.003 -0.0004 0.078"/>
                        <geom class="sphere_collision" pos="-0.003 -0.0004 0.078"/>
                        <geom class="sphere_collision" pos="0.003 -0.0004 0.07"/>
                        <geom class="sphere_collision" pos="-0.003 -0.0004 0.07"/>
                        <geom class="sphere_collision" pos="0.003 -0.0004 0.06"/>
                        <geom class="sphere_collision" pos="-0.003 -0.0004 0.06"/>
                      </body>
                    </body>
                  </body>
                  <body name="left_right_link_finger" pos="0.037 -0.0392 0.0605" quat="0.707107 0 0.707107 0" gravcomp="1">
                    <inertial pos="-0.0192995 0.0365902 -0.039774" quat="-0.757517 0.569023 -0.31997 0" mass="0.118" diaginertia="0.000159084 0.000154909 4.63655e-05"/>
                    <joint name="left_right_finger" class="finger" pos="0 0 0" axis="0 0 1" range="-0.037524 0.00205"/>
                    <geom class="visual" pos="0.171097 -0.124901 -0.037" quat="0.5 -0.5 -0.5 -0.5" material="black" mesh="model2__16"/>
                    <geom class="visual" pos="0.171097 -0.124901 -0.037" quat="0.5 -0.5 -0.5 -0.5" material="black" mesh="model2__17"/>
                    <body name="left_rf_rot" pos="0 0.0392 -0.037" quat="0.5 0.5 -0.5 -0.5" gravcomp="1">
                      <geom class="collision" size="0.01 0.03" pos="0 -0.02 0.012" quat="0.707107 0 0.707107 0" rgba="0.381493 0.492734 0.780446 1"/>
                      <geom class="collision" size="0.01 0.02" pos="0.02 -0.01 0.032" quat="0.371391 0 -0.928477 0" rgba="0.381493 0.492734 0.780446 1"/>
                      <body name="left_rf_down" pos="0.044 0 0" gravcomp="1">
                        <geom class="collision" size="0.01 0.01" pos="0 -0.02 0.012" quat="0.995037 -0.0995037 0 0" rgba="0.381493 0.492734 0.780446 1"/>
                        <geom class="collision" size="0.003 0.022" pos="0.005 -0.014 0.04" quat="0.980581 -0.196116 0 0" rgba="0.381493 0.492734 0.780446 1"/>
                        <geom class="collision" size="0.003 0.022" pos="-0.005 -0.014 0.04" quat="0.980581 -0.196116 0 0" rgba="0.381493 0.492734 0.780446 1"/>
                        <geom class="collision" size="0.006 0.002 0.04" pos="0 -0.0024 0.046" type="box" rgba="0.381493 0.492734 0.780446 1"/>
                        <geom class="collision" size="0.006 0.002 0.039" pos="-0.027 -0.0024 0.053" quat="0.371391 0 -0.928477 0" type="box" rgba="0.381493 0.492734 0.780446 1"/>
                        <geom class="sphere_collision" pos="0.003 -0.0004 0.078"/>
                        <geom class="sphere_collision" pos="-0.003 -0.0004 0.078"/>
                        <geom class="sphere_collision" pos="0.003 -0.0004 0.07"/>
                        <geom class="sphere_collision" pos="-0.003 -0.0004 0.07"/>
                        <geom class="sphere_collision" pos="0.003 -0.0004 0.06"/>
                        <geom class="sphere_collision" pos="-0.003 -0.0004 0.06"/>
                      </body>
                    </body>
                  </body>
                  <body name="left_camera_d405" pos="-0.0107 0.079729 0.066021" quat="0.953717 0.3007058 0 0">
                    <geom class="camera_visual" mass="0" rgba="0.792157 0.819608 0.933333 1" mesh="camera_d405"/>
                    <geom class="camera_collision" mesh="camera_d405"/>
                    <body name="left_camera_frame" pos="0.009 0 0" quat="0 0 0 1">
                        <camera name="left_camera_d405" pos="0 0 0" quat="0 1 0 0" resolution="1280 720" sensorsize="0.003896 0.00214" focal="0.00193 0.00193"/>
                    </body>
                  </body>
                </body>
              </body>
            </body>
          </body>
        </body>
      </body>
    </body>
    <body name="right_arm" childclass="yam" pos="0.2525 -0.31 0.75">
      <geom class="visual" pos="0 0 -0.0006" quat="0.707107 0 0 0.707107" material="black" mesh="model2"/>
      <geom class="collision" size="0.033 0.01" pos="0 0 0.026"/>
      <body name="right_link_1" pos="0 0 0.0631" quat="0.707107 0 0 0.707107">
        <inertial pos="-0.00192861 -0.00795735 0.0208176" quat="0.297851 0.642634 0.360045 0.607185" mass="0.12415" diaginertia="0.000180751 0.000145532 5.89179e-05"/>
        <joint name="right_joint1" class="dm4340" pos="0 0 0" axis="0 0 1" range="-2.61799 3.05433"/>
        <geom class="visual" pos="5.26159e-07 2.34355e-07 -0.0632" quat="1 0 0 0" material="black" mesh="model2__2"/>
        <body name="right_link_2" pos="2.5e-05 -0.02 0.0409" quat="0.5 0.5 0.5 0.5" gravcomp="1">
          <inertial pos="0.132008 2.10599e-06 0.000293073" quat="0.5 0.5 0.5 0.5" mass="1.24434" diaginertia="0.0121902 0.0121318 0.000683304"/>
          <joint name="right_joint2" class="dm4340" pos="0 0 0" axis="0 0 1" range="0 3.66519"/>
          <geom class="visual" pos="0.0199992 -0.1041 -2.44738e-05" quat="0.5 -0.5 -0.5 -0.5" material="black" mesh="model2__3"/>
          <geom class="visual" pos="0.0199992 -0.1041 -2.44738e-05" quat="0.5 -0.5 -0.5 -0.5" material="black" mesh="model2__4"/>
          <geom class="visual" pos="0.0199992 -0.1041 -2.44738e-05" quat="0.5 -0.5 -0.5 -0.5" material="white" mesh="model2__5"/>
          <geom class="collision" size="0.032 0.11" pos="0.13 0 0" quat="0.707107 0 0.707107 0"/>
          <geom class="collision" size="0.033 0.02"/>
          <geom class="collision" size="0.033 0.025" pos="0.265 0 0"/>
          <body name="right_link_3" pos="0.264 0 0" quat="0 1 0 0" gravcomp="1">
            <inertial pos="-0.121816 -0.054846 -0.000111108" quat="0.5 0.5 0.5 0.5" mass="0.853698" diaginertia="0.00699732 0.00696112 0.000788244"/>
            <joint name="right_joint3" class="dm4340" pos="0 0 0" axis="0 0 1" range="0 3.66519"/>
            <geom class="visual" pos="-0.244001 0.104101 2.44738e-05" quat="0.5 0.5 0.5 -0.5" material="black" mesh="model2__6"/>
            <geom class="visual" pos="-0.244001 0.104101 2.44738e-05" quat="0.5 0.5 0.5 -0.5" material="black" mesh="model2__7"/>
            <geom class="visual" pos="-0.244001 0.104101 2.44738e-05" quat="0.5 0.5 0.5 -0.5" material="white" mesh="model2__8"/>
            <geom class="visual" pos="-0.244001 0.104101 2.44738e-05" quat="0.5 0.5 0.5 -0.5" material="black" mesh="model2__9"/>
            <geom class="collision" size="0.034 0.12" pos="-0.14 -0.06 0" quat="0.707107 0 0.707107 0"/>
            <geom class="collision" size="0.034 0.015" pos="-0.24 -0.06 0"/>
            <body name="right_link_4" pos="-0.245 -0.06 0" gravcomp="1">
              <inertial pos="-0.0769778 -0.0527104 0.000154878" quat="0.66661 0.66661 -0.235862 -0.235862" mass="0.463511" diaginertia="0.000791532 0.000744733 0.000282116"/>
              <joint name="right_joint4" class="dm4310" pos="0 0 0" axis="0 0 1" range="-1.5708 1.5708"/>
              <geom class="visual" pos="0.00100023 0.164101 2.44738e-05" quat="0.5 0.5 0.5 -0.5" material="black" mesh="model2__10"/>
              <geom class="collision" size="0.03 0.015" pos="-0.073 -0.06 0" quat="0.707107 0.707107 0 0"/>
              <body name="right_link_5" pos="-0.074 -0.0395 2.5e-05" quat="0.5 -0.5 0.5 0.5" gravcomp="1">
                <inertial pos="3.64861e-05 0.00025665 0.0353526" mass="0.350962" diaginertia="0.000197802 0.0001775 0.000147402"/>
                <joint name="right_joint5" class="dm4310" pos="0 0 0" axis="0 0 1" range="-1.5708 1.5708"/>
                <geom class="visual" pos="0 -0.0749971 0.203601" quat="1.32679e-06 1 0 0" material="black" mesh="model2__11"/>
                <geom class="collision" size="0.03 0.015" pos="0 0.025 0.0395" quat="0.707107 0.707107 0 0"/>
                <body name="right_link_6" pos="0 0.0353 0.0395" quat="0.707107 -0.707107 0 0" gravcomp="1">
                  <inertial pos="-0.000217767 7.37059e-05 0.0270545" quat="0.707107 0.707107 0 0" mass="0.367476" diaginertia="0.000265958 0.000242686 0.000227409"/>
                  <joint name="right_joint6" class="dm4310" pos="0 0 0" axis="0 0 1" range="-2.0944 2.0944"/>
                  <geom class="visual" pos="0 -0.164101 -0.110597" quat="0.707107 -0.707107 0 0" material="black" mesh="model2__12"/>
                  <geom class="visual" pos="0 -0.164101 -0.110597" quat="0.707107 -0.707107 0 0" material="black" mesh="model2__13"/>
                  <geom class="collision" size="0.01 0.035" pos="0 0.039 0.052" quat="0.707107 0 0.707107 0"/>
                  <geom class="collision" size="0.03 0.005" pos="0 0 0.03" quat="0.707107 0 0 0.707107"/>
                  <geom class="collision" size="0.01 0.035" pos="0 -0.039 0.052" quat="0.707107 0 0.707107 0"/>
                  <body name="right_tcp" pos="0 0 0" quat="0 0 0 -1">
                    <site name="right_tcp_site" pos="0 0 0" rgba="1 0 0 1"/>
                    <site name="right_grasp_site" pos="0 0 0.1347" rgba="0 1 0 1"/>
                  </body>
                  <body name="right_left_link_finger" pos="-0.037 0.0392 0.0605" quat="0.707107 0 0.707107 0" gravcomp="1">
                    <inertial pos="-0.0192995 -0.0365902 0.039774" quat="0.757517 0.569023 -0.31997 0" mass="0.118" diaginertia="0.000159084 0.000154909 4.63655e-05"/>
                    <joint name="right_left_finger" class="finger" pos="0 0 0" axis="0 0 1" range="-0.00205 0.037524"/>
                    <geom class="visual" pos="0.171097 -0.203301 0.037" quat="0.5 -0.5 -0.5 -0.5" material="black" mesh="model2__14"/>
                    <geom class="visual" pos="0.171097 -0.203301 0.037" quat="0.5 -0.5 -0.5 -0.5" material="black" mesh="model2__15"/>
                    <body name="right_lf_rot" pos="0 -0.0392 0.037" quat="0.5 -0.5 -0.5 0.5" gravcomp="1">
                      <geom class="collision" size="0.01 0.03" pos="0 -0.02 0.012" quat="0.707107 0 0.707107 0" rgba="0.381493 0.492734 0.780446 1"/>
                      <geom class="collision" size="0.01 0.02" pos="-0.02 -0.01 0.032" quat="0.371391 0 0.928477 0" rgba="0.381493 0.492734 0.780446 1"/>
                      <body name="right_lf_down" pos="-0.044 0 0" gravcomp="1">
                        <geom class="collision" size="0.01 0.01" pos="0 -0.02 0.012" quat="0.995037 -0.0995037 0 0" rgba="0.381493 0.492734 0.780446 1"/>
                        <geom class="collision" size="0.003 0.022" pos="0.005 -0.014 0.04" quat="0.980581 -0.196116 0 0" rgba="0.381493 0.492734 0.780446 1"/>
                        <geom class="collision" size="0.003 0.022" pos="-0.005 -0.014 0.04" quat="0.980581 -0.196116 0 0" rgba="0.381493 0.492734 0.780446 1"/>
                        <geom class="collision" size="0.006 0.002 0.04" pos="0 -0.0024 0.046" type="box" rgba="0.381493 0.492734 0.780446 1"/>
                        <geom class="collision" size="0.006 0.002 0.039" pos="0.027 -0.0024 0.053" quat="0.371391 0 0.928477 0" type="box" rgba="0.381493 0.492734 0.780446 1"/>
                        <geom class="sphere_collision" pos="0.003 -0.0004 0.078"/>
                        <geom class="sphere_collision" pos="-0.003 -0.0004 0.078"/>
                        <geom class="sphere_collision" pos="0.003 -0.0004 0.07"/>
                        <geom class="sphere_collision" pos="-0.003 -0.0004 0.07"/>
                        <geom class="sphere_collision" pos="0.003 -0.0004 0.06"/>
                        <geom class="sphere_collision" pos="-0.003 -0.0004 0.06"/>
                      </body>
                    </body>
                  </body>
                  <body name="right_right_link_finger" pos="0.037 -0.0392 0.0605" quat="0.707107 0 0.707107 0" gravcomp="1">
                    <inertial pos="-0.0192995 0.0365902 -0.039774" quat="-0.757517 0.569023 -0.31997 0" mass="0.118" diaginertia="0.000159084 0.000154909 4.63655e-05"/>
                    <joint name="right_right_finger" class="finger" pos="0 0 0" axis="0 0 1" range="-0.037524 0.00205"/>
                    <geom class="visual" pos="0.171097 -0.124901 -0.037" quat="0.5 -0.5 -0.5 -0.5" material="black" mesh="model2__16"/>
                    <geom class="visual" pos="0.171097 -0.124901 -0.037" quat="0.5 -0.5 -0.5 -0.5" material="black" mesh="model2__17"/>
                    <body name="right_rf_rot" pos="0 0.0392 -0.037" quat="0.5 0.5 -0.5 -0.5" gravcomp="1">
                      <geom class="collision" size="0.01 0.03" pos="0 -0.02 0.012" quat="0.707107 0 0.707107 0" rgba="0.381493 0.492734 0.780446 1"/>
                      <geom class="collision" size="0.01 0.02" pos="0.02 -0.01 0.032" quat="0.371391 0 -0.928477 0" rgba="0.381493 0.492734 0.780446 1"/>
                      <body name="right_rf_down" pos="0.044 0 0" gravcomp="1">
                        <geom class="collision" size="0.01 0.01" pos="0 -0.02 0.012" quat="0.995037 -0.0995037 0 0" rgba="0.381493 0.492734 0.780446 1"/>
                        <geom class="collision" size="0.003 0.022" pos="0.005 -0.014 0.04" quat="0.980581 -0.196116 0 0" rgba="0.381493 0.492734 0.780446 1"/>
                        <geom class="collision" size="0.003 0.022" pos="-0.005 -0.014 0.04" quat="0.980581 -0.196116 0 0" rgba="0.381493 0.492734 0.780446 1"/>
                        <geom class="collision" size="0.006 0.002 0.04" pos="0 -0.0024 0.046" type="box" rgba="0.381493 0.492734 0.780446 1"/>
                        <geom class="collision" size="0.006 0.002 0.039" pos="-0.027 -0.0024 0.053" quat="0.371391 0 -0.928477 0" type="box" rgba="0.381493 0.492734 0.780446 1"/>
                        <geom class="sphere_collision" pos="0.003 -0.0004 0.078"/>
                        <geom class="sphere_collision" pos="-0.003 -0.0004 0.078"/>
                        <geom class="sphere_collision" pos="0.003 -0.0004 0.07"/>
                        <geom class="sphere_collision" pos="-0.003 -0.0004 0.07"/>
                        <geom class="sphere_collision" pos="0.003 -0.0004 0.06"/>
                        <geom class="sphere_collision" pos="-0.003 -0.0004 0.06"/>
                      </body>
                    </body>
                  </body>
                  <body name="right_camera_d405" pos="-0.0107 0.079729 0.066021" quat="0.953717 0.3007058 0 0">
                    <geom class="camera_visual" mass="0" rgba="0.792157 0.819608 0.933333 1" mesh="camera_d405"/>
                    <geom class="camera_collision" mesh="camera_d405"/>
                    <body name="right_camera_frame" pos="0.009 0 0" quat="0 0 0 1">
                        <camera name="right_camera_d405" pos="0 0 0" quat="0 1 0 0" resolution="1280 720" sensorsize="0.003896 0.00214" focal="0.00193 0.00193"/>
                    </body>
                  </body>
                </body>
              </body>
            </body>
          </body>
        </body>
      </body>
    </body>
  </worldbody>

  <equality>
    <joint joint1="left_left_finger" joint2="left_right_finger" polycoef="0 -1 0 0 0"/>
    <joint joint1="right_left_finger" joint2="right_right_finger" polycoef="0 -1 0 0 0"/>
  </equality>

  <actuator>
    <general name="left_joint1" class="dm4340" joint="left_joint1" ctrlrange="-2.61799 3.05433"/>
    <general name="left_joint2" class="dm4340" joint="left_joint2" ctrlrange="0 3.66519"/>
    <general name="left_joint3" class="dm4340" joint="left_joint3" ctrlrange="0 3.66519"/>
    <general name="left_joint4" class="dm4310" joint="left_joint4" ctrlrange="-1.5708 1.5708" gainprm="20" biasprm="0 -20 -0.5"/>
    <general name="left_joint5" class="dm4310" joint="left_joint5" ctrlrange="-1.5708 1.5708"/>
    <general name="left_joint6" class="dm4310" joint="left_joint6" ctrlrange="-2.0944 2.0944"/>
    <general name="left_gripper" class="finger" joint="left_left_finger"/>
    <general name="right_joint1" class="dm4340" joint="right_joint1" ctrlrange="-2.61799 3.05433"/>
    <general name="right_joint2" class="dm4340" joint="right_joint2" ctrlrange="0 3.66519"/>
    <general name="right_joint3" class="dm4340" joint="right_joint3" ctrlrange="0 3.66519"/>
    <general name="right_joint4" class="dm4310" joint="right_joint4" ctrlrange="-1.5708 1.5708" gainprm="20" biasprm="0 -20 -0.5"/>
    <general name="right_joint5" class="dm4310" joint="right_joint5" ctrlrange="-1.5708 1.5708"/>
    <general name="right_joint6" class="dm4310" joint="right_joint6" ctrlrange="-2.0944 2.0944"/>
    <general name="right_gripper" class="finger" joint="right_left_finger"/>
  </actuator>
</mujoco>
